Workbook
Name _Z99999: [1]Cliente!#REF!
Name _ZZ99: [1]Cliente!#REF!
Name capacidade: [2]Dados!$F$11
Name CERTIFICADO: [1]Cliente!$Y$8
Name data_receb: [2]Dados!$E$7
Name DATA_RECEBIMENTO: [1]Cliente!#REF!
Name ENTRADA: [1]Cliente!#REF!
Name equip: [2]Dados!$C$10
Name n_cert: [2]Dados!$C$8
Name n_ident: [2]Dados!$C$13
Name n_serie: [2]Dados!$C$14
Name pressão: [2]Dados!$D$27
Name proced: [2]Dados!$F$13
Name resolução: [2]Dados!$F$10
Name temp_ar: [2]Dados!$D$25
Name temp_carr: #REF!
Name umid: [2]Dados!#REF!
Name unid_e: [2]Dados!$D$31
Name versão: [2]Dados!$F$14

Sheet Cadastro dos Padrões
A1: 1 | B1: =A1+1 -> 2 | C1: =B1+1 -> 3 | D1: =C1+1 -> 4 | E1: =D1+1 -> 5 | F1: =E1+1 -> 6 | G1: =F1+1 -> 7 | H1: =G1+1 -> 8 | I1: =H1+1 -> 9 | ... V1: =U1+1 -> 22
A2: =ROUND(CONCATENATE(U2,V2),0) -> 1201 | B2: Padrão : | D2: Balança Eletrônica | U2: 1 | V2: 201
A3: =ROUND(CONCATENATE(U3,V3),0) -> 1202 | B3: Unidade de calibrada : | D3: g | E3: Resolução : | G3: 0.01 | H3: =IF(D4="","",D3) -> g | U3: =U2 -> 1 | V3: =V2+1 -> 202
A4: =ROUND(CONCATENATE(U4,V4),0) -> 1203 | B4: Identificação : | D4: E.MS.LQ-003 | K4: X8 | L4: X7 | M4: X6 | N4: X5 | O4: X4 | P4: X3 | Q4: X2 | R4: X1 | S4: X0 | U4: =U3 -> 1 | V4: =V3+1 -> 203 | X4: mg
A5: =ROUND(CONCATENATE(U5,V5),0) -> 1204 | B5: Orgão Calibrador : | D5: Elus | J5: =COUNTA(B17:B26) -> 7 | K5: =IF(L5-1<2,0,L5-1) -> 0 | L5: =IF(M5-1<2,0,M5-1) -> 0 | M5: =IF(N5-1<2,0,N5-1) -> 0 | N5: =IF(O5-1<2,0,O5-1) -> 2 | O5: =IF(P5-1<2,0,P5-1) -> 3 | P5: =IF(Q5-1<2,0,Q5-1) -> 4 | Q5: =IF(R5-1<2,0,R5-1) -> 5 | R5: =IF(S5-1<2,0,S5-1) -> 6 | S5: =J5 -> 7 | U5: =U4 -> 1 | V5: =V4+1 -> 204 | X5: g
A6: =ROUND(CONCATENATE(U6,V6),0) -> 1205 | B6: Rastreabilidade : | D6: RBC - CAL 0439 | J6: =CONCATENATE(J5,1) -> 71 | K6: =IF(K5=0,0,VLOOKUP(J6,J10:S40,K5,FALSE)) -> 0 | L6: =IF(L5=0,0,VLOOKUP(J6,J10:S40,L5,FALSE)) -> 0 | M6: =IF(M5=0,0,VLOOKUP(J6,J10:S40,M5,FALSE)) -> 0 | N6: =IF(N5=0,0,VLOOKUP(J6,J10:S40,N5,FALSE)) -> -2.1946624e-17 | O6: =IF(O5=0,0,VLOOKUP(J6,J10:S40,O5,FALSE)) -> 1.4356681e-13 | P6: =IF(P5=0,0,VLOOKUP(J6,J10:S40,P5,FALSE)) -> -3.2116745e-10 | Q6: =IF(Q5=0,0,VLOOKUP(J6,J10:S40,Q5,FALSE)) -> 3.130729e-07 | R6: =IF(R5=0,0,VLOOKUP(J6,J10:S40,R5,FALSE)) -> 0.99986579 | S6: =IF(S5=0,0,VLOOKUP(J6,J10:S40,S5,FALSE)) -> 0.00068337238 | U6: =U5 -> 1 | V6: =V5+1 -> 205 | X6: kg
A7: =ROUND(CONCATENATE(U7,V7),0) -> 1206 | B7: N° do certificado : | D7: E0011/26 | J7: =CONCATENATE(J5,2) -> 72 | K7: =IF(K5=0,0,VLOOKUP(J7,J10:S40,K5,FALSE)) -> 0 | L7: =IF(L5=0,0,VLOOKUP(J7,J10:S40,L5,FALSE)) -> 0 | M7: =IF(M5=0,0,VLOOKUP(J7,J10:S40,M5,FALSE)) -> 0 | N7: =IF(N5=0,0,VLOOKUP(J7,J10:S40,N5,FALSE)) -> 1.2284161e-17 | O7: =IF(O5=0,0,VLOOKUP(J7,J10:S40,O5,FALSE)) -> 5.9398576e-14 | P7: =IF(P5=0,0,VLOOKUP(J7,J10:S40,P5,FALSE)) -> 1.000214e-10 | Q7: =IF(Q5=0,0,VLOOKUP(J7,J10:S40,Q5,FALSE)) -> 6.8955532e-08 | R7: =IF(R5=0,0,VLOOKUP(J7,J10:S40,R5,FALSE)) -> 1.6840579e-05 | S7: =IF(S5=0,0,VLOOKUP(J7,J10:S40,S5,FALSE)) -> 0.00064401317 | U7: =U6 -> 1 | V7: =V6+1 -> 206 | X7: t
A8: =ROUND(CONCATENATE(U8,V8),0) -> 1207 | B8: Data da Calibração : | D8: 46031 | J8: =CONCATENATE(J5,3) -> 73 | N8: Veff curva = | O8: =J5-2 -> 5 | P8: Residuo = | Q8: =VLOOKUP(J8,J10:S40,3,FALSE) -> 0.00083868147 | R8: R² = | S8: =VLOOKUP(J8,J10:S40,2,FALSE) -> 1 | U8: =U7 -> 1 | V8: =V7+1 -> 207
A9: =ROUND(CONCATENATE(U9,V9),0) -> 1208 | B9: Vencimento da Calibração : | D9: 46417 | K9: 3 | L9: 3 | U9: =U8 -> 1 | V9: =V8+1 -> 208
A10: =ROUND(CONCATENATE(U10,V10),0) -> 1209 | B10: Faixa calibrada : | D10: =IF(D3="","",MIN(B17:B26)) -> 1 | E10: ~ | F10: =IF(D3="","",MAX(B17:B26)) -> 2000 | G10: =IF(D4="","",H3) -> g | J10: =CONCATENATE(K9,1) -> 31 | K10: {=LINEST(B17:B19,C17:C19^{1},TRUE,TRUE)} -> 0.99989491 | L10: 0.00055549995 | U10: =U9 -> 1 | V10: =V9+1 -> 209
A11: =ROUND(CONCATENATE(U11,V11),0) -> 1210 | J11: =CONCATENATE(K9,2) -> 32 | K11: 8.667101e-06 | L11: 0.00050296574 | U11: =U10 -> 1 | V11: =V10+1 -> 210
A12: =ROUND(CONCATENATE(U12,V12),0) -> 1211 | B12: Valores da Calibração Atual | G12: Calibração Anterior | J12: =CONCATENATE(K9,3) -> 33 | K12: 1 | L12: 0.00067108552 | U12: =U11 -> 1 | V12: =V11+1 -> 211
A13: =ROUND(CONCATENATE(U13,V13),0) -> 1212 | B13: Certificado de calibração : | E13: =D7 -> E0011/26 | G13: Certificado : | H13: R0011/25 | K13: 4 | L13: 4 | M13: 4 | U13: =U12 -> 1 | V13: =V12+1 -> 212
A14: =ROUND(CONCATENATE(U14,V14),0) -> 1213 | B14: Valor de referência | C14: Indicação do instrumento | D14: Incerteza de medição | E14: k | F14: Veff | G14: Valor de referência | H14: Indicação do instrumento | J14: =CONCATENATE(K13,1) -> 41 | K14: {=LINEST(B17:B20,C17:C20^{1,2},TRUE,TRUE)} -> 1.6099298e-07 | L14: 0.99987824 | M14: 0.00063096473 | U14: =U13 -> 1 | V14: =V13+1 -> 213
A15: =ROUND(CONCATENATE(U15,V15),0) -> 1214 | J15: =CONCATENATE(K13,2) -> 42 | K15: 2.3580717e-08 | L15: 1.2342701e-05 | M15: 0.00058186669 | U15: =U14 -> 1 | V15: =V14+1 -> 214
A16: =ROUND(CONCATENATE(U16,V16),0) -> 1215 | B16: =CONCATENATE("(",H3,")") -> (g) | C16: =B16 -> (g) | D16: =C16 -> (g) | G16: =B16 -> (g) | H16: =G16 -> (g) | J16: =CONCATENATE(K13,3) -> 43 | K16: 1 | L16: 0.00076749922 | M16: #N/A | U16: =U15 -> 1 | V16: =V15+1 -> 215
A17: =ROUND(CONCATENATE(U17,V17),0) -> 1216 | B17: 1 | C17: 1 | D17: 0.02 | E17: 2 | F17: 1000000 | G17: 1 | H17: 1 | K17: 5 | L17: 5 | M17: 5 | N17: 5 | U17: =U16 -> 1 | V17: =V16+1 -> 216
A18: =ROUND(CONCATENATE(U18,V18),0) -> 1217 | B18: 10 | C18: 10 | D18: 0.02 | E18: 2 | F18: 1000000 | G18: 10 | H18: 10 | J18: =CONCATENATE(K17,1) -> 51 | K18: {=LINEST(B17:B21,C17:C21^{1,2,3},TRUE,TRUE)} -> -1.3331322e-10 | L18: 2.4131471e-07 | M18: 0.99987134 | N18: 0.00066080973 | U18: =U17 -> 1 | V18: =V17+1 -> 217
A19: =ROUND(CONCATENATE(U19,V19),0) -> 1218 | B19: 100 | C19: 100.01 | D19: 0.02 | E19: 2 | F19: 1000000 | G19: 100 | H19: 100.02 | J19: =CONCATENATE(K17,2) -> 52 | K19: 2.7804464e-11 | L19: 4.1476258e-08 | M19: 1.4382454e-05 | N19: 0.00061529876 | U19: =U18 -> 1 | V19: =V18+1 -> 218
A20: =ROUND(CONCATENATE(U20,V20),0) -> 1219 | B20: 500 | C20: 500.02 | D20: 0.02 | E20: 2 | F20: 1000000 | G20: 500 | H20: 500.02 | J20: =CONCATENATE(K17,3) -> 53 | K20: 1 | L20: 0.00080688331 | M20: #N/A | N20: #N/A | U20: =U19 -> 1 | V20: =V19+1 -> 219
A21: =ROUND(CONCATENATE(U21,V21),0) -> 1220 | B21: 1000 | C21: 1000.02 | D21: 0.03 | E21: 2 | F21: 574 | G21: 1000 | H21: 1000.02 | K21: 6 | L21: 6 | M21: 6 | N21: 6 | O21: 6 | U21: =U20 -> 1 | V21: =V20+1 -> 220
A22: =ROUND(CONCATENATE(U22,V22),0) -> 1221 | B22: 1500 | C22: 1500.02 | D22: 0.04 | E22: 2 | F22: 1000000 | G22: 1500 | H22: 1500.01 | J22: =CONCATENATE(K21,1) -> 61 | K22: {=LINEST(B17:B22,C17:C22^{1,2,3,4},TRUE,TRUE)} -> 7.5578592e-14 | L22: -2.5434427e-10 | M22: 2.906419e-07 | N22: 0.99986745 | O22: 0.0006771054 | U22: =U21 -> 1 | V22: =V21+1 -> 221
A23: =ROUND(CONCATENATE(U23,V23),0) -> 1222 | B23: 2000 | C23: 1999.99 | D23: 0.05 | E23: 2 | F23: 1000000 | G23: 2000 | H23: 2000 | J23: =CONCATENATE(K21,2) -> 62 | K23: 2.1276966e-14 | L23: 6.2493042e-11 | M23: 5.6261885e-08 | N23: 1.5814433e-05 | O23: 0.00063470969 | U23: =U22 -> 1 | V23: =V22+1 -> 222
A24: =ROUND(CONCATENATE(U24,V24),0) -> 1223 | J24: =CONCATENATE(K21,3) -> 63 | K24: 1 | L24: 0.00082905973 | M24: #N/A | N24: #N/A | O24: #N/A | U24: =U23 -> 1 | V24: =V23+1 -> 223
A25: =ROUND(CONCATENATE(U25,V25),0) -> 1224 | K25: 7 | L25: 7 | M25: 7 | N25: 7 | O25: 7 | P25: 7 | U25: =U24 -> 1 | V25: =V24+1 -> 224
A26: =ROUND(CONCATENATE(U26,V26),0) -> 1225 | J26: =CONCATENATE(K25,1) -> 71 | K26: {=LINEST(B17:B23,C17:C23^{1,2,3,4,5},TRUE,TRUE)} -> -2.1946624e-17 | L26: 1.4356681e-13 | M26: -3.2116745e-10 | N26: 3.130729e-07 | O26: 0.99986579 | P26: 0.00068337238 | U26: =U25 -> 1 | V26: =V25+1 -> 225
A27: =ROUND(CONCATENATE(U27,V27),0) -> 1226 | B27: Excentricidade | J27: =CONCATENATE(K25,2) -> 72 | K27: 1.2284161e-17 | L27: 5.9398576e-14 | M27: 1.000214e-10 | N27: 6.8955532e-08 | O27: 1.6840579e-05 | P27: 0.00064401317 | U27: =U26 -> 1 | V27: =V26+1 -> 226
A28: =ROUND(CONCATENATE(U28,V28),0) -> 1227 | B28: Valor de ref. | C28: M | D28: A | E28: B | F28: C | G28: D | H28: M | J28: =CONCATENATE(K25,3) -> 73 | K28: 1 | L28: 0.00083868147 | M28: #N/A | N28: #N/A | O28: #N/A | P28: #N/A | U28: =U27 -> 1 | V28: =V27+1 -> 227
A29: =ROUND(CONCATENATE(U29,V29),0) -> 1228 | B29: 500 | C29: 500.02 | D29: 500.01 | E29: 500.01 | F29: 500.02 | G29: 499.99 | H29: 500.02 | K29: 8 | L29: 8 | M29: 8 | N29: 8 | O29: 8 | P29: 8 | Q29: 8 | U29: =U28 -> 1 | V29: =V28+1 -> 228
A30: =ROUND(CONCATENATE(U30,V30),0) -> 1229 | J30: =CONCATENATE(K29,1) -> 81 | K30: {=LINEST(B17:B24,C17:C24^{1,2,3,4,5,6},TRUE,TRUE)} -> #VALUE! | L30: #VALUE! | M30: #VALUE! | N30: #VALUE! | O30: #VALUE! | P30: #VALUE! | Q30: #VALUE! | U30: =U29 -> 1 | V30: =V29+1 -> 229
A31: =ROUND(CONCATENATE(U31,V31),0) -> 1230 | B31: Observações (particularidades para utilização) | J31: =CONCATENATE(K29,2) -> 82 | K31: #VALUE! | L31: #VALUE! | M31: #VALUE! | N31: #VALUE! | O31: #VALUE! | P31: #VALUE! | Q31: #VALUE! | U31: =U30 -> 1 | V31: =V30+1 -> 230
A32: =ROUND(CONCATENATE(U32,V32),0) -> 1231 | J32: =CONCATENATE(K29,3) -> 83 | K32: #VALUE! | L32: #VALUE! | M32: #VALUE! | N32: #VALUE! | O32: #VALUE! | P32: #VALUE! | Q32: #VALUE! | U32: =U31 -> 1 | V32: =V31+1 -> 231
A33: =ROUND(CONCATENATE(U33,V33),0) -> 1232 | K33: 9 | L33: 9 | M33: 9 | N33: 9 | O33: 9 | P33: 9 | Q33: 9 | R33: 9 | U33: =U32 -> 1 | V33: =V32+1 -> 232
A34: =ROUND(CONCATENATE(U34,V34),0) -> 1233 | J34: =CONCATENATE(K33,1) -> 91 | K34: {=LINEST(B17:B25,C17:C25^{1,2,3,4,5,6,7},TRUE,TRUE)} -> #VALUE! | L34: #VALUE! | M34: #VALUE! | N34: #VALUE! | O34: #VALUE! | P34: #VALUE! | Q34: #VALUE! | R34: #VALUE! | U34: =U33 -> 1 | V34: =V33+1 -> 233
A35: =ROUND(CONCATENATE(U35,V35),0) -> 1234 | B35: Erro Atual | C35: Erro Anterior | D35: Diferença | E35: Incerteza (un) | F35: Maior Deriva | J35: =CONCATENATE(K33,2) -> 92 | K35: #VALUE! | L35: #VALUE! | M35: #VALUE! | N35: #VALUE! | O35: #VALUE! | P35: #VALUE! | Q35: #VALUE! | R35: #VALUE! | U35: =U34 -> 1 | V35: =V34+1 -> 234
A36: =ROUND(CONCATENATE(U36,V36),0) -> 1235 | B36: =C17-B17 -> 0 | C36: =H17-G17 -> 0 | D36: =C36-B36 -> 0 | E36: =D17 -> 0.02 | F36: =IF(D4="","",MAX(G36,H36)) -> 0.01 | G36: =ABS(MIN(D36:D45)) -> 0.01 | H36: =ABS(MAX(D36:D45)) -> 0.01 | J36: =CONCATENATE(K33,3) -> 93 | K36: #VALUE! | L36: #VALUE! | M36: #VALUE! | N36: #VALUE! | O36: #VALUE! | P36: #VALUE! | Q36: #VALUE! | R36: #VALUE! | U36: =U35 -> 1 | V36: =V35+1 -> 235
A37: =ROUND(CONCATENATE(U37,V37),0) -> 1236 | B37: =C18-B18 -> 0 | C37: =H18-G18 -> 0 | D37: =C37-B37 -> 0 | E37: =D18 -> 0.02 | F37: Desvio Máximo | K37: 10 | L37: 10 | M37: 10 | N37: 10 | O37: 10 | P37: 10 | Q37: 10 | R37: 10 | S37: 10 | U37: =U36 -> 1 | V37: =V36+1 -> 236
A38: =ROUND(CONCATENATE(U38,V38),0) -> 1237 | B38: =C19-B19 -> 0.01 | C38: =H19-G19 -> 0.02 | D38: =C38-B38 -> 0.01 | E38: =D19 -> 0.02 | F38: =IF(D4="","",MAX(G38,H38)) -> 0.02 | G38: =ABS(MIN(B36:B45)) -> 0.01 | H38: =ABS(MAX(B36:B45)) -> 0.02 | J38: =CONCATENATE(K37,1) -> 101 | K38: {=LINEST(B17:B26,C17:C26^{1,2,3,4,5,6,7,8},TRUE,TRUE)} -> #VALUE! | L38: #VALUE! | M38: #VALUE! | N38: #VALUE! | O38: #VALUE! | P38: #VALUE! | Q38: #VALUE! | R38: #VALUE! | S38: #VALUE! | U38: =U37 -> 1 | V38: =V37+1 -> 237
A39: =ROUND(CONCATENATE(U39,V39),0) -> 1238 | B39: =C20-B20 -> 0.02 | C39: =H20-G20 -> 0.02 | D39: =C39-B39 -> 0 | E39: =D20 -> 0.02 | F39: Maior incerteza (em unidade) | J39: =CONCATENATE(K37,2) -> 102 | K39: #VALUE! | L39: #VALUE! | M39: #VALUE! | N39: #VALUE! | O39: #VALUE! | P39: #VALUE! | Q39: #VALUE! | R39: #VALUE! | S39: #VALUE! | U39: =U38 -> 1 | V39: =V38+1 -> 238
A40: =ROUND(CONCATENATE(U40,V40),0) -> 1239 | B40: =C21-B21 -> 0.02 | C40: =H21-G21 -> 0.02 | D40: =C40-B40 -> 0 | E40: =D21 -> 0.03 | F40: =IF(D4="","",MAX(G40,H40)) -> 0.05 | G40: =ABS(MIN(E36:E45)) -> 0 | H40: =ABS(MAX(E36:E45)) -> 0.05 | J40: =CONCATENATE(K37,3) -> 103 | K40: #VALUE! | L40: #VALUE! | M40: #VALUE! | N40: #VALUE! | O40: #VALUE! | P40: #VALUE! | Q40: #VALUE! | R40: #VALUE! | S40: #VALUE! | U40: =U39 -> 1 | V40: =V39+1 -> 239
...

Sheet Controle
B1: 4 | C1: 4 | D1: 4 | E1: 4 | F1: 4 | G1: 4 | H1: 4 | I1: 4 | J1: 4 | K1: 6 | L1: 7 | M1: 6 | N1: 6 | O1: 6 | P1: 6 | Q1: 17 | R1: 15 | S1: 11 | T1: 12 | U1: 13 | V1: 14 | W1: 15 | X1: 16 | Y1: 17 | Z1: 18 | AA1: 19 | AB1: 2 | AC1: 4 | AD1: 5 | AE1: 6 | AF1: 2 | AG1: 4 | AH1: 5 | AI1: 6 | AJ1: 2 | AK1: 4 | AL1: 5 | AM1: 6 | AN1: 2 | AO1: 4 | AP1: 5 | AQ1: 6 | AR1: 2 | AS1: 4 | AT1: 5 | AU1: 6 | AV1: 2 | AW1: 4 | AX1: 5 | AY1: 6 | AZ1: 2 | BA1: 4 | BB1: 5 | BC1: 6 | BD1: 2 | BE1: 4 | BF1: 5 | BG1: 6 | BH1: 2 | BI1: 4 | BJ1: 5 | BK1: 6 | BL1: 2 | BM1: 4 | BN1: 5 | BO1: 6 | BP1: 2 | BQ1: 2 | BR1: 2 | BS1: 2 | BT1: 2 | BU1: 2 | BV1: 2 | BW1: 2 | BX1: 2 | BY1: 2 | BZ1: 4 | CA1: 4 | CB1: 4 | CC1: 4 | CD1: 4 | CE1: 4 | CF1: 4 | CG1: 4 | CH1: 4 | CI1: 4
B2: 203 | C2: 201 | D2: 204 | E2: 205 | F2: 206 | G2: 207 | H2: 208 | I2: 202 | J2: 209 | K2: 209 | L2: 202 | M2: 237 | N2: 239 | O2: 235 | P2: 243 | Q2: 207 | R2: 207 | S2: 205 | T2: 205 | U2: 205 | V2: 205 | W2: 205 | X2: 205 | Y2: 205 | Z2: 205 | AA2: 205 | AB2: 216 | AC2: =AB2 -> 216 | AD2: =AC2 -> 216 | AE2: =AD2 -> 216 | AF2: =AE2+1 -> 217 | AG2: =AF2 -> 217 | AH2: =AG2 -> 217 | AI2: =AH2 -> 217 | AJ2: =AI2+1 -> 218 | AK2: =AJ2 -> 218 | AL2: =AK2 -> 218 | AM2: =AL2 -> 218 | AN2: =AM2+1 -> 219 | AO2: =AN2 -> 219 | AP2: =AO2 -> 219 | AQ2: =AP2 -> 219 | AR2: =AQ2+1 -> 220 | AS2: =AR2 -> 220 | AT2: =AS2 -> 220 | AU2: =AT2 -> 220 | AV2: =AU2+1 -> 221 | AW2: =AV2 -> 221 | AX2: =AW2 -> 221 | AY2: =AX2 -> 221 | AZ2: =AY2+1 -> 222 | BA2: =AZ2 -> 222 | BB2: =BA2 -> 222 | BC2: =BB2 -> 222 | BD2: =BC2+1 -> 223 | BE2: =BD2 -> 223 | BF2: =BE2 -> 223 | BG2: =BF2 -> 223 | BH2: =BG2+1 -> 224 | BI2: =BH2 -> 224 | BJ2: =BI2 -> 224 | BK2: =BJ2 -> 224 | BL2: =BK2+1 -> 225 | BM2: =BL2 -> 225 | BN2: =BM2 -> 225 | BO2: =BN2 -> 225 | BP2: 235 | BQ2: =BP2+1 -> 236 | BR2: =BQ2+1 -> 237 | BS2: =BR2+1 -> 238 | BT2: =BS2+1 -> 239 | BU2: =BT2+1 -> 240 | BV2: =BU2+1 -> 241 | BW2: =BV2+1 -> 242 | BX2: =BW2+1 -> 243 | BY2: =BX2+1 -> 244 | BZ2: 235 | CA2: =BZ2+1 -> 236 | CB2: =CA2+1 -> 237 | CC2: =CB2+1 -> 238 | CD2: =CC2+1 -> 239 | CE2: =CD2+1 -> 240 | CF2: =CE2+1 -> 241 | CG2: =CF2+1 -> 242 | CH2: =CG2+1 -> 243 | CI2: =CH2+1 -> 244
H3: =TODAY() -> 46036 | AB3: 1 | AC3: =AB3 -> 1 | AD3: =AC3 -> 1 | AE3: =AD3 -> 1 | AF3: =AE3+1 -> 2 | AG3: =AF3 -> 2 | AH3: =AG3 -> 2 | AI3: =AH3 -> 2 | AJ3: =AI3+1 -> 3 | AK3: =AJ3 -> 3 | AL3: =AK3 -> 3 | AM3: =AL3 -> 3 | AN3: =AM3+1 -> 4 | AO3: =AN3 -> 4 | AP3: =AO3 -> 4 | AQ3: =AP3 -> 4 | AR3: =AQ3+1 -> 5 | AS3: =AR3 -> 5 | AT3: =AS3 -> 5 | AU3: =AT3 -> 5 | AV3: =AU3+1 -> 6 | AW3: =AV3 -> 6 | AX3: =AW3 -> 6 | AY3: =AX3 -> 6 | AZ3: =AY3+1 -> 7 | BA3: =AZ3 -> 7 | BB3: =BA3 -> 7 | BC3: =BB3 -> 7 | BD3: =BC3+1 -> 8 | BE3: =BD3 -> 8 | BF3: =BE3 -> 8 | BG3: =BF3 -> 8 | BH3: =BG3+1 -> 9 | BI3: =BH3 -> 9 | BJ3: =BI3 -> 9 | BK3: =BJ3 -> 9 | BL3: =BK3+1 -> 10 | BM3: =BL3 -> 10 | BN3: =BM3 -> 10 | BO3: =BN3 -> 10 | BP3: 1 | BQ3: =BP3+1 -> 2 | BR3: =BQ3+1 -> 3 | BS3: =BR3+1 -> 4 | BT3: =BS3+1 -> 5 | BU3: =BT3+1 -> 6 | BV3: =BU3+1 -> 7 | BW3: =BV3+1 -> 8 | BX3: =BW3+1 -> 9 | BY3: =BX3+1 -> 10 | BZ3: 1 | CA3: =BZ3+1 -> 2 | CB3: =CA3+1 -> 3 | CC3: =CB3+1 -> 4 | CD3: =CC3+1 -> 5 | CE3: =CD3+1 -> 6 | CF3: =CE3+1 -> 7 | CG3: =CF3+1 -> 8 | CH3: =CG3+1 -> 9 | CI3: =CH3+1 -> 10
Q4: Polinômio da Curva | AB4: =CONCATENATE(AB3,"º Ponto") -> 1º Ponto | AF4: =CONCATENATE(AF3,"º Ponto") -> 2º Ponto | AJ4: =CONCATENATE(AJ3,"º Ponto") -> 3º Ponto | AN4: =CONCATENATE(AN3,"º Ponto") -> 4º Ponto | AR4: =CONCATENATE(AR3,"º Ponto") -> 5º Ponto | AV4: =CONCATENATE(AV3,"º Ponto") -> 6º Ponto | AZ4: =CONCATENATE(AZ3,"º Ponto") -> 7º Ponto | BD4: =CONCATENATE(BD3,"º Ponto") -> 8º Ponto | BH4: =CONCATENATE(BH3,"º Ponto") -> 9º Ponto | BL4: =CONCATENATE(BL3,"º Ponto") -> 10º Ponto | BP4: =CONCATENATE(BP3," - Erro") -> 1 - Erro | BQ4: =CONCATENATE(BQ3," - Erro") -> 2 - Erro | BR4: =CONCATENATE(BR3," - Erro") -> 3 - Erro | BS4: =CONCATENATE(BS3," - Erro") -> 4 - Erro | BT4: =CONCATENATE(BT3," - Erro") -> 5 - Erro | BU4: =CONCATENATE(BU3," - Erro") -> 6 - Erro | BV4: =CONCATENATE(BV3," - Erro") -> 7 - Erro | BW4: =CONCATENATE(BW3," - Erro") -> 8 - Erro | ... BY4: =CONCATENATE(BY3," - Erro") -> 10 - Erro | BZ4: =CONCATENATE(BZ3," - Deriva") -> 1 - Deriva | CA4: =CONCATENATE(CA3," - Deriva") -> 2 - Deriva | CB4: =CONCATENATE(CB3," - Deriva") -> 3 - Deriva | CC4: =CONCATENATE(CC3," - Deriva") -> 4 - Deriva | CD4: =CONCATENATE(CD3," - Deriva") -> 5 - Deriva | CE4: =CONCATENATE(CE3," - Deriva") -> 6 - Deriva | CF4: =CONCATENATE(CF3," - Deriva") -> 7 - Deriva | CG4: =CONCATENATE(CG3," - Deriva") -> 8 - Deriva | ... CI4: =CONCATENATE(CI3," - Deriva") -> 10 - Deriva
B5: TAG | C5: Padrão | D5: Calibrado por | E5: Rastreabilidade | F5: n° do certificado | G5: Data da Calibração | H5: Vencimento | I5: Unidade calibrada | J5: Faixa mínima | K5: Faixa máxima | L5: Resolução | M5: Maior desvio | N5: Maior Incerteza | O5: Deriva | P5: Maior desvio Exc.(%) | Q5: Residuo | R5: Veff | S5: X8 | T5: X7 | U5: X6 | V5: X5 | W5: X4 | X5: X3 | Y5: X2 | Z5: X1 | AA5: X0 | AB5: =CONCATENATE(AB3,"-VR") -> 1-VR | AC5: =CONCATENATE(AC3,"-U") -> 1-U | AD5: =CONCATENATE(AD3,"-K") -> 1-K | AE5: =CONCATENATE(AE3,"-GL") -> 1-GL | AF5: =CONCATENATE(AF3,"-VR") -> 2-VR | AG5: =CONCATENATE(AG3,"-U") -> 2-U | AH5: =CONCATENATE(AH3,"-K") -> 2-K | AI5: =CONCATENATE(AI3,"-GL") -> 2-GL | AJ5: =CONCATENATE(AJ3,"-VR") -> 3-VR | AK5: =CONCATENATE(AK3,"-U") -> 3-U | AL5: =CONCATENATE(AL3,"-K") -> 3-K | AM5: =CONCATENATE(AM3,"-GL") -> 3-GL | AN5: =CONCATENATE(AN3,"-VR") -> 4-VR | AO5: =CONCATENATE(AO3,"-U") -> 4-U | AP5: =CONCATENATE(AP3,"-K") -> 4-K | AQ5: =CONCATENATE(AQ3,"-GL") -> 4-GL | AR5: =CONCATENATE(AR3,"-VR") -> 5-VR | AS5: =CONCATENATE(AS3,"-U") -> 5-U | AT5: =CONCATENATE(AT3,"-K") -> 5-K | AU5: =CONCATENATE(AU3,"-GL") -> 5-GL | AV5: =CONCATENATE(AV3,"-VR") -> 6-VR | AW5: =CONCATENATE(AW3,"-U") -> 6-U | AX5: =CONCATENATE(AX3,"-K") -> 6-K | AY5: =CONCATENATE(AY3,"-GL") -> 6-GL | AZ5: =CONCATENATE(AZ3,"-VR") -> 7-VR | BA5: =CONCATENATE(BA3,"-U") -> 7-U | BB5: =CONCATENATE(BB3,"-K") -> 7-K | BC5: =CONCATENATE(BC3,"-GL") -> 7-GL | BD5: =CONCATENATE(BD3,"-VR") -> 8-VR | BE5: =CONCATENATE(BE3,"-U") -> 8-U | BF5: =CONCATENATE(BF3,"-K") -> 8-K | BG5: =CONCATENATE(BG3,"-GL") -> 8-GL | BH5: =CONCATENATE(BH3,"-VR") -> 9-VR | BI5: =CONCATENATE(BI3,"-U") -> 9-U | BJ5: =CONCATENATE(BJ3,"-K") -> 9-K | BK5: =CONCATENATE(BK3,"-GL") -> 9-GL | BL5: =CONCATENATE(BL3,"-VR") -> 10-VR | BM5: =CONCATENATE(BM3,"-U") -> 10-U | BN5: =CONCATENATE(BN3,"-K") -> 10-K | BO5: =CONCATENATE(BO3,"-GL") -> 10-GL | BP5: =CONCATENATE(BP3,"-ER") -> 1-ER | BQ5: =CONCATENATE(BQ3,"-ER") -> 2-ER | BR5: =CONCATENATE(BR3,"-ER") -> 3-ER | BS5: =CONCATENATE(BS3,"-ER") -> 4-ER | BT5: =CONCATENATE(BT3,"-ER") -> 5-ER | BU5: =CONCATENATE(BU3,"-ER") -> 6-ER | BV5: =CONCATENATE(BV3,"-ER") -> 7-ER | BW5: =CONCATENATE(BW3,"-ER") -> 8-ER | ... BY5: =CONCATENATE(BY3,"-ER") -> 10-ER | BZ5: =CONCATENATE(BZ3,"-D") -> 1-D | CA5: =CONCATENATE(CA3,"-D") -> 2-D | CB5: =CONCATENATE(CB3,"-D") -> 3-D | CC5: =CONCATENATE(CC3,"-D") -> 4-D | CD5: =CONCATENATE(CD3,"-D") -> 5-D | CE5: =CONCATENATE(CE3,"-D") -> 6-D | CF5: =CONCATENATE(CF3,"-D") -> 7-D | CG5: =CONCATENATE(CG3,"-D") -> 8-D | ... CI5: =CONCATENATE(CI3,"-D") -> 10-D
A6: 1 | B6: =IF(VLOOKUP(ROUND(CONCATENATE($A6,B$2),0),'Cadastro dos Padrões'!$A$2:$V$921,B$1,FALSE)="","-",VLOOKUP(ROUND(CONCATENATE($A6,B$2),0),'Cadastro dos Padrões'!$A$2:$V$921,B$1,FALSE)) -> E.MS.LQ-003 | C6: =IF(VLOOKUP(ROUND(CONCATENATE($A6,C$2),0),'Cadastro dos Padrões'!$A$2:$V$921,C$1,FALSE)="","-",VLOOKUP(ROUND(CONCATENATE($A6,C$2),0),'Cadastro dos Padrões'!$A$2:$V$921,C$1,FALSE)) -> Balança Eletrônica | D6: =IF(VLOOKUP(ROUND(CONCATENATE($A6,D$2),0),'Cadastro dos Padrões'!$A$2:$V$921,D$1,FALSE)="","-",VLOOKUP(ROUND(CONCATENATE($A6,D$2),0),'Cadastro dos Padrões'!$A$2:$V$921,D$1,FALSE)) -> Elus | E6: =IF(VLOOKUP(ROUND(CONCATENATE($A6,E$2),0),'Cadastro dos Padrões'!$A$2:$V$921,E$1,FALSE)="","-",VLOOKUP(ROUND(CONCATENATE($A6,E$2),0),'Cadastro dos Padrões'!$A$2:$V$921,E$1,FALSE)) -> RBC - CAL 0439 | F6: =IF(VLOOKUP(ROUND(CONCATENATE($A6,F$2),0),'Cadastro dos Padrões'!$A$2:$V$921,F$1,FALSE)="","-",VLOOKUP(ROUND(CONCATENATE($A6,F$2),0),'Cadastro dos Padrões'!$A$2:$V$921,F$1,FALSE)) -> E0011/26 | G6: =IF(VLOOKUP(ROUND(CONCATENATE($A6,G$2),0),'Cadastro dos Padrões'!$A$2:$V$921,G$1,FALSE)="","-",VLOOKUP(ROUND(CONCATENATE($A6,G$2),0),'Cadastro dos Padrões'!$A$2:$V$921,G$1,FALSE)) -> 46031 | H6: =IF(VLOOKUP(ROUND(CONCATENATE($A6,H$2),0),'Cadastro dos Padrões'!$A$2:$V$921,H$1,FALSE)="","-",VLOOKUP(ROUND(CONCATENATE($A6,H$2),0),'Cadastro dos Padrões'!$A$2:$V$921,H$1,FALSE)) -> 46417 | I6: =IF(VLOOKUP(ROUND(CONCATENATE($A6,I$2),0),'Cadastro dos Padrões'!$A$2:$V$921,I$1,FALSE)="","-",VLOOKUP(ROUND(CONCATENATE($A6,I$2),0),'Cadastro dos Padrões'!$A$2:$V$921,I$1,FALSE)) -> g | ... P6: =IF(VLOOKUP(ROUND(CONCATENATE($A6,P$2),0),'Cadastro dos Padrões'!$A$2:$V$921,P$1,FALSE)="","-",VLOOKUP(ROUND(CONCATENATE($A6,P$2),0),'Cadastro dos Padrões'!$A$2:$V$921,P$1,FALSE)) -> 0.004 | Q6: =IF($B6="-","-",VLOOKUP(ROUND(CONCATENATE($A6,Q$2),0),'Cadastro dos Padrões'!$A$2:$V$921,Q$1,FALSE)) -> 0.00083868147 | R6: =IF($B6="-","-",VLOOKUP(ROUND(CONCATENATE($A6,R$2),0),'Cadastro dos Padrões'!$A$2:$V$921,R$1,FALSE)) -> 5 | S6: =IF($B6="-","-",VLOOKUP(ROUND(CONCATENATE($A6,S$2),0),'Cadastro dos Padrões'!$A$2:$V$921,S$1,FALSE)) -> 0 | T6: =IF($B6="-","-",VLOOKUP(ROUND(CONCATENATE($A6,T$2),0),'Cadastro dos Padrões'!$A$2:$V$921,T$1,FALSE)) -> 0 | U6: =IF($B6="-","-",VLOOKUP(ROUND(CONCATENATE($A6,U$2),0),'Cadastro dos Padrões'!$A$2:$V$921,U$1,FALSE)) -> 0 | V6: =IF($B6="-","-",VLOOKUP(ROUND(CONCATENATE($A6,V$2),0),'Cadastro dos Padrões'!$A$2:$V$921,V$1,FALSE)) -> -2.1946624e-17 | W6: =IF($B6="-","-",VLOOKUP(ROUND(CONCATENATE($A6,W$2),0),'Cadastro dos Padrões'!$A$2:$V$921,W$1,FALSE)) -> 1.4356681e-13 | X6: =IF($B6="-","-",VLOOKUP(ROUND(CONCATENATE($A6,X$2),0),'Cadastro dos Padrões'!$A$2:$V$921,X$1,FALSE)) -> -3.2116745e-10 | ... AA6: =IF($B6="-","-",VLOOKUP(ROUND(CONCATENATE($A6,AA$2),0),'Cadastro dos Padrões'!$A$2:$V$921,AA$1,FALSE)) -> 0.00068337238 | AB6: =IF(VLOOKUP(ROUND(CONCATENATE($A6,AB$2),0),'Cadastro dos Padrões'!$A$2:$V$921,AB$1,FALSE)="","-",VLOOKUP(ROUND(CONCATENATE($A6,AB$2),0),'Cadastro dos Padrões'!$A$2:$V$921,AB$1,FALSE)) -> 1 | AC6: =IF(VLOOKUP(ROUND(CONCATENATE($A6,AC$2),0),'Cadastro dos Padrões'!$A$2:$V$921,AC$1,FALSE)="","-",VLOOKUP(ROUND(CONCATENATE($A6,AC$2),0),'Cadastro dos Padrões'!$A$2:$V$921,AC$1,FALSE)) -> 0.02 | AD6: =IF(VLOOKUP(ROUND(CONCATENATE($A6,AD$2),0),'Cadastro dos Padrões'!$A$2:$V$921,AD$1,FALSE)="","-",VLOOKUP(ROUND(CONCATENATE($A6,AD$2),0),'Cadastro dos Padrões'!$A$2:$V$921,AD$1,FALSE)) -> 2 | AE6: =IF(VLOOKUP(ROUND(CONCATENATE($A6,AE$2),0),'Cadastro dos Padrões'!$A$2:$V$921,AE$1,FALSE)="","-",VLOOKUP(ROUND(CONCATENATE($A6,AE$2),0),'Cadastro dos Padrões'!$A$2:$V$921,AE$1,FALSE)) -> 1000000 | AF6: =IF(VLOOKUP(ROUND(CONCATENATE($A6,AF$2),0),'Cadastro dos Padrões'!$A$2:$V$921,AF$1,FALSE)="","-",VLOOKUP(ROUND(CONCATENATE($A6,AF$2),0),'Cadastro dos Padrões'!$A$2:$V$921,AF$1,FALSE)) -> 10 | AG6: =IF(VLOOKUP(ROUND(CONCATENATE($A6,AG$2),0),'Cadastro dos Padrões'!$A$2:$V$921,AG$1,FALSE)="","-",VLOOKUP(ROUND(CONCATENATE($A6,AG$2),0),'Cadastro dos Padrões'!$A$2:$V$921,AG$1,FALSE)) -> 0.02 | AH6: =IF(VLOOKUP(ROUND(CONCATENATE($A6,AH$2),0),'Cadastro dos Padrões'!$A$2:$V$921,AH$1,FALSE)="","-",VLOOKUP(ROUND(CONCATENATE($A6,AH$2),0),'Cadastro dos Padrões'!$A$2:$V$921,AH$1,FALSE)) -> 2 | AI6: =IF(VLOOKUP(ROUND(CONCATENATE($A6,AI$2),0),'Cadastro dos Padrões'!$A$2:$V$921,AI$1,FALSE)="","-",VLOOKUP(ROUND(CONCATENATE($A6,AI$2),0),'Cadastro dos Padrões'!$A$2:$V$921,AI$1,FALSE)) -> 1000000 | ... CI6: =IF(VLOOKUP(ROUND(CONCATENATE($A6,CI$2),0),'Cadastro dos Padrões'!$A$2:$V$921,CI$1,FALSE)="","-",VLOOKUP(ROUND(CONCATENATE($A6,CI$2),0),'Cadastro dos Padrões'!$A$2:$V$921,CI$1,FALSE)) -> 0
A7: 2 | B7: =IF(VLOOKUP(ROUND(CONCATENATE($A7,B$2),0),'Cadastro dos Padrões'!$A$2:$V$921,B$1,FALSE)="","-",VLOOKUP(ROUND(CONCATENATE($A7,B$2),0),'Cadastro dos Padrões'!$A$2:$V$921,B$1,FALSE)) -> E.MS.LV-003 | C7: =IF(VLOOKUP(ROUND(CONCATENATE($A7,C$2),0),'Cadastro dos Padrões'!$A$2:$V$921,C$1,FALSE)="","-",VLOOKUP(ROUND(CONCATENATE($A7,C$2),0),'Cadastro dos Padrões'!$A$2:$V$921,C$1,FALSE)) -> Balança Eletrônica | D7: =IF(VLOOKUP(ROUND(CONCATENATE($A7,D$2),0),'Cadastro dos Padrões'!$A$2:$V$921,D$1,FALSE)="","-",VLOOKUP(ROUND(CONCATENATE($A7,D$2),0),'Cadastro dos Padrões'!$A$2:$V$921,D$1,FALSE)) -> Elus | E7: =IF(VLOOKUP(ROUND(CONCATENATE($A7,E$2),0),'Cadastro dos Padrões'!$A$2:$V$921,E$1,FALSE)="","-",VLOOKUP(ROUND(CONCATENATE($A7,E$2),0),'Cadastro dos Padrões'!$A$2:$V$921,E$1,FALSE)) -> RBC - CAL 0439 | F7: =IF(VLOOKUP(ROUND(CONCATENATE($A7,F$2),0),'Cadastro dos Padrões'!$A$2:$V$921,F$1,FALSE)="","-",VLOOKUP(ROUND(CONCATENATE($A7,F$2),0),'Cadastro dos Padrões'!$A$2:$V$921,F$1,FALSE)) -> E0017/26 | G7: =IF(VLOOKUP(ROUND(CONCATENATE($A7,G$2),0),'Cadastro dos Padrões'!$A$2:$V$921,G$1,FALSE)="","-",VLOOKUP(ROUND(CONCATENATE($A7,G$2),0),'Cadastro dos Padrões'!$A$2:$V$921,G$1,FALSE)) -> 46031 | H7: =IF(VLOOKUP(ROUND(CONCATENATE($A7,H$2),0),'Cadastro dos Padrões'!$A$2:$V$921,H$1,FALSE)="","-",VLOOKUP(ROUND(CONCATENATE($A7,H$2),0),'Cadastro dos Padrões'!$A$2:$V$921,H$1,FALSE)) -> 46417 | I7: =IF(VLOOKUP(ROUND(CONCATENATE($A7,I$2),0),'Cadastro dos Padrões'!$A$2:$V$921,I$1,FALSE)="","-",VLOOKUP(ROUND(CONCATENATE($A7,I$2),0),'Cadastro dos Padrões'!$A$2:$V$921,I$1,FALSE)) -> g | ... P7: =IF(VLOOKUP(ROUND(CONCATENATE($A7,P$2),0),'Cadastro dos Padrões'!$A$2:$V$921,P$1,FALSE)="","-",VLOOKUP(ROUND(CONCATENATE($A7,P$2),0),'Cadastro dos Padrões'!$A$2:$V$921,P$1,FALSE)) -> 0 | Q7: =IF($B7="-","-",VLOOKUP(ROUND(CONCATENATE($A7,Q$2),0),'Cadastro dos Padrões'!$A$2:$V$921,Q$1,FALSE)) -> 2.220446e-16 | R7: =IF($B7="-","-",VLOOKUP(ROUND(CONCATENATE($A7,R$2),0),'Cadastro dos Padrões'!$A$2:$V$921,R$1,FALSE)) -> 5 | S7: =IF($B7="-","-",VLOOKUP(ROUND(CONCATENATE($A7,S$2),0),'Cadastro dos Padrões'!$A$2:$V$921,S$1,FALSE)) -> 0 | T7: =IF($B7="-","-",VLOOKUP(ROUND(CONCATENATE($A7,T$2),0),'Cadastro dos Padrões'!$A$2:$V$921,T$1,FALSE)) -> 0 | U7: =IF($B7="-","-",VLOOKUP(ROUND(CONCATENATE($A7,U$2),0),'Cadastro dos Padrões'!$A$2:$V$921,U$1,FALSE)) -> 0 | V7: =IF($B7="-","-",VLOOKUP(ROUND(CONCATENATE($A7,V$2),0),'Cadastro dos Padrões'!$A$2:$V$921,V$1,FALSE)) -> -8.4933571e-26 | W7: =IF($B7="-","-",VLOOKUP(ROUND(CONCATENATE($A7,W$2),0),'Cadastro dos Padrões'!$A$2:$V$921,W$1,FALSE)) -> 9.1690581e-23 | X7: =IF($B7="-","-",VLOOKUP(ROUND(CONCATENATE($A7,X$2),0),'Cadastro dos Padrões'!$A$2:$V$921,X$1,FALSE)) -> -3.2533344e-20 | ... AA7: =IF($B7="-","-",VLOOKUP(ROUND(CONCATENATE($A7,AA$2),0),'Cadastro dos Padrões'!$A$2:$V$921,AA$1,FALSE)) -> -1.1641815e-14 | AB7: =IF(VLOOKUP(ROUND(CONCATENATE($A7,AB$2),0),'Cadastro dos Padrões'!$A$2:$V$921,AB$1,FALSE)="","-",VLOOKUP(ROUND(CONCATENATE($A7,AB$2),0),'Cadastro dos Padrões'!$A$2:$V$921,AB$1,FALSE)) -> 0 | AC7: =IF(VLOOKUP(ROUND(CONCATENATE($A7,AC$2),0),'Cadastro dos Padrões'!$A$2:$V$921,AC$1,FALSE)="","-",VLOOKUP(ROUND(CONCATENATE($A7,AC$2),0),'Cadastro dos Padrões'!$A$2:$V$921,AC$1,FALSE)) -> 0.2 | AD7: =IF(VLOOKUP(ROUND(CONCATENATE($A7,AD$2),0),'Cadastro dos Padrões'!$A$2:$V$921,AD$1,FALSE)="","-",VLOOKUP(ROUND(CONCATENATE($A7,AD$2),0),'Cadastro dos Padrões'!$A$2:$V$921,AD$1,FALSE)) -> 2 | AE7: =IF(VLOOKUP(ROUND(CONCATENATE($A7,AE$2),0),'Cadastro dos Padrões'!$A$2:$V$921,AE$1,FALSE)="","-",VLOOKUP(ROUND(CONCATENATE($A7,AE$2),0),'Cadastro dos Padrões'!$A$2:$V$921,AE$1,FALSE)) -> 1000000 | AF7: =IF(VLOOKUP(ROUND(CONCATENATE($A7,AF$2),0),'Cadastro dos Padrões'!$A$2:$V$921,AF$1,FALSE)="","-",VLOOKUP(ROUND(CONCATENATE($A7,AF$2),0),'Cadastro dos Padrões'!$A$2:$V$921,AF$1,FALSE)) -> 0.2 | AG7: =IF(VLOOKUP(ROUND(CONCATENATE($A7,AG$2),0),'Cadastro dos Padrões'!$A$2:$V$921,AG$1,FALSE)="","-",VLOOKUP(ROUND(CONCATENATE($A7,AG$2),0),'Cadastro dos Padrões'!$A$2:$V$921,AG$1,FALSE)) -> 0.2 | AH7: =IF(VLOOKUP(ROUND(CONCATENATE($A7,AH$2),0),'Cadastro dos Padrões'!$A$2:$V$921,AH$1,FALSE)="","-",VLOOKUP(ROUND(CONCATENATE($A7,AH$2),0),'Cadastro dos Padrões'!$A$2:$V$921,AH$1,FALSE)) -> 2 | AI7: =IF(VLOOKUP(ROUND(CONCATENATE($A7,AI$2),0),'Cadastro dos Padrões'!$A$2:$V$921,AI$1,FALSE)="","-",VLOOKUP(ROUND(CONCATENATE($A7,AI$2),0),'Cadastro dos Padrões'!$A$2:$V$921,AI$1,FALSE)) -> 1000000 | ... CI7: =IF(VLOOKUP(ROUND(CONCATENATE($A7,CI$2),0),'Cadastro dos Padrões'!$A$2:$V$921,CI$1,FALSE)="","-",VLOOKUP(ROUND(CONCATENATE($A7,CI$2),0),'Cadastro dos Padrões'!$A$2:$V$921,CI$1,FALSE)) -> 0
A8: 3 | B8: =IF(VLOOKUP(ROUND(CONCATENATE($A8,B$2),0),'Cadastro dos Padrões'!$A$2:$V$921,B$1,FALSE)="","-",VLOOKUP(ROUND(CONCATENATE($A8,B$2),0),'Cadastro dos Padrões'!$A$2:$V$921,B$1,FALSE)) -> E.MS.LV-002 | C8: =IF(VLOOKUP(ROUND(CONCATENATE($A8,C$2),0),'Cadastro dos Padrões'!$A$2:$V$921,C$1,FALSE)="","-",VLOOKUP(ROUND(CONCATENATE($A8,C$2),0),'Cadastro dos Padrões'!$A$2:$V$921,C$1,FALSE)) -> Balança Eletrônica | D8: =IF(VLOOKUP(ROUND(CONCATENATE($A8,D$2),0),'Cadastro dos Padrões'!$A$2:$V$921,D$1,FALSE)="","-",VLOOKUP(ROUND(CONCATENATE($A8,D$2),0),'Cadastro dos Padrões'!$A$2:$V$921,D$1,FALSE)) -> Elus | E8: =IF(VLOOKUP(ROUND(CONCATENATE($A8,E$2),0),'Cadastro dos Padrões'!$A$2:$V$921,E$1,FALSE)="","-",VLOOKUP(ROUND(CONCATENATE($A8,E$2),0),'Cadastro dos Padrões'!$A$2:$V$921,E$1,FALSE)) -> RBC - CAL 0439 | F8: =IF(VLOOKUP(ROUND(CONCATENATE($A8,F$2),0),'Cadastro dos Padrões'!$A$2:$V$921,F$1,FALSE)="","-",VLOOKUP(ROUND(CONCATENATE($A8,F$2),0),'Cadastro dos Padrões'!$A$2:$V$921,F$1,FALSE)) -> E0016/26 | G8: =IF(VLOOKUP(ROUND(CONCATENATE($A8,G$2),0),'Cadastro dos Padrões'!$A$2:$V$921,G$1,FALSE)="","-",VLOOKUP(ROUND(CONCATENATE($A8,G$2),0),'Cadastro dos Padrões'!$A$2:$V$921,G$1,FALSE)) -> 46031 | H8: =IF(VLOOKUP(ROUND(CONCATENATE($A8,H$2),0),'Cadastro dos Padrões'!$A$2:$V$921,H$1,FALSE)="","-",VLOOKUP(ROUND(CONCATENATE($A8,H$2),0),'Cadastro dos Padrões'!$A$2:$V$921,H$1,FALSE)) -> 46417 | I8: =IF(VLOOKUP(ROUND(CONCATENATE($A8,I$2),0),'Cadastro dos Padrões'!$A$2:$V$921,I$1,FALSE)="","-",VLOOKUP(ROUND(CONCATENATE($A8,I$2),0),'Cadastro dos Padrões'!$A$2:$V$921,I$1,FALSE)) -> kg | ... P8: =IF(VLOOKUP(ROUND(CONCATENATE($A8,P$2),0),'Cadastro dos Padrões'!$A$2:$V$921,P$1,FALSE)="","-",VLOOKUP(ROUND(CONCATENATE($A8,P$2),0),'Cadastro dos Padrões'!$A$2:$V$921,P$1,FALSE)) -> 0.000625 | Q8: =IF($B8="-","-",VLOOKUP(ROUND(CONCATENATE($A8,Q$2),0),'Cadastro dos Padrões'!$A$2:$V$921,Q$1,FALSE)) -> 0.00012310936 | R8: =IF($B8="-","-",VLOOKUP(ROUND(CONCATENATE($A8,R$2),0),'Cadastro dos Padrões'!$A$2:$V$921,R$1,FALSE)) -> 3 | S8: =IF($B8="-","-",VLOOKUP(ROUND(CONCATENATE($A8,S$2),0),'Cadastro dos Padrões'!$A$2:$V$921,S$1,FALSE)) -> 0 | T8: =IF($B8="-","-",VLOOKUP(ROUND(CONCATENATE($A8,T$2),0),'Cadastro dos Padrões'!$A$2:$V$921,T$1,FALSE)) -> 0 | U8: =IF($B8="-","-",VLOOKUP(ROUND(CONCATENATE($A8,U$2),0),'Cadastro dos Padrões'!$A$2:$V$921,U$1,FALSE)) -> 0 | V8: =IF($B8="-","-",VLOOKUP(ROUND(CONCATENATE($A8,V$2),0),'Cadastro dos Padrões'!$A$2:$V$921,V$1,FALSE)) -> 0 | W8: =IF($B8="-","-",VLOOKUP(ROUND(CONCATENATE($A8,W$2),0),'Cadastro dos Padrões'!$A$2:$V$921,W$1,FALSE)) -> 0 | X8: =IF($B8="-","-",VLOOKUP(ROUND(CONCATENATE($A8,X$2),0),'Cadastro dos Padrões'!$A$2:$V$921,X$1,FALSE)) -> 2.0540732e-11 | ... AA8: =IF($B8="-","-",VLOOKUP(ROUND(CONCATENATE($A8,AA$2),0),'Cadastro dos Padrões'!$A$2:$V$921,AA$1,FALSE)) -> -0.00015767507 | AB8: =IF(VLOOKUP(ROUND(CONCATENATE($A8,AB$2),0),'Cadastro dos Padrões'!$A$2:$V$921,AB$1,FALSE)="","-",VLOOKUP(ROUND(CONCATENATE($A8,AB$2),0),'Cadastro dos Padrões'!$A$2:$V$921,AB$1,FALSE)) -> 10 | AC8: =IF(VLOOKUP(ROUND(CONCATENATE($A8,AC$2),0),'Cadastro dos Padrões'!$A$2:$V$921,AC$1,FALSE)="","-",VLOOKUP(ROUND(CONCATENATE($A8,AC$2),0),'Cadastro dos Padrões'!$A$2:$V$921,AC$1,FALSE)) -> 0.002 | AD8: =IF(VLOOKUP(ROUND(CONCATENATE($A8,AD$2),0),'Cadastro dos Padrões'!$A$2:$V$921,AD$1,FALSE)="","-",VLOOKUP(ROUND(CONCATENATE($A8,AD$2),0),'Cadastro dos Padrões'!$A$2:$V$921,AD$1,FALSE)) -> 2 | AE8: =IF(VLOOKUP(ROUND(CONCATENATE($A8,AE$2),0),'Cadastro dos Padrões'!$A$2:$V$921,AE$1,FALSE)="","-",VLOOKUP(ROUND(CONCATENATE($A8,AE$2),0),'Cadastro dos Padrões'!$A$2:$V$921,AE$1,FALSE)) -> 1000000 | AF8: =IF(VLOOKUP(ROUND(CONCATENATE($A8,AF$2),0),'Cadastro dos Padrões'!$A$2:$V$921,AF$1,FALSE)="","-",VLOOKUP(ROUND(CONCATENATE($A8,AF$2),0),'Cadastro dos Padrões'!$A$2:$V$921,AF$1,FALSE)) -> 30 | AG8: =IF(VLOOKUP(ROUND(CONCATENATE($A8,AG$2),0),'Cadastro dos Padrões'!$A$2:$V$921,AG$1,FALSE)="","-",VLOOKUP(ROUND(CONCATENATE($A8,AG$2),0),'Cadastro dos Padrões'!$A$2:$V$921,AG$1,FALSE)) -> 0.002 | AH8: =IF(VLOOKUP(ROUND(CONCATENATE($A8,AH$2),0),'Cadastro dos Padrões'!$A$2:$V$921,AH$1,FALSE)="","-",VLOOKUP(ROUND(CONCATENATE($A8,AH$2),0),'Cadastro dos Padrões'!$A$2:$V$921,AH$1,FALSE)) -> 2 | AI8: =IF(VLOOKUP(ROUND(CONCATENATE($A8,AI$2),0),'Cadastro dos Padrões'!$A$2:$V$921,AI$1,FALSE)="","-",VLOOKUP(ROUND(CONCATENATE($A8,AI$2),0),'Cadastro dos Padrões'!$A$2:$V$921,AI$1,FALSE)) -> 1000000 | ... CI8: =IF(VLOOKUP(ROUND(CONCATENATE($A8,CI$2),0),'Cadastro dos Padrões'!$A$2:$V$921,CI$1,FALSE)="","-",VLOOKUP(ROUND(CONCATENATE($A8,CI$2),0),'Cadastro dos Padrões'!$A$2:$V$921,CI$1,FALSE)) -> 0
A9: 4 | B9: =IF(VLOOKUP(ROUND(CONCATENATE($A9,B$2),0),'Cadastro dos Padrões'!$A$2:$V$921,B$1,FALSE)="","-",VLOOKUP(ROUND(CONCATENATE($A9,B$2),0),'Cadastro dos Padrões'!$A$2:$V$921,B$1,FALSE)) -> E.MS.PMR-002 | C9: =IF(VLOOKUP(ROUND(CONCATENATE($A9,C$2),0),'Cadastro dos Padrões'!$A$2:$V$921,C$1,FALSE)="","-",VLOOKUP(ROUND(CONCATENATE($A9,C$2),0),'Cadastro dos Padrões'!$A$2:$V$921,C$1,FALSE)) -> Balança Eletrônica | D9: =IF(VLOOKUP(ROUND(CONCATENATE($A9,D$2),0),'Cadastro dos Padrões'!$A$2:$V$921,D$1,FALSE)="","-",VLOOKUP(ROUND(CONCATENATE($A9,D$2),0),'Cadastro dos Padrões'!$A$2:$V$921,D$1,FALSE)) -> Elus | E9: =IF(VLOOKUP(ROUND(CONCATENATE($A9,E$2),0),'Cadastro dos Padrões'!$A$2:$V$921,E$1,FALSE)="","-",VLOOKUP(ROUND(CONCATENATE($A9,E$2),0),'Cadastro dos Padrões'!$A$2:$V$921,E$1,FALSE)) -> RBC - CAL 0439 | F9: =IF(VLOOKUP(ROUND(CONCATENATE($A9,F$2),0),'Cadastro dos Padrões'!$A$2:$V$921,F$1,FALSE)="","-",VLOOKUP(ROUND(CONCATENATE($A9,F$2),0),'Cadastro dos Padrões'!$A$2:$V$921,F$1,FALSE)) -> E0019/26 | G9: =IF(VLOOKUP(ROUND(CONCATENATE($A9,G$2),0),'Cadastro dos Padrões'!$A$2:$V$921,G$1,FALSE)="","-",VLOOKUP(ROUND(CONCATENATE($A9,G$2),0),'Cadastro dos Padrões'!$A$2:$V$921,G$1,FALSE)) -> 46031 | H9: =IF(VLOOKUP(ROUND(CONCATENATE($A9,H$2),0),'Cadastro dos Padrões'!$A$2:$V$921,H$1,FALSE)="","-",VLOOKUP(ROUND(CONCATENATE($A9,H$2),0),'Cadastro dos Padrões'!$A$2:$V$921,H$1,FALSE)) -> 46417 | I9: =IF(VLOOKUP(ROUND(CONCATENATE($A9,I$2),0),'Cadastro dos Padrões'!$A$2:$V$921,I$1,FALSE)="","-",VLOOKUP(ROUND(CONCATENATE($A9,I$2),0),'Cadastro dos Padrões'!$A$2:$V$921,I$1,FALSE)) -> g | ... P9: =IF(VLOOKUP(ROUND(CONCATENATE($A9,P$2),0),'Cadastro dos Padrões'!$A$2:$V$921,P$1,FALSE)="","-",VLOOKUP(ROUND(CONCATENATE($A9,P$2),0),'Cadastro dos Padrões'!$A$2:$V$921,P$1,FALSE)) -> 0.001 | Q9: =IF($B9="-","-",VLOOKUP(ROUND(CONCATENATE($A9,Q$2),0),'Cadastro dos Padrões'!$A$2:$V$921,Q$1,FALSE)) -> 0.016848098 | R9: =IF($B9="-","-",VLOOKUP(ROUND(CONCATENATE($A9,R$2),0),'Cadastro dos Padrões'!$A$2:$V$921,R$1,FALSE)) -> 5 | S9: =IF($B9="-","-",VLOOKUP(ROUND(CONCATENATE($A9,S$2),0),'Cadastro dos Padrões'!$A$2:$V$921,S$1,FALSE)) -> 0 | T9: =IF($B9="-","-",VLOOKUP(ROUND(CONCATENATE($A9,T$2),0),'Cadastro dos Padrões'!$A$2:$V$921,T$1,FALSE)) -> 0 | U9: =IF($B9="-","-",VLOOKUP(ROUND(CONCATENATE($A9,U$2),0),'Cadastro dos Padrões'!$A$2:$V$921,U$1,FALSE)) -> 0 | V9: =IF($B9="-","-",VLOOKUP(ROUND(CONCATENATE($A9,V$2),0),'Cadastro dos Padrões'!$A$2:$V$921,V$1,FALSE)) -> -7.2974852e-23 | W9: =IF($B9="-","-",VLOOKUP(ROUND(CONCATENATE($A9,W$2),0),'Cadastro dos Padrões'!$A$2:$V$921,W$1,FALSE)) -> 6.6650732e-18 | X9: =IF($B9="-","-",VLOOKUP(ROUND(CONCATENATE($A9,X$2),0),'Cadastro dos Padrões'!$A$2:$V$921,X$1,FALSE)) -> -2.5448841e-13 | ... AA9: =IF($B9="-","-",VLOOKUP(ROUND(CONCATENATE($A9,AA$2),0),'Cadastro dos Padrões'!$A$2:$V$921,AA$1,FALSE)) -> 0.0097308651 | AB9: =IF(VLOOKUP(ROUND(CONCATENATE($A9,AB$2),0),'Cadastro dos Padrões'!$A$2:$V$921,AB$1,FALSE)="","-",VLOOKUP(ROUND(CONCATENATE($A9,AB$2),0),'Cadastro dos Padrões'!$A$2:$V$921,AB$1,FALSE)) -> 20 | AC9: =IF(VLOOKUP(ROUND(CONCATENATE($A9,AC$2),0),'Cadastro dos Padrões'!$A$2:$V$921,AC$1,FALSE)="","-",VLOOKUP(ROUND(CONCATENATE($A9,AC$2),0),'Cadastro dos Padrões'!$A$2:$V$921,AC$1,FALSE)) -> 0.2 | AD9: =IF(VLOOKUP(ROUND(CONCATENATE($A9,AD$2),0),'Cadastro dos Padrões'!$A$2:$V$921,AD$1,FALSE)="","-",VLOOKUP(ROUND(CONCATENATE($A9,AD$2),0),'Cadastro dos Padrões'!$A$2:$V$921,AD$1,FALSE)) -> 2 | AE9: =IF(VLOOKUP(ROUND(CONCATENATE($A9,AE$2),0),'Cadastro dos Padrões'!$A$2:$V$921,AE$1,FALSE)="","-",VLOOKUP(ROUND(CONCATENATE($A9,AE$2),0),'Cadastro dos Padrões'!$A$2:$V$921,AE$1,FALSE)) -> 1000000 | AF9: =IF(VLOOKUP(ROUND(CONCATENATE($A9,AF$2),0),'Cadastro dos Padrões'!$A$2:$V$921,AF$1,FALSE)="","-",VLOOKUP(ROUND(CONCATENATE($A9,AF$2),0),'Cadastro dos Padrões'!$A$2:$V$921,AF$1,FALSE)) -> 600 | AG9: =IF(VLOOKUP(ROUND(CONCATENATE($A9,AG$2),0),'Cadastro dos Padrões'!$A$2:$V$921,AG$1,FALSE)="","-",VLOOKUP(ROUND(CONCATENATE($A9,AG$2),0),'Cadastro dos Padrões'!$A$2:$V$921,AG$1,FALSE)) -> 0.2 | AH9: =IF(VLOOKUP(ROUND(CONCATENATE($A9,AH$2),0),'Cadastro dos Padrões'!$A$2:$V$921,AH$1,FALSE)="","-",VLOOKUP(ROUND(CONCATENATE($A9,AH$2),0),'Cadastro dos Padrões'!$A$2:$V$921,AH$1,FALSE)) -> 2 | AI9: =IF(VLOOKUP(ROUND(CONCATENATE($A9,AI$2),0),'Cadastro dos Padrões'!$A$2:$V$921,AI$1,FALSE)="","-",VLOOKUP(ROUND(CONCATENATE($A9,AI$2),0),'Cadastro dos Padrões'!$A$2:$V$921,AI$1,FALSE)) -> 1000000 | ... CI9: =IF(VLOOKUP(ROUND(CONCATENATE($A9,CI$2),0),'Cadastro dos Padrões'!$A$2:$V$921,CI$1,FALSE)="","-",VLOOKUP(ROUND(CONCATENATE($A9,CI$2),0),'Cadastro dos Padrões'!$A$2:$V$921,CI$1,FALSE)) -> 0
A10: 5 | B10: =IF(VLOOKUP(ROUND(CONCATENATE($A10,B$2),0),'Cadastro dos Padrões'!$A$2:$V$921,B$1,FALSE)="","-",VLOOKUP(ROUND(CONCATENATE($A10,B$2),0),'Cadastro dos Padrões'!$A$2:$V$921,B$1,FALSE)) -> E.MS.LV-001 | C10: =IF(VLOOKUP(ROUND(CONCATENATE($A10,C$2),0),'Cadastro dos Padrões'!$A$2:$V$921,C$1,FALSE)="","-",VLOOKUP(ROUND(CONCATENATE($A10,C$2),0),'Cadastro dos Padrões'!$A$2:$V$921,C$1,FALSE)) -> Balança Eletrônica | D10: =IF(VLOOKUP(ROUND(CONCATENATE($A10,D$2),0),'Cadastro dos Padrões'!$A$2:$V$921,D$1,FALSE)="","-",VLOOKUP(ROUND(CONCATENATE($A10,D$2),0),'Cadastro dos Padrões'!$A$2:$V$921,D$1,FALSE)) -> Metrolab | E10: =IF(VLOOKUP(ROUND(CONCATENATE($A10,E$2),0),'Cadastro dos Padrões'!$A$2:$V$921,E$1,FALSE)="","-",VLOOKUP(ROUND(CONCATENATE($A10,E$2),0),'Cadastro dos Padrões'!$A$2:$V$921,E$1,FALSE)) -> RBC - CAL 0215 | F10: =IF(VLOOKUP(ROUND(CONCATENATE($A10,F$2),0),'Cadastro dos Padrões'!$A$2:$V$921,F$1,FALSE)="","-",VLOOKUP(ROUND(CONCATENATE($A10,F$2),0),'Cadastro dos Padrões'!$A$2:$V$921,F$1,FALSE)) -> M0075/25 | G10: =IF(VLOOKUP(ROUND(CONCATENATE($A10,G$2),0),'Cadastro dos Padrões'!$A$2:$V$921,G$1,FALSE)="","-",VLOOKUP(ROUND(CONCATENATE($A10,G$2),0),'Cadastro dos Padrões'!$A$2:$V$921,G$1,FALSE)) -> 45876 | H10: =IF(VLOOKUP(ROUND(CONCATENATE($A10,H$2),0),'Cadastro dos Padrões'!$A$2:$V$921,H$1,FALSE)="","-",VLOOKUP(ROUND(CONCATENATE($A10,H$2),0),'Cadastro dos Padrões'!$A$2:$V$921,H$1,FALSE)) -> 46264 | I10: =IF(VLOOKUP(ROUND(CONCATENATE($A10,I$2),0),'Cadastro dos Padrões'!$A$2:$V$921,I$1,FALSE)="","-",VLOOKUP(ROUND(CONCATENATE($A10,I$2),0),'Cadastro dos Padrões'!$A$2:$V$921,I$1,FALSE)) -> kg | ... P10: =IF(VLOOKUP(ROUND(CONCATENATE($A10,P$2),0),'Cadastro dos Padrões'!$A$2:$V$921,P$1,FALSE)="","-",VLOOKUP(ROUND(CONCATENATE($A10,P$2),0),'Cadastro dos Padrões'!$A$2:$V$921,P$1,FALSE)) -> 0 | Q10: =IF($B10="-","-",VLOOKUP(ROUND(CONCATENATE($A10,Q$2),0),'Cadastro dos Padrões'!$A$2:$V$921,Q$1,FALSE)) -> 3.5527137e-15 | R10: =IF($B10="-","-",VLOOKUP(ROUND(CONCATENATE($A10,R$2),0),'Cadastro dos Padrões'!$A$2:$V$921,R$1,FALSE)) -> 5 | S10: =IF($B10="-","-",VLOOKUP(ROUND(CONCATENATE($A10,S$2),0),'Cadastro dos Padrões'!$A$2:$V$921,S$1,FALSE)) -> 0 | T10: =IF($B10="-","-",VLOOKUP(ROUND(CONCATENATE($A10,T$2),0),'Cadastro dos Padrões'!$A$2:$V$921,T$1,FALSE)) -> 0 | U10: =IF($B10="-","-",VLOOKUP(ROUND(CONCATENATE($A10,U$2),0),'Cadastro dos Padrões'!$A$2:$V$921,U$1,FALSE)) -> 0 | V10: =IF($B10="-","-",VLOOKUP(ROUND(CONCATENATE($A10,V$2),0),'Cadastro dos Padrões'!$A$2:$V$921,V$1,FALSE)) -> -2.890859e-28 | W10: =IF($B10="-","-",VLOOKUP(ROUND(CONCATENATE($A10,W$2),0),'Cadastro dos Padrões'!$A$2:$V$921,W$1,FALSE)) -> 1.4493146e-24 | X10: =IF($B10="-","-",VLOOKUP(ROUND(CONCATENATE($A10,X$2),0),'Cadastro dos Padrões'!$A$2:$V$921,X$1,FALSE)) -> -2.6811992e-21 | ... AA10: =IF($B10="-","-",VLOOKUP(ROUND(CONCATENATE($A10,AA$2),0),'Cadastro dos Padrões'!$A$2:$V$921,AA$1,FALSE)) -> 3.7971165e-14 | AB10: =IF(VLOOKUP(ROUND(CONCATENATE($A10,AB$2),0),'Cadastro dos Padrões'!$A$2:$V$921,AB$1,FALSE)="","-",VLOOKUP(ROUND(CONCATENATE($A10,AB$2),0),'Cadastro dos Padrões'!$A$2:$V$921,AB$1,FALSE)) -> 2 | AC10: =IF(VLOOKUP(ROUND(CONCATENATE($A10,AC$2),0),'Cadastro dos Padrões'!$A$2:$V$921,AC$1,FALSE)="","-",VLOOKUP(ROUND(CONCATENATE($A10,AC$2),0),'Cadastro dos Padrões'!$A$2:$V$921,AC$1,FALSE)) -> 0.1 | AD10: =IF(VLOOKUP(ROUND(CONCATENATE($A10,AD$2),0),'Cadastro dos Padrões'!$A$2:$V$921,AD$1,FALSE)="","-",VLOOKUP(ROUND(CONCATENATE($A10,AD$2),0),'Cadastro dos Padrões'!$A$2:$V$921,AD$1,FALSE)) -> 2 | AE10: =IF(VLOOKUP(ROUND(CONCATENATE($A10,AE$2),0),'Cadastro dos Padrões'!$A$2:$V$921,AE$1,FALSE)="","-",VLOOKUP(ROUND(CONCATENATE($A10,AE$2),0),'Cadastro dos Padrões'!$A$2:$V$921,AE$1,FALSE)) -> 1000000 | AF10: =IF(VLOOKUP(ROUND(CONCATENATE($A10,AF$2),0),'Cadastro dos Padrões'!$A$2:$V$921,AF$1,FALSE)="","-",VLOOKUP(ROUND(CONCATENATE($A10,AF$2),0),'Cadastro dos Padrões'!$A$2:$V$921,AF$1,FALSE)) -> 10 | AG10: =IF(VLOOKUP(ROUND(CONCATENATE($A10,AG$2),0),'Cadastro dos Padrões'!$A$2:$V$921,AG$1,FALSE)="","-",VLOOKUP(ROUND(CONCATENATE($A10,AG$2),0),'Cadastro dos Padrões'!$A$2:$V$921,AG$1,FALSE)) -> 0.1 | AH10: =IF(VLOOKUP(ROUND(CONCATENATE($A10,AH$2),0),'Cadastro dos Padrões'!$A$2:$V$921,AH$1,FALSE)="","-",VLOOKUP(ROUND(CONCATENATE($A10,AH$2),0),'Cadastro dos Padrões'!$A$2:$V$921,AH$1,FALSE)) -> 2 | AI10: =IF(VLOOKUP(ROUND(CONCATENATE($A10,AI$2),0),'Cadastro dos Padrões'!$A$2:$V$921,AI$1,FALSE)="","-",VLOOKUP(ROUND(CONCATENATE($A10,AI$2),0),'Cadastro dos Padrões'!$A$2:$V$921,AI$1,FALSE)) -> 1000000 | ... CI10: =IF(VLOOKUP(ROUND(CONCATENATE($A10,CI$2),0),'Cadastro dos Padrões'!$A$2:$V$921,CI$1,FALSE)="","-",VLOOKUP(ROUND(CONCATENATE($A10,CI$2),0),'Cadastro dos Padrões'!$A$2:$V$921,CI$1,FALSE)) -> 0
A11: 6 | B11: =IF(VLOOKUP(ROUND(CONCATENATE($A11,B$2),0),'Cadastro dos Padrões'!$A$2:$V$921,B$1,FALSE)="","-",VLOOKUP(ROUND(CONCATENATE($A11,B$2),0),'Cadastro dos Padrões'!$A$2:$V$921,B$1,FALSE)) -> E.MS.LQ-004 | C11: =IF(VLOOKUP(ROUND(CONCATENATE($A11,C$2),0),'Cadastro dos Padrões'!$A$2:$V$921,C$1,FALSE)="","-",VLOOKUP(ROUND(CONCATENATE($A11,C$2),0),'Cadastro dos Padrões'!$A$2:$V$921,C$1,FALSE)) -> Balança Analítica | D11: =IF(VLOOKUP(ROUND(CONCATENATE($A11,D$2),0),'Cadastro dos Padrões'!$A$2:$V$921,D$1,FALSE)="","-",VLOOKUP(ROUND(CONCATENATE($A11,D$2),0),'Cadastro dos Padrões'!$A$2:$V$921,D$1,FALSE)) -> Elus | E11: =IF(VLOOKUP(ROUND(CONCATENATE($A11,E$2),0),'Cadastro dos Padrões'!$A$2:$V$921,E$1,FALSE)="","-",VLOOKUP(ROUND(CONCATENATE($A11,E$2),0),'Cadastro dos Padrões'!$A$2:$V$921,E$1,FALSE)) -> RBC - CAL 0439 | F11: =IF(VLOOKUP(ROUND(CONCATENATE($A11,F$2),0),'Cadastro dos Padrões'!$A$2:$V$921,F$1,FALSE)="","-",VLOOKUP(ROUND(CONCATENATE($A11,F$2),0),'Cadastro dos Padrões'!$A$2:$V$921,F$1,FALSE)) -> E0012/26 | G11: =IF(VLOOKUP(ROUND(CONCATENATE($A11,G$2),0),'Cadastro dos Padrões'!$A$2:$V$921,G$1,FALSE)="","-",VLOOKUP(ROUND(CONCATENATE($A11,G$2),0),'Cadastro dos Padrões'!$A$2:$V$921,G$1,FALSE)) -> 46031 | H11: =IF(VLOOKUP(ROUND(CONCATENATE($A11,H$2),0),'Cadastro dos Padrões'!$A$2:$V$921,H$1,FALSE)="","-",VLOOKUP(ROUND(CONCATENATE($A11,H$2),0),'Cadastro dos Padrões'!$A$2:$V$921,H$1,FALSE)) -> 46417 | I11: =IF(VLOOKUP(ROUND(CONCATENATE($A11,I$2),0),'Cadastro dos Padrões'!$A$2:$V$921,I$1,FALSE)="","-",VLOOKUP(ROUND(CONCATENATE($A11,I$2),0),'Cadastro dos Padrões'!$A$2:$V$921,I$1,FALSE)) -> g | ... P11: =IF(VLOOKUP(ROUND(CONCATENATE($A11,P$2),0),'Cadastro dos Padrões'!$A$2:$V$921,P$1,FALSE)="","-",VLOOKUP(ROUND(CONCATENATE($A11,P$2),0),'Cadastro dos Padrões'!$A$2:$V$921,P$1,FALSE)) -> 0.00014285714 | Q11: =IF($B11="-","-",VLOOKUP(ROUND(CONCATENATE($A11,Q$2),0),'Cadastro dos Padrões'!$A$2:$V$921,Q$1,FALSE)) -> 3.1373604e-09 | R11: =IF($B11="-","-",VLOOKUP(ROUND(CONCATENATE($A11,R$2),0),'Cadastro dos Padrões'!$A$2:$V$921,R$1,FALSE)) -> 5 | S11: =IF($B11="-","-",VLOOKUP(ROUND(CONCATENATE($A11,S$2),0),'Cadastro dos Padrões'!$A$2:$V$921,S$1,FALSE)) -> 0 | T11: =IF($B11="-","-",VLOOKUP(ROUND(CONCATENATE($A11,T$2),0),'Cadastro dos Padrões'!$A$2:$V$921,T$1,FALSE)) -> 0 | U11: =IF($B11="-","-",VLOOKUP(ROUND(CONCATENATE($A11,U$2),0),'Cadastro dos Padrões'!$A$2:$V$921,U$1,FALSE)) -> 0 | V11: =IF($B11="-","-",VLOOKUP(ROUND(CONCATENATE($A11,V$2),0),'Cadastro dos Padrões'!$A$2:$V$921,V$1,FALSE)) -> -1.37531e-13 | W11: =IF($B11="-","-",VLOOKUP(ROUND(CONCATENATE($A11,W$2),0),'Cadastro dos Padrões'!$A$2:$V$921,W$1,FALSE)) -> 4.2669813e-11 | X11: =IF($B11="-","-",VLOOKUP(ROUND(CONCATENATE($A11,X$2),0),'Cadastro dos Padrões'!$A$2:$V$921,X$1,FALSE)) -> -3.2004748e-09 | ... AA11: =IF($B11="-","-",VLOOKUP(ROUND(CONCATENATE($A11,AA$2),0),'Cadastro dos Padrões'!$A$2:$V$921,AA$1,FALSE)) -> 7.1363804e-09 | AB11: =IF(VLOOKUP(ROUND(CONCATENATE($A11,AB$2),0),'Cadastro dos Padrões'!$A$2:$V$921,AB$1,FALSE)="","-",VLOOKUP(ROUND(CONCATENATE($A11,AB$2),0),'Cadastro dos Padrões'!$A$2:$V$921,AB$1,FALSE)) -> 0.2 | AC11: =IF(VLOOKUP(ROUND(CONCATENATE($A11,AC$2),0),'Cadastro dos Padrões'!$A$2:$V$921,AC$1,FALSE)="","-",VLOOKUP(ROUND(CONCATENATE($A11,AC$2),0),'Cadastro dos Padrões'!$A$2:$V$921,AC$1,FALSE)) -> 0.0002 | AD11: =IF(VLOOKUP(ROUND(CONCATENATE($A11,AD$2),0),'Cadastro dos Padrões'!$A$2:$V$921,AD$1,FALSE)="","-",VLOOKUP(ROUND(CONCATENATE($A11,AD$2),0),'Cadastro dos Padrões'!$A$2:$V$921,AD$1,FALSE)) -> 2 | AE11: =IF(VLOOKUP(ROUND(CONCATENATE($A11,AE$2),0),'Cadastro dos Padrões'!$A$2:$V$921,AE$1,FALSE)="","-",VLOOKUP(ROUND(CONCATENATE($A11,AE$2),0),'Cadastro dos Padrões'!$A$2:$V$921,AE$1,FALSE)) -> 1000000 | AF11: =IF(VLOOKUP(ROUND(CONCATENATE($A11,AF$2),0),'Cadastro dos Padrões'!$A$2:$V$921,AF$1,FALSE)="","-",VLOOKUP(ROUND(CONCATENATE($A11,AF$2),0),'Cadastro dos Padrões'!$A$2:$V$921,AF$1,FALSE)) -> 0.5 | AG11: =IF(VLOOKUP(ROUND(CONCATENATE($A11,AG$2),0),'Cadastro dos Padrões'!$A$2:$V$921,AG$1,FALSE)="","-",VLOOKUP(ROUND(CONCATENATE($A11,AG$2),0),'Cadastro dos Padrões'!$A$2:$V$921,AG$1,FALSE)) -> 0.0002 | AH11: =IF(VLOOKUP(ROUND(CONCATENATE($A11,AH$2),0),'Cadastro dos Padrões'!$A$2:$V$921,AH$1,FALSE)="","-",VLOOKUP(ROUND(CONCATENATE($A11,AH$2),0),'Cadastro dos Padrões'!$A$2:$V$921,AH$1,FALSE)) -> 2 | AI11: =IF(VLOOKUP(ROUND(CONCATENATE($A11,AI$2),0),'Cadastro dos Padrões'!$A$2:$V$921,AI$1,FALSE)="","-",VLOOKUP(ROUND(CONCATENATE($A11,AI$2),0),'Cadastro dos Padrões'!$A$2:$V$921,AI$1,FALSE)) -> 1000000 | ... CI11: =IF(VLOOKUP(ROUND(CONCATENATE($A11,CI$2),0),'Cadastro dos Padrões'!$A$2:$V$921,CI$1,FALSE)="","-",VLOOKUP(ROUND(CONCATENATE($A11,CI$2),0),'Cadastro dos Padrões'!$A$2:$V$921,CI$1,FALSE)) -> 0
A12: 7 | B12: =IF(VLOOKUP(ROUND(CONCATENATE($A12,B$2),0),'Cadastro dos Padrões'!$A$2:$V$921,B$1,FALSE)="","-",VLOOKUP(ROUND(CONCATENATE($A12,B$2),0),'Cadastro dos Padrões'!$A$2:$V$921,B$1,FALSE)) -> E.MS.PMR-001 | C12: =IF(VLOOKUP(ROUND(CONCATENATE($A12,C$2),0),'Cadastro dos Padrões'!$A$2:$V$921,C$1,FALSE)="","-",VLOOKUP(ROUND(CONCATENATE($A12,C$2),0),'Cadastro dos Padrões'!$A$2:$V$921,C$1,FALSE)) -> Balança Analítica | D12: =IF(VLOOKUP(ROUND(CONCATENATE($A12,D$2),0),'Cadastro dos Padrões'!$A$2:$V$921,D$1,FALSE)="","-",VLOOKUP(ROUND(CONCATENATE($A12,D$2),0),'Cadastro dos Padrões'!$A$2:$V$921,D$1,FALSE)) -> Elus | E12: =IF(VLOOKUP(ROUND(CONCATENATE($A12,E$2),0),'Cadastro dos Padrões'!$A$2:$V$921,E$1,FALSE)="","-",VLOOKUP(ROUND(CONCATENATE($A12,E$2),0),'Cadastro dos Padrões'!$A$2:$V$921,E$1,FALSE)) -> RBC - CAL 0439 | F12: =IF(VLOOKUP(ROUND(CONCATENATE($A12,F$2),0),'Cadastro dos Padrões'!$A$2:$V$921,F$1,FALSE)="","-",VLOOKUP(ROUND(CONCATENATE($A12,F$2),0),'Cadastro dos Padrões'!$A$2:$V$921,F$1,FALSE)) -> E0018/26 | G12: =IF(VLOOKUP(ROUND(CONCATENATE($A12,G$2),0),'Cadastro dos Padrões'!$A$2:$V$921,G$1,FALSE)="","-",VLOOKUP(ROUND(CONCATENATE($A12,G$2),0),'Cadastro dos Padrões'!$A$2:$V$921,G$1,FALSE)) -> 46031 | H12: =IF(VLOOKUP(ROUND(CONCATENATE($A12,H$2),0),'Cadastro dos Padrões'!$A$2:$V$921,H$1,FALSE)="","-",VLOOKUP(ROUND(CONCATENATE($A12,H$2),0),'Cadastro dos Padrões'!$A$2:$V$921,H$1,FALSE)) -> 46417 | I12: =IF(VLOOKUP(ROUND(CONCATENATE($A12,I$2),0),'Cadastro dos Padrões'!$A$2:$V$921,I$1,FALSE)="","-",VLOOKUP(ROUND(CONCATENATE($A12,I$2),0),'Cadastro dos Padrões'!$A$2:$V$921,I$1,FALSE)) -> g | ... P12: =IF(VLOOKUP(ROUND(CONCATENATE($A12,P$2),0),'Cadastro dos Padrões'!$A$2:$V$921,P$1,FALSE)="","-",VLOOKUP(ROUND(CONCATENATE($A12,P$2),0),'Cadastro dos Padrões'!$A$2:$V$921,P$1,FALSE)) -> 0.00074 | Q12: =IF($B12="-","-",VLOOKUP(ROUND(CONCATENATE($A12,Q$2),0),'Cadastro dos Padrões'!$A$2:$V$921,Q$1,FALSE)) -> 6.3200901e-06 | R12: =IF($B12="-","-",VLOOKUP(ROUND(CONCATENATE($A12,R$2),0),'Cadastro dos Padrões'!$A$2:$V$921,R$1,FALSE)) -> 8 | S12: =IF($B12="-","-",VLOOKUP(ROUND(CONCATENATE($A12,S$2),0),'Cadastro dos Padrões'!$A$2:$V$921,S$1,FALSE)) -> -7.3930558e-15 | T12: =IF($B12="-","-",VLOOKUP(ROUND(CONCATENATE($A12,T$2),0),'Cadastro dos Padrões'!$A$2:$V$921,T$1,FALSE)) -> 1.3808071e-12 | U12: =IF($B12="-","-",VLOOKUP(ROUND(CONCATENATE($A12,U$2),0),'Cadastro dos Padrões'!$A$2:$V$921,U$1,FALSE)) -> -8.0311927e-11 | V12: =IF($B12="-","-",VLOOKUP(ROUND(CONCATENATE($A12,V$2),0),'Cadastro dos Padrões'!$A$2:$V$921,V$1,FALSE)) -> 1.7448544e-09 | W12: =IF($B12="-","-",VLOOKUP(ROUND(CONCATENATE($A12,W$2),0),'Cadastro dos Padrões'!$A$2:$V$921,W$1,FALSE)) -> -1.2867425e-08 | X12: =IF($B12="-","-",VLOOKUP(ROUND(CONCATENATE($A12,X$2),0),'Cadastro dos Padrões'!$A$2:$V$921,X$1,FALSE)) -> 0 | ... AA12: =IF($B12="-","-",VLOOKUP(ROUND(CONCATENATE($A12,AA$2),0),'Cadastro dos Padrões'!$A$2:$V$921,AA$1,FALSE)) -> -4.178227e-06 | AB12: =IF(VLOOKUP(ROUND(CONCATENATE($A12,AB$2),0),'Cadastro dos Padrões'!$A$2:$V$921,AB$1,FALSE)="","-",VLOOKUP(ROUND(CONCATENATE($A12,AB$2),0),'Cadastro dos Padrões'!$A$2:$V$921,AB$1,FALSE)) -> 0.001 | AC12: =IF(VLOOKUP(ROUND(CONCATENATE($A12,AC$2),0),'Cadastro dos Padrões'!$A$2:$V$921,AC$1,FALSE)="","-",VLOOKUP(ROUND(CONCATENATE($A12,AC$2),0),'Cadastro dos Padrões'!$A$2:$V$921,AC$1,FALSE)) -> 2e-05 | AD12: =IF(VLOOKUP(ROUND(CONCATENATE($A12,AD$2),0),'Cadastro dos Padrões'!$A$2:$V$921,AD$1,FALSE)="","-",VLOOKUP(ROUND(CONCATENATE($A12,AD$2),0),'Cadastro dos Padrões'!$A$2:$V$921,AD$1,FALSE)) -> 2 | AE12: =IF(VLOOKUP(ROUND(CONCATENATE($A12,AE$2),0),'Cadastro dos Padrões'!$A$2:$V$921,AE$1,FALSE)="","-",VLOOKUP(ROUND(CONCATENATE($A12,AE$2),0),'Cadastro dos Padrões'!$A$2:$V$921,AE$1,FALSE)) -> 1000000 | AF12: =IF(VLOOKUP(ROUND(CONCATENATE($A12,AF$2),0),'Cadastro dos Padrões'!$A$2:$V$921,AF$1,FALSE)="","-",VLOOKUP(ROUND(CONCATENATE($A12,AF$2),0),'Cadastro dos Padrões'!$A$2:$V$921,AF$1,FALSE)) -> 0.005 | AG12: =IF(VLOOKUP(ROUND(CONCATENATE($A12,AG$2),0),'Cadastro dos Padrões'!$A$2:$V$921,AG$1,FALSE)="","-",VLOOKUP(ROUND(CONCATENATE($A12,AG$2),0),'Cadastro dos Padrões'!$A$2:$V$921,AG$1,FALSE)) -> 2e-05 | AH12: =IF(VLOOKUP(ROUND(CONCATENATE($A12,AH$2),0),'Cadastro dos Padrões'!$A$2:$V$921,AH$1,FALSE)="","-",VLOOKUP(ROUND(CONCATENATE($A12,AH$2),0),'Cadastro dos Padrões'!$A$2:$V$921,AH$1,FALSE)) -> 2 | AI12: =IF(VLOOKUP(ROUND(CONCATENATE($A12,AI$2),0),'Cadastro dos Padrões'!$A$2:$V$921,AI$1,FALSE)="","-",VLOOKUP(ROUND(CONCATENATE($A12,AI$2),0),'Cadastro dos Padrões'!$A$2:$V$921,AI$1,FALSE)) -> 1000000 | ... CI12: =IF(VLOOKUP(ROUND(CONCATENATE($A12,CI$2),0),'Cadastro dos Padrões'!$A$2:$V$921,CI$1,FALSE)="","-",VLOOKUP(ROUND(CONCATENATE($A12,CI$2),0),'Cadastro dos Padrões'!$A$2:$V$921,CI$1,FALSE)) -> 0.0005
A13: 8 | B13: =IF(VLOOKUP(ROUND(CONCATENATE($A13,B$2),0),'Cadastro dos Padrões'!$A$2:$V$921,B$1,FALSE)="","-",VLOOKUP(ROUND(CONCATENATE($A13,B$2),0),'Cadastro dos Padrões'!$A$2:$V$921,B$1,FALSE)) -> E.MS.PMR-003 | C13: =IF(VLOOKUP(ROUND(CONCATENATE($A13,C$2),0),'Cadastro dos Padrões'!$A$2:$V$921,C$1,FALSE)="","-",VLOOKUP(ROUND(CONCATENATE($A13,C$2),0),'Cadastro dos Padrões'!$A$2:$V$921,C$1,FALSE)) -> Balança eletrônica | D13: =IF(VLOOKUP(ROUND(CONCATENATE($A13,D$2),0),'Cadastro dos Padrões'!$A$2:$V$921,D$1,FALSE)="","-",VLOOKUP(ROUND(CONCATENATE($A13,D$2),0),'Cadastro dos Padrões'!$A$2:$V$921,D$1,FALSE)) -> Elus | E13: =IF(VLOOKUP(ROUND(CONCATENATE($A13,E$2),0),'Cadastro dos Padrões'!$A$2:$V$921,E$1,FALSE)="","-",VLOOKUP(ROUND(CONCATENATE($A13,E$2),0),'Cadastro dos Padrões'!$A$2:$V$921,E$1,FALSE)) -> RBC - CAL 0439 | F13: =IF(VLOOKUP(ROUND(CONCATENATE($A13,F$2),0),'Cadastro dos Padrões'!$A$2:$V$921,F$1,FALSE)="","-",VLOOKUP(ROUND(CONCATENATE($A13,F$2),0),'Cadastro dos Padrões'!$A$2:$V$921,F$1,FALSE)) -> E0020/26 | G13: =IF(VLOOKUP(ROUND(CONCATENATE($A13,G$2),0),'Cadastro dos Padrões'!$A$2:$V$921,G$1,FALSE)="","-",VLOOKUP(ROUND(CONCATENATE($A13,G$2),0),'Cadastro dos Padrões'!$A$2:$V$921,G$1,FALSE)) -> 46031 | H13: =IF(VLOOKUP(ROUND(CONCATENATE($A13,H$2),0),'Cadastro dos Padrões'!$A$2:$V$921,H$1,FALSE)="","-",VLOOKUP(ROUND(CONCATENATE($A13,H$2),0),'Cadastro dos Padrões'!$A$2:$V$921,H$1,FALSE)) -> 46417 | I13: =IF(VLOOKUP(ROUND(CONCATENATE($A13,I$2),0),'Cadastro dos Padrões'!$A$2:$V$921,I$1,FALSE)="","-",VLOOKUP(ROUND(CONCATENATE($A13,I$2),0),'Cadastro dos Padrões'!$A$2:$V$921,I$1,FALSE)) -> kg | ... P13: =IF(VLOOKUP(ROUND(CONCATENATE($A13,P$2),0),'Cadastro dos Padrões'!$A$2:$V$921,P$1,FALSE)="","-",VLOOKUP(ROUND(CONCATENATE($A13,P$2),0),'Cadastro dos Padrões'!$A$2:$V$921,P$1,FALSE)) -> 0.005 | Q13: =IF($B13="-","-",VLOOKUP(ROUND(CONCATENATE($A13,Q$2),0),'Cadastro dos Padrões'!$A$2:$V$921,Q$1,FALSE)) -> 0.00016372154 | R13: =IF($B13="-","-",VLOOKUP(ROUND(CONCATENATE($A13,R$2),0),'Cadastro dos Padrões'!$A$2:$V$921,R$1,FALSE)) -> 5 | S13: =IF($B13="-","-",VLOOKUP(ROUND(CONCATENATE($A13,S$2),0),'Cadastro dos Padrões'!$A$2:$V$921,S$1,FALSE)) -> 0 | T13: =IF($B13="-","-",VLOOKUP(ROUND(CONCATENATE($A13,T$2),0),'Cadastro dos Padrões'!$A$2:$V$921,T$1,FALSE)) -> 0 | U13: =IF($B13="-","-",VLOOKUP(ROUND(CONCATENATE($A13,U$2),0),'Cadastro dos Padrões'!$A$2:$V$921,U$1,FALSE)) -> 0 | V13: =IF($B13="-","-",VLOOKUP(ROUND(CONCATENATE($A13,V$2),0),'Cadastro dos Padrões'!$A$2:$V$921,V$1,FALSE)) -> -3.9706871e-11 | W13: =IF($B13="-","-",VLOOKUP(ROUND(CONCATENATE($A13,W$2),0),'Cadastro dos Padrões'!$A$2:$V$921,W$1,FALSE)) -> 3.2691648e-09 | X13: =IF($B13="-","-",VLOOKUP(ROUND(CONCATENATE($A13,X$2),0),'Cadastro dos Padrões'!$A$2:$V$921,X$1,FALSE)) -> -1.5669107e-08 | ... AA13: =IF($B13="-","-",VLOOKUP(ROUND(CONCATENATE($A13,AA$2),0),'Cadastro dos Padrões'!$A$2:$V$921,AA$1,FALSE)) -> -3.1110532e-05 | AB13: =IF(VLOOKUP(ROUND(CONCATENATE($A13,AB$2),0),'Cadastro dos Padrões'!$A$2:$V$921,AB$1,FALSE)="","-",VLOOKUP(ROUND(CONCATENATE($A13,AB$2),0),'Cadastro dos Padrões'!$A$2:$V$921,AB$1,FALSE)) -> 1 | AC13: =IF(VLOOKUP(ROUND(CONCATENATE($A13,AC$2),0),'Cadastro dos Padrões'!$A$2:$V$921,AC$1,FALSE)="","-",VLOOKUP(ROUND(CONCATENATE($A13,AC$2),0),'Cadastro dos Padrões'!$A$2:$V$921,AC$1,FALSE)) -> 0.002 | AD13: =IF(VLOOKUP(ROUND(CONCATENATE($A13,AD$2),0),'Cadastro dos Padrões'!$A$2:$V$921,AD$1,FALSE)="","-",VLOOKUP(ROUND(CONCATENATE($A13,AD$2),0),'Cadastro dos Padrões'!$A$2:$V$921,AD$1,FALSE)) -> 2 | AE13: =IF(VLOOKUP(ROUND(CONCATENATE($A13,AE$2),0),'Cadastro dos Padrões'!$A$2:$V$921,AE$1,FALSE)="","-",VLOOKUP(ROUND(CONCATENATE($A13,AE$2),0),'Cadastro dos Padrões'!$A$2:$V$921,AE$1,FALSE)) -> 1000000 | AF13: =IF(VLOOKUP(ROUND(CONCATENATE($A13,AF$2),0),'Cadastro dos Padrões'!$A$2:$V$921,AF$1,FALSE)="","-",VLOOKUP(ROUND(CONCATENATE($A13,AF$2),0),'Cadastro dos Padrões'!$A$2:$V$921,AF$1,FALSE)) -> 10 | AG13: =IF(VLOOKUP(ROUND(CONCATENATE($A13,AG$2),0),'Cadastro dos Padrões'!$A$2:$V$921,AG$1,FALSE)="","-",VLOOKUP(ROUND(CONCATENATE($A13,AG$2),0),'Cadastro dos Padrões'!$A$2:$V$921,AG$1,FALSE)) -> 0.002 | AH13: =IF(VLOOKUP(ROUND(CONCATENATE($A13,AH$2),0),'Cadastro dos Padrões'!$A$2:$V$921,AH$1,FALSE)="","-",VLOOKUP(ROUND(CONCATENATE($A13,AH$2),0),'Cadastro dos Padrões'!$A$2:$V$921,AH$1,FALSE)) -> 2 | AI13: =IF(VLOOKUP(ROUND(CONCATENATE($A13,AI$2),0),'Cadastro dos Padrões'!$A$2:$V$921,AI$1,FALSE)="","-",VLOOKUP(ROUND(CONCATENATE($A13,AI$2),0),'Cadastro dos Padrões'!$A$2:$V$921,AI$1,FALSE)) -> 1000000 | ... CI13: =IF(VLOOKUP(ROUND(CONCATENATE($A13,CI$2),0),'Cadastro dos Padrões'!$A$2:$V$921,CI$1,FALSE)="","-",VLOOKUP(ROUND(CONCATENATE($A13,CI$2),0),'Cadastro dos Padrões'!$A$2:$V$921,CI$1,FALSE)) -> 0
