Workbook
Name _Z99999: [1]Cliente!#REF!
Name _Z99999: [1]Cliente!#REF!
Name _ZZ99: [1]Cliente!#REF!
Name _ZZ99: [1]Cliente!#REF!
Name capacidade: [2]Dados!$F$11
Name CERTIFICADO: [1]Cliente!$Y$8
Name data_receb: [2]Dados!$E$7
Name DATA_RECEBIMENTO: [1]Cliente!#REF!
Name ENTRADA: [1]Cliente!#REF!
Name equip: [2]Dados!$C$10
Name n_cert: [2]Dados!$C$8
Name n_ident: [2]Dados!$C$13
Name n_serie: [2]Dados!$C$14
Name pressão: [2]Dados!$D$27
Name proced: [2]Dados!$F$13
Name resolução: [2]Dados!$F$10
Name temp_ar: [2]Dados!$D$25
Name temp_carr: #REF!
Name umid: [2]Dados!#REF!
Name unid_e: [2]Dados!$D$31
Name versão: [2]Dados!$F$14

Sheet Cadastro - Padrões
A1: 1 | B1: 2 | C1: =B1+1 -> 3 | D1: =C1+1 -> 4 | E1: =D1+1 -> 5 | F1: =E1+1 -> 6 | G1: =F1+1 -> 7 | H1: =G1+1 -> 8 | I1: =H1+1 -> 9 | J1: =I1+1 -> 10 | ... T1: =S1+1 -> 20
A2: =ROUND(CONCATENATE(S2,T2),0) -> 1201 | B2: Padrão : | D2: Barômetro Digital | L2: 1 | M2: 2 | N2: 3 | O2: 4 | P2: 5 | Q2: 6 | R2: 7 | S2: =A1 -> 1 | T2: 201 | V2: at
A3: =ROUND(CONCATENATE(S3,T3),0) -> 1202 | K3: Residuo | M3: X3 | N3: X2 | O3: X1 | P3: X0 | S3: =S2 -> 1 | T3: 202 | V3: atm
A4: =ROUND(CONCATENATE(S4,T4),0) -> 1203 | B4: Identificação : | D4: X.TH.LV-001 | K4: =IF(K6>=3,N6,LOOKUP(15-($B33+1),M2:R2,M6:P6)) -> 0.0085773889 | L4: =CONCATENATE($B33,"1") -> 41 | M4: =VLOOKUP(L4,J7:P58,O2,FALSE) -> -1.6624348e-09 | N4: =VLOOKUP(L4,J7:P58,P2,FALSE) -> 3.7566008e-06 | O4: =VLOOKUP(L4,J7:P58,Q2,FALSE) -> 0.99781208 | P4: =VLOOKUP(L4,J7:P58,R2,FALSE) -> -0.1364472 | S4: =S3 -> 1 | T4: 203 | V4: bar
A5: =ROUND(CONCATENATE(S5,T5),0) -> 1204 | B5: Orgão Calibrador : | D5: ELUS | K5: Veff | L5: =CONCATENATE($B33,"2") -> 42 | M5: =VLOOKUP(L5,J7:P58,O2,FALSE) -> 6.2048656e-10 | N5: =VLOOKUP(L5,J7:P58,P2,FALSE) -> 1.4922136e-06 | O5: =VLOOKUP(L5,J7:P58,Q2,FALSE) -> 0.001156908 | P5: =VLOOKUP(L5,J7:P58,R2,FALSE) -> 0.28800324 | S5: =S4 -> 1 | T5: 204 | V5: cmH2O
A6: =ROUND(CONCATENATE(S6,T6),0) -> 1205 | B6: Rastreabilidade : | D6: RBC - CAL 0439 | K6: =IF(B33>3,3,B33) -> 3 | L6: =CONCATENATE($B33,"3") -> 43 | M6: =VLOOKUP(L6,J7:P58,O2,FALSE) -> 1 | N6: =VLOOKUP(L6,J7:P58,P2,FALSE) -> 0.0085773889 | O6: =VLOOKUP(L6,J7:P58,Q2,FALSE) -> #N/A | P6: =VLOOKUP(L6,J7:P58,R2,FALSE) -> #N/A | S6: =S5 -> 1 | T6: 205 | V6: cmH2O (4 °C)
A7: =ROUND(CONCATENATE(S7,T7),0) -> 1206 | B7: N° do certificado : | D7: E0369B/24 | J7: 13 | M7: X3 | N7: X2 | O7: X1 | P7: X0 | S7: =S6 -> 1 | T7: 206 | V7: cmHg
A8: =ROUND(CONCATENATE(S8,T8),0) -> 1207 | B8: Data da Calibração : | D8: 45559 | J8: =CONCATENATE(J7,"1") -> 131 | M8: {=LINEST($B18:$B32,$C18:$C32^{1,2,3},TRUE,TRUE)} -> #VALUE! | N8: #VALUE! | O8: #VALUE! | P8: #VALUE! | S8: =S7 -> 1 | T8: 207 | V8: cmHg (0 °C)
A9: =ROUND(CONCATENATE(S9,T9),0) -> 1208 | B9: Vencimento da Calibração : | D9: =D8+365 -> 45924 | J9: =CONCATENATE(J7,"2") -> 132 | M9: #VALUE! | N9: #VALUE! | O9: #VALUE! | P9: #VALUE! | S9: =S8 -> 1 | T9: 208 | V9: dyn/cm²
A10: =ROUND(CONCATENATE(S10,T10),0) -> 1209 | B10: Divisão de escala : | D10: 0.01 | E10: Unidade calibrada : | H10: hPa | J10: =CONCATENATE(J7,"3") -> 133 | M10: #VALUE! | N10: #VALUE! | O10: #VALUE! | P10: #VALUE! | S10: =S9 -> 1 | T10: 209 | V10: ftH2O
A11: =ROUND(CONCATENATE(S11,T11),0) -> 1210 | B11: Faixa de medição : | D11: =MIN(B18:B32) -> 500.04 | E11: ~ | F11: =MAX(B18:B32) -> 1099.15 | G11: =IF(H10="","",H10) -> hPa | J11: =J7-1 -> 12 | M11: X3 | N11: X2 | O11: X1 | P11: X0 | S11: =S10 -> 1 | T11: 210 | V11: ftH2O (4 °C)
A12: =ROUND(CONCATENATE(S12,T12),0) -> 1211 | J12: =CONCATENATE(J11,"1") -> 121 | M12: {=LINEST($B18:$B31,$C18:$C31^{1,2,3},TRUE,TRUE)} -> #VALUE! | N12: #VALUE! | O12: #VALUE! | P12: #VALUE! | S12: =S11 -> 1 | T12: 211 | V12: ftHg
A13: =ROUND(CONCATENATE(S13,T13),0) -> 1212 | B13: Valores da Calibração Atual | G13: Calibração Anterior | J13: =CONCATENATE(J11,"2") -> 122 | M13: #VALUE! | N13: #VALUE! | O13: #VALUE! | P13: #VALUE! | S13: =S12 -> 1 | T13: 212 | V13: gf/cm²
A14: =ROUND(CONCATENATE(S14,T14),0) -> 1213 | B14: Certificado | E14: =IF(D7="","",D7) -> E0369B/24 | G14: Certificado | H14: E14052B/23 | J14: =CONCATENATE(J11,"3") -> 123 | M14: #VALUE! | N14: #VALUE! | O14: #VALUE! | P14: #VALUE! | S14: =S13 -> 1 | T14: 213 | V14: hPa
A15: =ROUND(CONCATENATE(S15,T15),0) -> 1214 | B15: Valor | C15: Leitura do | D15: Incerteza | F15: Grau de liberdade | G15: Valor | H15: Leitura do | J15: =J11-1 -> 11 | M15: X3 | N15: X2 | O15: X1 | P15: X0 | S15: =S14 -> 1 | T15: 214 | V15: inH2O
A16: =ROUND(CONCATENATE(S16,T16),0) -> 1215 | B16: Referência | C16: Instrumento | D16: de Medição | E16: k | G16: Referência | H16: Instrumento | J16: =CONCATENATE(J15,"1") -> 111 | M16: {=LINEST($B18:$B30,$C18:$C30^{1,2,3},TRUE,TRUE)} -> #VALUE! | N16: #VALUE! | O16: #VALUE! | P16: #VALUE! | S16: =S15 -> 1 | T16: 215 | V16: inH2O (15,6 °C)
A17: =ROUND(CONCATENATE(S17,T17),0) -> 1216 | B17: =IF(H10="","",H10) -> hPa | C17: =IF(H10="","",H10) -> hPa | D17: =IF(H10="","",H10) -> hPa | F17: =IF(I10="","",I10) | G17: =IF(H10="","",H10) -> hPa | H17: =IF(H10="","",H10) -> hPa | J17: =CONCATENATE(J15,"2") -> 112 | M17: #VALUE! | N17: #VALUE! | O17: #VALUE! | P17: #VALUE! | S17: =S16 -> 1 | T17: 216 | V17: inH2O (4 °C)
A18: =ROUND(CONCATENATE(S18,T18),0) -> 1217 | B18: 500.04 | C18: 500.54 | D18: 0.06 | E18: 2 | F18: 1000000 | G18: 500 | H18: 500.43 | J18: =CONCATENATE(J15,"3") -> 113 | M18: #VALUE! | N18: #VALUE! | O18: #VALUE! | P18: #VALUE! | S18: =S17 -> 1 | T18: 217 | V18: inHg
A19: =ROUND(CONCATENATE(S19,T19),0) -> 1218 | B19: 620.07 | C19: 620.51 | D19: 0.06 | E19: 2 | F19: 1000000 | G19: 619.61 | H19: 620 | J19: =J15-1 -> 10 | M19: X3 | N19: X2 | O19: X1 | P19: X0 | S19: =S18 -> 1 | T19: 218 | V19: inHg (0 °C)
A20: =ROUND(CONCATENATE(S20,T20),0) -> 1219 | B20: 740.11 | C20: 740.49 | D20: 0.08 | E20: 2 | F20: 1000000 | G20: 739.63 | H20: 740 | J20: =CONCATENATE(J19,"1") -> 101 | M20: {=LINEST($B18:$B29,$C18:$C29^{1,2,3},TRUE,TRUE)} -> #VALUE! | N20: #VALUE! | O20: #VALUE! | P20: #VALUE! | S20: =S19 -> 1 | T20: 219 | V20: inHg (15,6 °C)
A21: =ROUND(CONCATENATE(S21,T21),0) -> 1220 | B21: 860.13 | C21: 860.42 | D21: 0.09 | E21: 2 | F21: 1000000 | G21: 859.73 | H21: 860 | J21: =CONCATENATE(J19,"2") -> 102 | M21: #VALUE! | N21: #VALUE! | O21: #VALUE! | P21: #VALUE! | S21: =S20 -> 1 | T21: 220 | V21: kgf/cm²
A22: =ROUND(CONCATENATE(S22,T22),0) -> 1221 | B22: 980.15 | C22: 980.39 | D22: 0.1 | E22: 2 | F22: 1000000 | G22: 979.78 | H22: 980 | J22: =CONCATENATE(J19,"3") -> 103 | M22: #VALUE! | N22: #VALUE! | O22: #VALUE! | P22: #VALUE! | S22: =S21 -> 1 | T22: 221 | V22: kgf/m²
A23: =ROUND(CONCATENATE(S23,T23),0) -> 1222 | B23: 1099.15 | C23: 1099.36 | D23: 0.11 | E23: 2 | F23: 1000000 | G23: 1099.82 | H23: 1100 | J23: =J19-1 -> 9 | M23: X3 | N23: X2 | O23: X1 | P23: X0 | S23: =S22 -> 1 | T23: 222 | V23: kgf/mm²
A24: =ROUND(CONCATENATE(S24,T24),0) -> 1223 | J24: =CONCATENATE(J23,"1") -> 91 | M24: {=LINEST($B18:$B28,$C18:$C28^{1,2,3},TRUE,TRUE)} -> #VALUE! | N24: #VALUE! | O24: #VALUE! | P24: #VALUE! | S24: =S23 -> 1 | T24: 223 | V24: kip/in²
A25: =ROUND(CONCATENATE(S25,T25),0) -> 1224 | J25: =CONCATENATE(J23,"2") -> 92 | M25: #VALUE! | N25: #VALUE! | O25: #VALUE! | P25: #VALUE! | S25: =S24 -> 1 | T25: 224 | V25: kp/cm²
A26: =ROUND(CONCATENATE(S26,T26),0) -> 1225 | J26: =CONCATENATE(J23,"3") -> 93 | M26: #VALUE! | N26: #VALUE! | O26: #VALUE! | P26: #VALUE! | S26: =S25 -> 1 | T26: 225 | V26: kPa
A27: =ROUND(CONCATENATE(S27,T27),0) -> 1226 | J27: =J23-1 -> 8 | M27: X3 | N27: X2 | O27: X1 | P27: X0 | S27: =S26 -> 1 | T27: 226 | V27: ksi
A28: =ROUND(CONCATENATE(S28,T28),0) -> 1227 | J28: =CONCATENATE(J27,"1") -> 81 | M28: {=LINEST($B18:$B27,$C18:$C27^{1,2,3},TRUE,TRUE)} -> #VALUE! | N28: #VALUE! | O28: #VALUE! | P28: #VALUE! | S28: =S27 -> 1 | T28: 227 | V28: lbf/ft²
A29: =ROUND(CONCATENATE(S29,T29),0) -> 1228 | J29: =CONCATENATE(J27,"2") -> 82 | M29: #VALUE! | N29: #VALUE! | O29: #VALUE! | P29: #VALUE! | S29: =S28 -> 1 | T29: 228 | V29: lbf/in²
A30: =ROUND(CONCATENATE(S30,T30),0) -> 1229 | J30: =CONCATENATE(J27,"3") -> 83 | M30: #VALUE! | N30: #VALUE! | O30: #VALUE! | P30: #VALUE! | S30: =S29 -> 1 | T30: 229 | V30: mbar
A31: =ROUND(CONCATENATE(S31,T31),0) -> 1230 | J31: =J27-1 -> 7 | M31: X3 | N31: X2 | O31: X1 | P31: X0 | S31: =S30 -> 1 | T31: 230 | V31: mH2O
A32: =ROUND(CONCATENATE(S32,T32),0) -> 1231 | J32: =CONCATENATE(J31,"1") -> 71 | M32: {=LINEST($B18:$B26,$C18:$C26^{1,2,3},TRUE,TRUE)} -> #VALUE! | N32: #VALUE! | O32: #VALUE! | P32: #VALUE! | S32: =S31 -> 1 | T32: 231 | V32: mH2O (4 °C)
A33: =ROUND(CONCATENATE(S33,T33),0) -> 1232 | B33: =COUNT(B18:B32)-2 -> 4 | J33: =CONCATENATE(J31,"2") -> 72 | M33: #VALUE! | N33: #VALUE! | O33: #VALUE! | P33: #VALUE! | S33: =S32 -> 1 | T33: 232 | V33: mmH2O
A34: =ROUND(CONCATENATE(S34,T34),0) -> 1233 | J34: =CONCATENATE(J31,"3") -> 73 | M34: #VALUE! | N34: #VALUE! | O34: #VALUE! | P34: #VALUE! | S34: =S33 -> 1 | T34: 233 | V34: mmH2O (4 °C)
A35: =ROUND(CONCATENATE(S35,T35),0) -> 1234 | B35: Observações (particularidades para utilização) | J35: =J31-1 -> 6 | M35: X3 | N35: X2 | O35: X1 | P35: X0 | S35: =S34 -> 1 | T35: 234 | V35: mmHg
A36: =ROUND(CONCATENATE(S36,T36),0) -> 1235 | J36: =CONCATENATE(J35,"1") -> 61 | M36: {=LINEST($B18:$B25,$C18:$C25^{1,2,3},TRUE,TRUE)} -> #VALUE! | N36: #VALUE! | O36: #VALUE! | P36: #VALUE! | S36: =S35 -> 1 | T36: 235 | V36: mmHg (0 °C)
A37: =ROUND(CONCATENATE(S37,T37),0) -> 1236 | J37: =CONCATENATE(J35,"2") -> 62 | M37: #VALUE! | N37: #VALUE! | O37: #VALUE! | P37: #VALUE! | S37: =S36 -> 1 | T37: 236 | V37: MPa
A38: =ROUND(CONCATENATE(S38,T38),0) -> 1237 | J38: =CONCATENATE(J35,"3") -> 63 | M38: #VALUE! | N38: #VALUE! | O38: #VALUE! | P38: #VALUE! | S38: =S37 -> 1 | T38: 237 | V38: N/cm²
A39: =ROUND(CONCATENATE(S39,T39),0) -> 1238 | J39: =J35-1 -> 5 | M39: X3 | N39: X2 | O39: X1 | P39: X0 | S39: =S38 -> 1 | T39: 238 | V39: N/m²
A40: =ROUND(CONCATENATE(S40,T40),0) -> 1239 | J40: =CONCATENATE(J39,"1") -> 51 | M40: {=LINEST($B18:$B24,$C18:$C24^{1,2,3},TRUE,TRUE)} -> #VALUE! | N40: #VALUE! | O40: #VALUE! | P40: #VALUE! | S40: =S39 -> 1 | T40: 239 | V40: N/mm²
...

Sheet Controle
B1: 4 | C1: 4 | D1: 4 | E1: 4 | F1: 4 | G1: 4 | H1: 4 | I1: 8 | J1: 4 | K1: 6 | L1: 4 | M1: 5 | N1: 5 | O1: 5 | P1: 11 | Q1: 11 | R1: 13 | S1: 14 | T1: 15 | U1: 16 | V1: 2 | W1: 4 | X1: 5 | Y1: 6 | Z1: 2 | AA1: 4 | AB1: 5 | AC1: 6 | AD1: 2 | AE1: 4 | AF1: 5 | AG1: 6 | AH1: 2 | AI1: 4 | AJ1: 5 | AK1: 6 | AL1: 2 | AM1: 4 | AN1: 5 | AO1: 6 | AP1: 2 | AQ1: 4 | AR1: 5 | AS1: 6 | AT1: 2 | AU1: 4 | AV1: 5 | AW1: 6 | AX1: 2 | AY1: 4 | AZ1: 5 | BA1: 6 | BB1: 2 | BC1: 4 | BD1: 5 | BE1: 6 | BF1: 2 | BG1: 4 | BH1: 5 | BI1: 6 | BJ1: 2 | BK1: 4 | BL1: 5 | BM1: 6 | BN1: 2 | BO1: 4 | BP1: 5 | BQ1: 6 | BR1: 2 | BS1: 4 | BT1: 5 | BU1: 6 | BV1: 2 | BW1: 4 | BX1: 5 | BY1: 6 | BZ1: 2 | CA1: 4 | CB1: 5 | CC1: 6
B2: 203 | C2: 201 | D2: 204 | E2: 205 | F2: 206 | G2: 207 | H2: 208 | I2: 209 | J2: 210 | K2: 210 | L2: 209 | M2: 245 | N2: 249 | O2: 241 | P2: 203 | Q2: 205 | R2: 203 | S2: 203 | T2: 203 | U2: 203 | V2: 217 | W2: =V2 -> 217 | X2: =W2 -> 217 | Y2: =X2 -> 217 | Z2: =Y2+1 -> 218 | AA2: =Z2 -> 218 | AB2: =AA2 -> 218 | AC2: =AB2 -> 218 | AD2: =AC2+1 -> 219 | AE2: =AD2 -> 219 | AF2: =AE2 -> 219 | AG2: =AF2 -> 219 | AH2: =AG2+1 -> 220 | AI2: =AH2 -> 220 | AJ2: =AI2 -> 220 | AK2: =AJ2 -> 220 | AL2: =AK2+1 -> 221 | AM2: =AL2 -> 221 | AN2: =AM2 -> 221 | AO2: =AN2 -> 221 | AP2: =AO2+1 -> 222 | AQ2: =AP2 -> 222 | AR2: =AQ2 -> 222 | AS2: =AR2 -> 222 | AT2: =AS2+1 -> 223 | AU2: =AT2 -> 223 | AV2: =AU2 -> 223 | AW2: =AV2 -> 223 | AX2: =AW2+1 -> 224 | AY2: =AX2 -> 224 | AZ2: =AY2 -> 224 | BA2: =AZ2 -> 224 | BB2: =BA2+1 -> 225 | BC2: =BB2 -> 225 | BD2: =BC2 -> 225 | BE2: =BD2 -> 225 | BF2: =BE2+1 -> 226 | BG2: =BF2 -> 226 | BH2: =BG2 -> 226 | BI2: =BH2 -> 226 | BJ2: =BI2+1 -> 227 | BK2: =BJ2 -> 227 | BL2: =BK2 -> 227 | BM2: =BL2 -> 227 | BN2: =BM2+1 -> 228 | BO2: =BN2 -> 228 | BP2: =BO2 -> 228 | BQ2: =BP2 -> 228 | BR2: =BQ2+1 -> 229 | BS2: =BR2 -> 229 | BT2: =BS2 -> 229 | BU2: =BT2 -> 229 | BV2: =BU2+1 -> 230 | BW2: =BV2 -> 230 | BX2: =BW2 -> 230 | BY2: =BX2 -> 230 | BZ2: =BY2+1 -> 231 | CA2: =BZ2 -> 231 | CB2: =CA2 -> 231 | CC2: =CB2 -> 231
V3: 1 | W3: =V3 -> 1 | X3: =W3 -> 1 | Y3: =X3 -> 1 | Z3: =Y3+1 -> 2 | AA3: =Z3 -> 2 | AB3: =AA3 -> 2 | AC3: =AB3 -> 2 | AD3: =AC3+1 -> 3 | AE3: =AD3 -> 3 | AF3: =AE3 -> 3 | AG3: =AF3 -> 3 | AH3: =AG3+1 -> 4 | AI3: =AH3 -> 4 | AJ3: =AI3 -> 4 | AK3: =AJ3 -> 4 | AL3: =AK3+1 -> 5 | AM3: =AL3 -> 5 | AN3: =AM3 -> 5 | AO3: =AN3 -> 5 | AP3: =AO3+1 -> 6 | AQ3: =AP3 -> 6 | AR3: =AQ3 -> 6 | AS3: =AR3 -> 6 | AT3: =AS3+1 -> 7 | AU3: =AT3 -> 7 | AV3: =AU3 -> 7 | AW3: =AV3 -> 7 | AX3: =AW3+1 -> 8 | AY3: =AX3 -> 8 | AZ3: =AY3 -> 8 | BA3: =AZ3 -> 8 | BB3: =BA3+1 -> 9 | BC3: =BB3 -> 9 | BD3: =BC3 -> 9 | BE3: =BD3 -> 9 | BF3: =BE3+1 -> 10 | BG3: =BF3 -> 10 | BH3: =BG3 -> 10 | BI3: =BH3 -> 10 | BJ3: =BI3+1 -> 11 | BK3: =BJ3 -> 11 | BL3: =BK3 -> 11 | BM3: =BL3 -> 11 | BN3: =BM3+1 -> 12 | BO3: =BN3 -> 12 | BP3: =BO3 -> 12 | BQ3: =BP3 -> 12 | BR3: =BQ3+1 -> 13 | BS3: =BR3 -> 13 | BT3: =BS3 -> 13 | BU3: =BT3 -> 13 | BV3: =BU3+1 -> 14 | BW3: =BV3 -> 14 | BX3: =BW3 -> 14 | BY3: =BX3 -> 14 | BZ3: =BY3+1 -> 15 | CA3: =BZ3 -> 15 | CB3: =CA3 -> 15 | CC3: =CB3 -> 15
H4: =TODAY() -> 46076 | P4: Polinômio da Curva | V4: =CONCATENATE(V3,"º Ponto") -> 1º Ponto | Z4: =CONCATENATE(Z3,"º Ponto") -> 2º Ponto | AD4: =CONCATENATE(AD3,"º Ponto") -> 3º Ponto | AH4: =CONCATENATE(AH3,"º Ponto") -> 4º Ponto | AL4: =CONCATENATE(AL3,"º Ponto") -> 5º Ponto | AP4: =CONCATENATE(AP3,"º Ponto") -> 6º Ponto | AT4: =CONCATENATE(AT3,"º Ponto") -> 7º Ponto | AX4: =CONCATENATE(AX3,"º Ponto") -> 8º Ponto | BB4: =CONCATENATE(BB3,"º Ponto") -> 9º Ponto | BF4: =CONCATENATE(BF3,"º Ponto") -> 10º Ponto | BJ4: =CONCATENATE(BJ3,"º Ponto") -> 11º Ponto | BN4: =CONCATENATE(BN3,"º Ponto") -> 12º Ponto | BR4: =CONCATENATE(BR3,"º Ponto") -> 13º Ponto | BV4: =CONCATENATE(BV3,"º Ponto") -> 14º Ponto | BZ4: =CONCATENATE(BZ3,"º Ponto") -> 15º Ponto
B5: TAG | C5: Padrão | D5: Calibrado por | E5: Rastreabilidade | F5: n° do certificado | G5: Data da Calibração | H5: Vencimento | I5: Unidade calibrada | J5: Faixa mínima | K5: Faixa máxima | L5: Resolução | M5: Maior desvio | N5: Maior Incerteza | O5: Deriva | P5: Residuo | Q5: Veff | R5: X3 | S5: X2 | T5: X1 | U5: X0 | V5: =CONCATENATE(V3,"-VR") -> 1-VR | W5: =CONCATENATE(W3,"-U") -> 1-U | X5: =CONCATENATE(X3,"-K") -> 1-K | Y5: =CONCATENATE(Y3,"-GL") -> 1-GL | Z5: =CONCATENATE(Z3,"-VR") -> 2-VR | AA5: =CONCATENATE(AA3,"-U") -> 2-U | AB5: =CONCATENATE(AB3,"-K") -> 2-K | AC5: =CONCATENATE(AC3,"-GL") -> 2-GL | AD5: =CONCATENATE(AD3,"-VR") -> 3-VR | AE5: =CONCATENATE(AE3,"-U") -> 3-U | AF5: =CONCATENATE(AF3,"-K") -> 3-K | AG5: =CONCATENATE(AG3,"-GL") -> 3-GL | AH5: =CONCATENATE(AH3,"-VR") -> 4-VR | AI5: =CONCATENATE(AI3,"-U") -> 4-U | AJ5: =CONCATENATE(AJ3,"-K") -> 4-K | AK5: =CONCATENATE(AK3,"-GL") -> 4-GL | AL5: =CONCATENATE(AL3,"-VR") -> 5-VR | AM5: =CONCATENATE(AM3,"-U") -> 5-U | AN5: =CONCATENATE(AN3,"-K") -> 5-K | AO5: =CONCATENATE(AO3,"-GL") -> 5-GL | AP5: =CONCATENATE(AP3,"-VR") -> 6-VR | AQ5: =CONCATENATE(AQ3,"-U") -> 6-U | AR5: =CONCATENATE(AR3,"-K") -> 6-K | AS5: =CONCATENATE(AS3,"-GL") -> 6-GL | AT5: =CONCATENATE(AT3,"-VR") -> 7-VR | AU5: =CONCATENATE(AU3,"-U") -> 7-U | AV5: =CONCATENATE(AV3,"-K") -> 7-K | AW5: =CONCATENATE(AW3,"-GL") -> 7-GL | AX5: =CONCATENATE(AX3,"-VR") -> 8-VR | AY5: =CONCATENATE(AY3,"-U") -> 8-U | AZ5: =CONCATENATE(AZ3,"-K") -> 8-K | BA5: =CONCATENATE(BA3,"-GL") -> 8-GL | BB5: =CONCATENATE(BB3,"-VR") -> 9-VR | BC5: =CONCATENATE(BC3,"-U") -> 9-U | BD5: =CONCATENATE(BD3,"-K") -> 9-K | BE5: =CONCATENATE(BE3,"-GL") -> 9-GL | BF5: =CONCATENATE(BF3,"-VR") -> 10-VR | BG5: =CONCATENATE(BG3,"-U") -> 10-U | BH5: =CONCATENATE(BH3,"-K") -> 10-K | BI5: =CONCATENATE(BI3,"-GL") -> 10-GL | BJ5: =CONCATENATE(BJ3,"-VR") -> 11-VR | BK5: =CONCATENATE(BK3,"-U") -> 11-U | BL5: =CONCATENATE(BL3,"-K") -> 11-K | BM5: =CONCATENATE(BM3,"-GL") -> 11-GL | BN5: =CONCATENATE(BN3,"-VR") -> 12-VR | BO5: =CONCATENATE(BO3,"-U") -> 12-U | BP5: =CONCATENATE(BP3,"-K") -> 12-K | BQ5: =CONCATENATE(BQ3,"-GL") -> 12-GL | BR5: =CONCATENATE(BR3,"-VR") -> 13-VR | BS5: =CONCATENATE(BS3,"-U") -> 13-U | BT5: =CONCATENATE(BT3,"-K") -> 13-K | BU5: =CONCATENATE(BU3,"-GL") -> 13-GL | BV5: =CONCATENATE(BV3,"-VR") -> 14-VR | BW5: =CONCATENATE(BW3,"-U") -> 14-U | BX5: =CONCATENATE(BX3,"-K") -> 14-K | BY5: =CONCATENATE(BY3,"-GL") -> 14-GL | BZ5: =CONCATENATE(BZ3,"-VR") -> 15-VR | CA5: =CONCATENATE(CA3,"-U") -> 15-U | CB5: =CONCATENATE(CB3,"-K") -> 15-K | CC5: =CONCATENATE(CC3,"-GL") -> 15-GL
A6: 1 | B6: =IF(VLOOKUP(ROUND(CONCATENATE($A6,B$2),0),'Cadastro - Padrões'!$A$2:$T$1160,B$1,FALSE)="","-",VLOOKUP(ROUND(CONCATENATE($A6,B$2),0),'Cadastro - Padrões'!$A$2:$T$1160,B$1,FALSE)) -> X.TH.LV-001 | C6: =IF($B6="-","-",VLOOKUP(ROUND(CONCATENATE($A6,C$2),0),'Cadastro - Padrões'!$A$2:$T$1160,C$1,FALSE)) -> Barômetro Digital | D6: =IF($B6="-","-",VLOOKUP(ROUND(CONCATENATE($A6,D$2),0),'Cadastro - Padrões'!$A$2:$T$1160,D$1,FALSE)) -> ELUS | E6: =IF($B6="-","-",VLOOKUP(ROUND(CONCATENATE($A6,E$2),0),'Cadastro - Padrões'!$A$2:$T$1160,E$1,FALSE)) -> RBC - CAL 0439 | F6: =IF($B6="-","-",VLOOKUP(ROUND(CONCATENATE($A6,F$2),0),'Cadastro - Padrões'!$A$2:$T$1160,F$1,FALSE)) -> E0369B/24 | G6: =IF($B6="-","-",VLOOKUP(ROUND(CONCATENATE($A6,G$2),0),'Cadastro - Padrões'!$A$2:$T$1160,G$1,FALSE)) -> 45559 | H6: =IF($B6="-","-",VLOOKUP(ROUND(CONCATENATE($A6,H$2),0),'Cadastro - Padrões'!$A$2:$T$1160,H$1,FALSE)) -> 45924 | I6: =IF($B6="-","-",VLOOKUP(ROUND(CONCATENATE($A6,I$2),0),'Cadastro - Padrões'!$A$2:$T$1160,I$1,FALSE)) -> hPa | J6: =IF($B6="-","-",VLOOKUP(ROUND(CONCATENATE($A6,J$2),0),'Cadastro - Padrões'!$A$2:$T$1160,J$1,FALSE)) -> 500.04 | ... U6: =IF($B6="-","-",VLOOKUP(ROUND(CONCATENATE($A6,U$2),0),'Cadastro - Padrões'!$A$2:$T$1160,U$1,FALSE)) -> -0.1364472 | V6: =IF($B6="-","-",IF(VLOOKUP(ROUND(CONCATENATE($A6,V$2),0),'Cadastro - Padrões'!$A$2:$T$1160,V$1,FALSE)="","-",VLOOKUP(ROUND(CONCATENATE($A6,V$2),0),'Cadastro - Padrões'!$A$2:$T$1160,V$1,FALSE))) -> 500.04 | W6: =IF($B6="-","-",IF(VLOOKUP(ROUND(CONCATENATE($A6,W$2),0),'Cadastro - Padrões'!$A$2:$T$1160,W$1,FALSE)="","-",VLOOKUP(ROUND(CONCATENATE($A6,W$2),0),'Cadastro - Padrões'!$A$2:$T$1160,W$1,FALSE))) -> 0.06 | X6: =IF($B6="-","-",IF(VLOOKUP(ROUND(CONCATENATE($A6,X$2),0),'Cadastro - Padrões'!$A$2:$T$1160,X$1,FALSE)="","-",VLOOKUP(ROUND(CONCATENATE($A6,X$2),0),'Cadastro - Padrões'!$A$2:$T$1160,X$1,FALSE))) -> 2 | Y6: =IF($B6="-","-",IF(VLOOKUP(ROUND(CONCATENATE($A6,Y$2),0),'Cadastro - Padrões'!$A$2:$T$1160,Y$1,FALSE)="","-",VLOOKUP(ROUND(CONCATENATE($A6,Y$2),0),'Cadastro - Padrões'!$A$2:$T$1160,Y$1,FALSE))) -> 1000000 | Z6: =IF($B6="-","-",IF(VLOOKUP(ROUND(CONCATENATE($A6,Z$2),0),'Cadastro - Padrões'!$A$2:$T$1160,Z$1,FALSE)="","-",VLOOKUP(ROUND(CONCATENATE($A6,Z$2),0),'Cadastro - Padrões'!$A$2:$T$1160,Z$1,FALSE))) -> 620.07 | AA6: =IF($B6="-","-",IF(VLOOKUP(ROUND(CONCATENATE($A6,AA$2),0),'Cadastro - Padrões'!$A$2:$T$1160,AA$1,FALSE)="","-",VLOOKUP(ROUND(CONCATENATE($A6,AA$2),0),'Cadastro - Padrões'!$A$2:$T$1160,AA$1,FALSE))) -> 0.06 | AB6: =IF($B6="-","-",IF(VLOOKUP(ROUND(CONCATENATE($A6,AB$2),0),'Cadastro - Padrões'!$A$2:$T$1160,AB$1,FALSE)="","-",VLOOKUP(ROUND(CONCATENATE($A6,AB$2),0),'Cadastro - Padrões'!$A$2:$T$1160,AB$1,FALSE))) -> 2 | AC6: =IF($B6="-","-",IF(VLOOKUP(ROUND(CONCATENATE($A6,AC$2),0),'Cadastro - Padrões'!$A$2:$T$1160,AC$1,FALSE)="","-",VLOOKUP(ROUND(CONCATENATE($A6,AC$2),0),'Cadastro - Padrões'!$A$2:$T$1160,AC$1,FALSE))) -> 1000000 | ... CC6: =IF($B6="-","-",IF(VLOOKUP(ROUND(CONCATENATE($A6,CC$2),0),'Cadastro - Padrões'!$A$2:$T$1160,CC$1,FALSE)="","-",VLOOKUP(ROUND(CONCATENATE($A6,CC$2),0),'Cadastro - Padrões'!$A$2:$T$1160,CC$1,FALSE))) -> -
A7: =A6+1 -> 2 | B7: =IF(VLOOKUP(ROUND(CONCATENATE($A7,B$2),0),'Cadastro - Padrões'!$A$2:$T$1160,B$1,FALSE)="","-",VLOOKUP(ROUND(CONCATENATE($A7,B$2),0),'Cadastro - Padrões'!$A$2:$T$1160,B$1,FALSE)) -> E.PS.FS-001 | C7: =IF(VLOOKUP(ROUND(CONCATENATE($A7,C$2),0),'Cadastro - Padrões'!$A$2:$T$1160,C$1,FALSE)="","-",VLOOKUP(ROUND(CONCATENATE($A7,C$2),0),'Cadastro - Padrões'!$A$2:$T$1160,C$1,FALSE)) -> Barômetro Digital | D7: =IF($B7="-","-",VLOOKUP(ROUND(CONCATENATE($A7,D$2),0),'Cadastro - Padrões'!$A$2:$T$1160,D$1,FALSE)) -> ELUS | E7: =IF($B7="-","-",VLOOKUP(ROUND(CONCATENATE($A7,E$2),0),'Cadastro - Padrões'!$A$2:$T$1160,E$1,FALSE)) -> RBC - CAL 0439 | F7: =IF($B7="-","-",VLOOKUP(ROUND(CONCATENATE($A7,F$2),0),'Cadastro - Padrões'!$A$2:$T$1160,F$1,FALSE)) -> E0627/25 | G7: =IF($B7="-","-",VLOOKUP(ROUND(CONCATENATE($A7,G$2),0),'Cadastro - Padrões'!$A$2:$T$1160,G$1,FALSE)) -> 45905 | H7: =IF($B7="-","-",VLOOKUP(ROUND(CONCATENATE($A7,H$2),0),'Cadastro - Padrões'!$A$2:$T$1160,H$1,FALSE)) -> 46295 | I7: =IF($B7="-","-",VLOOKUP(ROUND(CONCATENATE($A7,I$2),0),'Cadastro - Padrões'!$A$2:$T$1160,I$1,FALSE)) -> hPa | J7: =IF($B7="-","-",VLOOKUP(ROUND(CONCATENATE($A7,J$2),0),'Cadastro - Padrões'!$A$2:$T$1160,J$1,FALSE)) -> 801 | K7: =IF($B7="-","-",VLOOKUP(ROUND(CONCATENATE($A7,K$2),0),'Cadastro - Padrões'!$A$2:$T$1160,K$1,FALSE)) -> 1100 | ... U7: =IF($B7="-","-",VLOOKUP(ROUND(CONCATENATE($A7,U$2),0),'Cadastro - Padrões'!$A$2:$T$1160,U$1,FALSE)) -> 175.88221 | V7: =IF($B7="-","-",IF(VLOOKUP(ROUND(CONCATENATE($A7,V$2),0),'Cadastro - Padrões'!$A$2:$T$1160,V$1,FALSE)="","-",VLOOKUP(ROUND(CONCATENATE($A7,V$2),0),'Cadastro - Padrões'!$A$2:$T$1160,V$1,FALSE))) -> 801 | W7: =IF($B7="-","-",IF(VLOOKUP(ROUND(CONCATENATE($A7,W$2),0),'Cadastro - Padrões'!$A$2:$T$1160,W$1,FALSE)="","-",VLOOKUP(ROUND(CONCATENATE($A7,W$2),0),'Cadastro - Padrões'!$A$2:$T$1160,W$1,FALSE))) -> 1 | X7: =IF($B7="-","-",IF(VLOOKUP(ROUND(CONCATENATE($A7,X$2),0),'Cadastro - Padrões'!$A$2:$T$1160,X$1,FALSE)="","-",VLOOKUP(ROUND(CONCATENATE($A7,X$2),0),'Cadastro - Padrões'!$A$2:$T$1160,X$1,FALSE))) -> 2 | Y7: =IF($B7="-","-",IF(VLOOKUP(ROUND(CONCATENATE($A7,Y$2),0),'Cadastro - Padrões'!$A$2:$T$1160,Y$1,FALSE)="","-",VLOOKUP(ROUND(CONCATENATE($A7,Y$2),0),'Cadastro - Padrões'!$A$2:$T$1160,Y$1,FALSE))) -> 1000000 | Z7: =IF($B7="-","-",IF(VLOOKUP(ROUND(CONCATENATE($A7,Z$2),0),'Cadastro - Padrões'!$A$2:$T$1160,Z$1,FALSE)="","-",VLOOKUP(ROUND(CONCATENATE($A7,Z$2),0),'Cadastro - Padrões'!$A$2:$T$1160,Z$1,FALSE))) -> 881 | AA7: =IF($B7="-","-",IF(VLOOKUP(ROUND(CONCATENATE($A7,AA$2),0),'Cadastro - Padrões'!$A$2:$T$1160,AA$1,FALSE)="","-",VLOOKUP(ROUND(CONCATENATE($A7,AA$2),0),'Cadastro - Padrões'!$A$2:$T$1160,AA$1,FALSE))) -> 1 | AB7: =IF($B7="-","-",IF(VLOOKUP(ROUND(CONCATENATE($A7,AB$2),0),'Cadastro - Padrões'!$A$2:$T$1160,AB$1,FALSE)="","-",VLOOKUP(ROUND(CONCATENATE($A7,AB$2),0),'Cadastro - Padrões'!$A$2:$T$1160,AB$1,FALSE))) -> 2 | AC7: =IF($B7="-","-",IF(VLOOKUP(ROUND(CONCATENATE($A7,AC$2),0),'Cadastro - Padrões'!$A$2:$T$1160,AC$1,FALSE)="","-",VLOOKUP(ROUND(CONCATENATE($A7,AC$2),0),'Cadastro - Padrões'!$A$2:$T$1160,AC$1,FALSE))) -> 1000000 | ... CC7: =IF($B7="-","-",IF(VLOOKUP(ROUND(CONCATENATE($A7,CC$2),0),'Cadastro - Padrões'!$A$2:$T$1160,CC$1,FALSE)="","-",VLOOKUP(ROUND(CONCATENATE($A7,CC$2),0),'Cadastro - Padrões'!$A$2:$T$1160,CC$1,FALSE))) -> -
A8: =A7+1 -> 3 | B8: =IF(VLOOKUP(ROUND(CONCATENATE($A8,B$2),0),'Cadastro - Padrões'!$A$2:$T$1160,B$1,FALSE)="","-",VLOOKUP(ROUND(CONCATENATE($A8,B$2),0),'Cadastro - Padrões'!$A$2:$T$1160,B$1,FALSE)) -> E.PS.FS-002 | C8: =IF(VLOOKUP(ROUND(CONCATENATE($A8,C$2),0),'Cadastro - Padrões'!$A$2:$T$1160,C$1,FALSE)="","-",VLOOKUP(ROUND(CONCATENATE($A8,C$2),0),'Cadastro - Padrões'!$A$2:$T$1160,C$1,FALSE)) -> Barômetro Digital | D8: =IF($B8="-","-",VLOOKUP(ROUND(CONCATENATE($A8,D$2),0),'Cadastro - Padrões'!$A$2:$T$1160,D$1,FALSE)) -> Elus | E8: =IF($B8="-","-",VLOOKUP(ROUND(CONCATENATE($A8,E$2),0),'Cadastro - Padrões'!$A$2:$T$1160,E$1,FALSE)) -> RBC - CAL 0439 | F8: =IF($B8="-","-",VLOOKUP(ROUND(CONCATENATE($A8,F$2),0),'Cadastro - Padrões'!$A$2:$T$1160,F$1,FALSE)) -> E0652/25 | G8: =IF($B8="-","-",VLOOKUP(ROUND(CONCATENATE($A8,G$2),0),'Cadastro - Padrões'!$A$2:$T$1160,G$1,FALSE)) -> 45917 | H8: =IF($B8="-","-",VLOOKUP(ROUND(CONCATENATE($A8,H$2),0),'Cadastro - Padrões'!$A$2:$T$1160,H$1,FALSE)) -> 46295 | I8: =IF($B8="-","-",VLOOKUP(ROUND(CONCATENATE($A8,I$2),0),'Cadastro - Padrões'!$A$2:$T$1160,I$1,FALSE)) -> hPa | J8: =IF($B8="-","-",VLOOKUP(ROUND(CONCATENATE($A8,J$2),0),'Cadastro - Padrões'!$A$2:$T$1160,J$1,FALSE)) -> 799.9 | K8: =IF($B8="-","-",VLOOKUP(ROUND(CONCATENATE($A8,K$2),0),'Cadastro - Padrões'!$A$2:$T$1160,K$1,FALSE)) -> 1050 | ... U8: =IF($B8="-","-",VLOOKUP(ROUND(CONCATENATE($A8,U$2),0),'Cadastro - Padrões'!$A$2:$T$1160,U$1,FALSE)) -> -123.89992 | V8: =IF($B8="-","-",IF(VLOOKUP(ROUND(CONCATENATE($A8,V$2),0),'Cadastro - Padrões'!$A$2:$T$1160,V$1,FALSE)="","-",VLOOKUP(ROUND(CONCATENATE($A8,V$2),0),'Cadastro - Padrões'!$A$2:$T$1160,V$1,FALSE))) -> 799.9 | W8: =IF($B8="-","-",IF(VLOOKUP(ROUND(CONCATENATE($A8,W$2),0),'Cadastro - Padrões'!$A$2:$T$1160,W$1,FALSE)="","-",VLOOKUP(ROUND(CONCATENATE($A8,W$2),0),'Cadastro - Padrões'!$A$2:$T$1160,W$1,FALSE))) -> 0.3 | X8: =IF($B8="-","-",IF(VLOOKUP(ROUND(CONCATENATE($A8,X$2),0),'Cadastro - Padrões'!$A$2:$T$1160,X$1,FALSE)="","-",VLOOKUP(ROUND(CONCATENATE($A8,X$2),0),'Cadastro - Padrões'!$A$2:$T$1160,X$1,FALSE))) -> 2 | Y8: =IF($B8="-","-",IF(VLOOKUP(ROUND(CONCATENATE($A8,Y$2),0),'Cadastro - Padrões'!$A$2:$T$1160,Y$1,FALSE)="","-",VLOOKUP(ROUND(CONCATENATE($A8,Y$2),0),'Cadastro - Padrões'!$A$2:$T$1160,Y$1,FALSE))) -> 1000000 | Z8: =IF($B8="-","-",IF(VLOOKUP(ROUND(CONCATENATE($A8,Z$2),0),'Cadastro - Padrões'!$A$2:$T$1160,Z$1,FALSE)="","-",VLOOKUP(ROUND(CONCATENATE($A8,Z$2),0),'Cadastro - Padrões'!$A$2:$T$1160,Z$1,FALSE))) -> 849.9 | AA8: =IF($B8="-","-",IF(VLOOKUP(ROUND(CONCATENATE($A8,AA$2),0),'Cadastro - Padrões'!$A$2:$T$1160,AA$1,FALSE)="","-",VLOOKUP(ROUND(CONCATENATE($A8,AA$2),0),'Cadastro - Padrões'!$A$2:$T$1160,AA$1,FALSE))) -> 0.3 | AB8: =IF($B8="-","-",IF(VLOOKUP(ROUND(CONCATENATE($A8,AB$2),0),'Cadastro - Padrões'!$A$2:$T$1160,AB$1,FALSE)="","-",VLOOKUP(ROUND(CONCATENATE($A8,AB$2),0),'Cadastro - Padrões'!$A$2:$T$1160,AB$1,FALSE))) -> 2 | AC8: =IF($B8="-","-",IF(VLOOKUP(ROUND(CONCATENATE($A8,AC$2),0),'Cadastro - Padrões'!$A$2:$T$1160,AC$1,FALSE)="","-",VLOOKUP(ROUND(CONCATENATE($A8,AC$2),0),'Cadastro - Padrões'!$A$2:$T$1160,AC$1,FALSE))) -> 1000000 | ... CC8: =IF($B8="-","-",IF(VLOOKUP(ROUND(CONCATENATE($A8,CC$2),0),'Cadastro - Padrões'!$A$2:$T$1160,CC$1,FALSE)="","-",VLOOKUP(ROUND(CONCATENATE($A8,CC$2),0),'Cadastro - Padrões'!$A$2:$T$1160,CC$1,FALSE))) -> -
A9: =A8+1 -> 4 | B9: =IF(VLOOKUP(ROUND(CONCATENATE($A9,B$2),0),'Cadastro - Padrões'!$A$2:$T$1160,B$1,FALSE)="","-",VLOOKUP(ROUND(CONCATENATE($A9,B$2),0),'Cadastro - Padrões'!$A$2:$T$1160,B$1,FALSE)) -> EL-193 | C9: =IF(VLOOKUP(ROUND(CONCATENATE($A9,C$2),0),'Cadastro - Padrões'!$A$2:$T$1160,C$1,FALSE)="","-",VLOOKUP(ROUND(CONCATENATE($A9,C$2),0),'Cadastro - Padrões'!$A$2:$T$1160,C$1,FALSE)) -> Barômetro Digital | D9: =IF($B9="-","-",VLOOKUP(ROUND(CONCATENATE($A9,D$2),0),'Cadastro - Padrões'!$A$2:$T$1160,D$1,FALSE)) -> CTA | E9: =IF($B9="-","-",VLOOKUP(ROUND(CONCATENATE($A9,E$2),0),'Cadastro - Padrões'!$A$2:$T$1160,E$1,FALSE)) -> RBC - CAL 0001 | F9: =IF($B9="-","-",VLOOKUP(ROUND(CONCATENATE($A9,F$2),0),'Cadastro - Padrões'!$A$2:$T$1160,F$1,FALSE)) -> MF-P 747/23 | G9: =IF($B9="-","-",VLOOKUP(ROUND(CONCATENATE($A9,G$2),0),'Cadastro - Padrões'!$A$2:$T$1160,G$1,FALSE)) -> 45254 | H9: =IF($B9="-","-",VLOOKUP(ROUND(CONCATENATE($A9,H$2),0),'Cadastro - Padrões'!$A$2:$T$1160,H$1,FALSE)) -> 45991 | I9: =IF($B9="-","-",VLOOKUP(ROUND(CONCATENATE($A9,I$2),0),'Cadastro - Padrões'!$A$2:$T$1160,I$1,FALSE)) -> hPa | J9: =IF($B9="-","-",VLOOKUP(ROUND(CONCATENATE($A9,J$2),0),'Cadastro - Padrões'!$A$2:$T$1160,J$1,FALSE)) -> 498.883 | K9: =IF($B9="-","-",VLOOKUP(ROUND(CONCATENATE($A9,K$2),0),'Cadastro - Padrões'!$A$2:$T$1160,K$1,FALSE)) -> 1099.655 | ... U9: =IF($B9="-","-",VLOOKUP(ROUND(CONCATENATE($A9,U$2),0),'Cadastro - Padrões'!$A$2:$T$1160,U$1,FALSE)) -> -0.0024334907 | V9: =IF($B9="-","-",IF(VLOOKUP(ROUND(CONCATENATE($A9,V$2),0),'Cadastro - Padrões'!$A$2:$T$1160,V$1,FALSE)="","-",VLOOKUP(ROUND(CONCATENATE($A9,V$2),0),'Cadastro - Padrões'!$A$2:$T$1160,V$1,FALSE))) -> 498.883 | W9: =IF($B9="-","-",IF(VLOOKUP(ROUND(CONCATENATE($A9,W$2),0),'Cadastro - Padrões'!$A$2:$T$1160,W$1,FALSE)="","-",VLOOKUP(ROUND(CONCATENATE($A9,W$2),0),'Cadastro - Padrões'!$A$2:$T$1160,W$1,FALSE))) -> 0.05 | X9: =IF($B9="-","-",IF(VLOOKUP(ROUND(CONCATENATE($A9,X$2),0),'Cadastro - Padrões'!$A$2:$T$1160,X$1,FALSE)="","-",VLOOKUP(ROUND(CONCATENATE($A9,X$2),0),'Cadastro - Padrões'!$A$2:$T$1160,X$1,FALSE))) -> 2 | Y9: =IF($B9="-","-",IF(VLOOKUP(ROUND(CONCATENATE($A9,Y$2),0),'Cadastro - Padrões'!$A$2:$T$1160,Y$1,FALSE)="","-",VLOOKUP(ROUND(CONCATENATE($A9,Y$2),0),'Cadastro - Padrões'!$A$2:$T$1160,Y$1,FALSE))) -> 1000000 | Z9: =IF($B9="-","-",IF(VLOOKUP(ROUND(CONCATENATE($A9,Z$2),0),'Cadastro - Padrões'!$A$2:$T$1160,Z$1,FALSE)="","-",VLOOKUP(ROUND(CONCATENATE($A9,Z$2),0),'Cadastro - Padrões'!$A$2:$T$1160,Z$1,FALSE))) -> 598.045 | AA9: =IF($B9="-","-",IF(VLOOKUP(ROUND(CONCATENATE($A9,AA$2),0),'Cadastro - Padrões'!$A$2:$T$1160,AA$1,FALSE)="","-",VLOOKUP(ROUND(CONCATENATE($A9,AA$2),0),'Cadastro - Padrões'!$A$2:$T$1160,AA$1,FALSE))) -> 0.05 | AB9: =IF($B9="-","-",IF(VLOOKUP(ROUND(CONCATENATE($A9,AB$2),0),'Cadastro - Padrões'!$A$2:$T$1160,AB$1,FALSE)="","-",VLOOKUP(ROUND(CONCATENATE($A9,AB$2),0),'Cadastro - Padrões'!$A$2:$T$1160,AB$1,FALSE))) -> 2 | AC9: =IF($B9="-","-",IF(VLOOKUP(ROUND(CONCATENATE($A9,AC$2),0),'Cadastro - Padrões'!$A$2:$T$1160,AC$1,FALSE)="","-",VLOOKUP(ROUND(CONCATENATE($A9,AC$2),0),'Cadastro - Padrões'!$A$2:$T$1160,AC$1,FALSE))) -> 1000000 | ... CC9: =IF($B9="-","-",IF(VLOOKUP(ROUND(CONCATENATE($A9,CC$2),0),'Cadastro - Padrões'!$A$2:$T$1160,CC$1,FALSE)="","-",VLOOKUP(ROUND(CONCATENATE($A9,CC$2),0),'Cadastro - Padrões'!$A$2:$T$1160,CC$1,FALSE))) -> -
A10: =A9+1 -> 5 | B10: =IF(VLOOKUP(ROUND(CONCATENATE($A10,B$2),0),'Cadastro - Padrões'!$A$2:$T$1160,B$1,FALSE)="","-",VLOOKUP(ROUND(CONCATENATE($A10,B$2),0),'Cadastro - Padrões'!$A$2:$T$1160,B$1,FALSE)) -> E.PS.FS-008 | C10: =IF(VLOOKUP(ROUND(CONCATENATE($A10,C$2),0),'Cadastro - Padrões'!$A$2:$T$1160,C$1,FALSE)="","-",VLOOKUP(ROUND(CONCATENATE($A10,C$2),0),'Cadastro - Padrões'!$A$2:$T$1160,C$1,FALSE)) -> Barômetro Digital | D10: =IF($B10="-","-",VLOOKUP(ROUND(CONCATENATE($A10,D$2),0),'Cadastro - Padrões'!$A$2:$T$1160,D$1,FALSE)) -> ELUS | E10: =IF($B10="-","-",VLOOKUP(ROUND(CONCATENATE($A10,E$2),0),'Cadastro - Padrões'!$A$2:$T$1160,E$1,FALSE)) -> RBC - CAL 0439 | F10: =IF($B10="-","-",VLOOKUP(ROUND(CONCATENATE($A10,F$2),0),'Cadastro - Padrões'!$A$2:$T$1160,F$1,FALSE)) -> E0047/26 | G10: =IF($B10="-","-",VLOOKUP(ROUND(CONCATENATE($A10,G$2),0),'Cadastro - Padrões'!$A$2:$T$1160,G$1,FALSE)) -> 46055 | H10: =IF($B10="-","-",VLOOKUP(ROUND(CONCATENATE($A10,H$2),0),'Cadastro - Padrões'!$A$2:$T$1160,H$1,FALSE)) -> 46446 | I10: =IF($B10="-","-",VLOOKUP(ROUND(CONCATENATE($A10,I$2),0),'Cadastro - Padrões'!$A$2:$T$1160,I$1,FALSE)) -> hPa | J10: =IF($B10="-","-",VLOOKUP(ROUND(CONCATENATE($A10,J$2),0),'Cadastro - Padrões'!$A$2:$T$1160,J$1,FALSE)) -> 501.5 | K10: =IF($B10="-","-",VLOOKUP(ROUND(CONCATENATE($A10,K$2),0),'Cadastro - Padrões'!$A$2:$T$1160,K$1,FALSE)) -> 1097 | ... U10: =IF($B10="-","-",VLOOKUP(ROUND(CONCATENATE($A10,U$2),0),'Cadastro - Padrões'!$A$2:$T$1160,U$1,FALSE)) -> 1.8687993 | V10: =IF($B10="-","-",IF(VLOOKUP(ROUND(CONCATENATE($A10,V$2),0),'Cadastro - Padrões'!$A$2:$T$1160,V$1,FALSE)="","-",VLOOKUP(ROUND(CONCATENATE($A10,V$2),0),'Cadastro - Padrões'!$A$2:$T$1160,V$1,FALSE))) -> 501.5 | W10: =IF($B10="-","-",IF(VLOOKUP(ROUND(CONCATENATE($A10,W$2),0),'Cadastro - Padrões'!$A$2:$T$1160,W$1,FALSE)="","-",VLOOKUP(ROUND(CONCATENATE($A10,W$2),0),'Cadastro - Padrões'!$A$2:$T$1160,W$1,FALSE))) -> 0.2 | X10: =IF($B10="-","-",IF(VLOOKUP(ROUND(CONCATENATE($A10,X$2),0),'Cadastro - Padrões'!$A$2:$T$1160,X$1,FALSE)="","-",VLOOKUP(ROUND(CONCATENATE($A10,X$2),0),'Cadastro - Padrões'!$A$2:$T$1160,X$1,FALSE))) -> 2 | Y10: =IF($B10="-","-",IF(VLOOKUP(ROUND(CONCATENATE($A10,Y$2),0),'Cadastro - Padrões'!$A$2:$T$1160,Y$1,FALSE)="","-",VLOOKUP(ROUND(CONCATENATE($A10,Y$2),0),'Cadastro - Padrões'!$A$2:$T$1160,Y$1,FALSE))) -> 1000000 | Z10: =IF($B10="-","-",IF(VLOOKUP(ROUND(CONCATENATE($A10,Z$2),0),'Cadastro - Padrões'!$A$2:$T$1160,Z$1,FALSE)="","-",VLOOKUP(ROUND(CONCATENATE($A10,Z$2),0),'Cadastro - Padrões'!$A$2:$T$1160,Z$1,FALSE))) -> 550.2 | AA10: =IF($B10="-","-",IF(VLOOKUP(ROUND(CONCATENATE($A10,AA$2),0),'Cadastro - Padrões'!$A$2:$T$1160,AA$1,FALSE)="","-",VLOOKUP(ROUND(CONCATENATE($A10,AA$2),0),'Cadastro - Padrões'!$A$2:$T$1160,AA$1,FALSE))) -> 0.2 | AB10: =IF($B10="-","-",IF(VLOOKUP(ROUND(CONCATENATE($A10,AB$2),0),'Cadastro - Padrões'!$A$2:$T$1160,AB$1,FALSE)="","-",VLOOKUP(ROUND(CONCATENATE($A10,AB$2),0),'Cadastro - Padrões'!$A$2:$T$1160,AB$1,FALSE))) -> 2 | AC10: =IF($B10="-","-",IF(VLOOKUP(ROUND(CONCATENATE($A10,AC$2),0),'Cadastro - Padrões'!$A$2:$T$1160,AC$1,FALSE)="","-",VLOOKUP(ROUND(CONCATENATE($A10,AC$2),0),'Cadastro - Padrões'!$A$2:$T$1160,AC$1,FALSE))) -> 1000000 | ... CC10: =IF($B10="-","-",IF(VLOOKUP(ROUND(CONCATENATE($A10,CC$2),0),'Cadastro - Padrões'!$A$2:$T$1160,CC$1,FALSE)="","-",VLOOKUP(ROUND(CONCATENATE($A10,CC$2),0),'Cadastro - Padrões'!$A$2:$T$1160,CC$1,FALSE))) -> -
A11: =A10+1 -> 6 | B11: =IF(VLOOKUP(ROUND(CONCATENATE($A11,B$2),0),'Cadastro - Padrões'!$A$2:$T$1160,B$1,FALSE)="","-",VLOOKUP(ROUND(CONCATENATE($A11,B$2),0),'Cadastro - Padrões'!$A$2:$T$1160,B$1,FALSE)) -> E.PS.FS-009 | C11: =IF(VLOOKUP(ROUND(CONCATENATE($A11,C$2),0),'Cadastro - Padrões'!$A$2:$T$1160,C$1,FALSE)="","-",VLOOKUP(ROUND(CONCATENATE($A11,C$2),0),'Cadastro - Padrões'!$A$2:$T$1160,C$1,FALSE)) -> Barômetro Digital | D11: =IF($B11="-","-",VLOOKUP(ROUND(CONCATENATE($A11,D$2),0),'Cadastro - Padrões'!$A$2:$T$1160,D$1,FALSE)) -> ELUS | E11: =IF($B11="-","-",VLOOKUP(ROUND(CONCATENATE($A11,E$2),0),'Cadastro - Padrões'!$A$2:$T$1160,E$1,FALSE)) -> RBC - CAL 0439 | F11: =IF($B11="-","-",VLOOKUP(ROUND(CONCATENATE($A11,F$2),0),'Cadastro - Padrões'!$A$2:$T$1160,F$1,FALSE)) -> E0094/26 | G11: =IF($B11="-","-",VLOOKUP(ROUND(CONCATENATE($A11,G$2),0),'Cadastro - Padrões'!$A$2:$T$1160,G$1,FALSE)) -> 46071 | H11: =IF($B11="-","-",VLOOKUP(ROUND(CONCATENATE($A11,H$2),0),'Cadastro - Padrões'!$A$2:$T$1160,H$1,FALSE)) -> 46446 | I11: =IF($B11="-","-",VLOOKUP(ROUND(CONCATENATE($A11,I$2),0),'Cadastro - Padrões'!$A$2:$T$1160,I$1,FALSE)) -> hPa | J11: =IF($B11="-","-",VLOOKUP(ROUND(CONCATENATE($A11,J$2),0),'Cadastro - Padrões'!$A$2:$T$1160,J$1,FALSE)) -> 500 | K11: =IF($B11="-","-",VLOOKUP(ROUND(CONCATENATE($A11,K$2),0),'Cadastro - Padrões'!$A$2:$T$1160,K$1,FALSE)) -> 1099.9 | ... U11: =IF($B11="-","-",VLOOKUP(ROUND(CONCATENATE($A11,U$2),0),'Cadastro - Padrões'!$A$2:$T$1160,U$1,FALSE)) -> 0.4010989 | V11: =IF($B11="-","-",IF(VLOOKUP(ROUND(CONCATENATE($A11,V$2),0),'Cadastro - Padrões'!$A$2:$T$1160,V$1,FALSE)="","-",VLOOKUP(ROUND(CONCATENATE($A11,V$2),0),'Cadastro - Padrões'!$A$2:$T$1160,V$1,FALSE))) -> 500 | W11: =IF($B11="-","-",IF(VLOOKUP(ROUND(CONCATENATE($A11,W$2),0),'Cadastro - Padrões'!$A$2:$T$1160,W$1,FALSE)="","-",VLOOKUP(ROUND(CONCATENATE($A11,W$2),0),'Cadastro - Padrões'!$A$2:$T$1160,W$1,FALSE))) -> 0.3 | X11: =IF($B11="-","-",IF(VLOOKUP(ROUND(CONCATENATE($A11,X$2),0),'Cadastro - Padrões'!$A$2:$T$1160,X$1,FALSE)="","-",VLOOKUP(ROUND(CONCATENATE($A11,X$2),0),'Cadastro - Padrões'!$A$2:$T$1160,X$1,FALSE))) -> 2 | Y11: =IF($B11="-","-",IF(VLOOKUP(ROUND(CONCATENATE($A11,Y$2),0),'Cadastro - Padrões'!$A$2:$T$1160,Y$1,FALSE)="","-",VLOOKUP(ROUND(CONCATENATE($A11,Y$2),0),'Cadastro - Padrões'!$A$2:$T$1160,Y$1,FALSE))) -> 1000000 | Z11: =IF($B11="-","-",IF(VLOOKUP(ROUND(CONCATENATE($A11,Z$2),0),'Cadastro - Padrões'!$A$2:$T$1160,Z$1,FALSE)="","-",VLOOKUP(ROUND(CONCATENATE($A11,Z$2),0),'Cadastro - Padrões'!$A$2:$T$1160,Z$1,FALSE))) -> 550 | AA11: =IF($B11="-","-",IF(VLOOKUP(ROUND(CONCATENATE($A11,AA$2),0),'Cadastro - Padrões'!$A$2:$T$1160,AA$1,FALSE)="","-",VLOOKUP(ROUND(CONCATENATE($A11,AA$2),0),'Cadastro - Padrões'!$A$2:$T$1160,AA$1,FALSE))) -> 0.3 | AB11: =IF($B11="-","-",IF(VLOOKUP(ROUND(CONCATENATE($A11,AB$2),0),'Cadastro - Padrões'!$A$2:$T$1160,AB$1,FALSE)="","-",VLOOKUP(ROUND(CONCATENATE($A11,AB$2),0),'Cadastro - Padrões'!$A$2:$T$1160,AB$1,FALSE))) -> 2 | AC11: =IF($B11="-","-",IF(VLOOKUP(ROUND(CONCATENATE($A11,AC$2),0),'Cadastro - Padrões'!$A$2:$T$1160,AC$1,FALSE)="","-",VLOOKUP(ROUND(CONCATENATE($A11,AC$2),0),'Cadastro - Padrões'!$A$2:$T$1160,AC$1,FALSE))) -> 1000000 | ... CC11: =IF($B11="-","-",IF(VLOOKUP(ROUND(CONCATENATE($A11,CC$2),0),'Cadastro - Padrões'!$A$2:$T$1160,CC$1,FALSE)="","-",VLOOKUP(ROUND(CONCATENATE($A11,CC$2),0),'Cadastro - Padrões'!$A$2:$T$1160,CC$1,FALSE))) -> -
A12: =A11+1 -> 7 | B12: =IF(VLOOKUP(ROUND(CONCATENATE($A12,B$2),0),'Cadastro - Padrões'!$A$2:$T$1160,B$1,FALSE)="","-",VLOOKUP(ROUND(CONCATENATE($A12,B$2),0),'Cadastro - Padrões'!$A$2:$T$1160,B$1,FALSE)) -> E.PS.FS-003 | C12: =IF(VLOOKUP(ROUND(CONCATENATE($A12,C$2),0),'Cadastro - Padrões'!$A$2:$T$1160,C$1,FALSE)="","-",VLOOKUP(ROUND(CONCATENATE($A12,C$2),0),'Cadastro - Padrões'!$A$2:$T$1160,C$1,FALSE)) -> Barômetro Digital | D12: =IF($B12="-","-",VLOOKUP(ROUND(CONCATENATE($A12,D$2),0),'Cadastro - Padrões'!$A$2:$T$1160,D$1,FALSE)) -> ELUS | E12: =IF($B12="-","-",VLOOKUP(ROUND(CONCATENATE($A12,E$2),0),'Cadastro - Padrões'!$A$2:$T$1160,E$1,FALSE)) -> RBC - CAL 0439 | F12: =IF($B12="-","-",VLOOKUP(ROUND(CONCATENATE($A12,F$2),0),'Cadastro - Padrões'!$A$2:$T$1160,F$1,FALSE)) -> E0817/25 | G12: =IF($B12="-","-",VLOOKUP(ROUND(CONCATENATE($A12,G$2),0),'Cadastro - Padrões'!$A$2:$T$1160,G$1,FALSE)) -> 45979 | H12: =IF($B12="-","-",VLOOKUP(ROUND(CONCATENATE($A12,H$2),0),'Cadastro - Padrões'!$A$2:$T$1160,H$1,FALSE)) -> 46356 | I12: =IF($B12="-","-",VLOOKUP(ROUND(CONCATENATE($A12,I$2),0),'Cadastro - Padrões'!$A$2:$T$1160,I$1,FALSE)) -> hPa | J12: =IF($B12="-","-",VLOOKUP(ROUND(CONCATENATE($A12,J$2),0),'Cadastro - Padrões'!$A$2:$T$1160,J$1,FALSE)) -> 751 | K12: =IF($B12="-","-",VLOOKUP(ROUND(CONCATENATE($A12,K$2),0),'Cadastro - Padrões'!$A$2:$T$1160,K$1,FALSE)) -> 1090 | ... U12: =IF($B12="-","-",VLOOKUP(ROUND(CONCATENATE($A12,U$2),0),'Cadastro - Padrões'!$A$2:$T$1160,U$1,FALSE)) -> 68.454917 | V12: =IF($B12="-","-",IF(VLOOKUP(ROUND(CONCATENATE($A12,V$2),0),'Cadastro - Padrões'!$A$2:$T$1160,V$1,FALSE)="","-",VLOOKUP(ROUND(CONCATENATE($A12,V$2),0),'Cadastro - Padrões'!$A$2:$T$1160,V$1,FALSE))) -> 751 | W12: =IF($B12="-","-",IF(VLOOKUP(ROUND(CONCATENATE($A12,W$2),0),'Cadastro - Padrões'!$A$2:$T$1160,W$1,FALSE)="","-",VLOOKUP(ROUND(CONCATENATE($A12,W$2),0),'Cadastro - Padrões'!$A$2:$T$1160,W$1,FALSE))) -> 1 | X12: =IF($B12="-","-",IF(VLOOKUP(ROUND(CONCATENATE($A12,X$2),0),'Cadastro - Padrões'!$A$2:$T$1160,X$1,FALSE)="","-",VLOOKUP(ROUND(CONCATENATE($A12,X$2),0),'Cadastro - Padrões'!$A$2:$T$1160,X$1,FALSE))) -> 2 | Y12: =IF($B12="-","-",IF(VLOOKUP(ROUND(CONCATENATE($A12,Y$2),0),'Cadastro - Padrões'!$A$2:$T$1160,Y$1,FALSE)="","-",VLOOKUP(ROUND(CONCATENATE($A12,Y$2),0),'Cadastro - Padrões'!$A$2:$T$1160,Y$1,FALSE))) -> 1000000 | Z12: =IF($B12="-","-",IF(VLOOKUP(ROUND(CONCATENATE($A12,Z$2),0),'Cadastro - Padrões'!$A$2:$T$1160,Z$1,FALSE)="","-",VLOOKUP(ROUND(CONCATENATE($A12,Z$2),0),'Cadastro - Padrões'!$A$2:$T$1160,Z$1,FALSE))) -> 800 | AA12: =IF($B12="-","-",IF(VLOOKUP(ROUND(CONCATENATE($A12,AA$2),0),'Cadastro - Padrões'!$A$2:$T$1160,AA$1,FALSE)="","-",VLOOKUP(ROUND(CONCATENATE($A12,AA$2),0),'Cadastro - Padrões'!$A$2:$T$1160,AA$1,FALSE))) -> 1 | AB12: =IF($B12="-","-",IF(VLOOKUP(ROUND(CONCATENATE($A12,AB$2),0),'Cadastro - Padrões'!$A$2:$T$1160,AB$1,FALSE)="","-",VLOOKUP(ROUND(CONCATENATE($A12,AB$2),0),'Cadastro - Padrões'!$A$2:$T$1160,AB$1,FALSE))) -> 2 | AC12: =IF($B12="-","-",IF(VLOOKUP(ROUND(CONCATENATE($A12,AC$2),0),'Cadastro - Padrões'!$A$2:$T$1160,AC$1,FALSE)="","-",VLOOKUP(ROUND(CONCATENATE($A12,AC$2),0),'Cadastro - Padrões'!$A$2:$T$1160,AC$1,FALSE))) -> 1000000 | ... CC12: =IF($B12="-","-",IF(VLOOKUP(ROUND(CONCATENATE($A12,CC$2),0),'Cadastro - Padrões'!$A$2:$T$1160,CC$1,FALSE)="","-",VLOOKUP(ROUND(CONCATENATE($A12,CC$2),0),'Cadastro - Padrões'!$A$2:$T$1160,CC$1,FALSE))) -> -
A13: =A12+1 -> 8 | B13: =IF(VLOOKUP(ROUND(CONCATENATE($A13,B$2),0),'Cadastro - Padrões'!$A$2:$T$1160,B$1,FALSE)="","-",VLOOKUP(ROUND(CONCATENATE($A13,B$2),0),'Cadastro - Padrões'!$A$2:$T$1160,B$1,FALSE)) -> E.TH.LP-001 | C13: =IF(VLOOKUP(ROUND(CONCATENATE($A13,C$2),0),'Cadastro - Padrões'!$A$2:$T$1160,C$1,FALSE)="","-",VLOOKUP(ROUND(CONCATENATE($A13,C$2),0),'Cadastro - Padrões'!$A$2:$T$1160,C$1,FALSE)) -> Barômetro Digital | D13: =IF($B13="-","-",VLOOKUP(ROUND(CONCATENATE($A13,D$2),0),'Cadastro - Padrões'!$A$2:$T$1160,D$1,FALSE)) -> Elus | E13: =IF($B13="-","-",VLOOKUP(ROUND(CONCATENATE($A13,E$2),0),'Cadastro - Padrões'!$A$2:$T$1160,E$1,FALSE)) -> RBC - CAL 0439 | F13: =IF($B13="-","-",VLOOKUP(ROUND(CONCATENATE($A13,F$2),0),'Cadastro - Padrões'!$A$2:$T$1160,F$1,FALSE)) -> E0396B/25 | G13: =IF($B13="-","-",VLOOKUP(ROUND(CONCATENATE($A13,G$2),0),'Cadastro - Padrões'!$A$2:$T$1160,G$1,FALSE)) -> 45822 | H13: =IF($B13="-","-",VLOOKUP(ROUND(CONCATENATE($A13,H$2),0),'Cadastro - Padrões'!$A$2:$T$1160,H$1,FALSE)) -> 46203 | I13: =IF($B13="-","-",VLOOKUP(ROUND(CONCATENATE($A13,I$2),0),'Cadastro - Padrões'!$A$2:$T$1160,I$1,FALSE)) -> hPa | J13: =IF($B13="-","-",VLOOKUP(ROUND(CONCATENATE($A13,J$2),0),'Cadastro - Padrões'!$A$2:$T$1160,J$1,FALSE)) -> 910 | K13: =IF($B13="-","-",VLOOKUP(ROUND(CONCATENATE($A13,K$2),0),'Cadastro - Padrões'!$A$2:$T$1160,K$1,FALSE)) -> 950 | ... U13: =IF($B13="-","-",VLOOKUP(ROUND(CONCATENATE($A13,U$2),0),'Cadastro - Padrões'!$A$2:$T$1160,U$1,FALSE)) -> -2.2737368e-13 | V13: =IF($B13="-","-",IF(VLOOKUP(ROUND(CONCATENATE($A13,V$2),0),'Cadastro - Padrões'!$A$2:$T$1160,V$1,FALSE)="","-",VLOOKUP(ROUND(CONCATENATE($A13,V$2),0),'Cadastro - Padrões'!$A$2:$T$1160,V$1,FALSE))) -> 910 | W13: =IF($B13="-","-",IF(VLOOKUP(ROUND(CONCATENATE($A13,W$2),0),'Cadastro - Padrões'!$A$2:$T$1160,W$1,FALSE)="","-",VLOOKUP(ROUND(CONCATENATE($A13,W$2),0),'Cadastro - Padrões'!$A$2:$T$1160,W$1,FALSE))) -> 0.2 | X13: =IF($B13="-","-",IF(VLOOKUP(ROUND(CONCATENATE($A13,X$2),0),'Cadastro - Padrões'!$A$2:$T$1160,X$1,FALSE)="","-",VLOOKUP(ROUND(CONCATENATE($A13,X$2),0),'Cadastro - Padrões'!$A$2:$T$1160,X$1,FALSE))) -> 2 | Y13: =IF($B13="-","-",IF(VLOOKUP(ROUND(CONCATENATE($A13,Y$2),0),'Cadastro - Padrões'!$A$2:$T$1160,Y$1,FALSE)="","-",VLOOKUP(ROUND(CONCATENATE($A13,Y$2),0),'Cadastro - Padrões'!$A$2:$T$1160,Y$1,FALSE))) -> 1000000 | Z13: =IF($B13="-","-",IF(VLOOKUP(ROUND(CONCATENATE($A13,Z$2),0),'Cadastro - Padrões'!$A$2:$T$1160,Z$1,FALSE)="","-",VLOOKUP(ROUND(CONCATENATE($A13,Z$2),0),'Cadastro - Padrões'!$A$2:$T$1160,Z$1,FALSE))) -> 930 | AA13: =IF($B13="-","-",IF(VLOOKUP(ROUND(CONCATENATE($A13,AA$2),0),'Cadastro - Padrões'!$A$2:$T$1160,AA$1,FALSE)="","-",VLOOKUP(ROUND(CONCATENATE($A13,AA$2),0),'Cadastro - Padrões'!$A$2:$T$1160,AA$1,FALSE))) -> 0.2 | AB13: =IF($B13="-","-",IF(VLOOKUP(ROUND(CONCATENATE($A13,AB$2),0),'Cadastro - Padrões'!$A$2:$T$1160,AB$1,FALSE)="","-",VLOOKUP(ROUND(CONCATENATE($A13,AB$2),0),'Cadastro - Padrões'!$A$2:$T$1160,AB$1,FALSE))) -> 2 | AC13: =IF($B13="-","-",IF(VLOOKUP(ROUND(CONCATENATE($A13,AC$2),0),'Cadastro - Padrões'!$A$2:$T$1160,AC$1,FALSE)="","-",VLOOKUP(ROUND(CONCATENATE($A13,AC$2),0),'Cadastro - Padrões'!$A$2:$T$1160,AC$1,FALSE))) -> 1000000 | ... CC13: =IF($B13="-","-",IF(VLOOKUP(ROUND(CONCATENATE($A13,CC$2),0),'Cadastro - Padrões'!$A$2:$T$1160,CC$1,FALSE)="","-",VLOOKUP(ROUND(CONCATENATE($A13,CC$2),0),'Cadastro - Padrões'!$A$2:$T$1160,CC$1,FALSE))) -> -
A14: =A13+1 -> 9 | B14: =IF(VLOOKUP(ROUND(CONCATENATE($A14,B$2),0),'Cadastro - Padrões'!$A$2:$T$1160,B$1,FALSE)="","-",VLOOKUP(ROUND(CONCATENATE($A14,B$2),0),'Cadastro - Padrões'!$A$2:$T$1160,B$1,FALSE)) -> E.TH.LQ-001 | C14: =IF(VLOOKUP(ROUND(CONCATENATE($A14,C$2),0),'Cadastro - Padrões'!$A$2:$T$1160,C$1,FALSE)="","-",VLOOKUP(ROUND(CONCATENATE($A14,C$2),0),'Cadastro - Padrões'!$A$2:$T$1160,C$1,FALSE)) -> Barômetro Digital | D14: =IF($B14="-","-",VLOOKUP(ROUND(CONCATENATE($A14,D$2),0),'Cadastro - Padrões'!$A$2:$T$1160,D$1,FALSE)) -> Elus | E14: =IF($B14="-","-",VLOOKUP(ROUND(CONCATENATE($A14,E$2),0),'Cadastro - Padrões'!$A$2:$T$1160,E$1,FALSE)) -> RBC - CAL 0439 | F14: =IF($B14="-","-",VLOOKUP(ROUND(CONCATENATE($A14,F$2),0),'Cadastro - Padrões'!$A$2:$T$1160,F$1,FALSE)) -> E0397B/25 | G14: =IF($B14="-","-",VLOOKUP(ROUND(CONCATENATE($A14,G$2),0),'Cadastro - Padrões'!$A$2:$T$1160,G$1,FALSE)) -> 45822 | H14: =IF($B14="-","-",VLOOKUP(ROUND(CONCATENATE($A14,H$2),0),'Cadastro - Padrões'!$A$2:$T$1160,H$1,FALSE)) -> 46203 | I14: =IF($B14="-","-",VLOOKUP(ROUND(CONCATENATE($A14,I$2),0),'Cadastro - Padrões'!$A$2:$T$1160,I$1,FALSE)) -> hPa | J14: =IF($B14="-","-",VLOOKUP(ROUND(CONCATENATE($A14,J$2),0),'Cadastro - Padrões'!$A$2:$T$1160,J$1,FALSE)) -> 910.1 | K14: =IF($B14="-","-",VLOOKUP(ROUND(CONCATENATE($A14,K$2),0),'Cadastro - Padrões'!$A$2:$T$1160,K$1,FALSE)) -> 950.2 | ... U14: =IF($B14="-","-",VLOOKUP(ROUND(CONCATENATE($A14,U$2),0),'Cadastro - Padrões'!$A$2:$T$1160,U$1,FALSE)) -> -2.1916667 | V14: =IF($B14="-","-",IF(VLOOKUP(ROUND(CONCATENATE($A14,V$2),0),'Cadastro - Padrões'!$A$2:$T$1160,V$1,FALSE)="","-",VLOOKUP(ROUND(CONCATENATE($A14,V$2),0),'Cadastro - Padrões'!$A$2:$T$1160,V$1,FALSE))) -> 910.1 | W14: =IF($B14="-","-",IF(VLOOKUP(ROUND(CONCATENATE($A14,W$2),0),'Cadastro - Padrões'!$A$2:$T$1160,W$1,FALSE)="","-",VLOOKUP(ROUND(CONCATENATE($A14,W$2),0),'Cadastro - Padrões'!$A$2:$T$1160,W$1,FALSE))) -> 0.2 | X14: =IF($B14="-","-",IF(VLOOKUP(ROUND(CONCATENATE($A14,X$2),0),'Cadastro - Padrões'!$A$2:$T$1160,X$1,FALSE)="","-",VLOOKUP(ROUND(CONCATENATE($A14,X$2),0),'Cadastro - Padrões'!$A$2:$T$1160,X$1,FALSE))) -> 2 | Y14: =IF($B14="-","-",IF(VLOOKUP(ROUND(CONCATENATE($A14,Y$2),0),'Cadastro - Padrões'!$A$2:$T$1160,Y$1,FALSE)="","-",VLOOKUP(ROUND(CONCATENATE($A14,Y$2),0),'Cadastro - Padrões'!$A$2:$T$1160,Y$1,FALSE))) -> 1000000 | Z14: =IF($B14="-","-",IF(VLOOKUP(ROUND(CONCATENATE($A14,Z$2),0),'Cadastro - Padrões'!$A$2:$T$1160,Z$1,FALSE)="","-",VLOOKUP(ROUND(CONCATENATE($A14,Z$2),0),'Cadastro - Padrões'!$A$2:$T$1160,Z$1,FALSE))) -> 930.1 | AA14: =IF($B14="-","-",IF(VLOOKUP(ROUND(CONCATENATE($A14,AA$2),0),'Cadastro - Padrões'!$A$2:$T$1160,AA$1,FALSE)="","-",VLOOKUP(ROUND(CONCATENATE($A14,AA$2),0),'Cadastro - Padrões'!$A$2:$T$1160,AA$1,FALSE))) -> 0.2 | AB14: =IF($B14="-","-",IF(VLOOKUP(ROUND(CONCATENATE($A14,AB$2),0),'Cadastro - Padrões'!$A$2:$T$1160,AB$1,FALSE)="","-",VLOOKUP(ROUND(CONCATENATE($A14,AB$2),0),'Cadastro - Padrões'!$A$2:$T$1160,AB$1,FALSE))) -> 2 | AC14: =IF($B14="-","-",IF(VLOOKUP(ROUND(CONCATENATE($A14,AC$2),0),'Cadastro - Padrões'!$A$2:$T$1160,AC$1,FALSE)="","-",VLOOKUP(ROUND(CONCATENATE($A14,AC$2),0),'Cadastro - Padrões'!$A$2:$T$1160,AC$1,FALSE))) -> 1000000 | ... CC14: =IF($B14="-","-",IF(VLOOKUP(ROUND(CONCATENATE($A14,CC$2),0),'Cadastro - Padrões'!$A$2:$T$1160,CC$1,FALSE)="","-",VLOOKUP(ROUND(CONCATENATE($A14,CC$2),0),'Cadastro - Padrões'!$A$2:$T$1160,CC$1,FALSE))) -> -
A15: =A14+1 -> 10 | B15: =IF(VLOOKUP(ROUND(CONCATENATE($A15,B$2),0),'Cadastro - Padrões'!$A$2:$T$1160,B$1,FALSE)="","-",VLOOKUP(ROUND(CONCATENATE($A15,B$2),0),'Cadastro - Padrões'!$A$2:$T$1160,B$1,FALSE)) -> E.TH.LQ-002 | C15: =IF(VLOOKUP(ROUND(CONCATENATE($A15,C$2),0),'Cadastro - Padrões'!$A$2:$T$1160,C$1,FALSE)="","-",VLOOKUP(ROUND(CONCATENATE($A15,C$2),0),'Cadastro - Padrões'!$A$2:$T$1160,C$1,FALSE)) -> Barômetro Digital | D15: =IF($B15="-","-",VLOOKUP(ROUND(CONCATENATE($A15,D$2),0),'Cadastro - Padrões'!$A$2:$T$1160,D$1,FALSE)) -> Elus | E15: =IF($B15="-","-",VLOOKUP(ROUND(CONCATENATE($A15,E$2),0),'Cadastro - Padrões'!$A$2:$T$1160,E$1,FALSE)) -> RBC - CAL 0439 | F15: =IF($B15="-","-",VLOOKUP(ROUND(CONCATENATE($A15,F$2),0),'Cadastro - Padrões'!$A$2:$T$1160,F$1,FALSE)) -> E0398B/25 | G15: =IF($B15="-","-",VLOOKUP(ROUND(CONCATENATE($A15,G$2),0),'Cadastro - Padrões'!$A$2:$T$1160,G$1,FALSE)) -> 45822 | H15: =IF($B15="-","-",VLOOKUP(ROUND(CONCATENATE($A15,H$2),0),'Cadastro - Padrões'!$A$2:$T$1160,H$1,FALSE)) -> 46203 | I15: =IF($B15="-","-",VLOOKUP(ROUND(CONCATENATE($A15,I$2),0),'Cadastro - Padrões'!$A$2:$T$1160,I$1,FALSE)) -> hPa | J15: =IF($B15="-","-",VLOOKUP(ROUND(CONCATENATE($A15,J$2),0),'Cadastro - Padrões'!$A$2:$T$1160,J$1,FALSE)) -> 910 | K15: =IF($B15="-","-",VLOOKUP(ROUND(CONCATENATE($A15,K$2),0),'Cadastro - Padrões'!$A$2:$T$1160,K$1,FALSE)) -> 950 | ... U15: =IF($B15="-","-",VLOOKUP(ROUND(CONCATENATE($A15,U$2),0),'Cadastro - Padrões'!$A$2:$T$1160,U$1,FALSE)) -> -2.2737368e-13 | V15: =IF($B15="-","-",IF(VLOOKUP(ROUND(CONCATENATE($A15,V$2),0),'Cadastro - Padrões'!$A$2:$T$1160,V$1,FALSE)="","-",VLOOKUP(ROUND(CONCATENATE($A15,V$2),0),'Cadastro - Padrões'!$A$2:$T$1160,V$1,FALSE))) -> 910 | W15: =IF($B15="-","-",IF(VLOOKUP(ROUND(CONCATENATE($A15,W$2),0),'Cadastro - Padrões'!$A$2:$T$1160,W$1,FALSE)="","-",VLOOKUP(ROUND(CONCATENATE($A15,W$2),0),'Cadastro - Padrões'!$A$2:$T$1160,W$1,FALSE))) -> 0.2 | X15: =IF($B15="-","-",IF(VLOOKUP(ROUND(CONCATENATE($A15,X$2),0),'Cadastro - Padrões'!$A$2:$T$1160,X$1,FALSE)="","-",VLOOKUP(ROUND(CONCATENATE($A15,X$2),0),'Cadastro - Padrões'!$A$2:$T$1160,X$1,FALSE))) -> 2 | Y15: =IF($B15="-","-",IF(VLOOKUP(ROUND(CONCATENATE($A15,Y$2),0),'Cadastro - Padrões'!$A$2:$T$1160,Y$1,FALSE)="","-",VLOOKUP(ROUND(CONCATENATE($A15,Y$2),0),'Cadastro - Padrões'!$A$2:$T$1160,Y$1,FALSE))) -> 1000000 | Z15: =IF($B15="-","-",IF(VLOOKUP(ROUND(CONCATENATE($A15,Z$2),0),'Cadastro - Padrões'!$A$2:$T$1160,Z$1,FALSE)="","-",VLOOKUP(ROUND(CONCATENATE($A15,Z$2),0),'Cadastro - Padrões'!$A$2:$T$1160,Z$1,FALSE))) -> 930 | AA15: =IF($B15="-","-",IF(VLOOKUP(ROUND(CONCATENATE($A15,AA$2),0),'Cadastro - Padrões'!$A$2:$T$1160,AA$1,FALSE)="","-",VLOOKUP(ROUND(CONCATENATE($A15,AA$2),0),'Cadastro - Padrões'!$A$2:$T$1160,AA$1,FALSE))) -> 0.2 | AB15: =IF($B15="-","-",IF(VLOOKUP(ROUND(CONCATENATE($A15,AB$2),0),'Cadastro - Padrões'!$A$2:$T$1160,AB$1,FALSE)="","-",VLOOKUP(ROUND(CONCATENATE($A15,AB$2),0),'Cadastro - Padrões'!$A$2:$T$1160,AB$1,FALSE))) -> 2 | AC15: =IF($B15="-","-",IF(VLOOKUP(ROUND(CONCATENATE($A15,AC$2),0),'Cadastro - Padrões'!$A$2:$T$1160,AC$1,FALSE)="","-",VLOOKUP(ROUND(CONCATENATE($A15,AC$2),0),'Cadastro - Padrões'!$A$2:$T$1160,AC$1,FALSE))) -> 1000000 | ... CC15: =IF($B15="-","-",IF(VLOOKUP(ROUND(CONCATENATE($A15,CC$2),0),'Cadastro - Padrões'!$A$2:$T$1160,CC$1,FALSE)="","-",VLOOKUP(ROUND(CONCATENATE($A15,CC$2),0),'Cadastro - Padrões'!$A$2:$T$1160,CC$1,FALSE))) -> -
A16: =A15+1 -> 11 | B16: =IF(VLOOKUP(ROUND(CONCATENATE($A16,B$2),0),'Cadastro - Padrões'!$A$2:$T$1160,B$1,FALSE)="","-",VLOOKUP(ROUND(CONCATENATE($A16,B$2),0),'Cadastro - Padrões'!$A$2:$T$1160,B$1,FALSE)) -> E.TH.LV-002 | C16: =IF(VLOOKUP(ROUND(CONCATENATE($A16,C$2),0),'Cadastro - Padrões'!$A$2:$T$1160,C$1,FALSE)="","-",VLOOKUP(ROUND(CONCATENATE($A16,C$2),0),'Cadastro - Padrões'!$A$2:$T$1160,C$1,FALSE)) -> Barômetro Digital | D16: =IF($B16="-","-",VLOOKUP(ROUND(CONCATENATE($A16,D$2),0),'Cadastro - Padrões'!$A$2:$T$1160,D$1,FALSE)) -> Elus | E16: =IF($B16="-","-",VLOOKUP(ROUND(CONCATENATE($A16,E$2),0),'Cadastro - Padrões'!$A$2:$T$1160,E$1,FALSE)) -> RBC - CAL 0439 | F16: =IF($B16="-","-",VLOOKUP(ROUND(CONCATENATE($A16,F$2),0),'Cadastro - Padrões'!$A$2:$T$1160,F$1,FALSE)) -> E0400B/25 | G16: =IF($B16="-","-",VLOOKUP(ROUND(CONCATENATE($A16,G$2),0),'Cadastro - Padrões'!$A$2:$T$1160,G$1,FALSE)) -> 45822 | H16: =IF($B16="-","-",VLOOKUP(ROUND(CONCATENATE($A16,H$2),0),'Cadastro - Padrões'!$A$2:$T$1160,H$1,FALSE)) -> 46203 | I16: =IF($B16="-","-",VLOOKUP(ROUND(CONCATENATE($A16,I$2),0),'Cadastro - Padrões'!$A$2:$T$1160,I$1,FALSE)) -> hPa | J16: =IF($B16="-","-",VLOOKUP(ROUND(CONCATENATE($A16,J$2),0),'Cadastro - Padrões'!$A$2:$T$1160,J$1,FALSE)) -> 909.77 | K16: =IF($B16="-","-",VLOOKUP(ROUND(CONCATENATE($A16,K$2),0),'Cadastro - Padrões'!$A$2:$T$1160,K$1,FALSE)) -> 949.75 | ... U16: =IF($B16="-","-",VLOOKUP(ROUND(CONCATENATE($A16,U$2),0),'Cadastro - Padrões'!$A$2:$T$1160,U$1,FALSE)) -> 0.22166667 | V16: =IF($B16="-","-",IF(VLOOKUP(ROUND(CONCATENATE($A16,V$2),0),'Cadastro - Padrões'!$A$2:$T$1160,V$1,FALSE)="","-",VLOOKUP(ROUND(CONCATENATE($A16,V$2),0),'Cadastro - Padrões'!$A$2:$T$1160,V$1,FALSE))) -> 909.77 | W16: =IF($B16="-","-",IF(VLOOKUP(ROUND(CONCATENATE($A16,W$2),0),'Cadastro - Padrões'!$A$2:$T$1160,W$1,FALSE)="","-",VLOOKUP(ROUND(CONCATENATE($A16,W$2),0),'Cadastro - Padrões'!$A$2:$T$1160,W$1,FALSE))) -> 0.12 | X16: =IF($B16="-","-",IF(VLOOKUP(ROUND(CONCATENATE($A16,X$2),0),'Cadastro - Padrões'!$A$2:$T$1160,X$1,FALSE)="","-",VLOOKUP(ROUND(CONCATENATE($A16,X$2),0),'Cadastro - Padrões'!$A$2:$T$1160,X$1,FALSE))) -> 2 | Y16: =IF($B16="-","-",IF(VLOOKUP(ROUND(CONCATENATE($A16,Y$2),0),'Cadastro - Padrões'!$A$2:$T$1160,Y$1,FALSE)="","-",VLOOKUP(ROUND(CONCATENATE($A16,Y$2),0),'Cadastro - Padrões'!$A$2:$T$1160,Y$1,FALSE))) -> 1000000 | Z16: =IF($B16="-","-",IF(VLOOKUP(ROUND(CONCATENATE($A16,Z$2),0),'Cadastro - Padrões'!$A$2:$T$1160,Z$1,FALSE)="","-",VLOOKUP(ROUND(CONCATENATE($A16,Z$2),0),'Cadastro - Padrões'!$A$2:$T$1160,Z$1,FALSE))) -> 929.75 | AA16: =IF($B16="-","-",IF(VLOOKUP(ROUND(CONCATENATE($A16,AA$2),0),'Cadastro - Padrões'!$A$2:$T$1160,AA$1,FALSE)="","-",VLOOKUP(ROUND(CONCATENATE($A16,AA$2),0),'Cadastro - Padrões'!$A$2:$T$1160,AA$1,FALSE))) -> 0.12 | AB16: =IF($B16="-","-",IF(VLOOKUP(ROUND(CONCATENATE($A16,AB$2),0),'Cadastro - Padrões'!$A$2:$T$1160,AB$1,FALSE)="","-",VLOOKUP(ROUND(CONCATENATE($A16,AB$2),0),'Cadastro - Padrões'!$A$2:$T$1160,AB$1,FALSE))) -> 2 | AC16: =IF($B16="-","-",IF(VLOOKUP(ROUND(CONCATENATE($A16,AC$2),0),'Cadastro - Padrões'!$A$2:$T$1160,AC$1,FALSE)="","-",VLOOKUP(ROUND(CONCATENATE($A16,AC$2),0),'Cadastro - Padrões'!$A$2:$T$1160,AC$1,FALSE))) -> 1000000 | ... CC16: =IF($B16="-","-",IF(VLOOKUP(ROUND(CONCATENATE($A16,CC$2),0),'Cadastro - Padrões'!$A$2:$T$1160,CC$1,FALSE)="","-",VLOOKUP(ROUND(CONCATENATE($A16,CC$2),0),'Cadastro - Padrões'!$A$2:$T$1160,CC$1,FALSE))) -> -
A17: =A16+1 -> 12 | B17: =IF(VLOOKUP(ROUND(CONCATENATE($A17,B$2),0),'Cadastro - Padrões'!$A$2:$T$1160,B$1,FALSE)="","-",VLOOKUP(ROUND(CONCATENATE($A17,B$2),0),'Cadastro - Padrões'!$A$2:$T$1160,B$1,FALSE)) -> - | C17: =IF(VLOOKUP(ROUND(CONCATENATE($A17,C$2),0),'Cadastro - Padrões'!$A$2:$T$1160,C$1,FALSE)="","-",VLOOKUP(ROUND(CONCATENATE($A17,C$2),0),'Cadastro - Padrões'!$A$2:$T$1160,C$1,FALSE)) -> - | D17: =IF($B17="-","-",VLOOKUP(ROUND(CONCATENATE($A17,D$2),0),'Cadastro - Padrões'!$A$2:$T$1160,D$1,FALSE)) -> - | E17: =IF($B17="-","-",VLOOKUP(ROUND(CONCATENATE($A17,E$2),0),'Cadastro - Padrões'!$A$2:$T$1160,E$1,FALSE)) -> - | F17: =IF($B17="-","-",VLOOKUP(ROUND(CONCATENATE($A17,F$2),0),'Cadastro - Padrões'!$A$2:$T$1160,F$1,FALSE)) -> - | G17: =IF($B17="-","-",VLOOKUP(ROUND(CONCATENATE($A17,G$2),0),'Cadastro - Padrões'!$A$2:$T$1160,G$1,FALSE)) -> - | H17: =IF($B17="-","-",VLOOKUP(ROUND(CONCATENATE($A17,H$2),0),'Cadastro - Padrões'!$A$2:$T$1160,H$1,FALSE)) -> - | I17: =IF($B17="-","-",VLOOKUP(ROUND(CONCATENATE($A17,I$2),0),'Cadastro - Padrões'!$A$2:$T$1160,I$1,FALSE)) -> - | J17: =IF($B17="-","-",VLOOKUP(ROUND(CONCATENATE($A17,J$2),0),'Cadastro - Padrões'!$A$2:$T$1160,J$1,FALSE)) -> - | K17: =IF($B17="-","-",VLOOKUP(ROUND(CONCATENATE($A17,K$2),0),'Cadastro - Padrões'!$A$2:$T$1160,K$1,FALSE)) -> - | ... U17: =IF($B17="-","-",VLOOKUP(ROUND(CONCATENATE($A17,U$2),0),'Cadastro - Padrões'!$A$2:$T$1160,U$1,FALSE)) -> - | V17: =IF($B17="-","-",IF(VLOOKUP(ROUND(CONCATENATE($A17,V$2),0),'Cadastro - Padrões'!$A$2:$T$1160,V$1,FALSE)="","-",VLOOKUP(ROUND(CONCATENATE($A17,V$2),0),'Cadastro - Padrões'!$A$2:$T$1160,V$1,FALSE))) -> - | W17: =IF($B17="-","-",IF(VLOOKUP(ROUND(CONCATENATE($A17,W$2),0),'Cadastro - Padrões'!$A$2:$T$1160,W$1,FALSE)="","-",VLOOKUP(ROUND(CONCATENATE($A17,W$2),0),'Cadastro - Padrões'!$A$2:$T$1160,W$1,FALSE))) -> - | X17: =IF($B17="-","-",IF(VLOOKUP(ROUND(CONCATENATE($A17,X$2),0),'Cadastro - Padrões'!$A$2:$T$1160,X$1,FALSE)="","-",VLOOKUP(ROUND(CONCATENATE($A17,X$2),0),'Cadastro - Padrões'!$A$2:$T$1160,X$1,FALSE))) -> - | Y17: =IF($B17="-","-",IF(VLOOKUP(ROUND(CONCATENATE($A17,Y$2),0),'Cadastro - Padrões'!$A$2:$T$1160,Y$1,FALSE)="","-",VLOOKUP(ROUND(CONCATENATE($A17,Y$2),0),'Cadastro - Padrões'!$A$2:$T$1160,Y$1,FALSE))) -> - | Z17: =IF($B17="-","-",IF(VLOOKUP(ROUND(CONCATENATE($A17,Z$2),0),'Cadastro - Padrões'!$A$2:$T$1160,Z$1,FALSE)="","-",VLOOKUP(ROUND(CONCATENATE($A17,Z$2),0),'Cadastro - Padrões'!$A$2:$T$1160,Z$1,FALSE))) -> - | AA17: =IF($B17="-","-",IF(VLOOKUP(ROUND(CONCATENATE($A17,AA$2),0),'Cadastro - Padrões'!$A$2:$T$1160,AA$1,FALSE)="","-",VLOOKUP(ROUND(CONCATENATE($A17,AA$2),0),'Cadastro - Padrões'!$A$2:$T$1160,AA$1,FALSE))) -> - | AB17: =IF($B17="-","-",IF(VLOOKUP(ROUND(CONCATENATE($A17,AB$2),0),'Cadastro - Padrões'!$A$2:$T$1160,AB$1,FALSE)="","-",VLOOKUP(ROUND(CONCATENATE($A17,AB$2),0),'Cadastro - Padrões'!$A$2:$T$1160,AB$1,FALSE))) -> - | AC17: =IF($B17="-","-",IF(VLOOKUP(ROUND(CONCATENATE($A17,AC$2),0),'Cadastro - Padrões'!$A$2:$T$1160,AC$1,FALSE)="","-",VLOOKUP(ROUND(CONCATENATE($A17,AC$2),0),'Cadastro - Padrões'!$A$2:$T$1160,AC$1,FALSE))) -> - | ... CC17: =IF($B17="-","-",IF(VLOOKUP(ROUND(CONCATENATE($A17,CC$2),0),'Cadastro - Padrões'!$A$2:$T$1160,CC$1,FALSE)="","-",VLOOKUP(ROUND(CONCATENATE($A17,CC$2),0),'Cadastro - Padrões'!$A$2:$T$1160,CC$1,FALSE))) -> -
