Workbook
Name _Z99999: [1]Cliente!#REF!
Name _ZZ99: [1]Cliente!#REF!
Name capacidade: [2]Dados!$F$11
Name CERTIFICADO: [1]Cliente!$Y$8
Name data_receb: [2]Dados!$E$7
Name DATA_RECEBIMENTO: [1]Cliente!#REF!
Name ENTRADA: [1]Cliente!#REF!
Name equip: [2]Dados!$C$10
Name n_cert: [2]Dados!$C$8
Name n_ident: [2]Dados!$C$13
Name n_serie: [2]Dados!$C$14
Name pressão: [2]Dados!$D$27
Name proced: [2]Dados!$F$13
Name resolução: [2]Dados!$F$10
Name temp_ar: [2]Dados!$D$25
Name temp_carr: #REF!
Name umid: [2]Dados!#REF!
Name unid_e: [2]Dados!$D$31
Name versão: [2]Dados!$F$14

Sheet Controle
B1: 4 | C1: 4 | D1: 4 | E1: 4 | F1: 4 | G1: 4 | H1: 4 | I1: 8 | J1: 4 | K1: 7 | L1: 4 | M1: 6 | N1: 4 | O1: 5 | P1: 5 | Q1: 5 | R1: 17 | S1: 15 | T1: 11 | U1: 12 | V1: 13 | W1: 14 | X1: 15 | Y1: 16 | Z1: 17 | AA1: 18 | AB1: 19 | AC1: 2 | AD1: 4 | AE1: 5 | AF1: 6 | AG1: 2 | AH1: 4 | AI1: 5 | AJ1: 6 | AK1: 2 | AL1: 4 | AM1: 5 | AN1: 6 | AO1: 2 | AP1: 4 | AQ1: 5 | AR1: 6 | AS1: 2 | AT1: 4 | AU1: 5 | AV1: 6 | AW1: 2 | AX1: 4 | AY1: 5 | AZ1: 6 | BA1: 2 | BB1: 4 | BC1: 5 | BD1: 6 | BE1: 2 | BF1: 4 | BG1: 5 | BH1: 6 | BI1: 2 | BJ1: 4 | BK1: 5 | BL1: 6 | BM1: 2 | BN1: 4 | BO1: 5 | BP1: 6
B2: 203 | C2: 201 | D2: 204 | E2: 205 | F2: 206 | G2: 207 | H2: 208 | I2: 209 | J2: 202 | K2: 202 | L2: 210 | M2: 210 | N2: 209 | O2: 237 | P2: 241 | Q2: 233 | R2: 208 | S2: 208 | T2: 206 | U2: 206 | V2: 206 | W2: 206 | X2: 206 | Y2: 206 | Z2: 206 | AA2: 206 | AB2: 206 | AC2: 217 | AD2: =AC2 -> 217 | AE2: =AD2 -> 217 | AF2: =AE2 -> 217 | AG2: =AF2+1 -> 218 | AH2: =AG2 -> 218 | AI2: =AH2 -> 218 | AJ2: =AI2 -> 218 | AK2: =AJ2+1 -> 219 | AL2: =AK2 -> 219 | AM2: =AL2 -> 219 | AN2: =AM2 -> 219 | AO2: =AN2+1 -> 220 | AP2: =AO2 -> 220 | AQ2: =AP2 -> 220 | AR2: =AQ2 -> 220 | AS2: =AR2+1 -> 221 | AT2: =AS2 -> 221 | AU2: =AT2 -> 221 | AV2: =AU2 -> 221 | AW2: =AV2+1 -> 222 | AX2: =AW2 -> 222 | AY2: =AX2 -> 222 | AZ2: =AY2 -> 222 | BA2: =AZ2+1 -> 223 | BB2: =BA2 -> 223 | BC2: =BB2 -> 223 | BD2: =BC2 -> 223 | BE2: =BD2+1 -> 224 | BF2: =BE2 -> 224 | BG2: =BF2 -> 224 | BH2: =BG2 -> 224 | BI2: =BH2+1 -> 225 | BJ2: =BI2 -> 225 | BK2: =BJ2 -> 225 | BL2: =BK2 -> 225 | BM2: =BL2+1 -> 226 | BN2: =BM2 -> 226 | BO2: =BN2 -> 226 | BP2: =BO2 -> 226
H3: =TODAY() -> 46076 | AC3: 1 | AD3: =AC3 -> 1 | AE3: =AD3 -> 1 | AF3: =AE3 -> 1 | AG3: =AF3+1 -> 2 | AH3: =AG3 -> 2 | AI3: =AH3 -> 2 | AJ3: =AI3 -> 2 | AK3: =AJ3+1 -> 3 | AL3: =AK3 -> 3 | AM3: =AL3 -> 3 | AN3: =AM3 -> 3 | AO3: =AN3+1 -> 4 | AP3: =AO3 -> 4 | AQ3: =AP3 -> 4 | AR3: =AQ3 -> 4 | AS3: =AR3+1 -> 5 | AT3: =AS3 -> 5 | AU3: =AT3 -> 5 | AV3: =AU3 -> 5 | AW3: =AV3+1 -> 6 | AX3: =AW3 -> 6 | AY3: =AX3 -> 6 | AZ3: =AY3 -> 6 | BA3: =AZ3+1 -> 7 | BB3: =BA3 -> 7 | BC3: =BB3 -> 7 | BD3: =BC3 -> 7 | BE3: =BD3+1 -> 8 | BF3: =BE3 -> 8 | BG3: =BF3 -> 8 | BH3: =BG3 -> 8 | BI3: =BH3+1 -> 9 | BJ3: =BI3 -> 9 | BK3: =BJ3 -> 9 | BL3: =BK3 -> 9 | BM3: =BL3+1 -> 10 | BN3: =BM3 -> 10 | BO3: =BN3 -> 10 | BP3: =BO3 -> 10
R4: Polinômio da Curva | AC4: =CONCATENATE(AC3,"º Ponto") -> 1º Ponto | AG4: =CONCATENATE(AG3,"º Ponto") -> 2º Ponto | AK4: =CONCATENATE(AK3,"º Ponto") -> 3º Ponto | AO4: =CONCATENATE(AO3,"º Ponto") -> 4º Ponto | AS4: =CONCATENATE(AS3,"º Ponto") -> 5º Ponto | AW4: =CONCATENATE(AW3,"º Ponto") -> 6º Ponto | BA4: =CONCATENATE(BA3,"º Ponto") -> 7º Ponto | BE4: =CONCATENATE(BE3,"º Ponto") -> 8º Ponto | BI4: =CONCATENATE(BI3,"º Ponto") -> 9º Ponto | BM4: =CONCATENATE(BM3,"º Ponto") -> 10º Ponto
B5: TAG | C5: Padrão | D5: Calibrado por | E5: Rastreabilidade | F5: n° do certificado | G5: Data da Calibração | H5: Vencimento | I5: Unidade calibrada | J5: Tipo de medição | K5: Tipo do sensor | L5: Faixa mínima | M5: Faixa máxima | N5: Resolução | O5: Maior desvio | P5: Maior Incerteza | Q5: Deriva | R5: Residuo | S5: Veff | T5: X8 | U5: X7 | V5: X6 | W5: X5 | X5: X4 | Y5: X3 | Z5: X2 | AA5: X1 | AB5: X0 | AC5: =CONCATENATE(AC3,"-VR") -> 1-VR | AD5: =CONCATENATE(AD3,"-U") -> 1-U | AE5: =CONCATENATE(AE3,"-K") -> 1-K | AF5: =CONCATENATE(AF3,"-GL") -> 1-GL | AG5: =CONCATENATE(AG3,"-VR") -> 2-VR | AH5: =CONCATENATE(AH3,"-U") -> 2-U | AI5: =CONCATENATE(AI3,"-K") -> 2-K | AJ5: =CONCATENATE(AJ3,"-GL") -> 2-GL | AK5: =CONCATENATE(AK3,"-VR") -> 3-VR | AL5: =CONCATENATE(AL3,"-U") -> 3-U | AM5: =CONCATENATE(AM3,"-K") -> 3-K | AN5: =CONCATENATE(AN3,"-GL") -> 3-GL | AO5: =CONCATENATE(AO3,"-VR") -> 4-VR | AP5: =CONCATENATE(AP3,"-U") -> 4-U | AQ5: =CONCATENATE(AQ3,"-K") -> 4-K | AR5: =CONCATENATE(AR3,"-GL") -> 4-GL | AS5: =CONCATENATE(AS3,"-VR") -> 5-VR | AT5: =CONCATENATE(AT3,"-U") -> 5-U | AU5: =CONCATENATE(AU3,"-K") -> 5-K | AV5: =CONCATENATE(AV3,"-GL") -> 5-GL | AW5: =CONCATENATE(AW3,"-VR") -> 6-VR | AX5: =CONCATENATE(AX3,"-U") -> 6-U | AY5: =CONCATENATE(AY3,"-K") -> 6-K | AZ5: =CONCATENATE(AZ3,"-GL") -> 6-GL | BA5: =CONCATENATE(BA3,"-VR") -> 7-VR | BB5: =CONCATENATE(BB3,"-U") -> 7-U | BC5: =CONCATENATE(BC3,"-K") -> 7-K | BD5: =CONCATENATE(BD3,"-GL") -> 7-GL | BE5: =CONCATENATE(BE3,"-VR") -> 8-VR | BF5: =CONCATENATE(BF3,"-U") -> 8-U | BG5: =CONCATENATE(BG3,"-K") -> 8-K | BH5: =CONCATENATE(BH3,"-GL") -> 8-GL | BI5: =CONCATENATE(BI3,"-VR") -> 9-VR | BJ5: =CONCATENATE(BJ3,"-U") -> 9-U | BK5: =CONCATENATE(BK3,"-K") -> 9-K | BL5: =CONCATENATE(BL3,"-GL") -> 9-GL | BM5: =CONCATENATE(BM3,"-VR") -> 10-VR | BN5: =CONCATENATE(BN3,"-U") -> 10-U | BO5: =CONCATENATE(BO3,"-K") -> 10-K | BP5: =CONCATENATE(BP3,"-GL") -> 10-GL
A6: 1 | B6: =IF(VLOOKUP(ROUND(CONCATENATE($A6,B$2),0),'Cadastro - Padrões'!$A$2:$V$10081,B$1,FALSE)="","-",VLOOKUP(ROUND(CONCATENATE($A6,B$2),0),'Cadastro - Padrões'!$A$2:$V$10081,B$1,FALSE)) -> E.TH.LT-010 | C6: =IF($B6="-","-",VLOOKUP(ROUND(CONCATENATE($A6,C$2),0),'Cadastro - Padrões'!$A$2:$V$10081,C$1,FALSE)) -> Termômetro Digital | D6: =IF($B6="-","-",VLOOKUP(ROUND(CONCATENATE($A6,D$2),0),'Cadastro - Padrões'!$A$2:$V$4272,D$1,FALSE)) -> Elus | E6: =IF($B6="-","-",VLOOKUP(ROUND(CONCATENATE($A6,E$2),0),'Cadastro - Padrões'!$A$2:$V$4272,E$1,FALSE)) -> RBC - CAL 0439 | F6: =IF($B6="-","-",VLOOKUP(ROUND(CONCATENATE($A6,F$2),0),'Cadastro - Padrões'!$A$2:$V$4272,F$1,FALSE)) -> E0319/25 | G6: =IF($B6="-","-",VLOOKUP(ROUND(CONCATENATE($A6,G$2),0),'Cadastro - Padrões'!$A$2:$V$10081,G$1,FALSE)) -> 45807 | H6: =IF($B6="-","-",VLOOKUP(ROUND(CONCATENATE($A6,H$2),0),'Cadastro - Padrões'!$A$2:$V$10081,H$1,FALSE)) -> 46172 | I6: =IF($B6="-","-",VLOOKUP(ROUND(CONCATENATE($A6,I$2),0),'Cadastro - Padrões'!$A$2:$V$10081,I$1,FALSE)) -> °C | J6: =IF($B6="-","-",VLOOKUP(ROUND(CONCATENATE($A6,J$2),0),'Cadastro - Padrões'!$A$2:$V$10081,J$1,FALSE)) -> Contato | K6: =IF($B6="-","-",VLOOKUP(ROUND(CONCATENATE($A6,K$2),0),'Cadastro - Padrões'!$A$2:$V$10081,K$1,FALSE)) -> Termoresisitivo | L6: =IF($B6="-","-",VLOOKUP(ROUND(CONCATENATE($A6,L$2),0),'Cadastro - Padrões'!$A$2:$V$10081,L$1,FALSE)) -> -90 | M6: =IF($B6="-","-",VLOOKUP(ROUND(CONCATENATE($A6,M$2),0),'Cadastro - Padrões'!$A$2:$V$10081,M$1,FALSE)) -> 300 | N6: =IF($B6="-","-",VLOOKUP(ROUND(CONCATENATE($A6,N$2),0),'Cadastro - Padrões'!$A$2:$V$10081,N$1,FALSE)) -> 0.001 | ... AB6: =IF($B6="-","-",VLOOKUP(ROUND(CONCATENATE($A6,AB$2),0),'Cadastro - Padrões'!$A$2:$V$10081,AB$1,FALSE)) -> -0.0032031676 | AC6: =IF($B6="-","-",IF(VLOOKUP(ROUND(CONCATENATE($A6,AC$2),0),'Cadastro - Padrões'!$A$2:$V$10081,AC$1,FALSE)="","-",VLOOKUP(ROUND(CONCATENATE($A6,AC$2),0),'Cadastro - Padrões'!$A$2:$V$10081,AC$1,FALSE))) -> -90 | AD6: =IF($B6="-","-",IF(VLOOKUP(ROUND(CONCATENATE($A6,AD$2),0),'Cadastro - Padrões'!$A$2:$V$10081,AD$1,FALSE)="","-",VLOOKUP(ROUND(CONCATENATE($A6,AD$2),0),'Cadastro - Padrões'!$A$2:$V$10081,AD$1,FALSE))) -> 0.07 | AE6: =IF($B6="-","-",IF(VLOOKUP(ROUND(CONCATENATE($A6,AE$2),0),'Cadastro - Padrões'!$A$2:$V$10081,AE$1,FALSE)="","-",VLOOKUP(ROUND(CONCATENATE($A6,AE$2),0),'Cadastro - Padrões'!$A$2:$V$10081,AE$1,FALSE))) -> 2 | AF6: =IF($B6="-","-",IF(VLOOKUP(ROUND(CONCATENATE($A6,AF$2),0),'Cadastro - Padrões'!$A$2:$V$10081,AF$1,FALSE)="","-",VLOOKUP(ROUND(CONCATENATE($A6,AF$2),0),'Cadastro - Padrões'!$A$2:$V$10081,AF$1,FALSE))) -> 1000000 | AG6: =IF($B6="-","-",IF(VLOOKUP(ROUND(CONCATENATE($A6,AG$2),0),'Cadastro - Padrões'!$A$2:$V$10081,AG$1,FALSE)="","-",VLOOKUP(ROUND(CONCATENATE($A6,AG$2),0),'Cadastro - Padrões'!$A$2:$V$10081,AG$1,FALSE))) -> -45 | AH6: =IF($B6="-","-",IF(VLOOKUP(ROUND(CONCATENATE($A6,AH$2),0),'Cadastro - Padrões'!$A$2:$V$10081,AH$1,FALSE)="","-",VLOOKUP(ROUND(CONCATENATE($A6,AH$2),0),'Cadastro - Padrões'!$A$2:$V$10081,AH$1,FALSE))) -> 0.03 | AI6: =IF($B6="-","-",IF(VLOOKUP(ROUND(CONCATENATE($A6,AI$2),0),'Cadastro - Padrões'!$A$2:$V$10081,AI$1,FALSE)="","-",VLOOKUP(ROUND(CONCATENATE($A6,AI$2),0),'Cadastro - Padrões'!$A$2:$V$10081,AI$1,FALSE))) -> 2 | AJ6: =IF($B6="-","-",IF(VLOOKUP(ROUND(CONCATENATE($A6,AJ$2),0),'Cadastro - Padrões'!$A$2:$V$10081,AJ$1,FALSE)="","-",VLOOKUP(ROUND(CONCATENATE($A6,AJ$2),0),'Cadastro - Padrões'!$A$2:$V$10081,AJ$1,FALSE))) -> 1000000 | ... BP6: =IF($B6="-","-",IF(VLOOKUP(ROUND(CONCATENATE($A6,BP$2),0),'Cadastro - Padrões'!$A$2:$V$10081,BP$1,FALSE)="","-",VLOOKUP(ROUND(CONCATENATE($A6,BP$2),0),'Cadastro - Padrões'!$A$2:$V$10081,BP$1,FALSE))) -> -
A7: =A6+1 -> 2 | B7: =IF(VLOOKUP(ROUND(CONCATENATE($A7,B$2),0),'Cadastro - Padrões'!$A$2:$V$10081,B$1,FALSE)="","-",VLOOKUP(ROUND(CONCATENATE($A7,B$2),0),'Cadastro - Padrões'!$A$2:$V$10081,B$1,FALSE)) -> E.TH.PMR-004 | C7: =IF($B7="-","-",VLOOKUP(ROUND(CONCATENATE($A7,C$2),0),'Cadastro - Padrões'!$A$2:$V$10081,C$1,FALSE)) -> Termohigrômetro Digital | D7: =IF($B7="-","-",VLOOKUP(ROUND(CONCATENATE($A7,D$2),0),'Cadastro - Padrões'!$A$2:$V$10081,D$1,FALSE)) -> Elus | E7: =IF($B7="-","-",VLOOKUP(ROUND(CONCATENATE($A7,E$2),0),'Cadastro - Padrões'!$A$2:$V$10081,E$1,FALSE)) -> RBC - CAL 0439 | F7: =IF($B7="-","-",VLOOKUP(ROUND(CONCATENATE($A7,F$2),0),'Cadastro - Padrões'!$A$2:$V$10081,F$1,FALSE)) -> E0401/25 | G7: =IF($B7="-","-",VLOOKUP(ROUND(CONCATENATE($A7,G$2),0),'Cadastro - Padrões'!$A$2:$V$10081,G$1,FALSE)) -> 45836 | H7: =IF($B7="-","-",VLOOKUP(ROUND(CONCATENATE($A7,H$2),0),'Cadastro - Padrões'!$A$2:$V$10081,H$1,FALSE)) -> 46203 | I7: =IF($B7="-","-",VLOOKUP(ROUND(CONCATENATE($A7,I$2),0),'Cadastro - Padrões'!$A$2:$V$10081,I$1,FALSE)) -> °C | J7: =IF($B7="-","-",VLOOKUP(ROUND(CONCATENATE($A7,J$2),0),'Cadastro - Padrões'!$A$2:$V$10081,J$1,FALSE)) -> IN | ... AB7: =IF($B7="-","-",VLOOKUP(ROUND(CONCATENATE($A7,AB$2),0),'Cadastro - Padrões'!$A$2:$V$10081,AB$1,FALSE)) -> 0.38992112 | AC7: =IF($B7="-","-",IF(VLOOKUP(ROUND(CONCATENATE($A7,AC$2),0),'Cadastro - Padrões'!$A$2:$V$10081,AC$1,FALSE)="","-",VLOOKUP(ROUND(CONCATENATE($A7,AC$2),0),'Cadastro - Padrões'!$A$2:$V$10081,AC$1,FALSE))) -> 15 | AD7: =IF($B7="-","-",IF(VLOOKUP(ROUND(CONCATENATE($A7,AD$2),0),'Cadastro - Padrões'!$A$2:$V$10081,AD$1,FALSE)="","-",VLOOKUP(ROUND(CONCATENATE($A7,AD$2),0),'Cadastro - Padrões'!$A$2:$V$10081,AD$1,FALSE))) -> 0.2 | AE7: =IF($B7="-","-",IF(VLOOKUP(ROUND(CONCATENATE($A7,AE$2),0),'Cadastro - Padrões'!$A$2:$V$10081,AE$1,FALSE)="","-",VLOOKUP(ROUND(CONCATENATE($A7,AE$2),0),'Cadastro - Padrões'!$A$2:$V$10081,AE$1,FALSE))) -> 2 | AF7: =IF($B7="-","-",IF(VLOOKUP(ROUND(CONCATENATE($A7,AF$2),0),'Cadastro - Padrões'!$A$2:$V$10081,AF$1,FALSE)="","-",VLOOKUP(ROUND(CONCATENATE($A7,AF$2),0),'Cadastro - Padrões'!$A$2:$V$10081,AF$1,FALSE))) -> 1000000 | AG7: =IF($B7="-","-",IF(VLOOKUP(ROUND(CONCATENATE($A7,AG$2),0),'Cadastro - Padrões'!$A$2:$V$10081,AG$1,FALSE)="","-",VLOOKUP(ROUND(CONCATENATE($A7,AG$2),0),'Cadastro - Padrões'!$A$2:$V$10081,AG$1,FALSE))) -> 25 | AH7: =IF($B7="-","-",IF(VLOOKUP(ROUND(CONCATENATE($A7,AH$2),0),'Cadastro - Padrões'!$A$2:$V$10081,AH$1,FALSE)="","-",VLOOKUP(ROUND(CONCATENATE($A7,AH$2),0),'Cadastro - Padrões'!$A$2:$V$10081,AH$1,FALSE))) -> 0.2 | AI7: =IF($B7="-","-",IF(VLOOKUP(ROUND(CONCATENATE($A7,AI$2),0),'Cadastro - Padrões'!$A$2:$V$10081,AI$1,FALSE)="","-",VLOOKUP(ROUND(CONCATENATE($A7,AI$2),0),'Cadastro - Padrões'!$A$2:$V$10081,AI$1,FALSE))) -> 2 | AJ7: =IF($B7="-","-",IF(VLOOKUP(ROUND(CONCATENATE($A7,AJ$2),0),'Cadastro - Padrões'!$A$2:$V$10081,AJ$1,FALSE)="","-",VLOOKUP(ROUND(CONCATENATE($A7,AJ$2),0),'Cadastro - Padrões'!$A$2:$V$10081,AJ$1,FALSE))) -> 1000000 | ... BP7: =IF($B7="-","-",IF(VLOOKUP(ROUND(CONCATENATE($A7,BP$2),0),'Cadastro - Padrões'!$A$2:$V$10081,BP$1,FALSE)="","-",VLOOKUP(ROUND(CONCATENATE($A7,BP$2),0),'Cadastro - Padrões'!$A$2:$V$10081,BP$1,FALSE))) -> -
A8: =A7+1 -> 3 | B8: =IF(VLOOKUP(ROUND(CONCATENATE($A8,B$2),0),'Cadastro - Padrões'!$A$2:$V$10081,B$1,FALSE)="","-",VLOOKUP(ROUND(CONCATENATE($A8,B$2),0),'Cadastro - Padrões'!$A$2:$V$10081,B$1,FALSE)) -> EL-800 | C8: =IF($B8="-","-",VLOOKUP(ROUND(CONCATENATE($A8,C$2),0),'Cadastro - Padrões'!$A$2:$V$10081,C$1,FALSE)) -> Termohigrômetro Digital | D8: =IF($B8="-","-",VLOOKUP(ROUND(CONCATENATE($A8,D$2),0),'Cadastro - Padrões'!$A$2:$V$10081,D$1,FALSE)) -> Elus | E8: =IF($B8="-","-",VLOOKUP(ROUND(CONCATENATE($A8,E$2),0),'Cadastro - Padrões'!$A$2:$V$10081,E$1,FALSE)) -> RBC - CAL 0439 | F8: =IF($B8="-","-",VLOOKUP(ROUND(CONCATENATE($A8,F$2),0),'Cadastro - Padrões'!$A$2:$V$10081,F$1,FALSE)) -> R0038/24 | G8: =IF($B8="-","-",VLOOKUP(ROUND(CONCATENATE($A8,G$2),0),'Cadastro - Padrões'!$A$2:$V$10081,G$1,FALSE)) -> 45412 | H8: =IF($B8="-","-",VLOOKUP(ROUND(CONCATENATE($A8,H$2),0),'Cadastro - Padrões'!$A$2:$V$10081,H$1,FALSE)) -> 45777 | I8: =IF($B8="-","-",VLOOKUP(ROUND(CONCATENATE($A8,I$2),0),'Cadastro - Padrões'!$A$2:$V$10081,I$1,FALSE)) -> °C | J8: =IF($B8="-","-",VLOOKUP(ROUND(CONCATENATE($A8,J$2),0),'Cadastro - Padrões'!$A$2:$V$10081,J$1,FALSE)) -> OUT | ... AB8: =IF($B8="-","-",VLOOKUP(ROUND(CONCATENATE($A8,AB$2),0),'Cadastro - Padrões'!$A$2:$V$10081,AB$1,FALSE)) -> 0.64237583 | AC8: =IF($B8="-","-",IF(VLOOKUP(ROUND(CONCATENATE($A8,AC$2),0),'Cadastro - Padrões'!$A$2:$V$10081,AC$1,FALSE)="","-",VLOOKUP(ROUND(CONCATENATE($A8,AC$2),0),'Cadastro - Padrões'!$A$2:$V$10081,AC$1,FALSE))) -> -10 | AD8: =IF($B8="-","-",IF(VLOOKUP(ROUND(CONCATENATE($A8,AD$2),0),'Cadastro - Padrões'!$A$2:$V$10081,AD$1,FALSE)="","-",VLOOKUP(ROUND(CONCATENATE($A8,AD$2),0),'Cadastro - Padrões'!$A$2:$V$10081,AD$1,FALSE))) -> 0.1 | AE8: =IF($B8="-","-",IF(VLOOKUP(ROUND(CONCATENATE($A8,AE$2),0),'Cadastro - Padrões'!$A$2:$V$10081,AE$1,FALSE)="","-",VLOOKUP(ROUND(CONCATENATE($A8,AE$2),0),'Cadastro - Padrões'!$A$2:$V$10081,AE$1,FALSE))) -> 2 | AF8: =IF($B8="-","-",IF(VLOOKUP(ROUND(CONCATENATE($A8,AF$2),0),'Cadastro - Padrões'!$A$2:$V$10081,AF$1,FALSE)="","-",VLOOKUP(ROUND(CONCATENATE($A8,AF$2),0),'Cadastro - Padrões'!$A$2:$V$10081,AF$1,FALSE))) -> 1000000 | AG8: =IF($B8="-","-",IF(VLOOKUP(ROUND(CONCATENATE($A8,AG$2),0),'Cadastro - Padrões'!$A$2:$V$10081,AG$1,FALSE)="","-",VLOOKUP(ROUND(CONCATENATE($A8,AG$2),0),'Cadastro - Padrões'!$A$2:$V$10081,AG$1,FALSE))) -> 25 | AH8: =IF($B8="-","-",IF(VLOOKUP(ROUND(CONCATENATE($A8,AH$2),0),'Cadastro - Padrões'!$A$2:$V$10081,AH$1,FALSE)="","-",VLOOKUP(ROUND(CONCATENATE($A8,AH$2),0),'Cadastro - Padrões'!$A$2:$V$10081,AH$1,FALSE))) -> 0.1 | AI8: =IF($B8="-","-",IF(VLOOKUP(ROUND(CONCATENATE($A8,AI$2),0),'Cadastro - Padrões'!$A$2:$V$10081,AI$1,FALSE)="","-",VLOOKUP(ROUND(CONCATENATE($A8,AI$2),0),'Cadastro - Padrões'!$A$2:$V$10081,AI$1,FALSE))) -> 2 | AJ8: =IF($B8="-","-",IF(VLOOKUP(ROUND(CONCATENATE($A8,AJ$2),0),'Cadastro - Padrões'!$A$2:$V$10081,AJ$1,FALSE)="","-",VLOOKUP(ROUND(CONCATENATE($A8,AJ$2),0),'Cadastro - Padrões'!$A$2:$V$10081,AJ$1,FALSE))) -> 1000000 | ... BP8: =IF($B8="-","-",IF(VLOOKUP(ROUND(CONCATENATE($A8,BP$2),0),'Cadastro - Padrões'!$A$2:$V$10081,BP$1,FALSE)="","-",VLOOKUP(ROUND(CONCATENATE($A8,BP$2),0),'Cadastro - Padrões'!$A$2:$V$10081,BP$1,FALSE))) -> -
A9: =A8+1 -> 4 | B9: =IF(VLOOKUP(ROUND(CONCATENATE($A9,B$2),0),'Cadastro - Padrões'!$A$2:$V$10081,B$1,FALSE)="","-",VLOOKUP(ROUND(CONCATENATE($A9,B$2),0),'Cadastro - Padrões'!$A$2:$V$10081,B$1,FALSE)) -> EL-800 | C9: =IF($B9="-","-",VLOOKUP(ROUND(CONCATENATE($A9,C$2),0),'Cadastro - Padrões'!$A$2:$V$10081,C$1,FALSE)) -> Termohigrômetro Digital | D9: =IF($B9="-","-",VLOOKUP(ROUND(CONCATENATE($A9,D$2),0),'Cadastro - Padrões'!$A$2:$V$10081,D$1,FALSE)) -> Elus | E9: =IF($B9="-","-",VLOOKUP(ROUND(CONCATENATE($A9,E$2),0),'Cadastro - Padrões'!$A$2:$V$10081,E$1,FALSE)) -> RBC - CAL 0439 | F9: =IF($B9="-","-",VLOOKUP(ROUND(CONCATENATE($A9,F$2),0),'Cadastro - Padrões'!$A$2:$V$10081,F$1,FALSE)) -> R0038/24 | G9: =IF($B9="-","-",VLOOKUP(ROUND(CONCATENATE($A9,G$2),0),'Cadastro - Padrões'!$A$2:$V$10081,G$1,FALSE)) -> 45412 | H9: =IF($B9="-","-",VLOOKUP(ROUND(CONCATENATE($A9,H$2),0),'Cadastro - Padrões'!$A$2:$V$10081,H$1,FALSE)) -> 45777 | I9: =IF($B9="-","-",VLOOKUP(ROUND(CONCATENATE($A9,I$2),0),'Cadastro - Padrões'!$A$2:$V$10081,I$1,FALSE)) -> °C | J9: =IF($B9="-","-",VLOOKUP(ROUND(CONCATENATE($A9,J$2),0),'Cadastro - Padrões'!$A$2:$V$10081,J$1,FALSE)) -> IN | ... AB9: =IF($B9="-","-",VLOOKUP(ROUND(CONCATENATE($A9,AB$2),0),'Cadastro - Padrões'!$A$2:$V$10081,AB$1,FALSE)) -> 0.20408163 | AC9: =IF($B9="-","-",IF(VLOOKUP(ROUND(CONCATENATE($A9,AC$2),0),'Cadastro - Padrões'!$A$2:$V$10081,AC$1,FALSE)="","-",VLOOKUP(ROUND(CONCATENATE($A9,AC$2),0),'Cadastro - Padrões'!$A$2:$V$10081,AC$1,FALSE))) -> 15 | AD9: =IF($B9="-","-",IF(VLOOKUP(ROUND(CONCATENATE($A9,AD$2),0),'Cadastro - Padrões'!$A$2:$V$10081,AD$1,FALSE)="","-",VLOOKUP(ROUND(CONCATENATE($A9,AD$2),0),'Cadastro - Padrões'!$A$2:$V$10081,AD$1,FALSE))) -> 0.2 | AE9: =IF($B9="-","-",IF(VLOOKUP(ROUND(CONCATENATE($A9,AE$2),0),'Cadastro - Padrões'!$A$2:$V$10081,AE$1,FALSE)="","-",VLOOKUP(ROUND(CONCATENATE($A9,AE$2),0),'Cadastro - Padrões'!$A$2:$V$10081,AE$1,FALSE))) -> 2 | AF9: =IF($B9="-","-",IF(VLOOKUP(ROUND(CONCATENATE($A9,AF$2),0),'Cadastro - Padrões'!$A$2:$V$10081,AF$1,FALSE)="","-",VLOOKUP(ROUND(CONCATENATE($A9,AF$2),0),'Cadastro - Padrões'!$A$2:$V$10081,AF$1,FALSE))) -> 1000000 | AG9: =IF($B9="-","-",IF(VLOOKUP(ROUND(CONCATENATE($A9,AG$2),0),'Cadastro - Padrões'!$A$2:$V$10081,AG$1,FALSE)="","-",VLOOKUP(ROUND(CONCATENATE($A9,AG$2),0),'Cadastro - Padrões'!$A$2:$V$10081,AG$1,FALSE))) -> 25 | AH9: =IF($B9="-","-",IF(VLOOKUP(ROUND(CONCATENATE($A9,AH$2),0),'Cadastro - Padrões'!$A$2:$V$10081,AH$1,FALSE)="","-",VLOOKUP(ROUND(CONCATENATE($A9,AH$2),0),'Cadastro - Padrões'!$A$2:$V$10081,AH$1,FALSE))) -> 0.2 | AI9: =IF($B9="-","-",IF(VLOOKUP(ROUND(CONCATENATE($A9,AI$2),0),'Cadastro - Padrões'!$A$2:$V$10081,AI$1,FALSE)="","-",VLOOKUP(ROUND(CONCATENATE($A9,AI$2),0),'Cadastro - Padrões'!$A$2:$V$10081,AI$1,FALSE))) -> 2 | AJ9: =IF($B9="-","-",IF(VLOOKUP(ROUND(CONCATENATE($A9,AJ$2),0),'Cadastro - Padrões'!$A$2:$V$10081,AJ$1,FALSE)="","-",VLOOKUP(ROUND(CONCATENATE($A9,AJ$2),0),'Cadastro - Padrões'!$A$2:$V$10081,AJ$1,FALSE))) -> 1000000 | ... BP9: =IF($B9="-","-",IF(VLOOKUP(ROUND(CONCATENATE($A9,BP$2),0),'Cadastro - Padrões'!$A$2:$V$10081,BP$1,FALSE)="","-",VLOOKUP(ROUND(CONCATENATE($A9,BP$2),0),'Cadastro - Padrões'!$A$2:$V$10081,BP$1,FALSE))) -> -
A10: =A9+1 -> 5 | B10: =IF(VLOOKUP(ROUND(CONCATENATE($A10,B$2),0),'Cadastro - Padrões'!$A$2:$V$10081,B$1,FALSE)="","-",VLOOKUP(ROUND(CONCATENATE($A10,B$2),0),'Cadastro - Padrões'!$A$2:$V$10081,B$1,FALSE)) -> E.VM.LQ-021 | C10: =IF($B10="-","-",VLOOKUP(ROUND(CONCATENATE($A10,C$2),0),'Cadastro - Padrões'!$A$2:$V$10081,C$1,FALSE)) -> Termômetro Digital | D10: =IF($B10="-","-",VLOOKUP(ROUND(CONCATENATE($A10,D$2),0),'Cadastro - Padrões'!$A$2:$V$10081,D$1,FALSE)) -> Elus | E10: =IF($B10="-","-",VLOOKUP(ROUND(CONCATENATE($A10,E$2),0),'Cadastro - Padrões'!$A$2:$V$10081,E$1,FALSE)) -> RBC - CAL 0439 | F10: =IF($B10="-","-",VLOOKUP(ROUND(CONCATENATE($A10,F$2),0),'Cadastro - Padrões'!$A$2:$V$10081,F$1,FALSE)) -> E0758/25 | G10: =IF($B10="-","-",VLOOKUP(ROUND(CONCATENATE($A10,G$2),0),'Cadastro - Padrões'!$A$2:$V$10081,G$1,FALSE)) -> 45959 | H10: =IF($B10="-","-",VLOOKUP(ROUND(CONCATENATE($A10,H$2),0),'Cadastro - Padrões'!$A$2:$V$10081,H$1,FALSE)) -> 46325 | I10: =IF($B10="-","-",VLOOKUP(ROUND(CONCATENATE($A10,I$2),0),'Cadastro - Padrões'!$A$2:$V$10081,I$1,FALSE)) -> °C | J10: =IF($B10="-","-",VLOOKUP(ROUND(CONCATENATE($A10,J$2),0),'Cadastro - Padrões'!$A$2:$V$10081,J$1,FALSE)) -> Contato | ... AB10: =IF($B10="-","-",VLOOKUP(ROUND(CONCATENATE($A10,AB$2),0),'Cadastro - Padrões'!$A$2:$V$10081,AB$1,FALSE)) -> -0.011384702 | AC10: =IF($B10="-","-",IF(VLOOKUP(ROUND(CONCATENATE($A10,AC$2),0),'Cadastro - Padrões'!$A$2:$V$10081,AC$1,FALSE)="","-",VLOOKUP(ROUND(CONCATENATE($A10,AC$2),0),'Cadastro - Padrões'!$A$2:$V$10081,AC$1,FALSE))) -> 9.99 | AD10: =IF($B10="-","-",IF(VLOOKUP(ROUND(CONCATENATE($A10,AD$2),0),'Cadastro - Padrões'!$A$2:$V$10081,AD$1,FALSE)="","-",VLOOKUP(ROUND(CONCATENATE($A10,AD$2),0),'Cadastro - Padrões'!$A$2:$V$10081,AD$1,FALSE))) -> 0.05 | AE10: =IF($B10="-","-",IF(VLOOKUP(ROUND(CONCATENATE($A10,AE$2),0),'Cadastro - Padrões'!$A$2:$V$10081,AE$1,FALSE)="","-",VLOOKUP(ROUND(CONCATENATE($A10,AE$2),0),'Cadastro - Padrões'!$A$2:$V$10081,AE$1,FALSE))) -> 2 | AF10: =IF($B10="-","-",IF(VLOOKUP(ROUND(CONCATENATE($A10,AF$2),0),'Cadastro - Padrões'!$A$2:$V$10081,AF$1,FALSE)="","-",VLOOKUP(ROUND(CONCATENATE($A10,AF$2),0),'Cadastro - Padrões'!$A$2:$V$10081,AF$1,FALSE))) -> 1000000 | AG10: =IF($B10="-","-",IF(VLOOKUP(ROUND(CONCATENATE($A10,AG$2),0),'Cadastro - Padrões'!$A$2:$V$10081,AG$1,FALSE)="","-",VLOOKUP(ROUND(CONCATENATE($A10,AG$2),0),'Cadastro - Padrões'!$A$2:$V$10081,AG$1,FALSE))) -> 14.99 | AH10: =IF($B10="-","-",IF(VLOOKUP(ROUND(CONCATENATE($A10,AH$2),0),'Cadastro - Padrões'!$A$2:$V$10081,AH$1,FALSE)="","-",VLOOKUP(ROUND(CONCATENATE($A10,AH$2),0),'Cadastro - Padrões'!$A$2:$V$10081,AH$1,FALSE))) -> 0.05 | AI10: =IF($B10="-","-",IF(VLOOKUP(ROUND(CONCATENATE($A10,AI$2),0),'Cadastro - Padrões'!$A$2:$V$10081,AI$1,FALSE)="","-",VLOOKUP(ROUND(CONCATENATE($A10,AI$2),0),'Cadastro - Padrões'!$A$2:$V$10081,AI$1,FALSE))) -> 2 | AJ10: =IF($B10="-","-",IF(VLOOKUP(ROUND(CONCATENATE($A10,AJ$2),0),'Cadastro - Padrões'!$A$2:$V$10081,AJ$1,FALSE)="","-",VLOOKUP(ROUND(CONCATENATE($A10,AJ$2),0),'Cadastro - Padrões'!$A$2:$V$10081,AJ$1,FALSE))) -> 1000000 | ... BP10: =IF($B10="-","-",IF(VLOOKUP(ROUND(CONCATENATE($A10,BP$2),0),'Cadastro - Padrões'!$A$2:$V$10081,BP$1,FALSE)="","-",VLOOKUP(ROUND(CONCATENATE($A10,BP$2),0),'Cadastro - Padrões'!$A$2:$V$10081,BP$1,FALSE))) -> -
A11: =A10+1 -> 6 | B11: =IF(VLOOKUP(ROUND(CONCATENATE($A11,B$2),0),'Cadastro - Padrões'!$A$2:$V$10081,B$1,FALSE)="","-",VLOOKUP(ROUND(CONCATENATE($A11,B$2),0),'Cadastro - Padrões'!$A$2:$V$10081,B$1,FALSE)) -> E.TH.PMR-006 | C11: =IF($B11="-","-",VLOOKUP(ROUND(CONCATENATE($A11,C$2),0),'Cadastro - Padrões'!$A$2:$V$10081,C$1,FALSE)) -> Termohigrômetro Digital | D11: =IF($B11="-","-",VLOOKUP(ROUND(CONCATENATE($A11,D$2),0),'Cadastro - Padrões'!$A$2:$V$10081,D$1,FALSE)) -> Elus | E11: =IF($B11="-","-",VLOOKUP(ROUND(CONCATENATE($A11,E$2),0),'Cadastro - Padrões'!$A$2:$V$10081,E$1,FALSE)) -> RBC - CAL 0439 | F11: =IF($B11="-","-",VLOOKUP(ROUND(CONCATENATE($A11,F$2),0),'Cadastro - Padrões'!$A$2:$V$10081,F$1,FALSE)) -> E0208/25 | G11: =IF($B11="-","-",VLOOKUP(ROUND(CONCATENATE($A11,G$2),0),'Cadastro - Padrões'!$A$2:$V$10081,G$1,FALSE)) -> 45761 | H11: =IF($B11="-","-",VLOOKUP(ROUND(CONCATENATE($A11,H$2),0),'Cadastro - Padrões'!$A$2:$V$10081,H$1,FALSE)) -> 46142 | I11: =IF($B11="-","-",VLOOKUP(ROUND(CONCATENATE($A11,I$2),0),'Cadastro - Padrões'!$A$2:$V$10081,I$1,FALSE)) -> °C | J11: =IF($B11="-","-",VLOOKUP(ROUND(CONCATENATE($A11,J$2),0),'Cadastro - Padrões'!$A$2:$V$10081,J$1,FALSE)) -> IN | ... AB11: =IF($B11="-","-",VLOOKUP(ROUND(CONCATENATE($A11,AB$2),0),'Cadastro - Padrões'!$A$2:$V$10081,AB$1,FALSE)) -> 0.1 | AC11: =IF($B11="-","-",IF(VLOOKUP(ROUND(CONCATENATE($A11,AC$2),0),'Cadastro - Padrões'!$A$2:$V$10081,AC$1,FALSE)="","-",VLOOKUP(ROUND(CONCATENATE($A11,AC$2),0),'Cadastro - Padrões'!$A$2:$V$10081,AC$1,FALSE))) -> 15 | AD11: =IF($B11="-","-",IF(VLOOKUP(ROUND(CONCATENATE($A11,AD$2),0),'Cadastro - Padrões'!$A$2:$V$10081,AD$1,FALSE)="","-",VLOOKUP(ROUND(CONCATENATE($A11,AD$2),0),'Cadastro - Padrões'!$A$2:$V$10081,AD$1,FALSE))) -> 0.1 | AE11: =IF($B11="-","-",IF(VLOOKUP(ROUND(CONCATENATE($A11,AE$2),0),'Cadastro - Padrões'!$A$2:$V$10081,AE$1,FALSE)="","-",VLOOKUP(ROUND(CONCATENATE($A11,AE$2),0),'Cadastro - Padrões'!$A$2:$V$10081,AE$1,FALSE))) -> 2 | AF11: =IF($B11="-","-",IF(VLOOKUP(ROUND(CONCATENATE($A11,AF$2),0),'Cadastro - Padrões'!$A$2:$V$10081,AF$1,FALSE)="","-",VLOOKUP(ROUND(CONCATENATE($A11,AF$2),0),'Cadastro - Padrões'!$A$2:$V$10081,AF$1,FALSE))) -> 1000000 | AG11: =IF($B11="-","-",IF(VLOOKUP(ROUND(CONCATENATE($A11,AG$2),0),'Cadastro - Padrões'!$A$2:$V$10081,AG$1,FALSE)="","-",VLOOKUP(ROUND(CONCATENATE($A11,AG$2),0),'Cadastro - Padrões'!$A$2:$V$10081,AG$1,FALSE))) -> 25 | AH11: =IF($B11="-","-",IF(VLOOKUP(ROUND(CONCATENATE($A11,AH$2),0),'Cadastro - Padrões'!$A$2:$V$10081,AH$1,FALSE)="","-",VLOOKUP(ROUND(CONCATENATE($A11,AH$2),0),'Cadastro - Padrões'!$A$2:$V$10081,AH$1,FALSE))) -> 0.1 | AI11: =IF($B11="-","-",IF(VLOOKUP(ROUND(CONCATENATE($A11,AI$2),0),'Cadastro - Padrões'!$A$2:$V$10081,AI$1,FALSE)="","-",VLOOKUP(ROUND(CONCATENATE($A11,AI$2),0),'Cadastro - Padrões'!$A$2:$V$10081,AI$1,FALSE))) -> 2 | AJ11: =IF($B11="-","-",IF(VLOOKUP(ROUND(CONCATENATE($A11,AJ$2),0),'Cadastro - Padrões'!$A$2:$V$10081,AJ$1,FALSE)="","-",VLOOKUP(ROUND(CONCATENATE($A11,AJ$2),0),'Cadastro - Padrões'!$A$2:$V$10081,AJ$1,FALSE))) -> 1000000 | ... BP11: =IF($B11="-","-",IF(VLOOKUP(ROUND(CONCATENATE($A11,BP$2),0),'Cadastro - Padrões'!$A$2:$V$10081,BP$1,FALSE)="","-",VLOOKUP(ROUND(CONCATENATE($A11,BP$2),0),'Cadastro - Padrões'!$A$2:$V$10081,BP$1,FALSE))) -> -
A12: =A11+1 -> 7 | B12: =IF(VLOOKUP(ROUND(CONCATENATE($A12,B$2),0),'Cadastro - Padrões'!$A$2:$V$10081,B$1,FALSE)="","-",VLOOKUP(ROUND(CONCATENATE($A12,B$2),0),'Cadastro - Padrões'!$A$2:$V$10081,B$1,FALSE)) -> E.TH.FS-051 | C12: =IF($B12="-","-",VLOOKUP(ROUND(CONCATENATE($A12,C$2),0),'Cadastro - Padrões'!$A$2:$V$10081,C$1,FALSE)) -> Termohigrômetro Digital | D12: =IF($B12="-","-",VLOOKUP(ROUND(CONCATENATE($A12,D$2),0),'Cadastro - Padrões'!$A$2:$V$10081,D$1,FALSE)) -> Elus | E12: =IF($B12="-","-",VLOOKUP(ROUND(CONCATENATE($A12,E$2),0),'Cadastro - Padrões'!$A$2:$V$10081,E$1,FALSE)) -> RBC - CAL 0439 | F12: =IF($B12="-","-",VLOOKUP(ROUND(CONCATENATE($A12,F$2),0),'Cadastro - Padrões'!$A$2:$V$10081,F$1,FALSE)) -> E0051/26 | G12: =IF($B12="-","-",VLOOKUP(ROUND(CONCATENATE($A12,G$2),0),'Cadastro - Padrões'!$A$2:$V$10081,G$1,FALSE)) -> 46056 | H12: =IF($B12="-","-",VLOOKUP(ROUND(CONCATENATE($A12,H$2),0),'Cadastro - Padrões'!$A$2:$V$10081,H$1,FALSE)) -> 46446 | I12: =IF($B12="-","-",VLOOKUP(ROUND(CONCATENATE($A12,I$2),0),'Cadastro - Padrões'!$A$2:$V$10081,I$1,FALSE)) -> °C | J12: =IF($B12="-","-",VLOOKUP(ROUND(CONCATENATE($A12,J$2),0),'Cadastro - Padrões'!$A$2:$V$10081,J$1,FALSE)) -> IN | ... AB12: =IF($B12="-","-",VLOOKUP(ROUND(CONCATENATE($A12,AB$2),0),'Cadastro - Padrões'!$A$2:$V$10081,AB$1,FALSE)) -> 0.59527241 | AC12: =IF($B12="-","-",IF(VLOOKUP(ROUND(CONCATENATE($A12,AC$2),0),'Cadastro - Padrões'!$A$2:$V$10081,AC$1,FALSE)="","-",VLOOKUP(ROUND(CONCATENATE($A12,AC$2),0),'Cadastro - Padrões'!$A$2:$V$10081,AC$1,FALSE))) -> 15 | AD12: =IF($B12="-","-",IF(VLOOKUP(ROUND(CONCATENATE($A12,AD$2),0),'Cadastro - Padrões'!$A$2:$V$10081,AD$1,FALSE)="","-",VLOOKUP(ROUND(CONCATENATE($A12,AD$2),0),'Cadastro - Padrões'!$A$2:$V$10081,AD$1,FALSE))) -> 0.2 | AE12: =IF($B12="-","-",IF(VLOOKUP(ROUND(CONCATENATE($A12,AE$2),0),'Cadastro - Padrões'!$A$2:$V$10081,AE$1,FALSE)="","-",VLOOKUP(ROUND(CONCATENATE($A12,AE$2),0),'Cadastro - Padrões'!$A$2:$V$10081,AE$1,FALSE))) -> 2 | AF12: =IF($B12="-","-",IF(VLOOKUP(ROUND(CONCATENATE($A12,AF$2),0),'Cadastro - Padrões'!$A$2:$V$10081,AF$1,FALSE)="","-",VLOOKUP(ROUND(CONCATENATE($A12,AF$2),0),'Cadastro - Padrões'!$A$2:$V$10081,AF$1,FALSE))) -> 1000000 | AG12: =IF($B12="-","-",IF(VLOOKUP(ROUND(CONCATENATE($A12,AG$2),0),'Cadastro - Padrões'!$A$2:$V$10081,AG$1,FALSE)="","-",VLOOKUP(ROUND(CONCATENATE($A12,AG$2),0),'Cadastro - Padrões'!$A$2:$V$10081,AG$1,FALSE))) -> 25 | AH12: =IF($B12="-","-",IF(VLOOKUP(ROUND(CONCATENATE($A12,AH$2),0),'Cadastro - Padrões'!$A$2:$V$10081,AH$1,FALSE)="","-",VLOOKUP(ROUND(CONCATENATE($A12,AH$2),0),'Cadastro - Padrões'!$A$2:$V$10081,AH$1,FALSE))) -> 0.2 | AI12: =IF($B12="-","-",IF(VLOOKUP(ROUND(CONCATENATE($A12,AI$2),0),'Cadastro - Padrões'!$A$2:$V$10081,AI$1,FALSE)="","-",VLOOKUP(ROUND(CONCATENATE($A12,AI$2),0),'Cadastro - Padrões'!$A$2:$V$10081,AI$1,FALSE))) -> 2 | AJ12: =IF($B12="-","-",IF(VLOOKUP(ROUND(CONCATENATE($A12,AJ$2),0),'Cadastro - Padrões'!$A$2:$V$10081,AJ$1,FALSE)="","-",VLOOKUP(ROUND(CONCATENATE($A12,AJ$2),0),'Cadastro - Padrões'!$A$2:$V$10081,AJ$1,FALSE))) -> 1000000 | ... BP12: =IF($B12="-","-",IF(VLOOKUP(ROUND(CONCATENATE($A12,BP$2),0),'Cadastro - Padrões'!$A$2:$V$10081,BP$1,FALSE)="","-",VLOOKUP(ROUND(CONCATENATE($A12,BP$2),0),'Cadastro - Padrões'!$A$2:$V$10081,BP$1,FALSE))) -> -
A13: =A12+1 -> 8 | B13: =IF(VLOOKUP(ROUND(CONCATENATE($A13,B$2),0),'Cadastro - Padrões'!$A$2:$V$10081,B$1,FALSE)="","-",VLOOKUP(ROUND(CONCATENATE($A13,B$2),0),'Cadastro - Padrões'!$A$2:$V$10081,B$1,FALSE)) -> E.TH.FS-051 | C13: =IF($B13="-","-",VLOOKUP(ROUND(CONCATENATE($A13,C$2),0),'Cadastro - Padrões'!$A$2:$V$10081,C$1,FALSE)) -> Termohigrômetro Digital | D13: =IF($B13="-","-",VLOOKUP(ROUND(CONCATENATE($A13,D$2),0),'Cadastro - Padrões'!$A$2:$V$10081,D$1,FALSE)) -> Elus | E13: =IF($B13="-","-",VLOOKUP(ROUND(CONCATENATE($A13,E$2),0),'Cadastro - Padrões'!$A$2:$V$10081,E$1,FALSE)) -> RBC - CAL 0439 | F13: =IF($B13="-","-",VLOOKUP(ROUND(CONCATENATE($A13,F$2),0),'Cadastro - Padrões'!$A$2:$V$10081,F$1,FALSE)) -> E0051/26 | G13: =IF($B13="-","-",VLOOKUP(ROUND(CONCATENATE($A13,G$2),0),'Cadastro - Padrões'!$A$2:$V$10081,G$1,FALSE)) -> 46056 | H13: =IF($B13="-","-",VLOOKUP(ROUND(CONCATENATE($A13,H$2),0),'Cadastro - Padrões'!$A$2:$V$10081,H$1,FALSE)) -> 46446 | I13: =IF($B13="-","-",VLOOKUP(ROUND(CONCATENATE($A13,I$2),0),'Cadastro - Padrões'!$A$2:$V$10081,I$1,FALSE)) -> °C | J13: =IF($B13="-","-",VLOOKUP(ROUND(CONCATENATE($A13,J$2),0),'Cadastro - Padrões'!$A$2:$V$10081,J$1,FALSE)) -> OUT | ... AB13: =IF($B13="-","-",VLOOKUP(ROUND(CONCATENATE($A13,AB$2),0),'Cadastro - Padrões'!$A$2:$V$10081,AB$1,FALSE)) -> 0.23829553 | AC13: =IF($B13="-","-",IF(VLOOKUP(ROUND(CONCATENATE($A13,AC$2),0),'Cadastro - Padrões'!$A$2:$V$10081,AC$1,FALSE)="","-",VLOOKUP(ROUND(CONCATENATE($A13,AC$2),0),'Cadastro - Padrões'!$A$2:$V$10081,AC$1,FALSE))) -> 15 | AD13: =IF($B13="-","-",IF(VLOOKUP(ROUND(CONCATENATE($A13,AD$2),0),'Cadastro - Padrões'!$A$2:$V$10081,AD$1,FALSE)="","-",VLOOKUP(ROUND(CONCATENATE($A13,AD$2),0),'Cadastro - Padrões'!$A$2:$V$10081,AD$1,FALSE))) -> 0.1 | AE13: =IF($B13="-","-",IF(VLOOKUP(ROUND(CONCATENATE($A13,AE$2),0),'Cadastro - Padrões'!$A$2:$V$10081,AE$1,FALSE)="","-",VLOOKUP(ROUND(CONCATENATE($A13,AE$2),0),'Cadastro - Padrões'!$A$2:$V$10081,AE$1,FALSE))) -> 2 | AF13: =IF($B13="-","-",IF(VLOOKUP(ROUND(CONCATENATE($A13,AF$2),0),'Cadastro - Padrões'!$A$2:$V$10081,AF$1,FALSE)="","-",VLOOKUP(ROUND(CONCATENATE($A13,AF$2),0),'Cadastro - Padrões'!$A$2:$V$10081,AF$1,FALSE))) -> 1000000 | AG13: =IF($B13="-","-",IF(VLOOKUP(ROUND(CONCATENATE($A13,AG$2),0),'Cadastro - Padrões'!$A$2:$V$10081,AG$1,FALSE)="","-",VLOOKUP(ROUND(CONCATENATE($A13,AG$2),0),'Cadastro - Padrões'!$A$2:$V$10081,AG$1,FALSE))) -> 25 | AH13: =IF($B13="-","-",IF(VLOOKUP(ROUND(CONCATENATE($A13,AH$2),0),'Cadastro - Padrões'!$A$2:$V$10081,AH$1,FALSE)="","-",VLOOKUP(ROUND(CONCATENATE($A13,AH$2),0),'Cadastro - Padrões'!$A$2:$V$10081,AH$1,FALSE))) -> 0.1 | AI13: =IF($B13="-","-",IF(VLOOKUP(ROUND(CONCATENATE($A13,AI$2),0),'Cadastro - Padrões'!$A$2:$V$10081,AI$1,FALSE)="","-",VLOOKUP(ROUND(CONCATENATE($A13,AI$2),0),'Cadastro - Padrões'!$A$2:$V$10081,AI$1,FALSE))) -> 2 | AJ13: =IF($B13="-","-",IF(VLOOKUP(ROUND(CONCATENATE($A13,AJ$2),0),'Cadastro - Padrões'!$A$2:$V$10081,AJ$1,FALSE)="","-",VLOOKUP(ROUND(CONCATENATE($A13,AJ$2),0),'Cadastro - Padrões'!$A$2:$V$10081,AJ$1,FALSE))) -> 1000000 | ... BP13: =IF($B13="-","-",IF(VLOOKUP(ROUND(CONCATENATE($A13,BP$2),0),'Cadastro - Padrões'!$A$2:$V$10081,BP$1,FALSE)="","-",VLOOKUP(ROUND(CONCATENATE($A13,BP$2),0),'Cadastro - Padrões'!$A$2:$V$10081,BP$1,FALSE))) -> -
A14: =A13+1 -> 9 | B14: =IF(VLOOKUP(ROUND(CONCATENATE($A14,B$2),0),'Cadastro - Padrões'!$A$2:$V$10081,B$1,FALSE)="","-",VLOOKUP(ROUND(CONCATENATE($A14,B$2),0),'Cadastro - Padrões'!$A$2:$V$10081,B$1,FALSE)) -> E.PS.LQ-020 | C14: =IF($B14="-","-",VLOOKUP(ROUND(CONCATENATE($A14,C$2),0),'Cadastro - Padrões'!$A$2:$V$10081,C$1,FALSE)) -> Termohigrômetro Digital | D14: =IF($B14="-","-",VLOOKUP(ROUND(CONCATENATE($A14,D$2),0),'Cadastro - Padrões'!$A$2:$V$10081,D$1,FALSE)) -> Elus | E14: =IF($B14="-","-",VLOOKUP(ROUND(CONCATENATE($A14,E$2),0),'Cadastro - Padrões'!$A$2:$V$10081,E$1,FALSE)) -> RBC - CAL 0439 | F14: =IF($B14="-","-",VLOOKUP(ROUND(CONCATENATE($A14,F$2),0),'Cadastro - Padrões'!$A$2:$V$10081,F$1,FALSE)) -> E0440/25 | G14: =IF($B14="-","-",VLOOKUP(ROUND(CONCATENATE($A14,G$2),0),'Cadastro - Padrões'!$A$2:$V$10081,G$1,FALSE)) -> 45839 | H14: =IF($B14="-","-",VLOOKUP(ROUND(CONCATENATE($A14,H$2),0),'Cadastro - Padrões'!$A$2:$V$10081,H$1,FALSE)) -> 46233 | I14: =IF($B14="-","-",VLOOKUP(ROUND(CONCATENATE($A14,I$2),0),'Cadastro - Padrões'!$A$2:$V$10081,I$1,FALSE)) -> °C | J14: =IF($B14="-","-",VLOOKUP(ROUND(CONCATENATE($A14,J$2),0),'Cadastro - Padrões'!$A$2:$V$10081,J$1,FALSE)) -> IN | ... AB14: =IF($B14="-","-",VLOOKUP(ROUND(CONCATENATE($A14,AB$2),0),'Cadastro - Padrões'!$A$2:$V$10081,AB$1,FALSE)) -> -0.62153736 | AC14: =IF($B14="-","-",IF(VLOOKUP(ROUND(CONCATENATE($A14,AC$2),0),'Cadastro - Padrões'!$A$2:$V$10081,AC$1,FALSE)="","-",VLOOKUP(ROUND(CONCATENATE($A14,AC$2),0),'Cadastro - Padrões'!$A$2:$V$10081,AC$1,FALSE))) -> 15 | AD14: =IF($B14="-","-",IF(VLOOKUP(ROUND(CONCATENATE($A14,AD$2),0),'Cadastro - Padrões'!$A$2:$V$10081,AD$1,FALSE)="","-",VLOOKUP(ROUND(CONCATENATE($A14,AD$2),0),'Cadastro - Padrões'!$A$2:$V$10081,AD$1,FALSE))) -> 0.2 | AE14: =IF($B14="-","-",IF(VLOOKUP(ROUND(CONCATENATE($A14,AE$2),0),'Cadastro - Padrões'!$A$2:$V$10081,AE$1,FALSE)="","-",VLOOKUP(ROUND(CONCATENATE($A14,AE$2),0),'Cadastro - Padrões'!$A$2:$V$10081,AE$1,FALSE))) -> 2 | AF14: =IF($B14="-","-",IF(VLOOKUP(ROUND(CONCATENATE($A14,AF$2),0),'Cadastro - Padrões'!$A$2:$V$10081,AF$1,FALSE)="","-",VLOOKUP(ROUND(CONCATENATE($A14,AF$2),0),'Cadastro - Padrões'!$A$2:$V$10081,AF$1,FALSE))) -> 1000000 | AG14: =IF($B14="-","-",IF(VLOOKUP(ROUND(CONCATENATE($A14,AG$2),0),'Cadastro - Padrões'!$A$2:$V$10081,AG$1,FALSE)="","-",VLOOKUP(ROUND(CONCATENATE($A14,AG$2),0),'Cadastro - Padrões'!$A$2:$V$10081,AG$1,FALSE))) -> 20 | AH14: =IF($B14="-","-",IF(VLOOKUP(ROUND(CONCATENATE($A14,AH$2),0),'Cadastro - Padrões'!$A$2:$V$10081,AH$1,FALSE)="","-",VLOOKUP(ROUND(CONCATENATE($A14,AH$2),0),'Cadastro - Padrões'!$A$2:$V$10081,AH$1,FALSE))) -> 0.2 | AI14: =IF($B14="-","-",IF(VLOOKUP(ROUND(CONCATENATE($A14,AI$2),0),'Cadastro - Padrões'!$A$2:$V$10081,AI$1,FALSE)="","-",VLOOKUP(ROUND(CONCATENATE($A14,AI$2),0),'Cadastro - Padrões'!$A$2:$V$10081,AI$1,FALSE))) -> 2 | AJ14: =IF($B14="-","-",IF(VLOOKUP(ROUND(CONCATENATE($A14,AJ$2),0),'Cadastro - Padrões'!$A$2:$V$10081,AJ$1,FALSE)="","-",VLOOKUP(ROUND(CONCATENATE($A14,AJ$2),0),'Cadastro - Padrões'!$A$2:$V$10081,AJ$1,FALSE))) -> 1000000 | ... BP14: =IF($B14="-","-",IF(VLOOKUP(ROUND(CONCATENATE($A14,BP$2),0),'Cadastro - Padrões'!$A$2:$V$10081,BP$1,FALSE)="","-",VLOOKUP(ROUND(CONCATENATE($A14,BP$2),0),'Cadastro - Padrões'!$A$2:$V$10081,BP$1,FALSE))) -> -
A15: =A14+1 -> 10 | B15: =IF(VLOOKUP(ROUND(CONCATENATE($A15,B$2),0),'Cadastro - Padrões'!$A$2:$V$10081,B$1,FALSE)="","-",VLOOKUP(ROUND(CONCATENATE($A15,B$2),0),'Cadastro - Padrões'!$A$2:$V$10081,B$1,FALSE)) -> E.TH.FS-041 | C15: =IF($B15="-","-",VLOOKUP(ROUND(CONCATENATE($A15,C$2),0),'Cadastro - Padrões'!$A$2:$V$10081,C$1,FALSE)) -> Termohigrômetro Digital | D15: =IF($B15="-","-",VLOOKUP(ROUND(CONCATENATE($A15,D$2),0),'Cadastro - Padrões'!$A$2:$V$10081,D$1,FALSE)) -> Elus | E15: =IF($B15="-","-",VLOOKUP(ROUND(CONCATENATE($A15,E$2),0),'Cadastro - Padrões'!$A$2:$V$10081,E$1,FALSE)) -> RBC - CAL 0439 | F15: =IF($B15="-","-",VLOOKUP(ROUND(CONCATENATE($A15,F$2),0),'Cadastro - Padrões'!$A$2:$V$10081,F$1,FALSE)) -> R0030/25 | G15: =IF($B15="-","-",VLOOKUP(ROUND(CONCATENATE($A15,G$2),0),'Cadastro - Padrões'!$A$2:$V$10081,G$1,FALSE)) -> 45692 | H15: =IF($B15="-","-",VLOOKUP(ROUND(CONCATENATE($A15,H$2),0),'Cadastro - Padrões'!$A$2:$V$10081,H$1,FALSE)) -> 46081 | I15: =IF($B15="-","-",VLOOKUP(ROUND(CONCATENATE($A15,I$2),0),'Cadastro - Padrões'!$A$2:$V$10081,I$1,FALSE)) -> °C | J15: =IF($B15="-","-",VLOOKUP(ROUND(CONCATENATE($A15,J$2),0),'Cadastro - Padrões'!$A$2:$V$10081,J$1,FALSE)) -> IN | ... AB15: =IF($B15="-","-",VLOOKUP(ROUND(CONCATENATE($A15,AB$2),0),'Cadastro - Padrões'!$A$2:$V$10081,AB$1,FALSE)) -> -0.50404993 | AC15: =IF($B15="-","-",IF(VLOOKUP(ROUND(CONCATENATE($A15,AC$2),0),'Cadastro - Padrões'!$A$2:$V$10081,AC$1,FALSE)="","-",VLOOKUP(ROUND(CONCATENATE($A15,AC$2),0),'Cadastro - Padrões'!$A$2:$V$10081,AC$1,FALSE))) -> 15 | AD15: =IF($B15="-","-",IF(VLOOKUP(ROUND(CONCATENATE($A15,AD$2),0),'Cadastro - Padrões'!$A$2:$V$10081,AD$1,FALSE)="","-",VLOOKUP(ROUND(CONCATENATE($A15,AD$2),0),'Cadastro - Padrões'!$A$2:$V$10081,AD$1,FALSE))) -> 0.2 | AE15: =IF($B15="-","-",IF(VLOOKUP(ROUND(CONCATENATE($A15,AE$2),0),'Cadastro - Padrões'!$A$2:$V$10081,AE$1,FALSE)="","-",VLOOKUP(ROUND(CONCATENATE($A15,AE$2),0),'Cadastro - Padrões'!$A$2:$V$10081,AE$1,FALSE))) -> 2 | AF15: =IF($B15="-","-",IF(VLOOKUP(ROUND(CONCATENATE($A15,AF$2),0),'Cadastro - Padrões'!$A$2:$V$10081,AF$1,FALSE)="","-",VLOOKUP(ROUND(CONCATENATE($A15,AF$2),0),'Cadastro - Padrões'!$A$2:$V$10081,AF$1,FALSE))) -> 1000000 | AG15: =IF($B15="-","-",IF(VLOOKUP(ROUND(CONCATENATE($A15,AG$2),0),'Cadastro - Padrões'!$A$2:$V$10081,AG$1,FALSE)="","-",VLOOKUP(ROUND(CONCATENATE($A15,AG$2),0),'Cadastro - Padrões'!$A$2:$V$10081,AG$1,FALSE))) -> 25 | AH15: =IF($B15="-","-",IF(VLOOKUP(ROUND(CONCATENATE($A15,AH$2),0),'Cadastro - Padrões'!$A$2:$V$10081,AH$1,FALSE)="","-",VLOOKUP(ROUND(CONCATENATE($A15,AH$2),0),'Cadastro - Padrões'!$A$2:$V$10081,AH$1,FALSE))) -> 0.2 | AI15: =IF($B15="-","-",IF(VLOOKUP(ROUND(CONCATENATE($A15,AI$2),0),'Cadastro - Padrões'!$A$2:$V$10081,AI$1,FALSE)="","-",VLOOKUP(ROUND(CONCATENATE($A15,AI$2),0),'Cadastro - Padrões'!$A$2:$V$10081,AI$1,FALSE))) -> 2 | AJ15: =IF($B15="-","-",IF(VLOOKUP(ROUND(CONCATENATE($A15,AJ$2),0),'Cadastro - Padrões'!$A$2:$V$10081,AJ$1,FALSE)="","-",VLOOKUP(ROUND(CONCATENATE($A15,AJ$2),0),'Cadastro - Padrões'!$A$2:$V$10081,AJ$1,FALSE))) -> 1000000 | ... BP15: =IF($B15="-","-",IF(VLOOKUP(ROUND(CONCATENATE($A15,BP$2),0),'Cadastro - Padrões'!$A$2:$V$10081,BP$1,FALSE)="","-",VLOOKUP(ROUND(CONCATENATE($A15,BP$2),0),'Cadastro - Padrões'!$A$2:$V$10081,BP$1,FALSE))) -> -
A16: =A15+1 -> 11 | B16: =IF(VLOOKUP(ROUND(CONCATENATE($A16,B$2),0),'Cadastro - Padrões'!$A$2:$V$10081,B$1,FALSE)="","-",VLOOKUP(ROUND(CONCATENATE($A16,B$2),0),'Cadastro - Padrões'!$A$2:$V$10081,B$1,FALSE)) -> E.TH.FS-041 | C16: =IF($B16="-","-",VLOOKUP(ROUND(CONCATENATE($A16,C$2),0),'Cadastro - Padrões'!$A$2:$V$10081,C$1,FALSE)) -> Termohigrômetro Digital | D16: =IF($B16="-","-",VLOOKUP(ROUND(CONCATENATE($A16,D$2),0),'Cadastro - Padrões'!$A$2:$V$10081,D$1,FALSE)) -> Elus | E16: =IF($B16="-","-",VLOOKUP(ROUND(CONCATENATE($A16,E$2),0),'Cadastro - Padrões'!$A$2:$V$10081,E$1,FALSE)) -> RBC - CAL 0439 | F16: =IF($B16="-","-",VLOOKUP(ROUND(CONCATENATE($A16,F$2),0),'Cadastro - Padrões'!$A$2:$V$10081,F$1,FALSE)) -> R0030/25 | G16: =IF($B16="-","-",VLOOKUP(ROUND(CONCATENATE($A16,G$2),0),'Cadastro - Padrões'!$A$2:$V$10081,G$1,FALSE)) -> 45692 | H16: =IF($B16="-","-",VLOOKUP(ROUND(CONCATENATE($A16,H$2),0),'Cadastro - Padrões'!$A$2:$V$10081,H$1,FALSE)) -> 46081 | I16: =IF($B16="-","-",VLOOKUP(ROUND(CONCATENATE($A16,I$2),0),'Cadastro - Padrões'!$A$2:$V$10081,I$1,FALSE)) -> °C | J16: =IF($B16="-","-",VLOOKUP(ROUND(CONCATENATE($A16,J$2),0),'Cadastro - Padrões'!$A$2:$V$10081,J$1,FALSE)) -> OUT | ... AB16: =IF($B16="-","-",VLOOKUP(ROUND(CONCATENATE($A16,AB$2),0),'Cadastro - Padrões'!$A$2:$V$10081,AB$1,FALSE)) -> 0.23829553 | AC16: =IF($B16="-","-",IF(VLOOKUP(ROUND(CONCATENATE($A16,AC$2),0),'Cadastro - Padrões'!$A$2:$V$10081,AC$1,FALSE)="","-",VLOOKUP(ROUND(CONCATENATE($A16,AC$2),0),'Cadastro - Padrões'!$A$2:$V$10081,AC$1,FALSE))) -> 15 | AD16: =IF($B16="-","-",IF(VLOOKUP(ROUND(CONCATENATE($A16,AD$2),0),'Cadastro - Padrões'!$A$2:$V$10081,AD$1,FALSE)="","-",VLOOKUP(ROUND(CONCATENATE($A16,AD$2),0),'Cadastro - Padrões'!$A$2:$V$10081,AD$1,FALSE))) -> 0.1 | AE16: =IF($B16="-","-",IF(VLOOKUP(ROUND(CONCATENATE($A16,AE$2),0),'Cadastro - Padrões'!$A$2:$V$10081,AE$1,FALSE)="","-",VLOOKUP(ROUND(CONCATENATE($A16,AE$2),0),'Cadastro - Padrões'!$A$2:$V$10081,AE$1,FALSE))) -> 2 | AF16: =IF($B16="-","-",IF(VLOOKUP(ROUND(CONCATENATE($A16,AF$2),0),'Cadastro - Padrões'!$A$2:$V$10081,AF$1,FALSE)="","-",VLOOKUP(ROUND(CONCATENATE($A16,AF$2),0),'Cadastro - Padrões'!$A$2:$V$10081,AF$1,FALSE))) -> 1000000 | AG16: =IF($B16="-","-",IF(VLOOKUP(ROUND(CONCATENATE($A16,AG$2),0),'Cadastro - Padrões'!$A$2:$V$10081,AG$1,FALSE)="","-",VLOOKUP(ROUND(CONCATENATE($A16,AG$2),0),'Cadastro - Padrões'!$A$2:$V$10081,AG$1,FALSE))) -> 25 | AH16: =IF($B16="-","-",IF(VLOOKUP(ROUND(CONCATENATE($A16,AH$2),0),'Cadastro - Padrões'!$A$2:$V$10081,AH$1,FALSE)="","-",VLOOKUP(ROUND(CONCATENATE($A16,AH$2),0),'Cadastro - Padrões'!$A$2:$V$10081,AH$1,FALSE))) -> 0.1 | AI16: =IF($B16="-","-",IF(VLOOKUP(ROUND(CONCATENATE($A16,AI$2),0),'Cadastro - Padrões'!$A$2:$V$10081,AI$1,FALSE)="","-",VLOOKUP(ROUND(CONCATENATE($A16,AI$2),0),'Cadastro - Padrões'!$A$2:$V$10081,AI$1,FALSE))) -> 2 | AJ16: =IF($B16="-","-",IF(VLOOKUP(ROUND(CONCATENATE($A16,AJ$2),0),'Cadastro - Padrões'!$A$2:$V$10081,AJ$1,FALSE)="","-",VLOOKUP(ROUND(CONCATENATE($A16,AJ$2),0),'Cadastro - Padrões'!$A$2:$V$10081,AJ$1,FALSE))) -> 1000000 | ... BP16: =IF($B16="-","-",IF(VLOOKUP(ROUND(CONCATENATE($A16,BP$2),0),'Cadastro - Padrões'!$A$2:$V$10081,BP$1,FALSE)="","-",VLOOKUP(ROUND(CONCATENATE($A16,BP$2),0),'Cadastro - Padrões'!$A$2:$V$10081,BP$1,FALSE))) -> -
A17: =A16+1 -> 12 | B17: =IF(VLOOKUP(ROUND(CONCATENATE($A17,B$2),0),'Cadastro - Padrões'!$A$2:$V$10081,B$1,FALSE)="","-",VLOOKUP(ROUND(CONCATENATE($A17,B$2),0),'Cadastro - Padrões'!$A$2:$V$10081,B$1,FALSE)) -> E.TH.PMR-007 | C17: =IF($B17="-","-",VLOOKUP(ROUND(CONCATENATE($A17,C$2),0),'Cadastro - Padrões'!$A$2:$V$10081,C$1,FALSE)) -> Termohigrômetro Digital | D17: =IF($B17="-","-",VLOOKUP(ROUND(CONCATENATE($A17,D$2),0),'Cadastro - Padrões'!$A$2:$V$10081,D$1,FALSE)) -> Elus | E17: =IF($B17="-","-",VLOOKUP(ROUND(CONCATENATE($A17,E$2),0),'Cadastro - Padrões'!$A$2:$V$10081,E$1,FALSE)) -> RBC - CAL 0439 | F17: =IF($B17="-","-",VLOOKUP(ROUND(CONCATENATE($A17,F$2),0),'Cadastro - Padrões'!$A$2:$V$10081,F$1,FALSE)) -> E0209/25 | G17: =IF($B17="-","-",VLOOKUP(ROUND(CONCATENATE($A17,G$2),0),'Cadastro - Padrões'!$A$2:$V$10081,G$1,FALSE)) -> 45761 | H17: =IF($B17="-","-",VLOOKUP(ROUND(CONCATENATE($A17,H$2),0),'Cadastro - Padrões'!$A$2:$V$10081,H$1,FALSE)) -> 46142 | I17: =IF($B17="-","-",VLOOKUP(ROUND(CONCATENATE($A17,I$2),0),'Cadastro - Padrões'!$A$2:$V$10081,I$1,FALSE)) -> °C | J17: =IF($B17="-","-",VLOOKUP(ROUND(CONCATENATE($A17,J$2),0),'Cadastro - Padrões'!$A$2:$V$10081,J$1,FALSE)) -> IN | ... AB17: =IF($B17="-","-",VLOOKUP(ROUND(CONCATENATE($A17,AB$2),0),'Cadastro - Padrões'!$A$2:$V$10081,AB$1,FALSE)) -> 0.1 | AC17: =IF($B17="-","-",IF(VLOOKUP(ROUND(CONCATENATE($A17,AC$2),0),'Cadastro - Padrões'!$A$2:$V$10081,AC$1,FALSE)="","-",VLOOKUP(ROUND(CONCATENATE($A17,AC$2),0),'Cadastro - Padrões'!$A$2:$V$10081,AC$1,FALSE))) -> 15 | AD17: =IF($B17="-","-",IF(VLOOKUP(ROUND(CONCATENATE($A17,AD$2),0),'Cadastro - Padrões'!$A$2:$V$10081,AD$1,FALSE)="","-",VLOOKUP(ROUND(CONCATENATE($A17,AD$2),0),'Cadastro - Padrões'!$A$2:$V$10081,AD$1,FALSE))) -> 0.1 | AE17: =IF($B17="-","-",IF(VLOOKUP(ROUND(CONCATENATE($A17,AE$2),0),'Cadastro - Padrões'!$A$2:$V$10081,AE$1,FALSE)="","-",VLOOKUP(ROUND(CONCATENATE($A17,AE$2),0),'Cadastro - Padrões'!$A$2:$V$10081,AE$1,FALSE))) -> 2 | AF17: =IF($B17="-","-",IF(VLOOKUP(ROUND(CONCATENATE($A17,AF$2),0),'Cadastro - Padrões'!$A$2:$V$10081,AF$1,FALSE)="","-",VLOOKUP(ROUND(CONCATENATE($A17,AF$2),0),'Cadastro - Padrões'!$A$2:$V$10081,AF$1,FALSE))) -> 1000000 | AG17: =IF($B17="-","-",IF(VLOOKUP(ROUND(CONCATENATE($A17,AG$2),0),'Cadastro - Padrões'!$A$2:$V$10081,AG$1,FALSE)="","-",VLOOKUP(ROUND(CONCATENATE($A17,AG$2),0),'Cadastro - Padrões'!$A$2:$V$10081,AG$1,FALSE))) -> 25 | AH17: =IF($B17="-","-",IF(VLOOKUP(ROUND(CONCATENATE($A17,AH$2),0),'Cadastro - Padrões'!$A$2:$V$10081,AH$1,FALSE)="","-",VLOOKUP(ROUND(CONCATENATE($A17,AH$2),0),'Cadastro - Padrões'!$A$2:$V$10081,AH$1,FALSE))) -> 0.1 | AI17: =IF($B17="-","-",IF(VLOOKUP(ROUND(CONCATENATE($A17,AI$2),0),'Cadastro - Padrões'!$A$2:$V$10081,AI$1,FALSE)="","-",VLOOKUP(ROUND(CONCATENATE($A17,AI$2),0),'Cadastro - Padrões'!$A$2:$V$10081,AI$1,FALSE))) -> 2 | AJ17: =IF($B17="-","-",IF(VLOOKUP(ROUND(CONCATENATE($A17,AJ$2),0),'Cadastro - Padrões'!$A$2:$V$10081,AJ$1,FALSE)="","-",VLOOKUP(ROUND(CONCATENATE($A17,AJ$2),0),'Cadastro - Padrões'!$A$2:$V$10081,AJ$1,FALSE))) -> 1000000 | ... BP17: =IF($B17="-","-",IF(VLOOKUP(ROUND(CONCATENATE($A17,BP$2),0),'Cadastro - Padrões'!$A$2:$V$10081,BP$1,FALSE)="","-",VLOOKUP(ROUND(CONCATENATE($A17,BP$2),0),'Cadastro - Padrões'!$A$2:$V$10081,BP$1,FALSE))) -> -
A18: =A17+1 -> 13 | B18: =IF(VLOOKUP(ROUND(CONCATENATE($A18,B$2),0),'Cadastro - Padrões'!$A$2:$V$10081,B$1,FALSE)="","-",VLOOKUP(ROUND(CONCATENATE($A18,B$2),0),'Cadastro - Padrões'!$A$2:$V$10081,B$1,FALSE)) -> E.TH.LT-021 | C18: =IF($B18="-","-",VLOOKUP(ROUND(CONCATENATE($A18,C$2),0),'Cadastro - Padrões'!$A$2:$V$10081,C$1,FALSE)) -> Termômetro Digital | D18: =IF($B18="-","-",VLOOKUP(ROUND(CONCATENATE($A18,D$2),0),'Cadastro - Padrões'!$A$2:$V$10081,D$1,FALSE)) -> Elus | E18: =IF($B18="-","-",VLOOKUP(ROUND(CONCATENATE($A18,E$2),0),'Cadastro - Padrões'!$A$2:$V$10081,E$1,FALSE)) -> RBC - CAL - 0439 | F18: =IF($B18="-","-",VLOOKUP(ROUND(CONCATENATE($A18,F$2),0),'Cadastro - Padrões'!$A$2:$V$10081,F$1,FALSE)) -> E0341/25 | G18: =IF($B18="-","-",VLOOKUP(ROUND(CONCATENATE($A18,G$2),0),'Cadastro - Padrões'!$A$2:$V$10081,G$1,FALSE)) -> 45807 | H18: =IF($B18="-","-",VLOOKUP(ROUND(CONCATENATE($A18,H$2),0),'Cadastro - Padrões'!$A$2:$V$10081,H$1,FALSE)) -> 46172 | I18: =IF($B18="-","-",VLOOKUP(ROUND(CONCATENATE($A18,I$2),0),'Cadastro - Padrões'!$A$2:$V$10081,I$1,FALSE)) -> °C | J18: =IF($B18="-","-",VLOOKUP(ROUND(CONCATENATE($A18,J$2),0),'Cadastro - Padrões'!$A$2:$V$10081,J$1,FALSE)) -> Contato | ... AB18: =IF($B18="-","-",VLOOKUP(ROUND(CONCATENATE($A18,AB$2),0),'Cadastro - Padrões'!$A$2:$V$10081,AB$1,FALSE)) -> -0.0087791671 | AC18: =IF($B18="-","-",IF(VLOOKUP(ROUND(CONCATENATE($A18,AC$2),0),'Cadastro - Padrões'!$A$2:$V$10081,AC$1,FALSE)="","-",VLOOKUP(ROUND(CONCATENATE($A18,AC$2),0),'Cadastro - Padrões'!$A$2:$V$10081,AC$1,FALSE))) -> -90 | AD18: =IF($B18="-","-",IF(VLOOKUP(ROUND(CONCATENATE($A18,AD$2),0),'Cadastro - Padrões'!$A$2:$V$10081,AD$1,FALSE)="","-",VLOOKUP(ROUND(CONCATENATE($A18,AD$2),0),'Cadastro - Padrões'!$A$2:$V$10081,AD$1,FALSE))) -> 0.07 | AE18: =IF($B18="-","-",IF(VLOOKUP(ROUND(CONCATENATE($A18,AE$2),0),'Cadastro - Padrões'!$A$2:$V$10081,AE$1,FALSE)="","-",VLOOKUP(ROUND(CONCATENATE($A18,AE$2),0),'Cadastro - Padrões'!$A$2:$V$10081,AE$1,FALSE))) -> 2 | AF18: =IF($B18="-","-",IF(VLOOKUP(ROUND(CONCATENATE($A18,AF$2),0),'Cadastro - Padrões'!$A$2:$V$10081,AF$1,FALSE)="","-",VLOOKUP(ROUND(CONCATENATE($A18,AF$2),0),'Cadastro - Padrões'!$A$2:$V$10081,AF$1,FALSE))) -> 1000000 | AG18: =IF($B18="-","-",IF(VLOOKUP(ROUND(CONCATENATE($A18,AG$2),0),'Cadastro - Padrões'!$A$2:$V$10081,AG$1,FALSE)="","-",VLOOKUP(ROUND(CONCATENATE($A18,AG$2),0),'Cadastro - Padrões'!$A$2:$V$10081,AG$1,FALSE))) -> -45 | AH18: =IF($B18="-","-",IF(VLOOKUP(ROUND(CONCATENATE($A18,AH$2),0),'Cadastro - Padrões'!$A$2:$V$10081,AH$1,FALSE)="","-",VLOOKUP(ROUND(CONCATENATE($A18,AH$2),0),'Cadastro - Padrões'!$A$2:$V$10081,AH$1,FALSE))) -> 0.03 | AI18: =IF($B18="-","-",IF(VLOOKUP(ROUND(CONCATENATE($A18,AI$2),0),'Cadastro - Padrões'!$A$2:$V$10081,AI$1,FALSE)="","-",VLOOKUP(ROUND(CONCATENATE($A18,AI$2),0),'Cadastro - Padrões'!$A$2:$V$10081,AI$1,FALSE))) -> 2 | AJ18: =IF($B18="-","-",IF(VLOOKUP(ROUND(CONCATENATE($A18,AJ$2),0),'Cadastro - Padrões'!$A$2:$V$10081,AJ$1,FALSE)="","-",VLOOKUP(ROUND(CONCATENATE($A18,AJ$2),0),'Cadastro - Padrões'!$A$2:$V$10081,AJ$1,FALSE))) -> 1000000 | ... BP18: =IF($B18="-","-",IF(VLOOKUP(ROUND(CONCATENATE($A18,BP$2),0),'Cadastro - Padrões'!$A$2:$V$10081,BP$1,FALSE)="","-",VLOOKUP(ROUND(CONCATENATE($A18,BP$2),0),'Cadastro - Padrões'!$A$2:$V$10081,BP$1,FALSE))) -> -
... A215: =A214+1 -> 210 | B215: =IF(VLOOKUP(ROUND(CONCATENATE($A215,B$2),0),'Cadastro - Padrões'!$A$2:$V$10081,B$1,FALSE)="","-",VLOOKUP(ROUND(CONCATENATE($A215,B$2),0),'Cadastro - Padrões'!$A$2:$V$10081,B$1,FALSE)) -> - | C215: =IF($B215="-","-",VLOOKUP(ROUND(CONCATENATE($A215,C$2),0),'Cadastro - Padrões'!$A$2:$V$10081,C$1,FALSE)) -> - | D215: =IF($B215="-","-",VLOOKUP(ROUND(CONCATENATE($A215,D$2),0),'Cadastro - Padrões'!$A$2:$V$10081,D$1,FALSE)) -> - | E215: =IF($B215="-","-",VLOOKUP(ROUND(CONCATENATE($A215,E$2),0),'Cadastro - Padrões'!$A$2:$V$10081,E$1,FALSE)) -> - | F215: =IF($B215="-","-",VLOOKUP(ROUND(CONCATENATE($A215,F$2),0),'Cadastro - Padrões'!$A$2:$V$10081,F$1,FALSE)) -> - | G215: =IF($B215="-","-",VLOOKUP(ROUND(CONCATENATE($A215,G$2),0),'Cadastro - Padrões'!$A$2:$V$10081,G$1,FALSE)) -> - | H215: =IF($B215="-","-",VLOOKUP(ROUND(CONCATENATE($A215,H$2),0),'Cadastro - Padrões'!$A$2:$V$10081,H$1,FALSE)) -> - | I215: =IF($B215="-","-",VLOOKUP(ROUND(CONCATENATE($A215,I$2),0),'Cadastro - Padrões'!$A$2:$V$10081,I$1,FALSE)) -> - | J215: =IF($B215="-","-",VLOOKUP(ROUND(CONCATENATE($A215,J$2),0),'Cadastro - Padrões'!$A$2:$V$10081,J$1,FALSE)) -> - | ... AB215: =IF($B215="-","-",VLOOKUP(ROUND(CONCATENATE($A215,AB$2),0),'Cadastro - Padrões'!$A$2:$V$10081,AB$1,FALSE)) -> - | AC215: =IF($B215="-","-",IF(VLOOKUP(ROUND(CONCATENATE($A215,AC$2),0),'Cadastro - Padrões'!$A$2:$V$10081,AC$1,FALSE)="","-",VLOOKUP(ROUND(CONCATENATE($A215,AC$2),0),'Cadastro - Padrões'!$A$2:$V$10081,AC$1,FALSE))) -> - | AD215: =IF($B215="-","-",IF(VLOOKUP(ROUND(CONCATENATE($A215,AD$2),0),'Cadastro - Padrões'!$A$2:$V$10081,AD$1,FALSE)="","-",VLOOKUP(ROUND(CONCATENATE($A215,AD$2),0),'Cadastro - Padrões'!$A$2:$V$10081,AD$1,FALSE))) -> - | AE215: =IF($B215="-","-",IF(VLOOKUP(ROUND(CONCATENATE($A215,AE$2),0),'Cadastro - Padrões'!$A$2:$V$10081,AE$1,FALSE)="","-",VLOOKUP(ROUND(CONCATENATE($A215,AE$2),0),'Cadastro - Padrões'!$A$2:$V$10081,AE$1,FALSE))) -> - | AF215: =IF($B215="-","-",IF(VLOOKUP(ROUND(CONCATENATE($A215,AF$2),0),'Cadastro - Padrões'!$A$2:$V$10081,AF$1,FALSE)="","-",VLOOKUP(ROUND(CONCATENATE($A215,AF$2),0),'Cadastro - Padrões'!$A$2:$V$10081,AF$1,FALSE))) -> - | AG215: =IF($B215="-","-",IF(VLOOKUP(ROUND(CONCATENATE($A215,AG$2),0),'Cadastro - Padrões'!$A$2:$V$10081,AG$1,FALSE)="","-",VLOOKUP(ROUND(CONCATENATE($A215,AG$2),0),'Cadastro - Padrões'!$A$2:$V$10081,AG$1,FALSE))) -> - | AH215: =IF($B215="-","-",IF(VLOOKUP(ROUND(CONCATENATE($A215,AH$2),0),'Cadastro - Padrões'!$A$2:$V$10081,AH$1,FALSE)="","-",VLOOKUP(ROUND(CONCATENATE($A215,AH$2),0),'Cadastro - Padrões'!$A$2:$V$10081,AH$1,FALSE))) -> - | AI215: =IF($B215="-","-",IF(VLOOKUP(ROUND(CONCATENATE($A215,AI$2),0),'Cadastro - Padrões'!$A$2:$V$10081,AI$1,FALSE)="","-",VLOOKUP(ROUND(CONCATENATE($A215,AI$2),0),'Cadastro - Padrões'!$A$2:$V$10081,AI$1,FALSE))) -> - | AJ215: =IF($B215="-","-",IF(VLOOKUP(ROUND(CONCATENATE($A215,AJ$2),0),'Cadastro - Padrões'!$A$2:$V$10081,AJ$1,FALSE)="","-",VLOOKUP(ROUND(CONCATENATE($A215,AJ$2),0),'Cadastro - Padrões'!$A$2:$V$10081,AJ$1,FALSE))) -> - | ... BP215: =IF($B215="-","-",IF(VLOOKUP(ROUND(CONCATENATE($A215,BP$2),0),'Cadastro - Padrões'!$A$2:$V$10081,BP$1,FALSE)="","-",VLOOKUP(ROUND(CONCATENATE($A215,BP$2),0),'Cadastro - Padrões'!$A$2:$V$10081,BP$1,FALSE))) -> -
A216: 1 | B216: =A216+1 -> 2 | C216: =B216+1 -> 3 | D216: =C216+1 -> 4 | E216: =D216+1 -> 5 | F216: =E216+1 -> 6 | G216: =F216+1 -> 7 | H216: =G216+1 -> 8 | I216: =H216+1 -> 9 | ... BP216: =BO216+1 -> 68

Sheet Cadastro - Padrões
A1: 1 | B1: 2 | C1: =B1+1 -> 3 | D1: =C1+1 -> 4 | E1: =D1+1 -> 5 | F1: =E1+1 -> 6 | G1: =F1+1 -> 7 | H1: =G1+1 -> 8 | I1: =H1+1 -> 9 | J1: =I1+1 -> 10 | ... V1: =U1+1 -> 22
A2: =ROUND(CONCATENATE(U2,V2),0) -> 1201 | B2: Padrão : | D2: Termômetro Digital | U2: 1 | V2: 201
A3: =ROUND(CONCATENATE(U3,V3),0) -> 1202 | B3: Tipo de medição : | D3: Contato | E3: Tipo do sensor : | G3: Termoresisitivo | U3: =U2 -> 1 | V3: =V2+1 -> 202
A4: =ROUND(CONCATENATE(U4,V4),0) -> 1203 | B4: Identificação : | D4: E.TH.LT-010 | U4: =U3 -> 1 | V4: =V3+1 -> 203 | X4: IN | Y4: NA
A5: =ROUND(CONCATENATE(U5,V5),0) -> 1204 | B5: Orgão Calibrador : | D5: Elus | K5: X8 | L5: X7 | M5: X6 | N5: X5 | O5: X4 | P5: X3 | Q5: X2 | R5: X1 | S5: X0 | U5: =U4 -> 1 | V5: =V4+1 -> 204 | X5: OUT | Y5: Termoresisitivo
A6: =ROUND(CONCATENATE(U6,V6),0) -> 1205 | B6: Rastreabilidade : | D6: RBC - CAL 0439 | J6: =COUNTA(B18:B27) -> 6 | K6: =IF(L6-1<2,0,L6-1) -> 0 | L6: =IF(M6-1<2,0,M6-1) -> 0 | M6: =IF(N6-1<2,0,N6-1) -> 0 | N6: =IF(O6-1<2,0,O6-1) -> 0 | O6: =IF(P6-1<2,0,P6-1) -> 2 | P6: =IF(Q6-1<2,0,Q6-1) -> 3 | Q6: =IF(R6-1<2,0,R6-1) -> 4 | R6: =IF(S6-1<2,0,S6-1) -> 5 | S6: =J6 -> 6 | U6: =U5 -> 1 | V6: =V5+1 -> 205 | X6: Contato | Y6: Termopar
A7: =ROUND(CONCATENATE(U7,V7),0) -> 1206 | B7: N° do certificado : | D7: E0319/25 | J7: =CONCATENATE(J6,1) -> 61 | K7: =IF(K6=0,0,VLOOKUP(J7,J11:S41,K6,FALSE)) -> 0 | L7: =IF(L6=0,0,VLOOKUP(J7,J11:S41,L6,FALSE)) -> 0 | M7: =IF(M6=0,0,VLOOKUP(J7,J11:S41,M6,FALSE)) -> 0 | N7: =IF(N6=0,0,VLOOKUP(J7,J11:S41,N6,FALSE)) -> 0 | O7: =IF(O6=0,0,VLOOKUP(J7,J11:S41,O6,FALSE)) -> 3.38621e-11 | P7: =IF(P6=0,0,VLOOKUP(J7,J11:S41,P6,FALSE)) -> -1.3708326e-08 | Q7: =IF(Q6=0,0,VLOOKUP(J7,J11:S41,Q6,FALSE)) -> 2.3422234e-07 | R7: =IF(R6=0,0,VLOOKUP(J7,J11:S41,R6,FALSE)) -> 1.0002898 | S7: =IF(S6=0,0,VLOOKUP(J7,J11:S41,S6,FALSE)) -> -0.0032031676 | U7: =U6 -> 1 | V7: =V6+1 -> 206
A8: =ROUND(CONCATENATE(U8,V8),0) -> 1207 | B8: Data da Calibração : | D8: 45807 | J8: =CONCATENATE(J6,2) -> 62 | K8: =IF(K6=0,0,VLOOKUP(J8,J11:S41,K6,FALSE)) -> 0 | L8: =IF(L6=0,0,VLOOKUP(J8,J11:S41,L6,FALSE)) -> 0 | M8: =IF(M6=0,0,VLOOKUP(J8,J11:S41,M6,FALSE)) -> 0 | N8: =IF(N6=0,0,VLOOKUP(J8,J11:S41,N6,FALSE)) -> 0 | O8: =IF(O6=0,0,VLOOKUP(J8,J11:S41,O6,FALSE)) -> 3.2893309e-11 | P8: =IF(P6=0,0,VLOOKUP(J8,J11:S41,P6,FALSE)) -> 1.2045677e-08 | Q8: =IF(Q6=0,0,VLOOKUP(J8,J11:S41,Q6,FALSE)) -> 6.5981224e-07 | R8: =IF(R6=0,0,VLOOKUP(J8,J11:S41,R6,FALSE)) -> 0.00011983017 | S8: =IF(S6=0,0,VLOOKUP(J8,J11:S41,S6,FALSE)) -> 0.0043830516 | U8: =U7 -> 1 | V8: =V7+1 -> 207
A9: =ROUND(CONCATENATE(U9,V9),0) -> 1208 | B9: Vencimento da Calibração : | D9: 46172 | J9: =CONCATENATE(J6,3) -> 63 | N9: Veff curva = | O9: =J6-2 -> 4 | P9: Residuo = | Q9: =VLOOKUP(J9,J11:S41,3,FALSE) -> 0.0065014406 | R9: R² = | S9: =VLOOKUP(J9,J11:S41,2,FALSE) -> 1 | U9: =U8 -> 1 | V9: =V8+1 -> 208
A10: =ROUND(CONCATENATE(U10,V10),0) -> 1209 | B10: Divisão de escala : | D10: 0.001 | E10: Unidade calibrada : | H10: °C | K10: 3 | L10: 3 | U10: =U9 -> 1 | V10: =V9+1 -> 209
A11: =ROUND(CONCATENATE(U11,V11),0) -> 1210 | B11: Faixa de medição : | D11: =MIN(B18:B27) -> -90 | E11: ~ | F11: =MAX(B18:B27) -> 300 | G11: =IF(H10="","",H10) -> °C | J11: =CONCATENATE(K10,1) -> 31 | K11: {=LINEST(B18:B20,C18:C20^{1},TRUE,TRUE)} -> 1.0000889 | L11: -0.0076681333 | U11: =U10 -> 1 | V11: =V10+1 -> 210
A12: =ROUND(CONCATENATE(U12,V12),0) -> 1211 | J12: =CONCATENATE(K10,2) -> 32 | K12: 1.2836563e-05 | L12: 0.00074559442 | U12: =U11 -> 1 | V12: =V11+1 -> 211
A13: =ROUND(CONCATENATE(U13,V13),0) -> 1212 | B13: Valores da Calibração Atual | G13: Calibração Anterior | J13: =CONCATENATE(K10,3) -> 33 | K13: 1 | L13: 0.00081693203 | U13: =U12 -> 1 | V13: =V12+1 -> 212
A14: =ROUND(CONCATENATE(U14,V14),0) -> 1213 | B14: Certificado | E14: =IF(D7="","",D7) -> E0319/25 | G14: Certificado | H14: R0106/24 | K14: 4 | L14: 4 | M14: 4 | U14: =U13 -> 1 | V14: =V13+1 -> 213
A15: =ROUND(CONCATENATE(U15,V15),0) -> 1214 | B15: Valor | C15: Leitura do | D15: Incerteza | F15: Grau de liberdade | G15: Valor | H15: Leitura do | J15: =CONCATENATE(K14,1) -> 41 | K15: {=LINEST(B18:B21,C18:C21^{1,2},TRUE,TRUE)} -> 1.7451515e-06 | L15: 1.0002646 | M15: -0.0053849014 | U15: =U14 -> 1 | V15: =V14+1 -> 214
A16: =ROUND(CONCATENATE(U16,V16),0) -> 1215 | B16: Referência | C16: Instrumento | D16: de Medição | E16: k | G16: Referência | H16: Instrumento | J16: =CONCATENATE(K14,2) -> 42 | K16: 9.1099065e-07 | L16: 5.2625135e-05 | M16: 0.0030191734 | U16: =U15 -> 1 | V16: =V15+1 -> 215
A17: =ROUND(CONCATENATE(U17,V17),0) -> 1216 | B17: =IF(H10="","",H10) -> °C | C17: =IF(H10="","",H10) -> °C | D17: =IF(H10="","",H10) -> °C | G17: =IF(H10="","",H10) -> °C | H17: =IF(H10="","",H10) -> °C | J17: =CONCATENATE(K14,3) -> 43 | K17: 1 | L17: 0.0039971845 | M17: #N/A | U17: =U16 -> 1 | V17: =V16+1 -> 216
A18: =ROUND(CONCATENATE(U18,V18),0) -> 1217 | B18: -90 | C18: -89.984 | D18: 0.07 | E18: 2 | F18: 1000000 | G18: -90 | H18: -89.991 | K18: 5 | L18: 5 | M18: 5 | N18: 5 | U18: =U17 -> 1 | V18: =V17+1 -> 217
A19: =ROUND(CONCATENATE(U19,V19),0) -> 1218 | B19: -45 | C19: -44.989 | D19: 0.03 | E19: 2 | F19: 1000000 | G19: -44.999 | H19: -44.993 | J19: =CONCATENATE(K18,1) -> 51 | K19: {=LINEST(B18:B22,C18:C22^{1,2,3},TRUE,TRUE)} -> -1.2140471e-08 | L19: 7.6668164e-07 | M19: 1.0002918 | N19: -0.0038735036 | U19: =U18 -> 1 | V19: =V18+1 -> 218
A20: =ROUND(CONCATENATE(U20,V20),0) -> 1219 | B20: 0.01 | C20: 0.018 | D20: 0.03 | E20: 2 | F20: 1000000 | G20: 0.01 | H20: 0.013 | J20: =CONCATENATE(K18,2) -> 52 | K20: 8.450314e-09 | L20: 8.1268741e-07 | M20: 9.8439883e-05 | N20: 0.0039541156 | U20: =U19 -> 1 | V20: =V19+1 -> 219
A21: =ROUND(CONCATENATE(U21,V21),0) -> 1220 | B21: 49.998 | C21: 49.985 | D21: 0.03 | E21: 2 | F21: 1000000 | G21: 50 | H21: 49.997 | J21: =CONCATENATE(K18,3) -> 53 | K21: 1 | L21: 0.0057186896 | M21: #N/A | N21: #N/A | U21: =U20 -> 1 | V21: =V20+1 -> 220
A22: =ROUND(CONCATENATE(U22,V22),0) -> 1221 | B22: 150 | C22: 149.984 | D22: 0.03 | E22: 2 | F22: 1000000 | G22: 149.999 | H22: 149.996 | K22: 6 | L22: 6 | M22: 6 | N22: 6 | O22: 6 | U22: =U21 -> 1 | V22: =V21+1 -> 221
A23: =ROUND(CONCATENATE(U23,V23),0) -> 1222 | B23: 300 | C23: 299.991 | D23: 0.05 | E23: 2 | F23: 1000000 | G23: 300 | H23: 299.99 | J23: =CONCATENATE(K22,1) -> 61 | K23: {=LINEST(B18:B23,C18:C23^{1,2,3,4},TRUE,TRUE)} -> 3.38621e-11 | L23: -1.3708326e-08 | M23: 2.3422234e-07 | N23: 1.0002898 | O23: -0.0032031676 | U23: =U22 -> 1 | V23: =V22+1 -> 222
A24: =ROUND(CONCATENATE(U24,V24),0) -> 1223 | J24: =CONCATENATE(K22,2) -> 62 | K24: 3.2893309e-11 | L24: 1.2045677e-08 | M24: 6.5981224e-07 | N24: 0.00011983017 | O24: 0.0043830516 | U24: =U23 -> 1 | V24: =V23+1 -> 223
A25: =ROUND(CONCATENATE(U25,V25),0) -> 1224 | J25: =CONCATENATE(K22,3) -> 63 | K25: 1 | L25: 0.0065014406 | M25: #N/A | N25: #N/A | O25: #N/A | U25: =U24 -> 1 | V25: =V24+1 -> 224
A26: =ROUND(CONCATENATE(U26,V26),0) -> 1225 | K26: 7 | L26: 7 | M26: 7 | N26: 7 | O26: 7 | P26: 7 | U26: =U25 -> 1 | V26: =V25+1 -> 225
A27: =ROUND(CONCATENATE(U27,V27),0) -> 1226 | J27: =CONCATENATE(K26,1) -> 71 | K27: {=LINEST(B18:B24,C18:C24^{1,2,3,4,5},TRUE,TRUE)} -> #VALUE! | L27: #VALUE! | M27: #VALUE! | N27: #VALUE! | O27: #VALUE! | P27: #VALUE! | U27: =U26 -> 1 | V27: =V26+1 -> 226
A28: =ROUND(CONCATENATE(U28,V28),0) -> 1227 | B28: =COUNT(B18:B27)-2 -> 4 | J28: =CONCATENATE(K26,2) -> 72 | K28: #VALUE! | L28: #VALUE! | M28: #VALUE! | N28: #VALUE! | O28: #VALUE! | P28: #VALUE! | U28: =U27 -> 1 | V28: =V27+1 -> 227
A29: =ROUND(CONCATENATE(U29,V29),0) -> 1228 | J29: =CONCATENATE(K26,3) -> 73 | K29: #VALUE! | L29: #VALUE! | M29: #VALUE! | N29: #VALUE! | O29: #VALUE! | P29: #VALUE! | U29: =U28 -> 1 | V29: =V28+1 -> 228
A30: =ROUND(CONCATENATE(U30,V30),0) -> 1229 | B30: Observações (particularidades para utilização) | K30: 8 | L30: 8 | M30: 8 | N30: 8 | O30: 8 | P30: 8 | Q30: 8 | U30: =U29 -> 1 | V30: =V29+1 -> 229
