Workbook
Name _Z99999: [1]Cliente!#REF!
Name _ZZ99: [1]Cliente!#REF!
Name capacidade: [2]Dados!$F$11
Name CERTIFICADO: [1]Cliente!$Y$8
Name data_receb: [2]Dados!$E$7
Name DATA_RECEBIMENTO: [1]Cliente!#REF!
Name ENTRADA: [1]Cliente!#REF!
Name equip: [2]Dados!$C$10
Name n_cert: [2]Dados!$C$8
Name n_ident: [2]Dados!$C$13
Name n_serie: [2]Dados!$C$14
Name pressão: [2]Dados!$D$27
Name proced: [2]Dados!$F$13
Name resolução: [2]Dados!$F$10
Name temp_ar: [2]Dados!$D$25
Name temp_carr: #REF!
Name umid: [2]Dados!#REF!
Name unid_e: [2]Dados!$D$31
Name versão: [2]Dados!$F$14

Sheet Controle
B1: 4 | C1: 4 | D1: 4 | E1: 4 | F1: 4 | G1: 4 | H1: 4 | I1: 4 | J1: 7 | K1: 4 | L1: 6 | M1: 4 | N1: 5 | O1: 5 | P1: 5 | Q1: 17 | R1: 15 | S1: 11 | T1: 12 | U1: 13 | V1: 14 | W1: 15 | X1: 16 | Y1: 17 | Z1: 18 | AA1: 19 | AB1: 2 | AC1: 4 | AD1: 5 | AE1: 6 | AF1: 2 | AG1: 4 | AH1: 5 | AI1: 6 | AJ1: 2 | AK1: 4 | AL1: 5 | AM1: 6 | AN1: 2 | AO1: 4 | AP1: 5 | AQ1: 6 | AR1: 2 | AS1: 4 | AT1: 5 | AU1: 6 | AV1: 2 | AW1: 4 | AX1: 5 | AY1: 6 | AZ1: 2 | BA1: 4 | BB1: 5 | BC1: 6 | BD1: 2 | BE1: 4 | BF1: 5 | BG1: 6 | BH1: 2 | BI1: 4 | BJ1: 5 | BK1: 6 | BL1: 2 | BM1: 4 | BN1: 5 | BO1: 6
B2: 203 | C2: 201 | D2: 202 | E2: 204 | F2: 205 | G2: 206 | H2: 207 | I2: 208 | J2: 210 | K2: 210 | L2: 210 | M2: 209 | N2: 235 | O2: 237 | P2: 233 | Q2: 207 | R2: 207 | S2: 205 | T2: 205 | U2: 205 | V2: 205 | W2: 205 | X2: 205 | Y2: 205 | Z2: 205 | AA2: 205 | AB2: 217 | AC2: =AB2 -> 217 | AD2: =AC2 -> 217 | AE2: =AD2 -> 217 | AF2: =AE2+1 -> 218 | AG2: =AF2 -> 218 | AH2: =AG2 -> 218 | AI2: =AH2 -> 218 | AJ2: =AI2+1 -> 219 | AK2: =AJ2 -> 219 | AL2: =AK2 -> 219 | AM2: =AL2 -> 219 | AN2: =AM2+1 -> 220 | AO2: =AN2 -> 220 | AP2: =AO2 -> 220 | AQ2: =AP2 -> 220 | AR2: =AQ2+1 -> 221 | AS2: =AR2 -> 221 | AT2: =AS2 -> 221 | AU2: =AT2 -> 221 | AV2: =AU2+1 -> 222 | AW2: =AV2 -> 222 | AX2: =AW2 -> 222 | AY2: =AX2 -> 222 | AZ2: =AY2+1 -> 223 | BA2: =AZ2 -> 223 | BB2: =BA2 -> 223 | BC2: =BB2 -> 223 | BD2: =BC2+1 -> 224 | BE2: =BD2 -> 224 | BF2: =BE2 -> 224 | BG2: =BF2 -> 224 | BH2: =BG2+1 -> 225 | BI2: =BH2 -> 225 | BJ2: =BI2 -> 225 | BK2: =BJ2 -> 225 | BL2: =BK2+1 -> 226 | BM2: =BL2 -> 226 | BN2: =BM2 -> 226 | BO2: =BN2 -> 226
I3: =TODAY() -> 46076 | AB3: 1 | AC3: =AB3 -> 1 | AD3: =AC3 -> 1 | AE3: =AD3 -> 1 | AF3: =AE3+1 -> 2 | AG3: =AF3 -> 2 | AH3: =AG3 -> 2 | AI3: =AH3 -> 2 | AJ3: =AI3+1 -> 3 | AK3: =AJ3 -> 3 | AL3: =AK3 -> 3 | AM3: =AL3 -> 3 | AN3: =AM3+1 -> 4 | AO3: =AN3 -> 4 | AP3: =AO3 -> 4 | AQ3: =AP3 -> 4 | AR3: =AQ3+1 -> 5 | AS3: =AR3 -> 5 | AT3: =AS3 -> 5 | AU3: =AT3 -> 5 | AV3: =AU3+1 -> 6 | AW3: =AV3 -> 6 | AX3: =AW3 -> 6 | AY3: =AX3 -> 6 | AZ3: =AY3+1 -> 7 | BA3: =AZ3 -> 7 | BB3: =BA3 -> 7 | BC3: =BB3 -> 7 | BD3: =BC3+1 -> 8 | BE3: =BD3 -> 8 | BF3: =BE3 -> 8 | BG3: =BF3 -> 8 | BH3: =BG3+1 -> 9 | BI3: =BH3 -> 9 | BJ3: =BI3 -> 9 | BK3: =BJ3 -> 9 | BL3: =BK3+1 -> 10 | BM3: =BL3 -> 10 | BN3: =BM3 -> 10 | BO3: =BN3 -> 10
Q4: Polinômio da Curva | AB4: =CONCATENATE(AB3,"º Ponto") -> 1º Ponto | AF4: =CONCATENATE(AF3,"º Ponto") -> 2º Ponto | AJ4: =CONCATENATE(AJ3,"º Ponto") -> 3º Ponto | AN4: =CONCATENATE(AN3,"º Ponto") -> 4º Ponto | AR4: =CONCATENATE(AR3,"º Ponto") -> 5º Ponto | AV4: =CONCATENATE(AV3,"º Ponto") -> 6º Ponto | AZ4: =CONCATENATE(AZ3,"º Ponto") -> 7º Ponto | BD4: =CONCATENATE(BD3,"º Ponto") -> 8º Ponto | BH4: =CONCATENATE(BH3,"º Ponto") -> 9º Ponto | BL4: =CONCATENATE(BL3,"º Ponto") -> 10º Ponto
B5: TAG | C5: Padrão | D5: Temperatura da umidade | E5: Calibrado por | F5: Rastreabilidade | G5: n° do certificado | H5: Data da Calibração | I5: Vencimento | J5: Unidade calibrada | K5: Faixa mínima | L5: Faixa máxima | M5: Resolução | N5: Maior desvio | O5: Maior Incerteza | P5: Deriva | Q5: Residuo | R5: Veff | S5: X8 | T5: X7 | U5: X6 | V5: X5 | W5: X4 | X5: X3 | Y5: X2 | Z5: X1 | AA5: X0 | AB5: =CONCATENATE(AB3,"-VR") -> 1-VR | AC5: =CONCATENATE(AC3,"-U") -> 1-U | AD5: =CONCATENATE(AD3,"-K") -> 1-K | AE5: =CONCATENATE(AE3,"-GL") -> 1-GL | AF5: =CONCATENATE(AF3,"-VR") -> 2-VR | AG5: =CONCATENATE(AG3,"-U") -> 2-U | AH5: =CONCATENATE(AH3,"-K") -> 2-K | AI5: =CONCATENATE(AI3,"-GL") -> 2-GL | AJ5: =CONCATENATE(AJ3,"-VR") -> 3-VR | AK5: =CONCATENATE(AK3,"-U") -> 3-U | AL5: =CONCATENATE(AL3,"-K") -> 3-K | AM5: =CONCATENATE(AM3,"-GL") -> 3-GL | AN5: =CONCATENATE(AN3,"-VR") -> 4-VR | AO5: =CONCATENATE(AO3,"-U") -> 4-U | AP5: =CONCATENATE(AP3,"-K") -> 4-K | AQ5: =CONCATENATE(AQ3,"-GL") -> 4-GL | AR5: =CONCATENATE(AR3,"-VR") -> 5-VR | AS5: =CONCATENATE(AS3,"-U") -> 5-U | AT5: =CONCATENATE(AT3,"-K") -> 5-K | AU5: =CONCATENATE(AU3,"-GL") -> 5-GL | AV5: =CONCATENATE(AV3,"-VR") -> 6-VR | AW5: =CONCATENATE(AW3,"-U") -> 6-U | AX5: =CONCATENATE(AX3,"-K") -> 6-K | AY5: =CONCATENATE(AY3,"-GL") -> 6-GL | AZ5: =CONCATENATE(AZ3,"-VR") -> 7-VR | BA5: =CONCATENATE(BA3,"-U") -> 7-U | BB5: =CONCATENATE(BB3,"-K") -> 7-K | BC5: =CONCATENATE(BC3,"-GL") -> 7-GL | BD5: =CONCATENATE(BD3,"-VR") -> 8-VR | BE5: =CONCATENATE(BE3,"-U") -> 8-U | BF5: =CONCATENATE(BF3,"-K") -> 8-K | BG5: =CONCATENATE(BG3,"-GL") -> 8-GL | BH5: =CONCATENATE(BH3,"-VR") -> 9-VR | BI5: =CONCATENATE(BI3,"-U") -> 9-U | BJ5: =CONCATENATE(BJ3,"-K") -> 9-K | BK5: =CONCATENATE(BK3,"-GL") -> 9-GL | BL5: =CONCATENATE(BL3,"-VR") -> 10-VR | BM5: =CONCATENATE(BM3,"-U") -> 10-U | BN5: =CONCATENATE(BN3,"-K") -> 10-K | BO5: =CONCATENATE(BO3,"-GL") -> 10-GL
A6: 1 | B6: =IF(VLOOKUP(ROUND(CONCATENATE($A6,B$2),0),'Cadastro dos Padrões'!$A$2:$V$4400,B$1,FALSE)="","-",VLOOKUP(ROUND(CONCATENATE($A6,B$2),0),'Cadastro dos Padrões'!$A$2:$V$4400,B$1,FALSE)) -> X.TH.LV-001 | C6: =IF($B6="-","-",VLOOKUP(ROUND(CONCATENATE($A6,C$2),0),'Cadastro dos Padrões'!$A$2:$V$4400,C$1,FALSE)) -> Termohigrômetro Digital | D6: =IF($B6="-","-",VLOOKUP(ROUND(CONCATENATE($A6,D$2),0),'Cadastro dos Padrões'!$A$2:$V$4400,D$1,FALSE)) -> 20 | E6: =IF($B6="-","-",VLOOKUP(ROUND(CONCATENATE($A6,E$2),0),'Cadastro dos Padrões'!$A$2:$V$4400,E$1,FALSE)) -> Elus | F6: =IF($B6="-","-",VLOOKUP(ROUND(CONCATENATE($A6,F$2),0),'Cadastro dos Padrões'!$A$2:$V$4400,F$1,FALSE)) -> RBC - CAL 0439 | G6: =IF($B6="-","-",VLOOKUP(ROUND(CONCATENATE($A6,G$2),0),'Cadastro dos Padrões'!$A$2:$V$4400,G$1,FALSE)) -> E0643A/25 | H6: =IF($B6="-","-",VLOOKUP(ROUND(CONCATENATE($A6,H$2),0),'Cadastro dos Padrões'!$A$2:$V$4400,H$1,FALSE)) -> 45910 | I6: =IF($B6="-","-",VLOOKUP(ROUND(CONCATENATE($A6,I$2),0),'Cadastro dos Padrões'!$A$2:$V$4400,I$1,FALSE)) -> 46295 | J6: =IF($B6="-","-",VLOOKUP(ROUND(CONCATENATE($A6,J$2),0),'Cadastro dos Padrões'!$A$2:$V$4400,J$1,FALSE)) -> %ur | ... AA6: =IF($B6="-","-",VLOOKUP(ROUND(CONCATENATE($A6,AA$2),0),'Cadastro dos Padrões'!$A$2:$V$4400,AA$1,FALSE)) -> -0.14499577 | AB6: =IF(VLOOKUP(ROUND(CONCATENATE($A6,AB$2),0),'Cadastro dos Padrões'!$A$2:$V$4400,AB$1,FALSE)="","-",VLOOKUP(ROUND(CONCATENATE($A6,AB$2),0),'Cadastro dos Padrões'!$A$2:$V$4400,AB$1,FALSE)) -> 10 | AC6: =IF(VLOOKUP(ROUND(CONCATENATE($A6,AC$2),0),'Cadastro dos Padrões'!$A$2:$V$4400,AC$1,FALSE)="","-",VLOOKUP(ROUND(CONCATENATE($A6,AC$2),0),'Cadastro dos Padrões'!$A$2:$V$4400,AC$1,FALSE)) -> 0.81 | AD6: =IF(VLOOKUP(ROUND(CONCATENATE($A6,AD$2),0),'Cadastro dos Padrões'!$A$2:$V$4400,AD$1,FALSE)="","-",VLOOKUP(ROUND(CONCATENATE($A6,AD$2),0),'Cadastro dos Padrões'!$A$2:$V$4400,AD$1,FALSE)) -> 2 | AE6: =IF(VLOOKUP(ROUND(CONCATENATE($A6,AE$2),0),'Cadastro dos Padrões'!$A$2:$V$4400,AE$1,FALSE)="","-",VLOOKUP(ROUND(CONCATENATE($A6,AE$2),0),'Cadastro dos Padrões'!$A$2:$V$4400,AE$1,FALSE)) -> 1000000 | AF6: =IF(VLOOKUP(ROUND(CONCATENATE($A6,AF$2),0),'Cadastro dos Padrões'!$A$2:$V$4400,AF$1,FALSE)="","-",VLOOKUP(ROUND(CONCATENATE($A6,AF$2),0),'Cadastro dos Padrões'!$A$2:$V$4400,AF$1,FALSE)) -> 30 | AG6: =IF(VLOOKUP(ROUND(CONCATENATE($A6,AG$2),0),'Cadastro dos Padrões'!$A$2:$V$4400,AG$1,FALSE)="","-",VLOOKUP(ROUND(CONCATENATE($A6,AG$2),0),'Cadastro dos Padrões'!$A$2:$V$4400,AG$1,FALSE)) -> 0.94 | AH6: =IF(VLOOKUP(ROUND(CONCATENATE($A6,AH$2),0),'Cadastro dos Padrões'!$A$2:$V$4400,AH$1,FALSE)="","-",VLOOKUP(ROUND(CONCATENATE($A6,AH$2),0),'Cadastro dos Padrões'!$A$2:$V$4400,AH$1,FALSE)) -> 2 | AI6: =IF(VLOOKUP(ROUND(CONCATENATE($A6,AI$2),0),'Cadastro dos Padrões'!$A$2:$V$4400,AI$1,FALSE)="","-",VLOOKUP(ROUND(CONCATENATE($A6,AI$2),0),'Cadastro dos Padrões'!$A$2:$V$4400,AI$1,FALSE)) -> 1000000 | ... BO6: =IF(VLOOKUP(ROUND(CONCATENATE($A6,BO$2),0),'Cadastro dos Padrões'!$A$2:$V$4400,BO$1,FALSE)="","-",VLOOKUP(ROUND(CONCATENATE($A6,BO$2),0),'Cadastro dos Padrões'!$A$2:$V$4400,BO$1,FALSE)) -> -
A7: =A6+1 -> 2 | B7: =IF(VLOOKUP(ROUND(CONCATENATE($A7,B$2),0),'Cadastro dos Padrões'!$A$2:$V$4400,B$1,FALSE)="","-",VLOOKUP(ROUND(CONCATENATE($A7,B$2),0),'Cadastro dos Padrões'!$A$2:$V$4400,B$1,FALSE)) -> EL-797 | C7: =IF($B7="-","-",VLOOKUP(ROUND(CONCATENATE($A7,C$2),0),'Cadastro dos Padrões'!$A$2:$V$4400,C$1,FALSE)) -> Termohigrômetro Digital | D7: =IF($B7="-","-",VLOOKUP(ROUND(CONCATENATE($A7,D$2),0),'Cadastro dos Padrões'!$A$2:$V$4400,D$1,FALSE)) -> 20 | E7: =IF($B7="-","-",VLOOKUP(ROUND(CONCATENATE($A7,E$2),0),'Cadastro dos Padrões'!$A$2:$V$4400,E$1,FALSE)) -> Elus | F7: =IF($B7="-","-",VLOOKUP(ROUND(CONCATENATE($A7,F$2),0),'Cadastro dos Padrões'!$A$2:$V$4400,F$1,FALSE)) -> RBC - CAL 0439 | G7: =IF($B7="-","-",VLOOKUP(ROUND(CONCATENATE($A7,G$2),0),'Cadastro dos Padrões'!$A$2:$V$4400,G$1,FALSE)) -> R51822/23 | H7: =IF($B7="-","-",VLOOKUP(ROUND(CONCATENATE($A7,H$2),0),'Cadastro dos Padrões'!$A$2:$V$4400,H$1,FALSE)) -> 45064 | I7: =IF($B7="-","-",VLOOKUP(ROUND(CONCATENATE($A7,I$2),0),'Cadastro dos Padrões'!$A$2:$V$4400,I$1,FALSE)) -> 45443 | J7: =IF($B7="-","-",VLOOKUP(ROUND(CONCATENATE($A7,J$2),0),'Cadastro dos Padrões'!$A$2:$V$4400,J$1,FALSE)) -> %ur | ... AA7: =IF($B7="-","-",VLOOKUP(ROUND(CONCATENATE($A7,AA$2),0),'Cadastro dos Padrões'!$A$2:$V$4400,AA$1,FALSE)) -> -11.136526 | AB7: =IF(VLOOKUP(ROUND(CONCATENATE($A7,AB$2),0),'Cadastro dos Padrões'!$A$2:$V$4400,AB$1,FALSE)="","-",VLOOKUP(ROUND(CONCATENATE($A7,AB$2),0),'Cadastro dos Padrões'!$A$2:$V$4400,AB$1,FALSE)) -> 30 | AC7: =IF(VLOOKUP(ROUND(CONCATENATE($A7,AC$2),0),'Cadastro dos Padrões'!$A$2:$V$4400,AC$1,FALSE)="","-",VLOOKUP(ROUND(CONCATENATE($A7,AC$2),0),'Cadastro dos Padrões'!$A$2:$V$4400,AC$1,FALSE)) -> 1 | AD7: =IF(VLOOKUP(ROUND(CONCATENATE($A7,AD$2),0),'Cadastro dos Padrões'!$A$2:$V$4400,AD$1,FALSE)="","-",VLOOKUP(ROUND(CONCATENATE($A7,AD$2),0),'Cadastro dos Padrões'!$A$2:$V$4400,AD$1,FALSE)) -> 2.01 | AE7: =IF(VLOOKUP(ROUND(CONCATENATE($A7,AE$2),0),'Cadastro dos Padrões'!$A$2:$V$4400,AE$1,FALSE)="","-",VLOOKUP(ROUND(CONCATENATE($A7,AE$2),0),'Cadastro dos Padrões'!$A$2:$V$4400,AE$1,FALSE)) -> 362 | AF7: =IF(VLOOKUP(ROUND(CONCATENATE($A7,AF$2),0),'Cadastro dos Padrões'!$A$2:$V$4400,AF$1,FALSE)="","-",VLOOKUP(ROUND(CONCATENATE($A7,AF$2),0),'Cadastro dos Padrões'!$A$2:$V$4400,AF$1,FALSE)) -> 50 | AG7: =IF(VLOOKUP(ROUND(CONCATENATE($A7,AG$2),0),'Cadastro dos Padrões'!$A$2:$V$4400,AG$1,FALSE)="","-",VLOOKUP(ROUND(CONCATENATE($A7,AG$2),0),'Cadastro dos Padrões'!$A$2:$V$4400,AG$1,FALSE)) -> 1 | AH7: =IF(VLOOKUP(ROUND(CONCATENATE($A7,AH$2),0),'Cadastro dos Padrões'!$A$2:$V$4400,AH$1,FALSE)="","-",VLOOKUP(ROUND(CONCATENATE($A7,AH$2),0),'Cadastro dos Padrões'!$A$2:$V$4400,AH$1,FALSE)) -> 2 | AI7: =IF(VLOOKUP(ROUND(CONCATENATE($A7,AI$2),0),'Cadastro dos Padrões'!$A$2:$V$4400,AI$1,FALSE)="","-",VLOOKUP(ROUND(CONCATENATE($A7,AI$2),0),'Cadastro dos Padrões'!$A$2:$V$4400,AI$1,FALSE)) -> 1000000 | ... BO7: =IF(VLOOKUP(ROUND(CONCATENATE($A7,BO$2),0),'Cadastro dos Padrões'!$A$2:$V$4400,BO$1,FALSE)="","-",VLOOKUP(ROUND(CONCATENATE($A7,BO$2),0),'Cadastro dos Padrões'!$A$2:$V$4400,BO$1,FALSE)) -> -
A8: =A7+1 -> 3 | B8: =IF(VLOOKUP(ROUND(CONCATENATE($A8,B$2),0),'Cadastro dos Padrões'!$A$2:$V$4400,B$1,FALSE)="","-",VLOOKUP(ROUND(CONCATENATE($A8,B$2),0),'Cadastro dos Padrões'!$A$2:$V$4400,B$1,FALSE)) -> EL-800 | C8: =IF($B8="-","-",VLOOKUP(ROUND(CONCATENATE($A8,C$2),0),'Cadastro dos Padrões'!$A$2:$V$4400,C$1,FALSE)) -> Termohigrômetro Digital | D8: =IF($B8="-","-",VLOOKUP(ROUND(CONCATENATE($A8,D$2),0),'Cadastro dos Padrões'!$A$2:$V$4400,D$1,FALSE)) -> 20 | E8: =IF($B8="-","-",VLOOKUP(ROUND(CONCATENATE($A8,E$2),0),'Cadastro dos Padrões'!$A$2:$V$4400,E$1,FALSE)) -> Elus | F8: =IF($B8="-","-",VLOOKUP(ROUND(CONCATENATE($A8,F$2),0),'Cadastro dos Padrões'!$A$2:$V$4400,F$1,FALSE)) -> RBC - CAL 0439 | G8: =IF($B8="-","-",VLOOKUP(ROUND(CONCATENATE($A8,G$2),0),'Cadastro dos Padrões'!$A$2:$V$4400,G$1,FALSE)) -> R0038/14 | H8: =IF($B8="-","-",VLOOKUP(ROUND(CONCATENATE($A8,H$2),0),'Cadastro dos Padrões'!$A$2:$V$4400,H$1,FALSE)) -> 45412 | I8: =IF($B8="-","-",VLOOKUP(ROUND(CONCATENATE($A8,I$2),0),'Cadastro dos Padrões'!$A$2:$V$4400,I$1,FALSE)) -> 45777 | J8: =IF($B8="-","-",VLOOKUP(ROUND(CONCATENATE($A8,J$2),0),'Cadastro dos Padrões'!$A$2:$V$4400,J$1,FALSE)) -> %ur | ... AA8: =IF($B8="-","-",VLOOKUP(ROUND(CONCATENATE($A8,AA$2),0),'Cadastro dos Padrões'!$A$2:$V$4400,AA$1,FALSE)) -> -4.7591743 | AB8: =IF(VLOOKUP(ROUND(CONCATENATE($A8,AB$2),0),'Cadastro dos Padrões'!$A$2:$V$4400,AB$1,FALSE)="","-",VLOOKUP(ROUND(CONCATENATE($A8,AB$2),0),'Cadastro dos Padrões'!$A$2:$V$4400,AB$1,FALSE)) -> 30 | AC8: =IF(VLOOKUP(ROUND(CONCATENATE($A8,AC$2),0),'Cadastro dos Padrões'!$A$2:$V$4400,AC$1,FALSE)="","-",VLOOKUP(ROUND(CONCATENATE($A8,AC$2),0),'Cadastro dos Padrões'!$A$2:$V$4400,AC$1,FALSE)) -> 2 | AD8: =IF(VLOOKUP(ROUND(CONCATENATE($A8,AD$2),0),'Cadastro dos Padrões'!$A$2:$V$4400,AD$1,FALSE)="","-",VLOOKUP(ROUND(CONCATENATE($A8,AD$2),0),'Cadastro dos Padrões'!$A$2:$V$4400,AD$1,FALSE)) -> 2 | AE8: =IF(VLOOKUP(ROUND(CONCATENATE($A8,AE$2),0),'Cadastro dos Padrões'!$A$2:$V$4400,AE$1,FALSE)="","-",VLOOKUP(ROUND(CONCATENATE($A8,AE$2),0),'Cadastro dos Padrões'!$A$2:$V$4400,AE$1,FALSE)) -> 1000000 | AF8: =IF(VLOOKUP(ROUND(CONCATENATE($A8,AF$2),0),'Cadastro dos Padrões'!$A$2:$V$4400,AF$1,FALSE)="","-",VLOOKUP(ROUND(CONCATENATE($A8,AF$2),0),'Cadastro dos Padrões'!$A$2:$V$4400,AF$1,FALSE)) -> 50 | AG8: =IF(VLOOKUP(ROUND(CONCATENATE($A8,AG$2),0),'Cadastro dos Padrões'!$A$2:$V$4400,AG$1,FALSE)="","-",VLOOKUP(ROUND(CONCATENATE($A8,AG$2),0),'Cadastro dos Padrões'!$A$2:$V$4400,AG$1,FALSE)) -> 2 | AH8: =IF(VLOOKUP(ROUND(CONCATENATE($A8,AH$2),0),'Cadastro dos Padrões'!$A$2:$V$4400,AH$1,FALSE)="","-",VLOOKUP(ROUND(CONCATENATE($A8,AH$2),0),'Cadastro dos Padrões'!$A$2:$V$4400,AH$1,FALSE)) -> 2 | AI8: =IF(VLOOKUP(ROUND(CONCATENATE($A8,AI$2),0),'Cadastro dos Padrões'!$A$2:$V$4400,AI$1,FALSE)="","-",VLOOKUP(ROUND(CONCATENATE($A8,AI$2),0),'Cadastro dos Padrões'!$A$2:$V$4400,AI$1,FALSE)) -> 1000000 | ... BO8: =IF(VLOOKUP(ROUND(CONCATENATE($A8,BO$2),0),'Cadastro dos Padrões'!$A$2:$V$4400,BO$1,FALSE)="","-",VLOOKUP(ROUND(CONCATENATE($A8,BO$2),0),'Cadastro dos Padrões'!$A$2:$V$4400,BO$1,FALSE)) -> -
A9: =A8+1 -> 4 | B9: =IF(VLOOKUP(ROUND(CONCATENATE($A9,B$2),0),'Cadastro dos Padrões'!$A$2:$V$4400,B$1,FALSE)="","-",VLOOKUP(ROUND(CONCATENATE($A9,B$2),0),'Cadastro dos Padrões'!$A$2:$V$4400,B$1,FALSE)) -> EL-159 | C9: =IF($B9="-","-",VLOOKUP(ROUND(CONCATENATE($A9,C$2),0),'Cadastro dos Padrões'!$A$2:$V$4400,C$1,FALSE)) -> Termohigrômetro Digital | D9: =IF($B9="-","-",VLOOKUP(ROUND(CONCATENATE($A9,D$2),0),'Cadastro dos Padrões'!$A$2:$V$4400,D$1,FALSE)) -> 20 | E9: =IF($B9="-","-",VLOOKUP(ROUND(CONCATENATE($A9,E$2),0),'Cadastro dos Padrões'!$A$2:$V$4400,E$1,FALSE)) -> Elus | F9: =IF($B9="-","-",VLOOKUP(ROUND(CONCATENATE($A9,F$2),0),'Cadastro dos Padrões'!$A$2:$V$4400,F$1,FALSE)) -> RBC - CAL 0439 | G9: =IF($B9="-","-",VLOOKUP(ROUND(CONCATENATE($A9,G$2),0),'Cadastro dos Padrões'!$A$2:$V$4400,G$1,FALSE)) -> R0371/21 | H9: =IF($B9="-","-",VLOOKUP(ROUND(CONCATENATE($A9,H$2),0),'Cadastro dos Padrões'!$A$2:$V$4400,H$1,FALSE)) -> 44498 | I9: =IF($B9="-","-",VLOOKUP(ROUND(CONCATENATE($A9,I$2),0),'Cadastro dos Padrões'!$A$2:$V$4400,I$1,FALSE)) -> 44865 | J9: =IF($B9="-","-",VLOOKUP(ROUND(CONCATENATE($A9,J$2),0),'Cadastro dos Padrões'!$A$2:$V$4400,J$1,FALSE)) -> %ur | ... AA9: =IF($B9="-","-",VLOOKUP(ROUND(CONCATENATE($A9,AA$2),0),'Cadastro dos Padrões'!$A$2:$V$4400,AA$1,FALSE)) -> 7.531219 | AB9: =IF(VLOOKUP(ROUND(CONCATENATE($A9,AB$2),0),'Cadastro dos Padrões'!$A$2:$V$4400,AB$1,FALSE)="","-",VLOOKUP(ROUND(CONCATENATE($A9,AB$2),0),'Cadastro dos Padrões'!$A$2:$V$4400,AB$1,FALSE)) -> 30 | AC9: =IF(VLOOKUP(ROUND(CONCATENATE($A9,AC$2),0),'Cadastro dos Padrões'!$A$2:$V$4400,AC$1,FALSE)="","-",VLOOKUP(ROUND(CONCATENATE($A9,AC$2),0),'Cadastro dos Padrões'!$A$2:$V$4400,AC$1,FALSE)) -> 2 | AD9: =IF(VLOOKUP(ROUND(CONCATENATE($A9,AD$2),0),'Cadastro dos Padrões'!$A$2:$V$4400,AD$1,FALSE)="","-",VLOOKUP(ROUND(CONCATENATE($A9,AD$2),0),'Cadastro dos Padrões'!$A$2:$V$4400,AD$1,FALSE)) -> 2 | AE9: =IF(VLOOKUP(ROUND(CONCATENATE($A9,AE$2),0),'Cadastro dos Padrões'!$A$2:$V$4400,AE$1,FALSE)="","-",VLOOKUP(ROUND(CONCATENATE($A9,AE$2),0),'Cadastro dos Padrões'!$A$2:$V$4400,AE$1,FALSE)) -> 1000000 | AF9: =IF(VLOOKUP(ROUND(CONCATENATE($A9,AF$2),0),'Cadastro dos Padrões'!$A$2:$V$4400,AF$1,FALSE)="","-",VLOOKUP(ROUND(CONCATENATE($A9,AF$2),0),'Cadastro dos Padrões'!$A$2:$V$4400,AF$1,FALSE)) -> 50 | AG9: =IF(VLOOKUP(ROUND(CONCATENATE($A9,AG$2),0),'Cadastro dos Padrões'!$A$2:$V$4400,AG$1,FALSE)="","-",VLOOKUP(ROUND(CONCATENATE($A9,AG$2),0),'Cadastro dos Padrões'!$A$2:$V$4400,AG$1,FALSE)) -> 2 | AH9: =IF(VLOOKUP(ROUND(CONCATENATE($A9,AH$2),0),'Cadastro dos Padrões'!$A$2:$V$4400,AH$1,FALSE)="","-",VLOOKUP(ROUND(CONCATENATE($A9,AH$2),0),'Cadastro dos Padrões'!$A$2:$V$4400,AH$1,FALSE)) -> 2 | AI9: =IF(VLOOKUP(ROUND(CONCATENATE($A9,AI$2),0),'Cadastro dos Padrões'!$A$2:$V$4400,AI$1,FALSE)="","-",VLOOKUP(ROUND(CONCATENATE($A9,AI$2),0),'Cadastro dos Padrões'!$A$2:$V$4400,AI$1,FALSE)) -> 1000000 | ... BO9: =IF(VLOOKUP(ROUND(CONCATENATE($A9,BO$2),0),'Cadastro dos Padrões'!$A$2:$V$4400,BO$1,FALSE)="","-",VLOOKUP(ROUND(CONCATENATE($A9,BO$2),0),'Cadastro dos Padrões'!$A$2:$V$4400,BO$1,FALSE)) -> -
A10: =A9+1 -> 5 | B10: =IF(VLOOKUP(ROUND(CONCATENATE($A10,B$2),0),'Cadastro dos Padrões'!$A$2:$V$4400,B$1,FALSE)="","-",VLOOKUP(ROUND(CONCATENATE($A10,B$2),0),'Cadastro dos Padrões'!$A$2:$V$4400,B$1,FALSE)) -> E.TH.FS-051 | C10: =IF($B10="-","-",VLOOKUP(ROUND(CONCATENATE($A10,C$2),0),'Cadastro dos Padrões'!$A$2:$V$4400,C$1,FALSE)) -> Termohigrômetro Digital | D10: =IF($B10="-","-",VLOOKUP(ROUND(CONCATENATE($A10,D$2),0),'Cadastro dos Padrões'!$A$2:$V$4400,D$1,FALSE)) -> 20 | E10: =IF($B10="-","-",VLOOKUP(ROUND(CONCATENATE($A10,E$2),0),'Cadastro dos Padrões'!$A$2:$V$4400,E$1,FALSE)) -> Elus | F10: =IF($B10="-","-",VLOOKUP(ROUND(CONCATENATE($A10,F$2),0),'Cadastro dos Padrões'!$A$2:$V$4400,F$1,FALSE)) -> RBC - CAL 0439 | G10: =IF($B10="-","-",VLOOKUP(ROUND(CONCATENATE($A10,G$2),0),'Cadastro dos Padrões'!$A$2:$V$4400,G$1,FALSE)) -> E0051/26 | H10: =IF($B10="-","-",VLOOKUP(ROUND(CONCATENATE($A10,H$2),0),'Cadastro dos Padrões'!$A$2:$V$4400,H$1,FALSE)) -> 46056 | I10: =IF($B10="-","-",VLOOKUP(ROUND(CONCATENATE($A10,I$2),0),'Cadastro dos Padrões'!$A$2:$V$4400,I$1,FALSE)) -> 46446 | J10: =IF($B10="-","-",VLOOKUP(ROUND(CONCATENATE($A10,J$2),0),'Cadastro dos Padrões'!$A$2:$V$4400,J$1,FALSE)) -> %ur | ... AA10: =IF($B10="-","-",VLOOKUP(ROUND(CONCATENATE($A10,AA$2),0),'Cadastro dos Padrões'!$A$2:$V$4400,AA$1,FALSE)) -> -2.8106348 | AB10: =IF(VLOOKUP(ROUND(CONCATENATE($A10,AB$2),0),'Cadastro dos Padrões'!$A$2:$V$4400,AB$1,FALSE)="","-",VLOOKUP(ROUND(CONCATENATE($A10,AB$2),0),'Cadastro dos Padrões'!$A$2:$V$4400,AB$1,FALSE)) -> 30 | AC10: =IF(VLOOKUP(ROUND(CONCATENATE($A10,AC$2),0),'Cadastro dos Padrões'!$A$2:$V$4400,AC$1,FALSE)="","-",VLOOKUP(ROUND(CONCATENATE($A10,AC$2),0),'Cadastro dos Padrões'!$A$2:$V$4400,AC$1,FALSE)) -> 2 | AD10: =IF(VLOOKUP(ROUND(CONCATENATE($A10,AD$2),0),'Cadastro dos Padrões'!$A$2:$V$4400,AD$1,FALSE)="","-",VLOOKUP(ROUND(CONCATENATE($A10,AD$2),0),'Cadastro dos Padrões'!$A$2:$V$4400,AD$1,FALSE)) -> 2 | AE10: =IF(VLOOKUP(ROUND(CONCATENATE($A10,AE$2),0),'Cadastro dos Padrões'!$A$2:$V$4400,AE$1,FALSE)="","-",VLOOKUP(ROUND(CONCATENATE($A10,AE$2),0),'Cadastro dos Padrões'!$A$2:$V$4400,AE$1,FALSE)) -> 1000000 | AF10: =IF(VLOOKUP(ROUND(CONCATENATE($A10,AF$2),0),'Cadastro dos Padrões'!$A$2:$V$4400,AF$1,FALSE)="","-",VLOOKUP(ROUND(CONCATENATE($A10,AF$2),0),'Cadastro dos Padrões'!$A$2:$V$4400,AF$1,FALSE)) -> 50 | AG10: =IF(VLOOKUP(ROUND(CONCATENATE($A10,AG$2),0),'Cadastro dos Padrões'!$A$2:$V$4400,AG$1,FALSE)="","-",VLOOKUP(ROUND(CONCATENATE($A10,AG$2),0),'Cadastro dos Padrões'!$A$2:$V$4400,AG$1,FALSE)) -> 2 | AH10: =IF(VLOOKUP(ROUND(CONCATENATE($A10,AH$2),0),'Cadastro dos Padrões'!$A$2:$V$4400,AH$1,FALSE)="","-",VLOOKUP(ROUND(CONCATENATE($A10,AH$2),0),'Cadastro dos Padrões'!$A$2:$V$4400,AH$1,FALSE)) -> 2 | AI10: =IF(VLOOKUP(ROUND(CONCATENATE($A10,AI$2),0),'Cadastro dos Padrões'!$A$2:$V$4400,AI$1,FALSE)="","-",VLOOKUP(ROUND(CONCATENATE($A10,AI$2),0),'Cadastro dos Padrões'!$A$2:$V$4400,AI$1,FALSE)) -> 1000000 | ... BO10: =IF(VLOOKUP(ROUND(CONCATENATE($A10,BO$2),0),'Cadastro dos Padrões'!$A$2:$V$4400,BO$1,FALSE)="","-",VLOOKUP(ROUND(CONCATENATE($A10,BO$2),0),'Cadastro dos Padrões'!$A$2:$V$4400,BO$1,FALSE)) -> -
A11: =A10+1 -> 6 | B11: =IF(VLOOKUP(ROUND(CONCATENATE($A11,B$2),0),'Cadastro dos Padrões'!$A$2:$V$4400,B$1,FALSE)="","-",VLOOKUP(ROUND(CONCATENATE($A11,B$2),0),'Cadastro dos Padrões'!$A$2:$V$4400,B$1,FALSE)) -> E.TH.PMR-006 | C11: =IF($B11="-","-",VLOOKUP(ROUND(CONCATENATE($A11,C$2),0),'Cadastro dos Padrões'!$A$2:$V$4400,C$1,FALSE)) -> Termohigrômetro Digital | D11: =IF($B11="-","-",VLOOKUP(ROUND(CONCATENATE($A11,D$2),0),'Cadastro dos Padrões'!$A$2:$V$4400,D$1,FALSE)) -> 20 | E11: =IF($B11="-","-",VLOOKUP(ROUND(CONCATENATE($A11,E$2),0),'Cadastro dos Padrões'!$A$2:$V$4400,E$1,FALSE)) -> Elus | F11: =IF($B11="-","-",VLOOKUP(ROUND(CONCATENATE($A11,F$2),0),'Cadastro dos Padrões'!$A$2:$V$4400,F$1,FALSE)) -> RBC - CAL 0439 | G11: =IF($B11="-","-",VLOOKUP(ROUND(CONCATENATE($A11,G$2),0),'Cadastro dos Padrões'!$A$2:$V$4400,G$1,FALSE)) -> E0208/25 | H11: =IF($B11="-","-",VLOOKUP(ROUND(CONCATENATE($A11,H$2),0),'Cadastro dos Padrões'!$A$2:$V$4400,H$1,FALSE)) -> 45761 | I11: =IF($B11="-","-",VLOOKUP(ROUND(CONCATENATE($A11,I$2),0),'Cadastro dos Padrões'!$A$2:$V$4400,I$1,FALSE)) -> 46142 | J11: =IF($B11="-","-",VLOOKUP(ROUND(CONCATENATE($A11,J$2),0),'Cadastro dos Padrões'!$A$2:$V$4400,J$1,FALSE)) -> %ur | ... AA11: =IF($B11="-","-",VLOOKUP(ROUND(CONCATENATE($A11,AA$2),0),'Cadastro dos Padrões'!$A$2:$V$4400,AA$1,FALSE)) -> 0.4734786 | AB11: =IF(VLOOKUP(ROUND(CONCATENATE($A11,AB$2),0),'Cadastro dos Padrões'!$A$2:$V$4400,AB$1,FALSE)="","-",VLOOKUP(ROUND(CONCATENATE($A11,AB$2),0),'Cadastro dos Padrões'!$A$2:$V$4400,AB$1,FALSE)) -> 20 | AC11: =IF(VLOOKUP(ROUND(CONCATENATE($A11,AC$2),0),'Cadastro dos Padrões'!$A$2:$V$4400,AC$1,FALSE)="","-",VLOOKUP(ROUND(CONCATENATE($A11,AC$2),0),'Cadastro dos Padrões'!$A$2:$V$4400,AC$1,FALSE)) -> 0.7 | AD11: =IF(VLOOKUP(ROUND(CONCATENATE($A11,AD$2),0),'Cadastro dos Padrões'!$A$2:$V$4400,AD$1,FALSE)="","-",VLOOKUP(ROUND(CONCATENATE($A11,AD$2),0),'Cadastro dos Padrões'!$A$2:$V$4400,AD$1,FALSE)) -> 2 | AE11: =IF(VLOOKUP(ROUND(CONCATENATE($A11,AE$2),0),'Cadastro dos Padrões'!$A$2:$V$4400,AE$1,FALSE)="","-",VLOOKUP(ROUND(CONCATENATE($A11,AE$2),0),'Cadastro dos Padrões'!$A$2:$V$4400,AE$1,FALSE)) -> 1000000 | AF11: =IF(VLOOKUP(ROUND(CONCATENATE($A11,AF$2),0),'Cadastro dos Padrões'!$A$2:$V$4400,AF$1,FALSE)="","-",VLOOKUP(ROUND(CONCATENATE($A11,AF$2),0),'Cadastro dos Padrões'!$A$2:$V$4400,AF$1,FALSE)) -> 50 | AG11: =IF(VLOOKUP(ROUND(CONCATENATE($A11,AG$2),0),'Cadastro dos Padrões'!$A$2:$V$4400,AG$1,FALSE)="","-",VLOOKUP(ROUND(CONCATENATE($A11,AG$2),0),'Cadastro dos Padrões'!$A$2:$V$4400,AG$1,FALSE)) -> 1.1 | AH11: =IF(VLOOKUP(ROUND(CONCATENATE($A11,AH$2),0),'Cadastro dos Padrões'!$A$2:$V$4400,AH$1,FALSE)="","-",VLOOKUP(ROUND(CONCATENATE($A11,AH$2),0),'Cadastro dos Padrões'!$A$2:$V$4400,AH$1,FALSE)) -> 2 | AI11: =IF(VLOOKUP(ROUND(CONCATENATE($A11,AI$2),0),'Cadastro dos Padrões'!$A$2:$V$4400,AI$1,FALSE)="","-",VLOOKUP(ROUND(CONCATENATE($A11,AI$2),0),'Cadastro dos Padrões'!$A$2:$V$4400,AI$1,FALSE)) -> 1000000 | ... BO11: =IF(VLOOKUP(ROUND(CONCATENATE($A11,BO$2),0),'Cadastro dos Padrões'!$A$2:$V$4400,BO$1,FALSE)="","-",VLOOKUP(ROUND(CONCATENATE($A11,BO$2),0),'Cadastro dos Padrões'!$A$2:$V$4400,BO$1,FALSE)) -> -
A12: =A11+1 -> 7 | B12: =IF(VLOOKUP(ROUND(CONCATENATE($A12,B$2),0),'Cadastro dos Padrões'!$A$2:$V$4400,B$1,FALSE)="","-",VLOOKUP(ROUND(CONCATENATE($A12,B$2),0),'Cadastro dos Padrões'!$A$2:$V$4400,B$1,FALSE)) -> E.TH.PMR-007 | C12: =IF($B12="-","-",VLOOKUP(ROUND(CONCATENATE($A12,C$2),0),'Cadastro dos Padrões'!$A$2:$V$4400,C$1,FALSE)) -> Termohigrômetro Digital | D12: =IF($B12="-","-",VLOOKUP(ROUND(CONCATENATE($A12,D$2),0),'Cadastro dos Padrões'!$A$2:$V$4400,D$1,FALSE)) -> 20 | E12: =IF($B12="-","-",VLOOKUP(ROUND(CONCATENATE($A12,E$2),0),'Cadastro dos Padrões'!$A$2:$V$4400,E$1,FALSE)) -> Elus | F12: =IF($B12="-","-",VLOOKUP(ROUND(CONCATENATE($A12,F$2),0),'Cadastro dos Padrões'!$A$2:$V$4400,F$1,FALSE)) -> RBC - CAL 0439 | G12: =IF($B12="-","-",VLOOKUP(ROUND(CONCATENATE($A12,G$2),0),'Cadastro dos Padrões'!$A$2:$V$4400,G$1,FALSE)) -> E0209/25 | H12: =IF($B12="-","-",VLOOKUP(ROUND(CONCATENATE($A12,H$2),0),'Cadastro dos Padrões'!$A$2:$V$4400,H$1,FALSE)) -> 45761 | I12: =IF($B12="-","-",VLOOKUP(ROUND(CONCATENATE($A12,I$2),0),'Cadastro dos Padrões'!$A$2:$V$4400,I$1,FALSE)) -> 46142 | J12: =IF($B12="-","-",VLOOKUP(ROUND(CONCATENATE($A12,J$2),0),'Cadastro dos Padrões'!$A$2:$V$4400,J$1,FALSE)) -> %ur | ... AA12: =IF($B12="-","-",VLOOKUP(ROUND(CONCATENATE($A12,AA$2),0),'Cadastro dos Padrões'!$A$2:$V$4400,AA$1,FALSE)) -> 0.28613556 | AB12: =IF(VLOOKUP(ROUND(CONCATENATE($A12,AB$2),0),'Cadastro dos Padrões'!$A$2:$V$4400,AB$1,FALSE)="","-",VLOOKUP(ROUND(CONCATENATE($A12,AB$2),0),'Cadastro dos Padrões'!$A$2:$V$4400,AB$1,FALSE)) -> 20 | AC12: =IF(VLOOKUP(ROUND(CONCATENATE($A12,AC$2),0),'Cadastro dos Padrões'!$A$2:$V$4400,AC$1,FALSE)="","-",VLOOKUP(ROUND(CONCATENATE($A12,AC$2),0),'Cadastro dos Padrões'!$A$2:$V$4400,AC$1,FALSE)) -> 0.7 | AD12: =IF(VLOOKUP(ROUND(CONCATENATE($A12,AD$2),0),'Cadastro dos Padrões'!$A$2:$V$4400,AD$1,FALSE)="","-",VLOOKUP(ROUND(CONCATENATE($A12,AD$2),0),'Cadastro dos Padrões'!$A$2:$V$4400,AD$1,FALSE)) -> 2 | AE12: =IF(VLOOKUP(ROUND(CONCATENATE($A12,AE$2),0),'Cadastro dos Padrões'!$A$2:$V$4400,AE$1,FALSE)="","-",VLOOKUP(ROUND(CONCATENATE($A12,AE$2),0),'Cadastro dos Padrões'!$A$2:$V$4400,AE$1,FALSE)) -> 1000000 | AF12: =IF(VLOOKUP(ROUND(CONCATENATE($A12,AF$2),0),'Cadastro dos Padrões'!$A$2:$V$4400,AF$1,FALSE)="","-",VLOOKUP(ROUND(CONCATENATE($A12,AF$2),0),'Cadastro dos Padrões'!$A$2:$V$4400,AF$1,FALSE)) -> 50 | AG12: =IF(VLOOKUP(ROUND(CONCATENATE($A12,AG$2),0),'Cadastro dos Padrões'!$A$2:$V$4400,AG$1,FALSE)="","-",VLOOKUP(ROUND(CONCATENATE($A12,AG$2),0),'Cadastro dos Padrões'!$A$2:$V$4400,AG$1,FALSE)) -> 1.1 | AH12: =IF(VLOOKUP(ROUND(CONCATENATE($A12,AH$2),0),'Cadastro dos Padrões'!$A$2:$V$4400,AH$1,FALSE)="","-",VLOOKUP(ROUND(CONCATENATE($A12,AH$2),0),'Cadastro dos Padrões'!$A$2:$V$4400,AH$1,FALSE)) -> 2 | AI12: =IF(VLOOKUP(ROUND(CONCATENATE($A12,AI$2),0),'Cadastro dos Padrões'!$A$2:$V$4400,AI$1,FALSE)="","-",VLOOKUP(ROUND(CONCATENATE($A12,AI$2),0),'Cadastro dos Padrões'!$A$2:$V$4400,AI$1,FALSE)) -> 1000000 | ... BO12: =IF(VLOOKUP(ROUND(CONCATENATE($A12,BO$2),0),'Cadastro dos Padrões'!$A$2:$V$4400,BO$1,FALSE)="","-",VLOOKUP(ROUND(CONCATENATE($A12,BO$2),0),'Cadastro dos Padrões'!$A$2:$V$4400,BO$1,FALSE)) -> -
A13: =A12+1 -> 8 | B13: =IF(VLOOKUP(ROUND(CONCATENATE($A13,B$2),0),'Cadastro dos Padrões'!$A$2:$V$4400,B$1,FALSE)="","-",VLOOKUP(ROUND(CONCATENATE($A13,B$2),0),'Cadastro dos Padrões'!$A$2:$V$4400,B$1,FALSE)) -> E.TH.PMR-008 | C13: =IF($B13="-","-",VLOOKUP(ROUND(CONCATENATE($A13,C$2),0),'Cadastro dos Padrões'!$A$2:$V$4400,C$1,FALSE)) -> Termohigrômetro Digital | D13: =IF($B13="-","-",VLOOKUP(ROUND(CONCATENATE($A13,D$2),0),'Cadastro dos Padrões'!$A$2:$V$4400,D$1,FALSE)) -> 20 | E13: =IF($B13="-","-",VLOOKUP(ROUND(CONCATENATE($A13,E$2),0),'Cadastro dos Padrões'!$A$2:$V$4400,E$1,FALSE)) -> Elus | F13: =IF($B13="-","-",VLOOKUP(ROUND(CONCATENATE($A13,F$2),0),'Cadastro dos Padrões'!$A$2:$V$4400,F$1,FALSE)) -> RBC - CAL 0439 | G13: =IF($B13="-","-",VLOOKUP(ROUND(CONCATENATE($A13,G$2),0),'Cadastro dos Padrões'!$A$2:$V$4400,G$1,FALSE)) -> E0210/25 | H13: =IF($B13="-","-",VLOOKUP(ROUND(CONCATENATE($A13,H$2),0),'Cadastro dos Padrões'!$A$2:$V$4400,H$1,FALSE)) -> 45761 | I13: =IF($B13="-","-",VLOOKUP(ROUND(CONCATENATE($A13,I$2),0),'Cadastro dos Padrões'!$A$2:$V$4400,I$1,FALSE)) -> 46142 | J13: =IF($B13="-","-",VLOOKUP(ROUND(CONCATENATE($A13,J$2),0),'Cadastro dos Padrões'!$A$2:$V$4400,J$1,FALSE)) -> %ur | ... AA13: =IF($B13="-","-",VLOOKUP(ROUND(CONCATENATE($A13,AA$2),0),'Cadastro dos Padrões'!$A$2:$V$4400,AA$1,FALSE)) -> 0.55318003 | AB13: =IF(VLOOKUP(ROUND(CONCATENATE($A13,AB$2),0),'Cadastro dos Padrões'!$A$2:$V$4400,AB$1,FALSE)="","-",VLOOKUP(ROUND(CONCATENATE($A13,AB$2),0),'Cadastro dos Padrões'!$A$2:$V$4400,AB$1,FALSE)) -> 20 | AC13: =IF(VLOOKUP(ROUND(CONCATENATE($A13,AC$2),0),'Cadastro dos Padrões'!$A$2:$V$4400,AC$1,FALSE)="","-",VLOOKUP(ROUND(CONCATENATE($A13,AC$2),0),'Cadastro dos Padrões'!$A$2:$V$4400,AC$1,FALSE)) -> 0.7 | AD13: =IF(VLOOKUP(ROUND(CONCATENATE($A13,AD$2),0),'Cadastro dos Padrões'!$A$2:$V$4400,AD$1,FALSE)="","-",VLOOKUP(ROUND(CONCATENATE($A13,AD$2),0),'Cadastro dos Padrões'!$A$2:$V$4400,AD$1,FALSE)) -> 2 | AE13: =IF(VLOOKUP(ROUND(CONCATENATE($A13,AE$2),0),'Cadastro dos Padrões'!$A$2:$V$4400,AE$1,FALSE)="","-",VLOOKUP(ROUND(CONCATENATE($A13,AE$2),0),'Cadastro dos Padrões'!$A$2:$V$4400,AE$1,FALSE)) -> 1000000 | AF13: =IF(VLOOKUP(ROUND(CONCATENATE($A13,AF$2),0),'Cadastro dos Padrões'!$A$2:$V$4400,AF$1,FALSE)="","-",VLOOKUP(ROUND(CONCATENATE($A13,AF$2),0),'Cadastro dos Padrões'!$A$2:$V$4400,AF$1,FALSE)) -> 50 | AG13: =IF(VLOOKUP(ROUND(CONCATENATE($A13,AG$2),0),'Cadastro dos Padrões'!$A$2:$V$4400,AG$1,FALSE)="","-",VLOOKUP(ROUND(CONCATENATE($A13,AG$2),0),'Cadastro dos Padrões'!$A$2:$V$4400,AG$1,FALSE)) -> 1.1 | AH13: =IF(VLOOKUP(ROUND(CONCATENATE($A13,AH$2),0),'Cadastro dos Padrões'!$A$2:$V$4400,AH$1,FALSE)="","-",VLOOKUP(ROUND(CONCATENATE($A13,AH$2),0),'Cadastro dos Padrões'!$A$2:$V$4400,AH$1,FALSE)) -> 2 | AI13: =IF(VLOOKUP(ROUND(CONCATENATE($A13,AI$2),0),'Cadastro dos Padrões'!$A$2:$V$4400,AI$1,FALSE)="","-",VLOOKUP(ROUND(CONCATENATE($A13,AI$2),0),'Cadastro dos Padrões'!$A$2:$V$4400,AI$1,FALSE)) -> 1000000 | ... BO13: =IF(VLOOKUP(ROUND(CONCATENATE($A13,BO$2),0),'Cadastro dos Padrões'!$A$2:$V$4400,BO$1,FALSE)="","-",VLOOKUP(ROUND(CONCATENATE($A13,BO$2),0),'Cadastro dos Padrões'!$A$2:$V$4400,BO$1,FALSE)) -> -
A14: =A13+1 -> 9 | B14: =IF(VLOOKUP(ROUND(CONCATENATE($A14,B$2),0),'Cadastro dos Padrões'!$A$2:$V$4400,B$1,FALSE)="","-",VLOOKUP(ROUND(CONCATENATE($A14,B$2),0),'Cadastro dos Padrões'!$A$2:$V$4400,B$1,FALSE)) -> E.TH.LT-006 | C14: =IF($B14="-","-",VLOOKUP(ROUND(CONCATENATE($A14,C$2),0),'Cadastro dos Padrões'!$A$2:$V$4400,C$1,FALSE)) -> Termohigrômetro Digital | D14: =IF($B14="-","-",VLOOKUP(ROUND(CONCATENATE($A14,D$2),0),'Cadastro dos Padrões'!$A$2:$V$4400,D$1,FALSE)) -> 20 | E14: =IF($B14="-","-",VLOOKUP(ROUND(CONCATENATE($A14,E$2),0),'Cadastro dos Padrões'!$A$2:$V$4400,E$1,FALSE)) -> Elus | F14: =IF($B14="-","-",VLOOKUP(ROUND(CONCATENATE($A14,F$2),0),'Cadastro dos Padrões'!$A$2:$V$4400,F$1,FALSE)) -> RBC - CAL 0439 | G14: =IF($B14="-","-",VLOOKUP(ROUND(CONCATENATE($A14,G$2),0),'Cadastro dos Padrões'!$A$2:$V$4400,G$1,FALSE)) -> E0843/25 | H14: =IF($B14="-","-",VLOOKUP(ROUND(CONCATENATE($A14,H$2),0),'Cadastro dos Padrões'!$A$2:$V$4400,H$1,FALSE)) -> 45989 | I14: =IF($B14="-","-",VLOOKUP(ROUND(CONCATENATE($A14,I$2),0),'Cadastro dos Padrões'!$A$2:$V$4400,I$1,FALSE)) -> 46170 | J14: =IF($B14="-","-",VLOOKUP(ROUND(CONCATENATE($A14,J$2),0),'Cadastro dos Padrões'!$A$2:$V$4400,J$1,FALSE)) -> %ur | ... AA14: =IF($B14="-","-",VLOOKUP(ROUND(CONCATENATE($A14,AA$2),0),'Cadastro dos Padrões'!$A$2:$V$4400,AA$1,FALSE)) -> 0.23473039 | AB14: =IF(VLOOKUP(ROUND(CONCATENATE($A14,AB$2),0),'Cadastro dos Padrões'!$A$2:$V$4400,AB$1,FALSE)="","-",VLOOKUP(ROUND(CONCATENATE($A14,AB$2),0),'Cadastro dos Padrões'!$A$2:$V$4400,AB$1,FALSE)) -> 5.01 | AC14: =IF(VLOOKUP(ROUND(CONCATENATE($A14,AC$2),0),'Cadastro dos Padrões'!$A$2:$V$4400,AC$1,FALSE)="","-",VLOOKUP(ROUND(CONCATENATE($A14,AC$2),0),'Cadastro dos Padrões'!$A$2:$V$4400,AC$1,FALSE)) -> 0.25 | AD14: =IF(VLOOKUP(ROUND(CONCATENATE($A14,AD$2),0),'Cadastro dos Padrões'!$A$2:$V$4400,AD$1,FALSE)="","-",VLOOKUP(ROUND(CONCATENATE($A14,AD$2),0),'Cadastro dos Padrões'!$A$2:$V$4400,AD$1,FALSE)) -> 2.03 | AE14: =IF(VLOOKUP(ROUND(CONCATENATE($A14,AE$2),0),'Cadastro dos Padrões'!$A$2:$V$4400,AE$1,FALSE)="","-",VLOOKUP(ROUND(CONCATENATE($A14,AE$2),0),'Cadastro dos Padrões'!$A$2:$V$4400,AE$1,FALSE)) -> 87 | AF14: =IF(VLOOKUP(ROUND(CONCATENATE($A14,AF$2),0),'Cadastro dos Padrões'!$A$2:$V$4400,AF$1,FALSE)="","-",VLOOKUP(ROUND(CONCATENATE($A14,AF$2),0),'Cadastro dos Padrões'!$A$2:$V$4400,AF$1,FALSE)) -> 20.01 | AG14: =IF(VLOOKUP(ROUND(CONCATENATE($A14,AG$2),0),'Cadastro dos Padrões'!$A$2:$V$4400,AG$1,FALSE)="","-",VLOOKUP(ROUND(CONCATENATE($A14,AG$2),0),'Cadastro dos Padrões'!$A$2:$V$4400,AG$1,FALSE)) -> 0.27 | AH14: =IF(VLOOKUP(ROUND(CONCATENATE($A14,AH$2),0),'Cadastro dos Padrões'!$A$2:$V$4400,AH$1,FALSE)="","-",VLOOKUP(ROUND(CONCATENATE($A14,AH$2),0),'Cadastro dos Padrões'!$A$2:$V$4400,AH$1,FALSE)) -> 2.04 | AI14: =IF(VLOOKUP(ROUND(CONCATENATE($A14,AI$2),0),'Cadastro dos Padrões'!$A$2:$V$4400,AI$1,FALSE)="","-",VLOOKUP(ROUND(CONCATENATE($A14,AI$2),0),'Cadastro dos Padrões'!$A$2:$V$4400,AI$1,FALSE)) -> 65 | ... BO14: =IF(VLOOKUP(ROUND(CONCATENATE($A14,BO$2),0),'Cadastro dos Padrões'!$A$2:$V$4400,BO$1,FALSE)="","-",VLOOKUP(ROUND(CONCATENATE($A14,BO$2),0),'Cadastro dos Padrões'!$A$2:$V$4400,BO$1,FALSE)) -> -
A15: =A14+1 -> 10 | B15: =IF(VLOOKUP(ROUND(CONCATENATE($A15,B$2),0),'Cadastro dos Padrões'!$A$2:$V$4400,B$1,FALSE)="","-",VLOOKUP(ROUND(CONCATENATE($A15,B$2),0),'Cadastro dos Padrões'!$A$2:$V$4400,B$1,FALSE)) -> E.TH.LT-006 | C15: =IF($B15="-","-",VLOOKUP(ROUND(CONCATENATE($A15,C$2),0),'Cadastro dos Padrões'!$A$2:$V$4400,C$1,FALSE)) -> Termohigrômetro Digital | D15: =IF($B15="-","-",VLOOKUP(ROUND(CONCATENATE($A15,D$2),0),'Cadastro dos Padrões'!$A$2:$V$4400,D$1,FALSE)) -> 25 | E15: =IF($B15="-","-",VLOOKUP(ROUND(CONCATENATE($A15,E$2),0),'Cadastro dos Padrões'!$A$2:$V$4400,E$1,FALSE)) -> Elus | F15: =IF($B15="-","-",VLOOKUP(ROUND(CONCATENATE($A15,F$2),0),'Cadastro dos Padrões'!$A$2:$V$4400,F$1,FALSE)) -> RBC - CAL 0439 | G15: =IF($B15="-","-",VLOOKUP(ROUND(CONCATENATE($A15,G$2),0),'Cadastro dos Padrões'!$A$2:$V$4400,G$1,FALSE)) -> E0843/25 | H15: =IF($B15="-","-",VLOOKUP(ROUND(CONCATENATE($A15,H$2),0),'Cadastro dos Padrões'!$A$2:$V$4400,H$1,FALSE)) -> 45989 | I15: =IF($B15="-","-",VLOOKUP(ROUND(CONCATENATE($A15,I$2),0),'Cadastro dos Padrões'!$A$2:$V$4400,I$1,FALSE)) -> 46170 | J15: =IF($B15="-","-",VLOOKUP(ROUND(CONCATENATE($A15,J$2),0),'Cadastro dos Padrões'!$A$2:$V$4400,J$1,FALSE)) -> %ur | ... AA15: =IF($B15="-","-",VLOOKUP(ROUND(CONCATENATE($A15,AA$2),0),'Cadastro dos Padrões'!$A$2:$V$4400,AA$1,FALSE)) -> 0.84446984 | AB15: =IF(VLOOKUP(ROUND(CONCATENATE($A15,AB$2),0),'Cadastro dos Padrões'!$A$2:$V$4400,AB$1,FALSE)="","-",VLOOKUP(ROUND(CONCATENATE($A15,AB$2),0),'Cadastro dos Padrões'!$A$2:$V$4400,AB$1,FALSE)) -> 5.01 | AC15: =IF(VLOOKUP(ROUND(CONCATENATE($A15,AC$2),0),'Cadastro dos Padrões'!$A$2:$V$4400,AC$1,FALSE)="","-",VLOOKUP(ROUND(CONCATENATE($A15,AC$2),0),'Cadastro dos Padrões'!$A$2:$V$4400,AC$1,FALSE)) -> 0.25 | AD15: =IF(VLOOKUP(ROUND(CONCATENATE($A15,AD$2),0),'Cadastro dos Padrões'!$A$2:$V$4400,AD$1,FALSE)="","-",VLOOKUP(ROUND(CONCATENATE($A15,AD$2),0),'Cadastro dos Padrões'!$A$2:$V$4400,AD$1,FALSE)) -> 2.03 | AE15: =IF(VLOOKUP(ROUND(CONCATENATE($A15,AE$2),0),'Cadastro dos Padrões'!$A$2:$V$4400,AE$1,FALSE)="","-",VLOOKUP(ROUND(CONCATENATE($A15,AE$2),0),'Cadastro dos Padrões'!$A$2:$V$4400,AE$1,FALSE)) -> 87 | AF15: =IF(VLOOKUP(ROUND(CONCATENATE($A15,AF$2),0),'Cadastro dos Padrões'!$A$2:$V$4400,AF$1,FALSE)="","-",VLOOKUP(ROUND(CONCATENATE($A15,AF$2),0),'Cadastro dos Padrões'!$A$2:$V$4400,AF$1,FALSE)) -> 19.99 | AG15: =IF(VLOOKUP(ROUND(CONCATENATE($A15,AG$2),0),'Cadastro dos Padrões'!$A$2:$V$4400,AG$1,FALSE)="","-",VLOOKUP(ROUND(CONCATENATE($A15,AG$2),0),'Cadastro dos Padrões'!$A$2:$V$4400,AG$1,FALSE)) -> 0.25 | AH15: =IF(VLOOKUP(ROUND(CONCATENATE($A15,AH$2),0),'Cadastro dos Padrões'!$A$2:$V$4400,AH$1,FALSE)="","-",VLOOKUP(ROUND(CONCATENATE($A15,AH$2),0),'Cadastro dos Padrões'!$A$2:$V$4400,AH$1,FALSE)) -> 2.04 | AI15: =IF(VLOOKUP(ROUND(CONCATENATE($A15,AI$2),0),'Cadastro dos Padrões'!$A$2:$V$4400,AI$1,FALSE)="","-",VLOOKUP(ROUND(CONCATENATE($A15,AI$2),0),'Cadastro dos Padrões'!$A$2:$V$4400,AI$1,FALSE)) -> 66 | ... BO15: =IF(VLOOKUP(ROUND(CONCATENATE($A15,BO$2),0),'Cadastro dos Padrões'!$A$2:$V$4400,BO$1,FALSE)="","-",VLOOKUP(ROUND(CONCATENATE($A15,BO$2),0),'Cadastro dos Padrões'!$A$2:$V$4400,BO$1,FALSE)) -> -
A16: =A15+1 -> 11 | B16: =IF(VLOOKUP(ROUND(CONCATENATE($A16,B$2),0),'Cadastro dos Padrões'!$A$2:$V$4400,B$1,FALSE)="","-",VLOOKUP(ROUND(CONCATENATE($A16,B$2),0),'Cadastro dos Padrões'!$A$2:$V$4400,B$1,FALSE)) -> - | C16: =IF($B16="-","-",VLOOKUP(ROUND(CONCATENATE($A16,C$2),0),'Cadastro dos Padrões'!$A$2:$V$4400,C$1,FALSE)) -> - | D16: =IF($B16="-","-",VLOOKUP(ROUND(CONCATENATE($A16,D$2),0),'Cadastro dos Padrões'!$A$2:$V$4400,D$1,FALSE)) -> - | E16: =IF($B16="-","-",VLOOKUP(ROUND(CONCATENATE($A16,E$2),0),'Cadastro dos Padrões'!$A$2:$V$4400,E$1,FALSE)) -> - | F16: =IF($B16="-","-",VLOOKUP(ROUND(CONCATENATE($A16,F$2),0),'Cadastro dos Padrões'!$A$2:$V$4400,F$1,FALSE)) -> - | G16: =IF($B16="-","-",VLOOKUP(ROUND(CONCATENATE($A16,G$2),0),'Cadastro dos Padrões'!$A$2:$V$4400,G$1,FALSE)) -> - | H16: =IF($B16="-","-",VLOOKUP(ROUND(CONCATENATE($A16,H$2),0),'Cadastro dos Padrões'!$A$2:$V$4400,H$1,FALSE)) -> - | I16: =IF($B16="-","-",VLOOKUP(ROUND(CONCATENATE($A16,I$2),0),'Cadastro dos Padrões'!$A$2:$V$4400,I$1,FALSE)) -> - | J16: =IF($B16="-","-",VLOOKUP(ROUND(CONCATENATE($A16,J$2),0),'Cadastro dos Padrões'!$A$2:$V$4400,J$1,FALSE)) -> - | ... AA16: =IF($B16="-","-",VLOOKUP(ROUND(CONCATENATE($A16,AA$2),0),'Cadastro dos Padrões'!$A$2:$V$4400,AA$1,FALSE)) -> - | AB16: =IF(VLOOKUP(ROUND(CONCATENATE($A16,AB$2),0),'Cadastro dos Padrões'!$A$2:$V$4400,AB$1,FALSE)="","-",VLOOKUP(ROUND(CONCATENATE($A16,AB$2),0),'Cadastro dos Padrões'!$A$2:$V$4400,AB$1,FALSE)) -> - | AC16: =IF(VLOOKUP(ROUND(CONCATENATE($A16,AC$2),0),'Cadastro dos Padrões'!$A$2:$V$4400,AC$1,FALSE)="","-",VLOOKUP(ROUND(CONCATENATE($A16,AC$2),0),'Cadastro dos Padrões'!$A$2:$V$4400,AC$1,FALSE)) -> - | AD16: =IF(VLOOKUP(ROUND(CONCATENATE($A16,AD$2),0),'Cadastro dos Padrões'!$A$2:$V$4400,AD$1,FALSE)="","-",VLOOKUP(ROUND(CONCATENATE($A16,AD$2),0),'Cadastro dos Padrões'!$A$2:$V$4400,AD$1,FALSE)) -> - | AE16: =IF(VLOOKUP(ROUND(CONCATENATE($A16,AE$2),0),'Cadastro dos Padrões'!$A$2:$V$4400,AE$1,FALSE)="","-",VLOOKUP(ROUND(CONCATENATE($A16,AE$2),0),'Cadastro dos Padrões'!$A$2:$V$4400,AE$1,FALSE)) -> - | AF16: =IF(VLOOKUP(ROUND(CONCATENATE($A16,AF$2),0),'Cadastro dos Padrões'!$A$2:$V$4400,AF$1,FALSE)="","-",VLOOKUP(ROUND(CONCATENATE($A16,AF$2),0),'Cadastro dos Padrões'!$A$2:$V$4400,AF$1,FALSE)) -> - | AG16: =IF(VLOOKUP(ROUND(CONCATENATE($A16,AG$2),0),'Cadastro dos Padrões'!$A$2:$V$4400,AG$1,FALSE)="","-",VLOOKUP(ROUND(CONCATENATE($A16,AG$2),0),'Cadastro dos Padrões'!$A$2:$V$4400,AG$1,FALSE)) -> - | AH16: =IF(VLOOKUP(ROUND(CONCATENATE($A16,AH$2),0),'Cadastro dos Padrões'!$A$2:$V$4400,AH$1,FALSE)="","-",VLOOKUP(ROUND(CONCATENATE($A16,AH$2),0),'Cadastro dos Padrões'!$A$2:$V$4400,AH$1,FALSE)) -> - | AI16: =IF(VLOOKUP(ROUND(CONCATENATE($A16,AI$2),0),'Cadastro dos Padrões'!$A$2:$V$4400,AI$1,FALSE)="","-",VLOOKUP(ROUND(CONCATENATE($A16,AI$2),0),'Cadastro dos Padrões'!$A$2:$V$4400,AI$1,FALSE)) -> - | ... BO16: =IF(VLOOKUP(ROUND(CONCATENATE($A16,BO$2),0),'Cadastro dos Padrões'!$A$2:$V$4400,BO$1,FALSE)="","-",VLOOKUP(ROUND(CONCATENATE($A16,BO$2),0),'Cadastro dos Padrões'!$A$2:$V$4400,BO$1,FALSE)) -> -
A17: =A16+1 -> 12 | B17: =IF(VLOOKUP(ROUND(CONCATENATE($A17,B$2),0),'Cadastro dos Padrões'!$A$2:$V$4400,B$1,FALSE)="","-",VLOOKUP(ROUND(CONCATENATE($A17,B$2),0),'Cadastro dos Padrões'!$A$2:$V$4400,B$1,FALSE)) -> E.TH.LT-019 | C17: =IF($B17="-","-",VLOOKUP(ROUND(CONCATENATE($A17,C$2),0),'Cadastro dos Padrões'!$A$2:$V$4400,C$1,FALSE)) -> Higrômetro de Ponto de Orvalho | D17: =IF($B17="-","-",VLOOKUP(ROUND(CONCATENATE($A17,D$2),0),'Cadastro dos Padrões'!$A$2:$V$4400,D$1,FALSE)) -> - | E17: =IF($B17="-","-",VLOOKUP(ROUND(CONCATENATE($A17,E$2),0),'Cadastro dos Padrões'!$A$2:$V$4400,E$1,FALSE)) -> Elus | F17: =IF($B17="-","-",VLOOKUP(ROUND(CONCATENATE($A17,F$2),0),'Cadastro dos Padrões'!$A$2:$V$4400,F$1,FALSE)) -> RBC - CAL 0439 | G17: =IF($B17="-","-",VLOOKUP(ROUND(CONCATENATE($A17,G$2),0),'Cadastro dos Padrões'!$A$2:$V$4400,G$1,FALSE)) -> E0177/25 | H17: =IF($B17="-","-",VLOOKUP(ROUND(CONCATENATE($A17,H$2),0),'Cadastro dos Padrões'!$A$2:$V$4400,H$1,FALSE)) -> 45748 | I17: =IF($B17="-","-",VLOOKUP(ROUND(CONCATENATE($A17,I$2),0),'Cadastro dos Padrões'!$A$2:$V$4400,I$1,FALSE)) -> 46142 | J17: =IF($B17="-","-",VLOOKUP(ROUND(CONCATENATE($A17,J$2),0),'Cadastro dos Padrões'!$A$2:$V$4400,J$1,FALSE)) -> °CTd/f | ... AA17: =IF($B17="-","-",VLOOKUP(ROUND(CONCATENATE($A17,AA$2),0),'Cadastro dos Padrões'!$A$2:$V$4400,AA$1,FALSE)) -> -1.5552394 | AB17: =IF(VLOOKUP(ROUND(CONCATENATE($A17,AB$2),0),'Cadastro dos Padrões'!$A$2:$V$4400,AB$1,FALSE)="","-",VLOOKUP(ROUND(CONCATENATE($A17,AB$2),0),'Cadastro dos Padrões'!$A$2:$V$4400,AB$1,FALSE)) -> -60 | AC17: =IF(VLOOKUP(ROUND(CONCATENATE($A17,AC$2),0),'Cadastro dos Padrões'!$A$2:$V$4400,AC$1,FALSE)="","-",VLOOKUP(ROUND(CONCATENATE($A17,AC$2),0),'Cadastro dos Padrões'!$A$2:$V$4400,AC$1,FALSE)) -> 0.26 | AD17: =IF(VLOOKUP(ROUND(CONCATENATE($A17,AD$2),0),'Cadastro dos Padrões'!$A$2:$V$4400,AD$1,FALSE)="","-",VLOOKUP(ROUND(CONCATENATE($A17,AD$2),0),'Cadastro dos Padrões'!$A$2:$V$4400,AD$1,FALSE)) -> 2 | AE17: =IF(VLOOKUP(ROUND(CONCATENATE($A17,AE$2),0),'Cadastro dos Padrões'!$A$2:$V$4400,AE$1,FALSE)="","-",VLOOKUP(ROUND(CONCATENATE($A17,AE$2),0),'Cadastro dos Padrões'!$A$2:$V$4400,AE$1,FALSE)) -> 1000000 | AF17: =IF(VLOOKUP(ROUND(CONCATENATE($A17,AF$2),0),'Cadastro dos Padrões'!$A$2:$V$4400,AF$1,FALSE)="","-",VLOOKUP(ROUND(CONCATENATE($A17,AF$2),0),'Cadastro dos Padrões'!$A$2:$V$4400,AF$1,FALSE)) -> -50 | AG17: =IF(VLOOKUP(ROUND(CONCATENATE($A17,AG$2),0),'Cadastro dos Padrões'!$A$2:$V$4400,AG$1,FALSE)="","-",VLOOKUP(ROUND(CONCATENATE($A17,AG$2),0),'Cadastro dos Padrões'!$A$2:$V$4400,AG$1,FALSE)) -> 0.26 | AH17: =IF(VLOOKUP(ROUND(CONCATENATE($A17,AH$2),0),'Cadastro dos Padrões'!$A$2:$V$4400,AH$1,FALSE)="","-",VLOOKUP(ROUND(CONCATENATE($A17,AH$2),0),'Cadastro dos Padrões'!$A$2:$V$4400,AH$1,FALSE)) -> 2 | AI17: =IF(VLOOKUP(ROUND(CONCATENATE($A17,AI$2),0),'Cadastro dos Padrões'!$A$2:$V$4400,AI$1,FALSE)="","-",VLOOKUP(ROUND(CONCATENATE($A17,AI$2),0),'Cadastro dos Padrões'!$A$2:$V$4400,AI$1,FALSE)) -> 1000000 | ... BO17: =IF(VLOOKUP(ROUND(CONCATENATE($A17,BO$2),0),'Cadastro dos Padrões'!$A$2:$V$4400,BO$1,FALSE)="","-",VLOOKUP(ROUND(CONCATENATE($A17,BO$2),0),'Cadastro dos Padrões'!$A$2:$V$4400,BO$1,FALSE)) -> -
A18: =A17+1 -> 13 | B18: =IF(VLOOKUP(ROUND(CONCATENATE($A18,B$2),0),'Cadastro dos Padrões'!$A$2:$V$4400,B$1,FALSE)="","-",VLOOKUP(ROUND(CONCATENATE($A18,B$2),0),'Cadastro dos Padrões'!$A$2:$V$4400,B$1,FALSE)) -> EL-194 | C18: =IF($B18="-","-",VLOOKUP(ROUND(CONCATENATE($A18,C$2),0),'Cadastro dos Padrões'!$A$2:$V$4400,C$1,FALSE)) -> Higrômetro de Ponto de Orvalho | D18: =IF($B18="-","-",VLOOKUP(ROUND(CONCATENATE($A18,D$2),0),'Cadastro dos Padrões'!$A$2:$V$4400,D$1,FALSE)) -> - | E18: =IF($B18="-","-",VLOOKUP(ROUND(CONCATENATE($A18,E$2),0),'Cadastro dos Padrões'!$A$2:$V$4400,E$1,FALSE)) -> Elus | F18: =IF($B18="-","-",VLOOKUP(ROUND(CONCATENATE($A18,F$2),0),'Cadastro dos Padrões'!$A$2:$V$4400,F$1,FALSE)) -> RBC - CAL 0439 | G18: =IF($B18="-","-",VLOOKUP(ROUND(CONCATENATE($A18,G$2),0),'Cadastro dos Padrões'!$A$2:$V$4400,G$1,FALSE)) -> R0124/22 | H18: =IF($B18="-","-",VLOOKUP(ROUND(CONCATENATE($A18,H$2),0),'Cadastro dos Padrões'!$A$2:$V$4400,H$1,FALSE)) -> 44607 | I18: =IF($B18="-","-",VLOOKUP(ROUND(CONCATENATE($A18,I$2),0),'Cadastro dos Padrões'!$A$2:$V$4400,I$1,FALSE)) -> 44985 | J18: =IF($B18="-","-",VLOOKUP(ROUND(CONCATENATE($A18,J$2),0),'Cadastro dos Padrões'!$A$2:$V$4400,J$1,FALSE)) -> °CTd/f | ... AA18: =IF($B18="-","-",VLOOKUP(ROUND(CONCATENATE($A18,AA$2),0),'Cadastro dos Padrões'!$A$2:$V$4400,AA$1,FALSE)) -> -1.5951149 | AB18: =IF(VLOOKUP(ROUND(CONCATENATE($A18,AB$2),0),'Cadastro dos Padrões'!$A$2:$V$4400,AB$1,FALSE)="","-",VLOOKUP(ROUND(CONCATENATE($A18,AB$2),0),'Cadastro dos Padrões'!$A$2:$V$4400,AB$1,FALSE)) -> -60 | AC18: =IF(VLOOKUP(ROUND(CONCATENATE($A18,AC$2),0),'Cadastro dos Padrões'!$A$2:$V$4400,AC$1,FALSE)="","-",VLOOKUP(ROUND(CONCATENATE($A18,AC$2),0),'Cadastro dos Padrões'!$A$2:$V$4400,AC$1,FALSE)) -> 0.28 | AD18: =IF(VLOOKUP(ROUND(CONCATENATE($A18,AD$2),0),'Cadastro dos Padrões'!$A$2:$V$4400,AD$1,FALSE)="","-",VLOOKUP(ROUND(CONCATENATE($A18,AD$2),0),'Cadastro dos Padrões'!$A$2:$V$4400,AD$1,FALSE)) -> 2 | AE18: =IF(VLOOKUP(ROUND(CONCATENATE($A18,AE$2),0),'Cadastro dos Padrões'!$A$2:$V$4400,AE$1,FALSE)="","-",VLOOKUP(ROUND(CONCATENATE($A18,AE$2),0),'Cadastro dos Padrões'!$A$2:$V$4400,AE$1,FALSE)) -> 1000000 | AF18: =IF(VLOOKUP(ROUND(CONCATENATE($A18,AF$2),0),'Cadastro dos Padrões'!$A$2:$V$4400,AF$1,FALSE)="","-",VLOOKUP(ROUND(CONCATENATE($A18,AF$2),0),'Cadastro dos Padrões'!$A$2:$V$4400,AF$1,FALSE)) -> -50 | AG18: =IF(VLOOKUP(ROUND(CONCATENATE($A18,AG$2),0),'Cadastro dos Padrões'!$A$2:$V$4400,AG$1,FALSE)="","-",VLOOKUP(ROUND(CONCATENATE($A18,AG$2),0),'Cadastro dos Padrões'!$A$2:$V$4400,AG$1,FALSE)) -> 0.28 | AH18: =IF(VLOOKUP(ROUND(CONCATENATE($A18,AH$2),0),'Cadastro dos Padrões'!$A$2:$V$4400,AH$1,FALSE)="","-",VLOOKUP(ROUND(CONCATENATE($A18,AH$2),0),'Cadastro dos Padrões'!$A$2:$V$4400,AH$1,FALSE)) -> 2 | AI18: =IF(VLOOKUP(ROUND(CONCATENATE($A18,AI$2),0),'Cadastro dos Padrões'!$A$2:$V$4400,AI$1,FALSE)="","-",VLOOKUP(ROUND(CONCATENATE($A18,AI$2),0),'Cadastro dos Padrões'!$A$2:$V$4400,AI$1,FALSE)) -> 1000000 | ... BO18: =IF(VLOOKUP(ROUND(CONCATENATE($A18,BO$2),0),'Cadastro dos Padrões'!$A$2:$V$4400,BO$1,FALSE)="","-",VLOOKUP(ROUND(CONCATENATE($A18,BO$2),0),'Cadastro dos Padrões'!$A$2:$V$4400,BO$1,FALSE)) -> -
... A105: =A104+1 -> 100 | B105: =IF(VLOOKUP(ROUND(CONCATENATE($A105,B$2),0),'Cadastro dos Padrões'!$A$2:$V$4400,B$1,FALSE)="","-",VLOOKUP(ROUND(CONCATENATE($A105,B$2),0),'Cadastro dos Padrões'!$A$2:$V$4400,B$1,FALSE)) -> - | C105: =IF($B105="-","-",VLOOKUP(ROUND(CONCATENATE($A105,C$2),0),'Cadastro dos Padrões'!$A$2:$V$4400,C$1,FALSE)) -> - | D105: =IF($B105="-","-",VLOOKUP(ROUND(CONCATENATE($A105,D$2),0),'Cadastro dos Padrões'!$A$2:$V$4400,D$1,FALSE)) -> - | E105: =IF($B105="-","-",VLOOKUP(ROUND(CONCATENATE($A105,E$2),0),'Cadastro dos Padrões'!$A$2:$V$4400,E$1,FALSE)) -> - | F105: =IF($B105="-","-",VLOOKUP(ROUND(CONCATENATE($A105,F$2),0),'Cadastro dos Padrões'!$A$2:$V$4400,F$1,FALSE)) -> - | G105: =IF($B105="-","-",VLOOKUP(ROUND(CONCATENATE($A105,G$2),0),'Cadastro dos Padrões'!$A$2:$V$4400,G$1,FALSE)) -> - | H105: =IF($B105="-","-",VLOOKUP(ROUND(CONCATENATE($A105,H$2),0),'Cadastro dos Padrões'!$A$2:$V$4400,H$1,FALSE)) -> - | I105: =IF($B105="-","-",VLOOKUP(ROUND(CONCATENATE($A105,I$2),0),'Cadastro dos Padrões'!$A$2:$V$4400,I$1,FALSE)) -> - | J105: =IF($B105="-","-",VLOOKUP(ROUND(CONCATENATE($A105,J$2),0),'Cadastro dos Padrões'!$A$2:$V$4400,J$1,FALSE)) -> - | ... AA105: =IF($B105="-","-",VLOOKUP(ROUND(CONCATENATE($A105,AA$2),0),'Cadastro dos Padrões'!$A$2:$V$4400,AA$1,FALSE)) -> - | AB105: =IF(VLOOKUP(ROUND(CONCATENATE($A105,AB$2),0),'Cadastro dos Padrões'!$A$2:$V$4400,AB$1,FALSE)="","-",VLOOKUP(ROUND(CONCATENATE($A105,AB$2),0),'Cadastro dos Padrões'!$A$2:$V$4400,AB$1,FALSE)) -> - | AC105: =IF(VLOOKUP(ROUND(CONCATENATE($A105,AC$2),0),'Cadastro dos Padrões'!$A$2:$V$4400,AC$1,FALSE)="","-",VLOOKUP(ROUND(CONCATENATE($A105,AC$2),0),'Cadastro dos Padrões'!$A$2:$V$4400,AC$1,FALSE)) -> - | AD105: =IF(VLOOKUP(ROUND(CONCATENATE($A105,AD$2),0),'Cadastro dos Padrões'!$A$2:$V$4400,AD$1,FALSE)="","-",VLOOKUP(ROUND(CONCATENATE($A105,AD$2),0),'Cadastro dos Padrões'!$A$2:$V$4400,AD$1,FALSE)) -> - | AE105: =IF(VLOOKUP(ROUND(CONCATENATE($A105,AE$2),0),'Cadastro dos Padrões'!$A$2:$V$4400,AE$1,FALSE)="","-",VLOOKUP(ROUND(CONCATENATE($A105,AE$2),0),'Cadastro dos Padrões'!$A$2:$V$4400,AE$1,FALSE)) -> - | AF105: =IF(VLOOKUP(ROUND(CONCATENATE($A105,AF$2),0),'Cadastro dos Padrões'!$A$2:$V$4400,AF$1,FALSE)="","-",VLOOKUP(ROUND(CONCATENATE($A105,AF$2),0),'Cadastro dos Padrões'!$A$2:$V$4400,AF$1,FALSE)) -> - | AG105: =IF(VLOOKUP(ROUND(CONCATENATE($A105,AG$2),0),'Cadastro dos Padrões'!$A$2:$V$4400,AG$1,FALSE)="","-",VLOOKUP(ROUND(CONCATENATE($A105,AG$2),0),'Cadastro dos Padrões'!$A$2:$V$4400,AG$1,FALSE)) -> - | AH105: =IF(VLOOKUP(ROUND(CONCATENATE($A105,AH$2),0),'Cadastro dos Padrões'!$A$2:$V$4400,AH$1,FALSE)="","-",VLOOKUP(ROUND(CONCATENATE($A105,AH$2),0),'Cadastro dos Padrões'!$A$2:$V$4400,AH$1,FALSE)) -> - | AI105: =IF(VLOOKUP(ROUND(CONCATENATE($A105,AI$2),0),'Cadastro dos Padrões'!$A$2:$V$4400,AI$1,FALSE)="","-",VLOOKUP(ROUND(CONCATENATE($A105,AI$2),0),'Cadastro dos Padrões'!$A$2:$V$4400,AI$1,FALSE)) -> - | ... BO105: =IF(VLOOKUP(ROUND(CONCATENATE($A105,BO$2),0),'Cadastro dos Padrões'!$A$2:$V$4400,BO$1,FALSE)="","-",VLOOKUP(ROUND(CONCATENATE($A105,BO$2),0),'Cadastro dos Padrões'!$A$2:$V$4400,BO$1,FALSE)) -> -
A106: 1 | B106: =A106+1 -> 2 | C106: =B106+1 -> 3 | D106: =C106+1 -> 4 | E106: =D106+1 -> 5 | F106: =E106+1 -> 6 | G106: =F106+1 -> 7 | H106: =G106+1 -> 8 | I106: =H106+1 -> 9 | ... BO106: =BN106+1 -> 67

Sheet Cadastro dos Padrões
A1: 1 | B1: =A1+1 -> 2 | C1: =B1+1 -> 3 | D1: =C1+1 -> 4 | E1: =D1+1 -> 5 | F1: =E1+1 -> 6 | G1: =F1+1 -> 7 | H1: =G1+1 -> 8 | I1: =H1+1 -> 9 | ... V1: =U1+1 -> 22
A2: =ROUND(CONCATENATE(U2,V2),0) -> 1201 | B2: Padrão : | D2: Termohigrômetro Digital | U2: 1 | V2: 201
A3: =ROUND(CONCATENATE(U3,V3),0) -> 1202 | B3: Temperatura da Calibração : | D3: 20 | E3: °C | U3: =U2 -> 1 | V3: =V2+1 -> 202 | X3: %ur
A4: =ROUND(CONCATENATE(U4,V4),0) -> 1203 | B4: Identificação : | D4: X.TH.LV-001 | K4: X8 | L4: X7 | M4: X6 | N4: X5 | O4: X4 | P4: X3 | Q4: X2 | R4: X1 | S4: X0 | U4: =U3 -> 1 | V4: =V3+1 -> 203 | X4: °CTd
A5: =ROUND(CONCATENATE(U5,V5),0) -> 1204 | B5: Orgão Calibrador : | D5: Elus | J5: =COUNTA(B18:B27) -> 6 | K5: =IF(L5-1<2,0,L5-1) -> 0 | L5: =IF(M5-1<2,0,M5-1) -> 0 | M5: =IF(N5-1<2,0,N5-1) -> 0 | N5: =IF(O5-1<2,0,O5-1) -> 0 | O5: =IF(P5-1<2,0,P5-1) -> 2 | P5: =IF(Q5-1<2,0,Q5-1) -> 3 | Q5: =IF(R5-1<2,0,R5-1) -> 4 | R5: =IF(S5-1<2,0,S5-1) -> 5 | S5: =J5 -> 6 | U5: =U4 -> 1 | V5: =V4+1 -> 204 | X5: °CTd/f
A6: =ROUND(CONCATENATE(U6,V6),0) -> 1205 | B6: Rastreabilidade : | D6: RBC - CAL 0439 | J6: =CONCATENATE(J5,1) -> 61 | K6: =IF(K5=0,0,VLOOKUP(J6,J10:S40,K5,FALSE)) -> 0 | L6: =IF(L5=0,0,VLOOKUP(J6,J10:S40,L5,FALSE)) -> 0 | M6: =IF(M5=0,0,VLOOKUP(J6,J10:S40,M5,FALSE)) -> 0 | N6: =IF(N5=0,0,VLOOKUP(J6,J10:S40,N5,FALSE)) -> 0 | O6: =IF(O5=0,0,VLOOKUP(J6,J10:S40,O5,FALSE)) -> -3.2655712e-07 | P6: =IF(P5=0,0,VLOOKUP(J6,J10:S40,P5,FALSE)) -> 6.0579676e-05 | Q6: =IF(Q5=0,0,VLOOKUP(J6,J10:S40,Q5,FALSE)) -> -0.0037173889 | R6: =IF(R5=0,0,VLOOKUP(J6,J10:S40,R5,FALSE)) -> 1.0702837 | S6: =IF(S5=0,0,VLOOKUP(J6,J10:S40,S5,FALSE)) -> -0.14499577 | U6: =U5 -> 1 | V6: =V5+1 -> 205
A7: =ROUND(CONCATENATE(U7,V7),0) -> 1206 | B7: N° do certificado : | D7: E0643A/25 | J7: =CONCATENATE(J5,2) -> 62 | K7: =IF(K5=0,0,VLOOKUP(J7,J10:S40,K5,FALSE)) -> 0 | L7: =IF(L5=0,0,VLOOKUP(J7,J10:S40,L5,FALSE)) -> 0 | M7: =IF(M5=0,0,VLOOKUP(J7,J10:S40,M5,FALSE)) -> 0 | N7: =IF(N5=0,0,VLOOKUP(J7,J10:S40,N5,FALSE)) -> 0 | O7: =IF(O5=0,0,VLOOKUP(J7,J10:S40,O5,FALSE)) -> 1.4325496e-08 | P7: =IF(P5=0,0,VLOOKUP(J7,J10:S40,P5,FALSE)) -> 2.9658369e-06 | Q7: =IF(Q5=0,0,VLOOKUP(J7,J10:S40,Q5,FALSE)) -> 0.00020607722 | R7: =IF(R5=0,0,VLOOKUP(J7,J10:S40,R5,FALSE)) -> 0.0053744503 | S7: =IF(S5=0,0,VLOOKUP(J7,J10:S40,S5,FALSE)) -> 0.039585232 | U7: =U6 -> 1 | V7: =V6+1 -> 206
A8: =ROUND(CONCATENATE(U8,V8),0) -> 1207 | B8: Data da Calibração : | D8: 45910 | J8: =CONCATENATE(J5,3) -> 63 | N8: Veff curva = | O8: =J5-2 -> 4 | P8: Residuo = | Q8: =VLOOKUP(J8,J10:S40,3,FALSE) -> 0.008987612 | R8: R² = | S8: =VLOOKUP(J8,J10:S40,2,FALSE) -> 0.99999998 | U8: =U7 -> 1 | V8: =V7+1 -> 207
A9: =ROUND(CONCATENATE(U9,V9),0) -> 1208 | B9: Vencimento da Calibração : | D9: 46295 | K9: 3 | L9: 3 | U9: =U8 -> 1 | V9: =V8+1 -> 208
A10: =ROUND(CONCATENATE(U10,V10),0) -> 1209 | B10: Divisão de escala : | D10: 0.01 | E10: Unidade calibrada : | H10: %ur | J10: =CONCATENATE(K9,1) -> 31 | K10: {=LINEST(B18:B20,C18:C20^{1},TRUE,TRUE)} -> 0.98424808 | L10: 0.41678369 | U10: =U9 -> 1 | V10: =V9+1 -> 209
A11: =ROUND(CONCATENATE(U11,V11),0) -> 1210 | B11: Faixa de medição : | D11: =MIN(B18:B27) -> 10 | E11: ~ | F11: =MAX(B18:B27) -> 90 | G11: =IF(H10="","",H10) -> %ur | J11: =CONCATENATE(K9,2) -> 32 | K11: 0.0019575744 | L11: 0.067207056 | U11: =U10 -> 1 | V11: =V10+1 -> 210
A12: =ROUND(CONCATENATE(U12,V12),0) -> 1211 | J12: =CONCATENATE(K9,3) -> 33 | K12: 0.99999604 | L12: 0.056254574 | U12: =U11 -> 1 | V12: =V11+1 -> 211
A13: =ROUND(CONCATENATE(U13,V13),0) -> 1212 | B13: Valores da Calibração Atual | G13: Calibração Anterior | K13: 4 | L13: 4 | M13: 4 | U13: =U12 -> 1 | V13: =V12+1 -> 212
A14: =ROUND(CONCATENATE(U14,V14),0) -> 1213 | B14: Certificado de calibração : | E14: =D7 -> E0643A/25 | G14: Certificado : | H14: E0369A/24 | J14: =CONCATENATE(K13,1) -> 41 | K14: {=LINEST(B18:B21,C18:C21^{1,2},TRUE,TRUE)} -> 9.0170812e-05 | L14: 0.97987517 | M14: 0.44910966 | U14: =U13 -> 1 | V14: =V13+1 -> 213
A15: =ROUND(CONCATENATE(U15,V15),0) -> 1214 | B15: Valor | C15: Leitura do | D15: Incerteza | F15: Grau | G15: Valor | H15: Leitura do | J15: =CONCATENATE(K13,2) -> 42 | K15: 0.00011619961 | L15: 0.0095578096 | M15: 0.1600285 | U15: =U14 -> 1 | V15: =V14+1 -> 214
A16: =ROUND(CONCATENATE(U16,V16),0) -> 1215 | B16: Referência | C16: Instrumento | D16: de Medição | E16: k | F16: de liberdade | G16: Referência | H16: Instrumento | J16: =CONCATENATE(K13,3) -> 43 | K16: 0.99999548 | L16: 0.095097274 | M16: #N/A | U16: =U15 -> 1 | V16: =V15+1 -> 215
A17: =ROUND(CONCATENATE(U17,V17),0) -> 1216 | B17: =H10 -> %ur | C17: =B17 -> %ur | D17: =C17 -> %ur | G17: =D17 -> %ur | H17: =G17 -> %ur | K17: 5 | L17: 5 | M17: 5 | N17: 5 | U17: =U16 -> 1 | V17: =V16+1 -> 216
A18: =ROUND(CONCATENATE(U18,V18),0) -> 1217 | B18: 10 | C18: 9.76 | D18: 0.81 | E18: 2 | F18: 1000000 | G18: 10 | H18: 9.45 | J18: =CONCATENATE(K17,1) -> 51 | K18: {=LINEST(B18:B22,C18:C22^{1,2,3},TRUE,TRUE)} -> 3.4931099e-07 | L18: -4.6379147e-06 | M18: 0.98488733 | N18: 0.39738654 | U18: =U17 -> 1 | V18: =V17+1 -> 217
A19: =ROUND(CONCATENATE(U19,V19),0) -> 1218 | B19: 30 | C19: 30.01 | D19: 0.94 | E19: 2 | F19: 1000000 | G19: 30.01 | H19: 29.66 | J19: =CONCATENATE(K17,2) -> 52 | K19: 5.5514214e-06 | L19: 0.000752145 | M19: 0.028926047 | N19: 0.28796205 | U19: =U18 -> 1 | V19: =V18+1 -> 218
A20: =ROUND(CONCATENATE(U20,V20),0) -> 1219 | B20: 50 | C20: 50.4 | D20: 1.1 | E20: 2 | F20: 1000000 | G20: 50 | H20: 50.5 | J20: =CONCATENATE(K17,3) -> 53 | K20: 0.99999629 | L20: 0.11032571 | M20: #N/A | N20: #N/A | U20: =U19 -> 1 | V20: =V19+1 -> 219
A21: =ROUND(CONCATENATE(U21,V21),0) -> 1220 | B21: 70 | C21: 70.5 | D21: 1.1 | E21: 2 | F21: 1000000 | G21: 70 | H21: 71.4 | K21: 6 | L21: 6 | M21: 6 | N21: 6 | O21: 6 | U21: =U20 -> 1 | V21: =V20+1 -> 220
A22: =ROUND(CONCATENATE(U22,V22),0) -> 1221 | B22: 80 | C22: 80.7 | D22: 1.2 | E22: 2 | F22: 1000000 | G22: 80 | H22: 82.1 | J22: =CONCATENATE(K21,1) -> 61 | K22: {=LINEST(B18:B23,C18:C23^{1,2,3,4},TRUE,TRUE)} -> -3.2655712e-07 | L22: 6.0579676e-05 | M22: -0.0037173889 | N22: 1.0702837 | O22: -0.14499577 | U22: =U21 -> 1 | V22: =V21+1 -> 221
A23: =ROUND(CONCATENATE(U23,V23),0) -> 1222 | B23: 90 | C23: 91.3 | D23: 1.2 | E23: 2 | F23: 1000000 | G23: 90 | H23: 92.8 | J23: =CONCATENATE(K21,2) -> 62 | K23: 1.4325496e-08 | L23: 2.9658369e-06 | M23: 0.00020607722 | N23: 0.0053744503 | O23: 0.039585232 | U23: =U22 -> 1 | V23: =V22+1 -> 222
A24: =ROUND(CONCATENATE(U24,V24),0) -> 1223 | J24: =CONCATENATE(K21,3) -> 63 | K24: 0.99999998 | L24: 0.008987612 | M24: #N/A | N24: #N/A | O24: #N/A | U24: =U23 -> 1 | V24: =V23+1 -> 223
A25: =ROUND(CONCATENATE(U25,V25),0) -> 1224 | K25: 7 | L25: 7 | M25: 7 | N25: 7 | O25: 7 | P25: 7 | U25: =U24 -> 1 | V25: =V24+1 -> 224
A26: =ROUND(CONCATENATE(U26,V26),0) -> 1225 | J26: =CONCATENATE(K25,1) -> 71 | K26: {=LINEST(B18:B24,C18:C24^{1,2,3,4,5},TRUE,TRUE)} -> #VALUE! | L26: #VALUE! | M26: #VALUE! | N26: #VALUE! | O26: #VALUE! | P26: #VALUE! | U26: =U25 -> 1 | V26: =V25+1 -> 225
A27: =ROUND(CONCATENATE(U27,V27),0) -> 1226 | J27: =CONCATENATE(K25,2) -> 72 | K27: #VALUE! | L27: #VALUE! | M27: #VALUE! | N27: #VALUE! | O27: #VALUE! | P27: #VALUE! | U27: =U26 -> 1 | V27: =V26+1 -> 226
A28: =ROUND(CONCATENATE(U28,V28),0) -> 1227 | J28: =CONCATENATE(K25,3) -> 73 | K28: #VALUE! | L28: #VALUE! | M28: #VALUE! | N28: #VALUE! | O28: #VALUE! | P28: #VALUE! | U28: =U27 -> 1 | V28: =V27+1 -> 227
A29: =ROUND(CONCATENATE(U29,V29),0) -> 1228 | B29: Observações (particularidades para utilização) | K29: 8 | L29: 8 | M29: 8 | N29: 8 | O29: 8 | P29: 8 | Q29: 8 | U29: =U28 -> 1 | V29: =V28+1 -> 228
A30: =ROUND(CONCATENATE(U30,V30),0) -> 1229 | J30: =CONCATENATE(K29,1) -> 81 | K30: {=LINEST(B18:B25,C18:C25^{1,2,3,4,5,6},TRUE,TRUE)} -> #VALUE! | L30: #VALUE! | M30: #VALUE! | N30: #VALUE! | O30: #VALUE! | P30: #VALUE! | Q30: #VALUE! | U30: =U29 -> 1 | V30: =V29+1 -> 229
A31: =ROUND(CONCATENATE(U31,V31),0) -> 1230 | J31: =CONCATENATE(K29,2) -> 82 | K31: #VALUE! | L31: #VALUE! | M31: #VALUE! | N31: #VALUE! | O31: #VALUE! | P31: #VALUE! | Q31: #VALUE! | U31: =U30 -> 1 | V31: =V30+1 -> 230
A32: =ROUND(CONCATENATE(U32,V32),0) -> 1231 | J32: =CONCATENATE(K29,3) -> 83 | K32: #VALUE! | L32: #VALUE! | M32: #VALUE! | N32: #VALUE! | O32: #VALUE! | P32: #VALUE! | Q32: #VALUE! | U32: =U31 -> 1 | V32: =V31+1 -> 231
A33: =ROUND(CONCATENATE(U33,V33),0) -> 1232 | B33: Erro Atual | C33: Erro Anterior | D33: Diferença | E33: Maior Deriva | K33: 9 | L33: 9 | M33: 9 | N33: 9 | O33: 9 | P33: 9 | Q33: 9 | R33: 9 | U33: =U32 -> 1 | V33: =V32+1 -> 232
A34: =ROUND(CONCATENATE(U34,V34),0) -> 1233 | B34: =C18-B18 -> -0.24 | C34: =H18-G18 -> -0.55 | D34: =C34-B34 -> -0.31 | E34: =IF(D9="","",MAX(F34,G34)) -> 1.5 | F34: =ABS(MIN(D34:D43)) -> 0.36 | G34: =ABS(MAX(D34:D43)) -> 1.5 | J34: =CONCATENATE(K33,1) -> 91 | K34: {=LINEST(B18:B26,C18:C26^{1,2,3,4,5,6,7},TRUE,TRUE)} -> #VALUE! | L34: #VALUE! | M34: #VALUE! | N34: #VALUE! | O34: #VALUE! | P34: #VALUE! | Q34: #VALUE! | R34: #VALUE! | U34: =U33 -> 1 | V34: =V33+1 -> 233
A35: =ROUND(CONCATENATE(U35,V35),0) -> 1234 | B35: =C19-B19 -> 0.01 | C35: =H19-G19 -> -0.35 | D35: =C35-B35 -> -0.36 | E35: Desvio Máximo | J35: =CONCATENATE(K33,2) -> 92 | K35: #VALUE! | L35: #VALUE! | M35: #VALUE! | N35: #VALUE! | O35: #VALUE! | P35: #VALUE! | Q35: #VALUE! | R35: #VALUE! | U35: =U34 -> 1 | V35: =V34+1 -> 234
A36: =ROUND(CONCATENATE(U36,V36),0) -> 1235 | B36: =C20-B20 -> 0.4 | C36: =H20-G20 -> 0.5 | D36: =C36-B36 -> 0.1 | E36: =IF(D9="","",MAX(F36,G36)) -> 1.3 | F36: =ABS(MIN(B34:B43)) -> 0.24 | G36: =ABS(MAX(B34:B43)) -> 1.3 | J36: =CONCATENATE(K33,3) -> 93 | K36: #VALUE! | L36: #VALUE! | M36: #VALUE! | N36: #VALUE! | O36: #VALUE! | P36: #VALUE! | Q36: #VALUE! | R36: #VALUE! | U36: =U35 -> 1 | V36: =V35+1 -> 235
A37: =ROUND(CONCATENATE(U37,V37),0) -> 1236 | B37: =C21-B21 -> 0.5 | C37: =H21-G21 -> 1.4 | D37: =C37-B37 -> 0.9 | E37: Maior incerteza (em unidade) | K37: 10 | L37: 10 | M37: 10 | N37: 10 | O37: 10 | P37: 10 | Q37: 10 | R37: 10 | S37: 10 | U37: =U36 -> 1 | V37: =V36+1 -> 236
